Workbook

Sheet Compare_ACS_5Yr_1Yr
A1: Share of Workers Who Worked At Home (Compare 5-Year & 1-Year ACS)
AA5: Share of Workers that Worked at Home | AM5: Margin of Error - Worked at Home | AY5: 5-Year ACS
AA6: Wasatch Front | AM6: Wasatch Front | AY6: Share of Workers that Worked at Home
AB7: 2010 | AC7: 2011 | AD7: 2012 | AE7: 2013 | AF7: 2014 | AG7: 2015 | AH7: 2016 | AI7: 2017 | AJ7: 2018 | AK7: 2019 | AN7: 2010 | AO7: 2011 | AP7: 2012 | AQ7: 2013 | AR7: 2014 | AS7: 2015 | AT7: 2016 | AU7: 2017 | AV7: 2018 | AW7: 2019 | AZ7: 2010 | BA7: 2011 | BB7: 2012 | BC7: 2013 | BD7: 2014 | BE7: 2015 | BF7: 2016 | BG7: 2017 | BH7: 2018 | BI7: 2019
AA8: 5-Year ACS | AB8: =VLOOKUP($AA6, $AY$8:$BI$14, COLUMNS($AY$7:AZ$7), FALSE) -> 0.046040703 | AC8: =VLOOKUP($AA6, $AY$8:$BI$14, COLUMNS($AY$7:BA$7), FALSE) -> 0.046933978 | AD8: =VLOOKUP($AA6, $AY$8:$BI$14, COLUMNS($AY$7:BB$7), FALSE) -> 0.045984966 | AE8: =VLOOKUP($AA6, $AY$8:$BI$14, COLUMNS($AY$7:BC$7), FALSE) -> 0.047455799 | AF8: =VLOOKUP($AA6, $AY$8:$BI$14, COLUMNS($AY$7:BD$7), FALSE) -> 0.048848668 | AG8: =VLOOKUP($AA6, $AY$8:$BI$14, COLUMNS($AY$7:BE$7), FALSE) -> 0.051658859 | AH8: =VLOOKUP($AA6, $AY$8:$BI$14, COLUMNS($AY$7:BF$7), FALSE) -> 0.053139977 | AI8: =VLOOKUP($AA6, $AY$8:$BI$14, COLUMNS($AY$7:BG$7), FALSE) -> 0.057194228 | ... AK8: =VLOOKUP($AA6, $AY$8:$BI$14, COLUMNS($AY$7:BI$7), FALSE) -> 0.06316136 | AM8: 5-Year ACS | AN8: =VLOOKUP($AM6, $AY$18:$BI$24, COLUMNS($AY$17:AZ$17), FALSE) -> 0.056180297 | AO8: =VLOOKUP($AM6, $AY$18:$BI$24, COLUMNS($AY$17:BA$17), FALSE) -> 0.060317745 | AP8: =VLOOKUP($AM6, $AY$18:$BI$24, COLUMNS($AY$17:BB$17), FALSE) -> 0.060490512 | AQ8: =VLOOKUP($AM6, $AY$18:$BI$24, COLUMNS($AY$17:BC$17), FALSE) -> 0.057796573 | AR8: =VLOOKUP($AM6, $AY$18:$BI$24, COLUMNS($AY$17:BD$17), FALSE) -> 0.055966144 | AS8: =VLOOKUP($AM6, $AY$18:$BI$24, COLUMNS($AY$17:BE$17), FALSE) -> 0.061544292 | AT8: =VLOOKUP($AM6, $AY$18:$BI$24, COLUMNS($AY$17:BF$17), FALSE) -> 0.053258145 | AU8: =VLOOKUP($AM6, $AY$18:$BI$24, COLUMNS($AY$17:BG$17), FALSE) -> 0.051783864 | ... AW8: =VLOOKUP($AM6, $AY$18:$BI$24, COLUMNS($AY$17:BI$17), FALSE) -> 0.054222947 | AY8: Wasatch Front | AZ8: =Summary!BG7 -> 0.046040703 | BA8: =Summary!BH7 -> 0.046933978 | BB8: =Summary!BI7 -> 0.045984966 | BC8: =Summary!BJ7 -> 0.047455799 | BD8: =Summary!BK7 -> 0.048848668 | BE8: =Summary!BL7 -> 0.051658859 | BF8: =Summary!BM7 -> 0.053139977 | BG8: =Summary!BN7 -> 0.057194228 | ... BI8: =Summary!BP7 -> 0.06316136
AA9: 1-Year ACS | AB9: =VLOOKUP($AA6, $AY$30:$BI$36, COLUMNS($AY$29:AZ$29), FALSE) -> 0.042651351 | AC9: =VLOOKUP($AA6, $AY$30:$BI$36, COLUMNS($AY$29:BA$29), FALSE) -> 0.047216212 | AD9: =VLOOKUP($AA6, $AY$30:$BI$36, COLUMNS($AY$29:BB$29), FALSE) -> 0.047348698 | AE9: =VLOOKUP($AA6, $AY$30:$BI$36, COLUMNS($AY$29:BC$29), FALSE) -> 0.051169945 | AF9: =VLOOKUP($AA6, $AY$30:$BI$36, COLUMNS($AY$29:BD$29), FALSE) -> 0.056006562 | AG9: =VLOOKUP($AA6, $AY$30:$BI$36, COLUMNS($AY$29:BE$29), FALSE) -> 0.056594397 | AH9: =VLOOKUP($AA6, $AY$30:$BI$36, COLUMNS($AY$29:BF$29), FALSE) -> 0.057802638 | AI9: =VLOOKUP($AA6, $AY$30:$BI$36, COLUMNS($AY$29:BG$29), FALSE) -> 0.066791542 | ... AK9: =VLOOKUP($AA6, $AY$30:$BI$36, COLUMNS($AY$29:BI$29), FALSE) -> 0.070460042 | AM9: 1-Year ACS | AN9: =VLOOKUP($AM6, $AY$40:$BI$46, COLUMNS($AY$39:AZ$39), FALSE) -> 0.14514908 | AO9: =VLOOKUP($AM6, $AY$40:$BI$46, COLUMNS($AY$39:BA$39), FALSE) -> 0.16064697 | AP9: =VLOOKUP($AM6, $AY$40:$BI$46, COLUMNS($AY$39:BB$39), FALSE) -> 0.12923194 | AQ9: =VLOOKUP($AM6, $AY$40:$BI$46, COLUMNS($AY$39:BC$39), FALSE) -> 0.12939356 | AR9: =VLOOKUP($AM6, $AY$40:$BI$46, COLUMNS($AY$39:BD$39), FALSE) -> 0.11763703 | AS9: =VLOOKUP($AM6, $AY$40:$BI$46, COLUMNS($AY$39:BE$39), FALSE) -> 0.12220369 | AT9: =VLOOKUP($AM6, $AY$40:$BI$46, COLUMNS($AY$39:BF$39), FALSE) -> 0.11699057 | AU9: =VLOOKUP($AM6, $AY$40:$BI$46, COLUMNS($AY$39:BG$39), FALSE) -> 0.12476978 | ... AW9: =VLOOKUP($AM6, $AY$40:$BI$46, COLUMNS($AY$39:BI$39), FALSE) -> 0.11396312 | AY9: Weber | AZ9: =Summary!BG8 -> 0.031489478 | BA9: =Summary!BH8 -> 0.03423657 | BB9: =Summary!BI8 -> 0.032300393 | BC9: =Summary!BJ8 -> 0.033006032 | BD9: =Summary!BK8 -> 0.035722947 | BE9: =Summary!BL8 -> 0.041130466 | BF9: =Summary!BM8 -> 0.041244982 | BG9: =Summary!BN8 -> 0.046252189 | ... BI9: =Summary!BP8 -> 0.054330715
AA10: Difference | AB10: =AB9-AB8 -> -0.0033893514 | AC10: =AC9-AC8 -> 0.00028223355 | AD10: =AD9-AD8 -> 0.0013637322 | AE10: =AE9-AE8 -> 0.0037141462 | AF10: =AF9-AF8 -> 0.0071578938 | AG10: =AG9-AG8 -> 0.0049355379 | AH10: =AH9-AH8 -> 0.0046626607 | AI10: =AI9-AI8 -> 0.0095973146 | ... AK10: =AK9-AK8 -> 0.007298682 | AM10: Difference | AN10: =AN9-AN8 -> 0.088968787 | AO10: =AO9-AO8 -> 0.10032923 | AP10: =AP9-AP8 -> 0.068741423 | AQ10: =AQ9-AQ8 -> 0.071596985 | AR10: =AR9-AR8 -> 0.061670886 | AS10: =AS9-AS8 -> 0.060659397 | AT10: =AT9-AT8 -> 0.063732423 | AU10: =AU9-AU8 -> 0.072985915 | ... AW10: =AW9-AW8 -> 0.059740175 | AY10: Davis | AZ10: =Summary!BG9 -> 0.044575681 | BA10: =Summary!BH9 -> 0.047153855 | BB10: =Summary!BI9 -> 0.045106261 | BC10: =Summary!BJ9 -> 0.047290962 | BD10: =Summary!BK9 -> 0.049455062 | BE10: =Summary!BL9 -> 0.052148088 | BF10: =Summary!BM9 -> 0.05199921 | BG10: =Summary!BN9 -> 0.055483498 | ... BI10: =Summary!BP9 -> 0.058858596
AA11: % Difference | AB11: =AB10/AB8 -> -0.073616413 | AC11: =AC10/AC8 -> 0.0060134164 | AD11: =AD10/AD8 -> 0.029656045 | AE11: =AE10/AE8 -> 0.078265381 | AF11: =AF10/AF8 -> 0.14653202 | AG11: =AG10/AG8 -> 0.095540979 | AH11: =AH10/AH8 -> 0.087742994 | AI11: =AI10/AI8 -> 0.16780215 | ... AK11: =AK10/AK8 -> 0.11555613 | AM11: % Difference | AN11: =AN10/AN8 -> 1.5836297 | AO11: =AO10/AO8 -> 1.6633451 | AP11: =AP10/AP8 -> 1.1364001 | AQ11: =AQ10/AQ8 -> 1.2387756 | AR11: =AR10/AR8 -> 1.101932 | AS11: =AS10/AS8 -> 0.98562183 | AT11: =AT10/AT8 -> 1.19667 | AU11: =AU10/AU8 -> 1.4094335 | ... AW11: =AW10/AW8 -> 1.1017508 | AY11: Salt Lake | AZ11: =Summary!BG10 -> 0.042931884 | BA11: =Summary!BH10 -> 0.043507812 | BB11: =Summary!BI10 -> 0.043455383 | BC11: =Summary!BJ10 -> 0.04479927 | BD11: =Summary!BK10 -> 0.046272278 | BE11: =Summary!BL10 -> 0.049433922 | BF11: =Summary!BM10 -> 0.051318901 | BG11: =Summary!BN10 -> 0.055654606 | ... BI11: =Summary!BP10 -> 0.06205852
AY12: Utah | AZ12: =Summary!BG11 -> 0.061534608 | BA12: =Summary!BH11 -> 0.060800768 | BB12: =Summary!BI11 -> 0.058871541 | BC12: =Summary!BJ11 -> 0.060458232 | BD12: =Summary!BK11 -> 0.06048057 | BE12: =Summary!BL11 -> 0.061172555 | BF12: =Summary!BM11 -> 0.063242199 | BG12: =Summary!BN11 -> 0.066567673 | ... BI12: =Summary!BP11 -> 0.071920744
AA13: Weber | AM13: Weber | AY13: State of Utah | AZ13: =Summary!BG12 -> 0.048247967 | BA13: =Summary!BH12 -> 0.048146251 | BB13: =Summary!BI12 -> 0.047170408 | BC13: =Summary!BJ12 -> 0.048242532 | BD13: =Summary!BK12 -> 0.048818053 | BE13: =Summary!BL12 -> 0.051301419 | BF13: =Summary!BM12 -> 0.053654326 | BG13: =Summary!BN12 -> 0.057712073 | ... BI13: =Summary!BP12 -> 0.065641119
AB14: 2010 | AC14: 2011 | AD14: 2012 | AE14: 2013 | AF14: 2014 | AG14: 2015 | AH14: 2016 | AI14: 2017 | AJ14: 2018 | AK14: 2019 | AN14: 2010 | AO14: 2011 | AP14: 2012 | AQ14: 2013 | AR14: 2014 | AS14: 2015 | AT14: 2016 | AU14: 2017 | AV14: 2018 | AW14: 2019 | AY14: USA | AZ14: =Summary!BG13 -> 0.041360975 | BA14: =Summary!BH13 -> 0.042224129 | BB14: =Summary!BI13 -> 0.042729813 | BC14: =Summary!BJ13 -> 0.043254384 | BD14: =Summary!BK13 -> 0.043665739 | BE14: =Summary!BL13 -> 0.044232594 | BF14: =Summary!BM13 -> 0.045672811 | BG14: =Summary!BN13 -> 0.047344292 | ... BI14: =Summary!BP13 -> 0.051713986
AA15: 5-Year ACS | AB15: =VLOOKUP($AA13, $AY$8:$BI$14, COLUMNS($AY$7:AZ$7), FALSE) -> 0.031489478 | AC15: =VLOOKUP($AA13, $AY$8:$BI$14, COLUMNS($AY$7:BA$7), FALSE) -> 0.03423657 | AD15: =VLOOKUP($AA13, $AY$8:$BI$14, COLUMNS($AY$7:BB$7), FALSE) -> 0.032300393 | AE15: =VLOOKUP($AA13, $AY$8:$BI$14, COLUMNS($AY$7:BC$7), FALSE) -> 0.033006032 | AF15: =VLOOKUP($AA13, $AY$8:$BI$14, COLUMNS($AY$7:BD$7), FALSE) -> 0.035722947 | AG15: =VLOOKUP($AA13, $AY$8:$BI$14, COLUMNS($AY$7:BE$7), FALSE) -> 0.041130466 | AH15: =VLOOKUP($AA13, $AY$8:$BI$14, COLUMNS($AY$7:BF$7), FALSE) -> 0.041244982 | AI15: =VLOOKUP($AA13, $AY$8:$BI$14, COLUMNS($AY$7:BG$7), FALSE) -> 0.046252189 | ... AK15: =VLOOKUP($AA13, $AY$8:$BI$14, COLUMNS($AY$7:BI$7), FALSE) -> 0.054330715 | AM15: 5-Year ACS | AN15: =VLOOKUP($AM13, $AY$18:$BI$24, COLUMNS($AY$17:AZ$17), FALSE) -> 0.12384188 | AO15: =VLOOKUP($AM13, $AY$18:$BI$24, COLUMNS($AY$17:BA$17), FALSE) -> 0.1062447 | AP15: =VLOOKUP($AM13, $AY$18:$BI$24, COLUMNS($AY$17:BB$17), FALSE) -> 0.11775096 | AQ15: =VLOOKUP($AM13, $AY$18:$BI$24, COLUMNS($AY$17:BC$17), FALSE) -> 0.10060536 | AR15: =VLOOKUP($AM13, $AY$18:$BI$24, COLUMNS($AY$17:BD$17), FALSE) -> 0.10391645 | AS15: =VLOOKUP($AM13, $AY$18:$BI$24, COLUMNS($AY$17:BE$17), FALSE) -> 0.11892497 | AT15: =VLOOKUP($AM13, $AY$18:$BI$24, COLUMNS($AY$17:BF$17), FALSE) -> 0.094056172 | AU15: =VLOOKUP($AM13, $AY$18:$BI$24, COLUMNS($AY$17:BG$17), FALSE) -> 0.093335858 | ... AW15: =VLOOKUP($AM13, $AY$18:$BI$24, COLUMNS($AY$17:BI$17), FALSE) -> 0.098149272
AA16: 1-Year ACS | AB16: =VLOOKUP($AA13, $AY$30:$BI$36, COLUMNS($AY$29:AZ$29), FALSE) -> 0.028318247 | AC16: =VLOOKUP($AA13, $AY$30:$BI$36, COLUMNS($AY$29:BA$29), FALSE) -> 0.038284382 | AD16: =VLOOKUP($AA13, $AY$30:$BI$36, COLUMNS($AY$29:BB$29), FALSE) -> 0.03045163 | AE16: =VLOOKUP($AA13, $AY$30:$BI$36, COLUMNS($AY$29:BC$29), FALSE) -> 0.036499328 | AF16: =VLOOKUP($AA13, $AY$30:$BI$36, COLUMNS($AY$29:BD$29), FALSE) -> 0.042279542 | AG16: =VLOOKUP($AA13, $AY$30:$BI$36, COLUMNS($AY$29:BE$29), FALSE) -> 0.052443014 | AH16: =VLOOKUP($AA13, $AY$30:$BI$36, COLUMNS($AY$29:BF$29), FALSE) -> 0.039414424 | AI16: =VLOOKUP($AA13, $AY$30:$BI$36, COLUMNS($AY$29:BG$29), FALSE) -> 0.051506727 | ... AK16: =VLOOKUP($AA13, $AY$30:$BI$36, COLUMNS($AY$29:BI$29), FALSE) -> 0.072031505 | AM16: 1-Year ACS | AN16: =VLOOKUP($AM13, $AY$40:$BI$46, COLUMNS($AY$39:AZ$39), FALSE) -> 0.29239569 | AO16: =VLOOKUP($AM13, $AY$40:$BI$46, COLUMNS($AY$39:BA$39), FALSE) -> 0.25748804 | AP16: =VLOOKUP($AM13, $AY$40:$BI$46, COLUMNS($AY$39:BB$39), FALSE) -> 0.24261796 | AQ16: =VLOOKUP($AM13, $AY$40:$BI$46, COLUMNS($AY$39:BC$39), FALSE) -> 0.24460249 | AR16: =VLOOKUP($AM13, $AY$40:$BI$46, COLUMNS($AY$39:BD$39), FALSE) -> 0.23907563 | AS16: =VLOOKUP($AM13, $AY$40:$BI$46, COLUMNS($AY$39:BE$39), FALSE) -> 0.1991863 | AT16: =VLOOKUP($AM13, $AY$40:$BI$46, COLUMNS($AY$39:BF$39), FALSE) -> 0.22983521 | AU16: =VLOOKUP($AM13, $AY$40:$BI$46, COLUMNS($AY$39:BG$39), FALSE) -> 0.22779116 | ... AW16: =VLOOKUP($AM13, $AY$40:$BI$46, COLUMNS($AY$39:BI$39), FALSE) -> 0.2147188 | AY16: Margin of Error - Workers that Worked at Home
AA17: Difference | AB17: =AB16-AB15 -> -0.0031712308 | AC17: =AC16-AC15 -> 0.0040478118 | AD17: =AD16-AD15 -> -0.0018487631 | AE17: =AE16-AE15 -> 0.0034932956 | AF17: =AF16-AF15 -> 0.0065565958 | AG17: =AG16-AG15 -> 0.011312548 | AH17: =AH16-AH15 -> -0.0018305584 | AI17: =AI16-AI15 -> 0.0052545378 | ... AK17: =AK16-AK15 -> 0.01770079 | AM17: Difference | AN17: =AN16-AN15 -> 0.16855382 | AO17: =AO16-AO15 -> 0.15124334 | AP17: =AP16-AP15 -> 0.124867 | AQ17: =AQ16-AQ15 -> 0.14399713 | AR17: =AR16-AR15 -> 0.13515918 | AS17: =AS16-AS15 -> 0.080261331 | AT17: =AT16-AT15 -> 0.13577904 | AU17: =AU16-AU15 -> 0.13445531 | ... AW17: =AW16-AW15 -> 0.11656952 | AZ17: 2010 | BA17: 2011 | BB17: 2012 | BC17: 2013 | BD17: 2014 | BE17: 2015 | BF17: 2016 | BG17: 2017 | BH17: 2018 | BI17: 2019
AA18: % Difference | AB18: =AB17/AB15 -> -0.10070763 | AC18: =AC17/AC15 -> 0.11823065 | AD18: =AD17/AD15 -> -0.05723655 | AE18: =AE17/AE15 -> 0.1058381 | AF18: =AF17/AF15 -> 0.18354017 | AG18: =AG17/AG15 -> 0.2750406 | AH18: =AH17/AH15 -> -0.044382572 | AI18: =AI17/AI15 -> 0.11360625 | ... AK18: =AK17/AK15 -> 0.32579711 | AM18: % Difference | AN18: =AN17/AN15 -> 1.3610405 | AO18: =AO17/AO15 -> 1.4235377 | AP18: =AP17/AP15 -> 1.060433 | AQ18: =AQ17/AQ15 -> 1.4313067 | AR18: =AR17/AR15 -> 1.3006524 | AS18: =AS17/AS15 -> 0.67489047 | AT18: =AT17/AT15 -> 1.4435952 | AU18: =AU17/AU15 -> 1.4405536 | ... AW18: =AW17/AW15 -> 1.1876759 | AY18: Wasatch Front | AZ18: =Summary!BT77 -> 0.056180297 | BA18: =Summary!BU77 -> 0.060317745 | BB18: =Summary!BV77 -> 0.060490512 | BC18: =Summary!BW77 -> 0.057796573 | BD18: =Summary!BX77 -> 0.055966144 | BE18: =Summary!BY77 -> 0.061544292 | BF18: =Summary!BZ77 -> 0.053258145 | BG18: =Summary!CA77 -> 0.051783864 | ... BI18: =Summary!CC77 -> 0.054222947
AY19: Weber | AZ19: =Summary!BT78 -> 0.12384188 | BA19: =Summary!BU78 -> 0.1062447 | BB19: =Summary!BV78 -> 0.11775096 | BC19: =Summary!BW78 -> 0.10060536 | BD19: =Summary!BX78 -> 0.10391645 | BE19: =Summary!BY78 -> 0.11892497 | BF19: =Summary!BZ78 -> 0.094056172 | BG19: =Summary!CA78 -> 0.093335858 | ... BI19: =Summary!CC78 -> 0.098149272
AA20: Davis | AM20: Davis | AY20: Davis | AZ20: =Summary!BT79 -> 0.065908331 | BA20: =Summary!BU79 -> 0.087662338 | BB20: =Summary!BV79 -> 0.080406801 | BC20: =Summary!BW79 -> 0.072243917 | BD20: =Summary!BX79 -> 0.071348156 | BE20: =Summary!BY79 -> 0.076624385 | BF20: =Summary!BZ79 -> 0.074360274 | BG20: =Summary!CA79 -> 0.076727231 | ... BI20: =Summary!CC79 -> 0.073480777
AB21: 2010 | AC21: 2011 | AD21: 2012 | AE21: 2013 | AF21: 2014 | AG21: 2015 | AH21: 2016 | AI21: 2017 | AJ21: 2018 | AK21: 2019 | AN21: 2010 | AO21: 2011 | AP21: 2012 | AQ21: 2013 | AR21: 2014 | AS21: 2015 | AT21: 2016 | AU21: 2017 | AV21: 2018 | AW21: 2019 | AY21: Salt Lake | AZ21: =Summary!BT80 -> 0.041286583 | BA21: =Summary!BU80 -> 0.042960759 | BB21: =Summary!BV80 -> 0.049953959 | BC21: =Summary!BW80 -> 0.048127158 | BD21: =Summary!BX80 -> 0.046210176 | BE21: =Summary!BY80 -> 0.049852699 | BF21: =Summary!BZ80 -> 0.045008448 | BG21: =Summary!CA80 -> 0.042487983 | ... BI21: =Summary!CC80 -> 0.045882971
AA22: 5-Year ACS | AB22: =VLOOKUP($AA20, $AY$8:$BI$14, COLUMNS($AY$7:AZ$7), FALSE) -> 0.044575681 | AC22: =VLOOKUP($AA20, $AY$8:$BI$14, COLUMNS($AY$7:BA$7), FALSE) -> 0.047153855 | AD22: =VLOOKUP($AA20, $AY$8:$BI$14, COLUMNS($AY$7:BB$7), FALSE) -> 0.045106261 | AE22: =VLOOKUP($AA20, $AY$8:$BI$14, COLUMNS($AY$7:BC$7), FALSE) -> 0.047290962 | AF22: =VLOOKUP($AA20, $AY$8:$BI$14, COLUMNS($AY$7:BD$7), FALSE) -> 0.049455062 | AG22: =VLOOKUP($AA20, $AY$8:$BI$14, COLUMNS($AY$7:BE$7), FALSE) -> 0.052148088 | AH22: =VLOOKUP($AA20, $AY$8:$BI$14, COLUMNS($AY$7:BF$7), FALSE) -> 0.05199921 | AI22: =VLOOKUP($AA20, $AY$8:$BI$14, COLUMNS($AY$7:BG$7), FALSE) -> 0.055483498 | ... AK22: =VLOOKUP($AA20, $AY$8:$BI$14, COLUMNS($AY$7:BI$7), FALSE) -> 0.058858596 | AM22: 5-Year ACS | AN22: =VLOOKUP($AM20, $AY$18:$BI$24, COLUMNS($AY$17:AZ$17), FALSE) -> 0.065908331 | AO22: =VLOOKUP($AM20, $AY$18:$BI$24, COLUMNS($AY$17:BA$17), FALSE) -> 0.087662338 | AP22: =VLOOKUP($AM20, $AY$18:$BI$24, COLUMNS($AY$17:BB$17), FALSE) -> 0.080406801 | AQ22: =VLOOKUP($AM20, $AY$18:$BI$24, COLUMNS($AY$17:BC$17), FALSE) -> 0.072243917 | AR22: =VLOOKUP($AM20, $AY$18:$BI$24, COLUMNS($AY$17:BD$17), FALSE) -> 0.071348156 | AS22: =VLOOKUP($AM20, $AY$18:$BI$24, COLUMNS($AY$17:BE$17), FALSE) -> 0.076624385 | AT22: =VLOOKUP($AM20, $AY$18:$BI$24, COLUMNS($AY$17:BF$17), FALSE) -> 0.074360274 | AU22: =VLOOKUP($AM20, $AY$18:$BI$24, COLUMNS($AY$17:BG$17), FALSE) -> 0.076727231 | ... AW22: =VLOOKUP($AM20, $AY$18:$BI$24, COLUMNS($AY$17:BI$17), FALSE) -> 0.073480777 | AY22: Utah | AZ22: =Summary!BT81 -> 0.059016907 | BA22: =Summary!BU81 -> 0.062916699 | BB22: =Summary!BV81 -> 0.053442801 | BC22: =Summary!BW81 -> 0.055833396 | BD22: =Summary!BX81 -> 0.051517136 | BE22: =Summary!BY81 -> 0.056897626 | BF22: =Summary!BZ81 -> 0.04525585 | BG22: =Summary!CA81 -> 0.043070717 | ... BI22: =Summary!CC81 -> 0.045463689
AA23: 1-Year ACS | AB23: =VLOOKUP($AA20, $AY$30:$BI$36, COLUMNS($AY$29:AZ$29), FALSE) -> 0.039490417 | AC23: =VLOOKUP($AA20, $AY$30:$BI$36, COLUMNS($AY$29:BA$29), FALSE) -> 0.047190329 | AD23: =VLOOKUP($AA20, $AY$30:$BI$36, COLUMNS($AY$29:BB$29), FALSE) -> 0.046062039 | AE23: =VLOOKUP($AA20, $AY$30:$BI$36, COLUMNS($AY$29:BC$29), FALSE) -> 0.045401095 | AF23: =VLOOKUP($AA20, $AY$30:$BI$36, COLUMNS($AY$29:BD$29), FALSE) -> 0.065840263 | AG23: =VLOOKUP($AA20, $AY$30:$BI$36, COLUMNS($AY$29:BE$29), FALSE) -> 0.059433135 | AH23: =VLOOKUP($AA20, $AY$30:$BI$36, COLUMNS($AY$29:BF$29), FALSE) -> 0.046643415 | AI23: =VLOOKUP($AA20, $AY$30:$BI$36, COLUMNS($AY$29:BG$29), FALSE) -> 0.067344885 | ... AK23: =VLOOKUP($AA20, $AY$30:$BI$36, COLUMNS($AY$29:BI$29), FALSE) -> 0.072788694 | AM23: 1-Year ACS | AN23: =VLOOKUP($AM20, $AY$40:$BI$46, COLUMNS($AY$39:AZ$39), FALSE) -> 0.1920904 | AO23: =VLOOKUP($AM20, $AY$40:$BI$46, COLUMNS($AY$39:BA$39), FALSE) -> 0.18988478 | AP23: =VLOOKUP($AM20, $AY$40:$BI$46, COLUMNS($AY$39:BB$39), FALSE) -> 0.20880597 | AQ23: =VLOOKUP($AM20, $AY$40:$BI$46, COLUMNS($AY$39:BC$39), FALSE) -> 0.16671628 | AR23: =VLOOKUP($AM20, $AY$40:$BI$46, COLUMNS($AY$39:BD$39), FALSE) -> 0.19061166 | AS23: =VLOOKUP($AM20, $AY$40:$BI$46, COLUMNS($AY$39:BE$39), FALSE) -> 0.16666667 | AT23: =VLOOKUP($AM20, $AY$40:$BI$46, COLUMNS($AY$39:BF$39), FALSE) -> 0.18131286 | AU23: =VLOOKUP($AM20, $AY$40:$BI$46, COLUMNS($AY$39:BG$39), FALSE) -> 0.18311127 | ... AW23: =VLOOKUP($AM20, $AY$40:$BI$46, COLUMNS($AY$39:BI$39), FALSE) -> 0.16476243 | AY23: State of Utah | AZ23: =Summary!BT82 -> 0.022597235 | BA23: =Summary!BU82 -> 0.025329451 | BB23: =Summary!BV82 -> 0.028477417 | BC23: =Summary!BW82 -> 0.026962519 | BD23: =Summary!BX82 -> 0.0254948 | BE23: =Summary!BY82 -> 0.027069335 | BF23: =Summary!BZ82 -> 0.027488243 | BG23: =Summary!CA82 -> 0.024113916 | ... BI23: =Summary!CC82 -> 0.024826493
AA24: Difference | AB24: =AB23-AB22 -> -0.0050852635 | AC24: =AC23-AC22 -> 3.6473786e-05 | AD24: =AD23-AD22 -> 0.0009557784 | AE24: =AE23-AE22 -> -0.0018898675 | AF24: =AF23-AF22 -> 0.016385201 | AG24: =AG23-AG22 -> 0.0072850464 | AH24: =AH23-AH22 -> -0.0053557946 | AI24: =AI23-AI22 -> 0.011861387 | ... AK24: =AK23-AK22 -> 0.013930098 | AM24: Difference | AN24: =AN23-AN22 -> 0.12618206 | AO24: =AO23-AO22 -> 0.10222244 | AP24: =AP23-AP22 -> 0.12839917 | AQ24: =AQ23-AQ22 -> 0.094472368 | AR24: =AR23-AR22 -> 0.11926351 | AS24: =AS23-AS22 -> 0.090042281 | AT24: =AT23-AT22 -> 0.10695259 | AU24: =AU23-AU22 -> 0.10638404 | ... AW24: =AW23-AW22 -> 0.091281653 | AY24: USA | AZ24: =Summary!BT83 -> 0.0034182193 | BA24: =Summary!BU83 -> 0.0032969041 | BB24: =Summary!BV83 -> 0.0027047513 | BC24: =Summary!BW83 -> 0.0035140005 | BD24: =Summary!BX83 -> 0.003179083 | BE24: =Summary!BY83 -> 0.0028370449 | BF24: =Summary!BZ83 -> 0.0029051807 | BG24: =Summary!CA83 -> 0.0028748856 | ... BI24: =Summary!CC83 -> 0.0034492293
AA25: % Difference | AB25: =AB24/AB22 -> -0.11408157 | AC25: =AC24/AC22 -> 0.00077350593 | AD25: =AD24/AD22 -> 0.021189484 | AE25: =AE24/AE22 -> -0.039962551 | AF25: =AF24/AF22 -> 0.33131494 | AG25: =AG24/AG22 -> 0.1396992 | AH25: =AH24/AH22 -> -0.10299762 | AI25: =AI24/AI22 -> 0.21378224 | ... AK25: =AK24/AK22 -> 0.23667059 | AM25: % Difference | AN25: =AN24/AN22 -> 1.9145086 | AO25: =AO24/AO22 -> 1.1660931 | AP25: =AP24/AP22 -> 1.5968695 | AQ25: =AQ24/AQ22 -> 1.3076861 | AR25: =AR24/AR22 -> 1.671571 | AS25: =AS24/AS22 -> 1.1751126 | AT25: =AT24/AT22 -> 1.4383028 | AU25: =AU24/AU22 -> 1.3865226 | ... AW25: =AW24/AW22 -> 1.2422521
AA27: Salt Lake | AM27: Salt Lake | AY27: 1-Year ACS (copied from 1-Year ACS File Summary)
AB28: 2010 | AC28: 2011 | AD28: 2012 | AE28: 2013 | AF28: 2014 | AG28: 2015 | AH28: 2016 | AI28: 2017 | AJ28: 2018 | AK28: 2019 | AN28: 2010 | AO28: 2011 | AP28: 2012 | AQ28: 2013 | AR28: 2014 | AS28: 2015 | AT28: 2016 | AU28: 2017 | AV28: 2018 | AW28: 2019 | AY28: Share of Workers that Worked at Home
AA29: 5-Year ACS | AB29: =VLOOKUP($AA27, $AY$8:$BI$14, COLUMNS($AY$7:AZ$7), FALSE) -> 0.042931884 | AC29: =VLOOKUP($AA27, $AY$8:$BI$14, COLUMNS($AY$7:BA$7), FALSE) -> 0.043507812 | AD29: =VLOOKUP($AA27, $AY$8:$BI$14, COLUMNS($AY$7:BB$7), FALSE) -> 0.043455383 | AE29: =VLOOKUP($AA27, $AY$8:$BI$14, COLUMNS($AY$7:BC$7), FALSE) -> 0.04479927 | AF29: =VLOOKUP($AA27, $AY$8:$BI$14, COLUMNS($AY$7:BD$7), FALSE) -> 0.046272278 | AG29: =VLOOKUP($AA27, $AY$8:$BI$14, COLUMNS($AY$7:BE$7), FALSE) -> 0.049433922 | AH29: =VLOOKUP($AA27, $AY$8:$BI$14, COLUMNS($AY$7:BF$7), FALSE) -> 0.051318901 | AI29: =VLOOKUP($AA27, $AY$8:$BI$14, COLUMNS($AY$7:BG$7), FALSE) -> 0.055654606 | ... AK29: =VLOOKUP($AA27, $AY$8:$BI$14, COLUMNS($AY$7:BI$7), FALSE) -> 0.06205852 | AM29: 5-Year ACS | AN29: =VLOOKUP($AM27, $AY$18:$BI$24, COLUMNS($AY$17:AZ$17), FALSE) -> 0.041286583 | AO29: =VLOOKUP($AM27, $AY$18:$BI$24, COLUMNS($AY$17:BA$17), FALSE) -> 0.042960759 | AP29: =VLOOKUP($AM27, $AY$18:$BI$24, COLUMNS($AY$17:BB$17), FALSE) -> 0.049953959 | AQ29: =VLOOKUP($AM27, $AY$18:$BI$24, COLUMNS($AY$17:BC$17), FALSE) -> 0.048127158 | AR29: =VLOOKUP($AM27, $AY$18:$BI$24, COLUMNS($AY$17:BD$17), FALSE) -> 0.046210176 | AS29: =VLOOKUP($AM27, $AY$18:$BI$24, COLUMNS($AY$17:BE$17), FALSE) -> 0.049852699 | AT29: =VLOOKUP($AM27, $AY$18:$BI$24, COLUMNS($AY$17:BF$17), FALSE) -> 0.045008448 | AU29: =VLOOKUP($AM27, $AY$18:$BI$24, COLUMNS($AY$17:BG$17), FALSE) -> 0.042487983 | ... AW29: =VLOOKUP($AM27, $AY$18:$BI$24, COLUMNS($AY$17:BI$17), FALSE) -> 0.045882971 | AZ29: 2010 | BA29: 2011 | BB29: 2012 | BC29: 2013 | BD29: 2014 | BE29: 2015 | BF29: 2016 | BG29: 2017 | BH29: 2018 | BI29: 2019
AA30: 1-Year ACS | AB30: =VLOOKUP($AA27, $AY$30:$BI$36, COLUMNS($AY$29:AZ$29), FALSE) -> 0.037803653 | AC30: =VLOOKUP($AA27, $AY$30:$BI$36, COLUMNS($AY$29:BA$29), FALSE) -> 0.044610058 | AD30: =VLOOKUP($AA27, $AY$30:$BI$36, COLUMNS($AY$29:BB$29), FALSE) -> 0.045343058 | AE30: =VLOOKUP($AA27, $AY$30:$BI$36, COLUMNS($AY$29:BC$29), FALSE) -> 0.052094166 | AF30: =VLOOKUP($AA27, $AY$30:$BI$36, COLUMNS($AY$29:BD$29), FALSE) -> 0.054016938 | AG30: =VLOOKUP($AA27, $AY$30:$BI$36, COLUMNS($AY$29:BE$29), FALSE) -> 0.052384531 | AH30: =VLOOKUP($AA27, $AY$30:$BI$36, COLUMNS($AY$29:BF$29), FALSE) -> 0.057821636 | AI30: =VLOOKUP($AA27, $AY$30:$BI$36, COLUMNS($AY$29:BG$29), FALSE) -> 0.066352797 | ... AK30: =VLOOKUP($AA27, $AY$30:$BI$36, COLUMNS($AY$29:BI$29), FALSE) -> 0.066119608 | AM30: 1-Year ACS | AN30: =VLOOKUP($AM27, $AY$40:$BI$46, COLUMNS($AY$39:AZ$39), FALSE) -> 0.11574431 | AO30: =VLOOKUP($AM27, $AY$40:$BI$46, COLUMNS($AY$39:BA$39), FALSE) -> 0.13325593 | AP30: =VLOOKUP($AM27, $AY$40:$BI$46, COLUMNS($AY$39:BB$39), FALSE) -> 0.10092374 | AQ30: =VLOOKUP($AM27, $AY$40:$BI$46, COLUMNS($AY$39:BC$39), FALSE) -> 0.10928302 | AR30: =VLOOKUP($AM27, $AY$40:$BI$46, COLUMNS($AY$39:BD$39), FALSE) -> 0.080542646 | AS30: =VLOOKUP($AM27, $AY$40:$BI$46, COLUMNS($AY$39:BE$39), FALSE) -> 0.10429322 | AT30: =VLOOKUP($AM27, $AY$40:$BI$46, COLUMNS($AY$39:BF$39), FALSE) -> 0.098589852 | AU30: =VLOOKUP($AM27, $AY$40:$BI$46, COLUMNS($AY$39:BG$39), FALSE) -> 0.088950589 | ... AW30: =VLOOKUP($AM27, $AY$40:$BI$46, COLUMNS($AY$39:BI$39), FALSE) -> 0.083372493 | AY30: Wasatch Front | AZ30: 0.042651351 | BA30: 0.047216212 | BB30: 0.047348698 | BC30: 0.051169945 | BD30: 0.056006562 | BE30: 0.056594397 | BF30: 0.057802638 | BG30: 0.066791542 | BH30: 0.064732827 | BI30: 0.070460042
AA31: Difference | AB31: =AB30-AB29 -> -0.0051282307 | AC31: =AC30-AC29 -> 0.0011022456 | AD31: =AD30-AD29 -> 0.0018876753 | AE31: =AE30-AE29 -> 0.007294896 | AF31: =AF30-AF29 -> 0.0077446592 | AG31: =AG30-AG29 -> 0.0029506085 | AH31: =AH30-AH29 -> 0.0065027344 | AI31: =AI30-AI29 -> 0.01069819 | ... AK31: =AK30-AK29 -> 0.0040610884 | AM31: Difference | AN31: =AN30-AN29 -> 0.074457723 | AO31: =AO30-AO29 -> 0.090295169 | AP31: =AP30-AP29 -> 0.050969778 | AQ31: =AQ30-AQ29 -> 0.061155866 | AR31: =AR30-AR29 -> 0.03433247 | AS31: =AS30-AS29 -> 0.054440516 | AT31: =AT30-AT29 -> 0.053581404 | AU31: =AU30-AU29 -> 0.046462606 | ... AW31: =AW30-AW29 -> 0.037489522 | AY31: Weber | AZ31: 0.028318247 | BA31: 0.038284382 | BB31: 0.03045163 | BC31: 0.036499328 | BD31: 0.042279542 | BE31: 0.052443014 | BF31: 0.039414424 | BG31: 0.051506727 | BH31: 0.051950839 | BI31: 0.072031505
AA32: % Difference | AB32: =AB31/AB29 -> -0.1194504 | AC32: =AC31/AC29 -> 0.02533443 | AD32: =AD31/AD29 -> 0.043439388 | AE32: =AE31/AE29 -> 0.16283515 | AF32: =AF31/AF29 -> 0.16737147 | AG32: =AG31/AG29 -> 0.059687929 | AH32: =AH31/AH29 -> 0.12671227 | AI32: =AI31/AI29 -> 0.1922247 | ... AK32: =AK31/AK29 -> 0.06543966 | AM32: % Difference | AN32: =AN31/AN29 -> 1.8034363 | AO32: =AO31/AO29 -> 2.1018057 | AP32: =AP31/AP29 -> 1.0203351 | AQ32: =AQ31/AQ29 -> 1.2707142 | AR32: =AR31/AR29 -> 0.7429634 | AS32: =AS31/AS29 -> 1.0920275 | AT32: =AT31/AT29 -> 1.1904744 | AU32: =AU31/AU29 -> 1.093547 | ... AW32: =AW31/AW29 -> 0.81706832 | AY32: Davis | AZ32: 0.039490417 | BA32: 0.047190329 | BB32: 0.046062039 | BC32: 0.045401095 | BD32: 0.065840263 | BE32: 0.059433135 | BF32: 0.046643415 | BG32: 0.067344885 | BH32: 0.055353643 | BI32: 0.072788694
AY33: Salt Lake | AZ33: 0.037803653 | BA33: 0.044610058 | BB33: 0.045343058 | BC33: 0.052094166 | BD33: 0.054016938 | BE33: 0.052384531 | BF33: 0.057821636 | BG33: 0.066352797 | BH33: 0.068253497 | BI33: 0.066119608
AA34: Utah | AM34: Utah | AY34: Utah | AZ34: 0.063018401 | BA34: 0.057439143 | BB34: 0.06020214 | BC34: 0.059674101 | BD34: 0.060743844 | BE34: 0.065875863 | BF34: 0.072547819 | BG34: 0.074134321 | BH34: 0.068474823 | BI34: 0.077160372
AB35: 2010 | AC35: 2011 | AD35: 2012 | AE35: 2013 | AF35: 2014 | AG35: 2015 | AH35: 2016 | AI35: 2017 | AJ35: 2018 | AK35: 2019 | AN35: 2010 | AO35: 2011 | AP35: 2012 | AQ35: 2013 | AR35: 2014 | AS35: 2015 | AT35: 2016 | AU35: 2017 | AV35: 2018 | AW35: 2019 | AY35: State of Utah | AZ35: 0.043812499 | BA35: 0.046437087 | BB35: 0.047667153 | BC35: 0.051400175 | BD35: 0.054802237 | BE35: 0.055468298 | BF35: 0.060708921 | BG35: 0.068117505 | BH35: 0.068867889 | BI35: 0.074297828
AA36: 5-Year ACS | AB36: =VLOOKUP($AA34, $AY$8:$BI$14, COLUMNS($AY$7:AZ$7), FALSE) -> 0.061534608 | AC36: =VLOOKUP($AA34, $AY$8:$BI$14, COLUMNS($AY$7:BA$7), FALSE) -> 0.060800768 | AD36: =VLOOKUP($AA34, $AY$8:$BI$14, COLUMNS($AY$7:BB$7), FALSE) -> 0.058871541 | AE36: =VLOOKUP($AA34, $AY$8:$BI$14, COLUMNS($AY$7:BC$7), FALSE) -> 0.060458232 | AF36: =VLOOKUP($AA34, $AY$8:$BI$14, COLUMNS($AY$7:BD$7), FALSE) -> 0.06048057 | AG36: =VLOOKUP($AA34, $AY$8:$BI$14, COLUMNS($AY$7:BE$7), FALSE) -> 0.061172555 | AH36: =VLOOKUP($AA34, $AY$8:$BI$14, COLUMNS($AY$7:BF$7), FALSE) -> 0.063242199 | AI36: =VLOOKUP($AA34, $AY$8:$BI$14, COLUMNS($AY$7:BG$7), FALSE) -> 0.066567673 | ... AK36: =VLOOKUP($AA34, $AY$8:$BI$14, COLUMNS($AY$7:BI$7), FALSE) -> 0.071920744 | AM36: 5-Year ACS | AN36: =VLOOKUP($AM34, $AY$18:$BI$24, COLUMNS($AY$17:AZ$17), FALSE) -> 0.059016907 | AO36: =VLOOKUP($AM34, $AY$18:$BI$24, COLUMNS($AY$17:BA$17), FALSE) -> 0.062916699 | AP36: =VLOOKUP($AM34, $AY$18:$BI$24, COLUMNS($AY$17:BB$17), FALSE) -> 0.053442801 | AQ36: =VLOOKUP($AM34, $AY$18:$BI$24, COLUMNS($AY$17:BC$17), FALSE) -> 0.055833396 | AR36: =VLOOKUP($AM34, $AY$18:$BI$24, COLUMNS($AY$17:BD$17), FALSE) -> 0.051517136 | AS36: =VLOOKUP($AM34, $AY$18:$BI$24, COLUMNS($AY$17:BE$17), FALSE) -> 0.056897626 | AT36: =VLOOKUP($AM34, $AY$18:$BI$24, COLUMNS($AY$17:BF$17), FALSE) -> 0.04525585 | AU36: =VLOOKUP($AM34, $AY$18:$BI$24, COLUMNS($AY$17:BG$17), FALSE) -> 0.043070717 | ... AW36: =VLOOKUP($AM34, $AY$18:$BI$24, COLUMNS($AY$17:BI$17), FALSE) -> 0.045463689 | AY36: USA | AZ36: 0.043260963 | BA36: 0.043350907 | BB36: 0.043616455 | BC36: 0.043570987 | BD36: 0.044851942 | BE36: 0.046135316 | BF36: 0.050485014 | BG36: 0.052317927 | BH36: 0.053372257 | BI36: 0.057160208
AA37: 1-Year ACS | AB37: =VLOOKUP($AA34, $AY$30:$BI$36, COLUMNS($AY$29:AZ$29), FALSE) -> 0.063018401 | AC37: =VLOOKUP($AA34, $AY$30:$BI$36, COLUMNS($AY$29:BA$29), FALSE) -> 0.057439143 | AD37: =VLOOKUP($AA34, $AY$30:$BI$36, COLUMNS($AY$29:BB$29), FALSE) -> 0.06020214 | AE37: =VLOOKUP($AA34, $AY$30:$BI$36, COLUMNS($AY$29:BC$29), FALSE) -> 0.059674101 | AF37: =VLOOKUP($AA34, $AY$30:$BI$36, COLUMNS($AY$29:BD$29), FALSE) -> 0.060743844 | AG37: =VLOOKUP($AA34, $AY$30:$BI$36, COLUMNS($AY$29:BE$29), FALSE) -> 0.065875863 | AH37: =VLOOKUP($AA34, $AY$30:$BI$36, COLUMNS($AY$29:BF$29), FALSE) -> 0.072547819 | AI37: =VLOOKUP($AA34, $AY$30:$BI$36, COLUMNS($AY$29:BG$29), FALSE) -> 0.074134321 | ... AK37: =VLOOKUP($AA34, $AY$30:$BI$36, COLUMNS($AY$29:BI$29), FALSE) -> 0.077160372 | AM37: 1-Year ACS | AN37: =VLOOKUP($AM34, $AY$40:$BI$46, COLUMNS($AY$39:AZ$39), FALSE) -> 0.13359126 | AO37: =VLOOKUP($AM34, $AY$40:$BI$46, COLUMNS($AY$39:BA$39), FALSE) -> 0.16328802 | AP37: =VLOOKUP($AM34, $AY$40:$BI$46, COLUMNS($AY$39:BB$39), FALSE) -> 0.11189941 | AQ37: =VLOOKUP($AM34, $AY$40:$BI$46, COLUMNS($AY$39:BC$39), FALSE) -> 0.11812404 | AR37: =VLOOKUP($AM34, $AY$40:$BI$46, COLUMNS($AY$39:BD$39), FALSE) -> 0.10338765 | AS37: =VLOOKUP($AM34, $AY$40:$BI$46, COLUMNS($AY$39:BE$39), FALSE) -> 0.10145533 | AT37: =VLOOKUP($AM34, $AY$40:$BI$46, COLUMNS($AY$39:BF$39), FALSE) -> 0.096618109 | AU37: =VLOOKUP($AM34, $AY$40:$BI$46, COLUMNS($AY$39:BG$39), FALSE) -> 0.12988291 | ... AW37: =VLOOKUP($AM34, $AY$40:$BI$46, COLUMNS($AY$39:BI$39), FALSE) -> 0.098139396
AA38: Difference | AB38: =AB37-AB36 -> 0.0014837923 | AC38: =AC37-AC36 -> -0.0033616249 | AD38: =AD37-AD36 -> 0.0013305984 | AE38: =AE37-AE36 -> -0.00078413093 | AF38: =AF37-AF36 -> 0.00026327374 | AG38: =AG37-AG36 -> 0.0047033078 | AH38: =AH37-AH36 -> 0.0093056193 | AI38: =AI37-AI36 -> 0.0075666481 | ... AK38: =AK37-AK36 -> 0.0052396282 | AM38: Difference | AN38: =AN37-AN36 -> 0.074574354 | AO38: =AO37-AO36 -> 0.10037132 | AP38: =AP37-AP36 -> 0.058456609 | AQ38: =AQ37-AQ36 -> 0.062290646 | AR38: =AR37-AR36 -> 0.051870517 | AS38: =AS37-AS36 -> 0.0445577 | AT38: =AT37-AT36 -> 0.051362259 | AU38: =AU37-AU36 -> 0.086812192 | ... AW38: =AW37-AW36 -> 0.052675707 | AY38: Margin of Error - Workers that Worked at Home
AA39: % Difference | AB39: =AB38/AB36 -> 0.024113134 | AC39: =AC38/AC36 -> -0.055289184 | AD39: =AD38/AD36 -> 0.022601725 | AE39: =AE38/AE36 -> -0.012969796 | AF39: =AF38/AF36 -> 0.00435303 | AG39: =AG38/AG36 -> 0.076885914 | AH39: =AH38/AH36 -> 0.14714256 | AI39: =AI38/AI36 -> 0.11366851 | ... AK39: =AK38/AK36 -> 0.072852809 | AM39: % Difference | AN39: =AN38/AN36 -> 1.26361 | AO39: =AO38/AO36 -> 1.595305 | AP39: =AP38/AP36 -> 1.0938164 | AQ39: =AQ38/AQ36 -> 1.1156521 | AR39: =AR38/AR36 -> 1.0068595 | AS39: =AS38/AS36 -> 0.78312056 | AT39: =AT38/AT36 -> 1.1349308 | AU39: =AU38/AU36 -> 2.0155734 | ... AW39: =AW38/AW36 -> 1.1586325 | AZ39: 2010 | BA39: 2011 | BB39: 2012 | BC39: 2013 | BD39: 2014 | BE39: 2015 | BF39: 2016 | BG39: 2017 | BH39: 2018 | BI39: 2019
AY40: Wasatch Front | AZ40: 0.14514908 | BA40: 0.16064697 | BB40: 0.12923194 | BC40: 0.12939356 | BD40: 0.11763703 | BE40: 0.12220369 | BF40: 0.11699057 | BG40: 0.12476978 | BH40: 0.10833609 | BI40: 0.11396312
AA41: State of Utah | AM41: State of Utah | AY41: Weber | AZ41: 0.29239569 | BA41: 0.25748804 | BB41: 0.24261796 | BC41: 0.24460249 | BD41: 0.23907563 | BE41: 0.1991863 | BF41: 0.22983521 | BG41: 0.22779116 | BH41: 0.16725325 | BI41: 0.2147188
AB42: 2010 | AC42: 2011 | AD42: 2012 | AE42: 2013 | AF42: 2014 | AG42: 2015 | AH42: 2016 | AI42: 2017 | AJ42: 2018 | AK42: 2019 | AN42: 2010 | AO42: 2011 | AP42: 2012 | AQ42: 2013 | AR42: 2014 | AS42: 2015 | AT42: 2016 | AU42: 2017 | AV42: 2018 | AW42: 2019 | AY42: Davis | AZ42: 0.1920904 | BA42: 0.18988478 | BB42: 0.20880597 | BC42: 0.16671628 | BD42: 0.19061166 | BE42: 0.16666667 | BF42: 0.18131286 | BG42: 0.18311127 | BH42: 0.17976543 | BI42: 0.16476243
AA43: 5-Year ACS | AB43: =VLOOKUP($AA41, $AY$8:$BI$14, COLUMNS($AY$7:AZ$7), FALSE) -> 0.048247967 | AC43: =VLOOKUP($AA41, $AY$8:$BI$14, COLUMNS($AY$7:BA$7), FALSE) -> 0.048146251 | AD43: =VLOOKUP($AA41, $AY$8:$BI$14, COLUMNS($AY$7:BB$7), FALSE) -> 0.047170408 | AE43: =VLOOKUP($AA41, $AY$8:$BI$14, COLUMNS($AY$7:BC$7), FALSE) -> 0.048242532 | AF43: =VLOOKUP($AA41, $AY$8:$BI$14, COLUMNS($AY$7:BD$7), FALSE) -> 0.048818053 | AG43: =VLOOKUP($AA41, $AY$8:$BI$14, COLUMNS($AY$7:BE$7), FALSE) -> 0.051301419 | AH43: =VLOOKUP($AA41, $AY$8:$BI$14, COLUMNS($AY$7:BF$7), FALSE) -> 0.053654326 | AI43: =VLOOKUP($AA41, $AY$8:$BI$14, COLUMNS($AY$7:BG$7), FALSE) -> 0.057712073 | ... AK43: =VLOOKUP($AA41, $AY$8:$BI$14, COLUMNS($AY$7:BI$7), FALSE) -> 0.065641119 | AM43: 5-Year ACS | AN43: =VLOOKUP($AM41, $AY$18:$BI$24, COLUMNS($AY$17:AZ$17), FALSE) -> 0.022597235 | AO43: =VLOOKUP($AM41, $AY$18:$BI$24, COLUMNS($AY$17:BA$17), FALSE) -> 0.025329451 | AP43: =VLOOKUP($AM41, $AY$18:$BI$24, COLUMNS($AY$17:BB$17), FALSE) -> 0.028477417 | AQ43: =VLOOKUP($AM41, $AY$18:$BI$24, COLUMNS($AY$17:BC$17), FALSE) -> 0.026962519 | AR43: =VLOOKUP($AM41, $AY$18:$BI$24, COLUMNS($AY$17:BD$17), FALSE) -> 0.0254948 | AS43: =VLOOKUP($AM41, $AY$18:$BI$24, COLUMNS($AY$17:BE$17), FALSE) -> 0.027069335 | AT43: =VLOOKUP($AM41, $AY$18:$BI$24, COLUMNS($AY$17:BF$17), FALSE) -> 0.027488243 | AU43: =VLOOKUP($AM41, $AY$18:$BI$24, COLUMNS($AY$17:BG$17), FALSE) -> 0.024113916 | ... AW43: =VLOOKUP($AM41, $AY$18:$BI$24, COLUMNS($AY$17:BI$17), FALSE) -> 0.024826493 | AY43: Salt Lake | AZ43: 0.11574431 | BA43: 0.13325593 | BB43: 0.10092374 | BC43: 0.10928302 | BD43: 0.080542646 | BE43: 0.10429322 | BF43: 0.098589852 | BG43: 0.088950589 | BH43: 0.087047939 | BI43: 0.083372493
AA44: 1-Year ACS | AB44: =VLOOKUP($AA41, $AY$30:$BI$36, COLUMNS($AY$29:AZ$29), FALSE) -> 0.043812499 | AC44: =VLOOKUP($AA41, $AY$30:$BI$36, COLUMNS($AY$29:BA$29), FALSE) -> 0.046437087 | AD44: =VLOOKUP($AA41, $AY$30:$BI$36, COLUMNS($AY$29:BB$29), FALSE) -> 0.047667153 | AE44: =VLOOKUP($AA41, $AY$30:$BI$36, COLUMNS($AY$29:BC$29), FALSE) -> 0.051400175 | AF44: =VLOOKUP($AA41, $AY$30:$BI$36, COLUMNS($AY$29:BD$29), FALSE) -> 0.054802237 | AG44: =VLOOKUP($AA41, $AY$30:$BI$36, COLUMNS($AY$29:BE$29), FALSE) -> 0.055468298 | AH44: =VLOOKUP($AA41, $AY$30:$BI$36, COLUMNS($AY$29:BF$29), FALSE) -> 0.060708921 | AI44: =VLOOKUP($AA41, $AY$30:$BI$36, COLUMNS($AY$29:BG$29), FALSE) -> 0.068117505 | ... AK44: =VLOOKUP($AA41, $AY$30:$BI$36, COLUMNS($AY$29:BI$29), FALSE) -> 0.074297828 | AM44: 1-Year ACS | AN44: =VLOOKUP($AM41, $AY$40:$BI$46, COLUMNS($AY$39:AZ$39), FALSE) -> 0.065605312 | AO44: =VLOOKUP($AM41, $AY$40:$BI$46, COLUMNS($AY$39:BA$39), FALSE) -> 0.07745469 | AP44: =VLOOKUP($AM41, $AY$40:$BI$46, COLUMNS($AY$39:BB$39), FALSE) -> 0.060408005 | AQ44: =VLOOKUP($AM41, $AY$40:$BI$46, COLUMNS($AY$39:BC$39), FALSE) -> 0.06107052 | AR44: =VLOOKUP($AM41, $AY$40:$BI$46, COLUMNS($AY$39:BD$39), FALSE) -> 0.049914572 | AS44: =VLOOKUP($AM41, $AY$40:$BI$46, COLUMNS($AY$39:BE$39), FALSE) -> 0.058027579 | AT44: =VLOOKUP($AM41, $AY$40:$BI$46, COLUMNS($AY$39:BF$39), FALSE) -> 0.05232051 | AU44: =VLOOKUP($AM41, $AY$40:$BI$46, COLUMNS($AY$39:BG$39), FALSE) -> 0.061440322 | ... AW44: =VLOOKUP($AM41, $AY$40:$BI$46, COLUMNS($AY$39:BI$39), FALSE) -> 0.057183168 | AY44: Utah | AZ44: 0.13359126 | BA44: 0.16328802 | BB44: 0.11189941 | BC44: 0.11812404 | BD44: 0.10338765 | BE44: 0.10145533 | BF44: 0.096618109 | BG44: 0.12988291 | BH44: 0.099329958 | BI44: 0.098139396
...

Sheet Summary
A1: Share of Workers Mode of Transportation (All Modes, 1 Geography) | AD1: Share of Workers Mode of Transportation (1 Mode, All Geogrpahy) | AR1: Share of Workers that Used Auto Mode | BE1: Summary of Mode Typically Took by Worker | BR1: Margin of Error
BE2: ACS: Table B08006 - SEX OF WORKERS BY MEANS OF TRANSPORTATION TO WORK
BE3: Universe: Workers 16 years and over
BE5: 117 | BF5: Share of Workers that Worked at Home | BR5: 201 | BS5: Drove Alone
BG6: 2010 | BH6: 2011 | BI6: 2012 | BJ6: 2013 | BK6: 2014 | BL6: 2015 | BM6: 2016 | BN6: 2017 | BO6: 2018 | BP6: 2019 | BT6: 2010 | BU6: 2011 | BV6: 2012 | BW6: 2013 | BX6: 2014 | BY6: 2015 | BZ6: 2016 | CA6: 2017 | CB6: 2018 | CC6: 2019
BF7: Wasatch Front | BG7: =VLOOKUP(BE5, WasatchFront!$B:$M, COLUMNS(WasatchFront!$B$31:D$31), FALSE) -> 0.046040703 | BH7: =VLOOKUP(BE5, WasatchFront!$B:$M, COLUMNS(WasatchFront!$B$31:E$31), FALSE) -> 0.046933978 | BI7: =VLOOKUP(BE5, WasatchFront!$B:$M, COLUMNS(WasatchFront!$B$31:F$31), FALSE) -> 0.045984966 | BJ7: =VLOOKUP(BE5, WasatchFront!$B:$M, COLUMNS(WasatchFront!$B$31:G$31), FALSE) -> 0.047455799 | BK7: =VLOOKUP(BE5, WasatchFront!$B:$M, COLUMNS(WasatchFront!$B$31:H$31), FALSE) -> 0.048848668 | BL7: =VLOOKUP(BE5, WasatchFront!$B:$M, COLUMNS(WasatchFront!$B$31:I$31), FALSE) -> 0.051658859 | BM7: =VLOOKUP(BE5, WasatchFront!$B:$M, COLUMNS(WasatchFront!$B$31:J$31), FALSE) -> 0.053139977 | BN7: =VLOOKUP(BE5, WasatchFront!$B:$M, COLUMNS(WasatchFront!$B$31:K$31), FALSE) -> 0.057194228 | BO7: =VLOOKUP(BE5, WasatchFront!$B:$M, COLUMNS(WasatchFront!$B$31:L$31), FALSE) -> 0.060327376 | BP7: =VLOOKUP(BE5, WasatchFront!$B:$M, COLUMNS(WasatchFront!$B$31:M$31), FALSE) -> 0.06316136 | BS7: Wasatch Front | BT7: =VLOOKUP(BR5, WasatchFront!$B:$M, COLUMNS(WasatchFront!$B$31:D$31), FALSE) -> 0.0070761907 | BU7: =VLOOKUP(BR5, WasatchFront!$B:$M, COLUMNS(WasatchFront!$B$31:E$31), FALSE) -> 0.0069404658 | BV7: =VLOOKUP(BR5, WasatchFront!$B:$M, COLUMNS(WasatchFront!$B$31:F$31), FALSE) -> 0.0071310366 | BW7: =VLOOKUP(BR5, WasatchFront!$B:$M, COLUMNS(WasatchFront!$B$31:G$31), FALSE) -> 0.0073761811 | BX7: =VLOOKUP(BR5, WasatchFront!$B:$M, COLUMNS(WasatchFront!$B$31:H$31), FALSE) -> 0.0071417479 | BY7: =VLOOKUP(BR5, WasatchFront!$B:$M, COLUMNS(WasatchFront!$B$31:I$31), FALSE) -> 0.0068265065 | BZ7: =VLOOKUP(BR5, WasatchFront!$B:$M, COLUMNS(WasatchFront!$B$31:J$31), FALSE) -> 0.0071129182 | CA7: =VLOOKUP(BR5, WasatchFront!$B:$M, COLUMNS(WasatchFront!$B$31:K$31), FALSE) -> 0.0071113193 | CB7: =VLOOKUP(BR5, WasatchFront!$B:$M, COLUMNS(WasatchFront!$B$31:L$31), FALSE) -> 0.0067959548 | CC7: =VLOOKUP(BR5, WasatchFront!$B:$M, COLUMNS(WasatchFront!$B$31:M$31), FALSE) -> 0.0063928926
BF8: Weber | BG8: =VLOOKUP(BE5, Weber!$B:$M, COLUMNS(Weber!$B$31:D$31), FALSE) -> 0.031489478 | BH8: =VLOOKUP(BE5, Weber!$B:$M, COLUMNS(Weber!$B$31:E$31), FALSE) -> 0.03423657 | BI8: =VLOOKUP(BE5, Weber!$B:$M, COLUMNS(Weber!$B$31:F$31), FALSE) -> 0.032300393 | BJ8: =VLOOKUP(BE5, Weber!$B:$M, COLUMNS(Weber!$B$31:G$31), FALSE) -> 0.033006032 | BK8: =VLOOKUP(BE5, Weber!$B:$M, COLUMNS(Weber!$B$31:H$31), FALSE) -> 0.035722947 | BL8: =VLOOKUP(BE5, Weber!$B:$M, COLUMNS(Weber!$B$31:I$31), FALSE) -> 0.041130466 | BM8: =VLOOKUP(BE5, Weber!$B:$M, COLUMNS(Weber!$B$31:J$31), FALSE) -> 0.041244982 | BN8: =VLOOKUP(BE5, Weber!$B:$M, COLUMNS(Weber!$B$31:K$31), FALSE) -> 0.046252189 | BO8: =VLOOKUP(BE5, Weber!$B:$M, COLUMNS(Weber!$B$31:L$31), FALSE) -> 0.048962571 | BP8: =VLOOKUP(BE5, Weber!$B:$M, COLUMNS(Weber!$B$31:M$31), FALSE) -> 0.054330715 | BS8: Weber | BT8: =VLOOKUP(BR5, Weber!$B:$M, COLUMNS(Weber!$B$31:D$31), FALSE) -> 0.012603571 | BU8: =VLOOKUP(BR5, Weber!$B:$M, COLUMNS(Weber!$B$31:E$31), FALSE) -> 0.0120926 | BV8: =VLOOKUP(BR5, Weber!$B:$M, COLUMNS(Weber!$B$31:F$31), FALSE) -> 0.011762021 | BW8: =VLOOKUP(BR5, Weber!$B:$M, COLUMNS(Weber!$B$31:G$31), FALSE) -> 0.01033282 | BX8: =VLOOKUP(BR5, Weber!$B:$M, COLUMNS(Weber!$B$31:H$31), FALSE) -> 0.013636279 | BY8: =VLOOKUP(BR5, Weber!$B:$M, COLUMNS(Weber!$B$31:I$31), FALSE) -> 0.013264921 | BZ8: =VLOOKUP(BR5, Weber!$B:$M, COLUMNS(Weber!$B$31:J$31), FALSE) -> 0.012589912 | CA8: =VLOOKUP(BR5, Weber!$B:$M, COLUMNS(Weber!$B$31:K$31), FALSE) -> 0.011532399 | CB8: =VLOOKUP(BR5, Weber!$B:$M, COLUMNS(Weber!$B$31:L$31), FALSE) -> 0.011117434 | CC8: =VLOOKUP(BR5, Weber!$B:$M, COLUMNS(Weber!$B$31:M$31), FALSE) -> 0.011340877
BF9: Davis | BG9: =VLOOKUP(BE5, Davis!$B:$M, COLUMNS(Davis!$B$31:D$31), FALSE) -> 0.044575681 | BH9: =VLOOKUP(BE5, Davis!$B:$M, COLUMNS(Davis!$B$31:E$31), FALSE) -> 0.047153855 | BI9: =VLOOKUP(BE5, Davis!$B:$M, COLUMNS(Davis!$B$31:F$31), FALSE) -> 0.045106261 | BJ9: =VLOOKUP(BE5, Davis!$B:$M, COLUMNS(Davis!$B$31:G$31), FALSE) -> 0.047290962 | BK9: =VLOOKUP(BE5, Davis!$B:$M, COLUMNS(Davis!$B$31:H$31), FALSE) -> 0.049455062 | BL9: =VLOOKUP(BE5, Davis!$B:$M, COLUMNS(Davis!$B$31:I$31), FALSE) -> 0.052148088 | BM9: =VLOOKUP(BE5, Davis!$B:$M, COLUMNS(Davis!$B$31:J$31), FALSE) -> 0.05199921 | BN9: =VLOOKUP(BE5, Davis!$B:$M, COLUMNS(Davis!$B$31:K$31), FALSE) -> 0.055483498 | BO9: =VLOOKUP(BE5, Davis!$B:$M, COLUMNS(Davis!$B$31:L$31), FALSE) -> 0.058273372 | BP9: =VLOOKUP(BE5, Davis!$B:$M, COLUMNS(Davis!$B$31:M$31), FALSE) -> 0.058858596 | BS9: Davis | BT9: =VLOOKUP(BR5, Davis!$B:$M, COLUMNS(Davis!$B$31:D$31), FALSE) -> 0.0086123974 | BU9: =VLOOKUP(BR5, Davis!$B:$M, COLUMNS(Davis!$B$31:E$31), FALSE) -> 0.0088723317 | BV9: =VLOOKUP(BR5, Davis!$B:$M, COLUMNS(Davis!$B$31:F$31), FALSE) -> 0.0087875856 | BW9: =VLOOKUP(BR5, Davis!$B:$M, COLUMNS(Davis!$B$31:G$31), FALSE) -> 0.010384408 | BX9: =VLOOKUP(BR5, Davis!$B:$M, COLUMNS(Davis!$B$31:H$31), FALSE) -> 0.0093258912 | BY9: =VLOOKUP(BR5, Davis!$B:$M, COLUMNS(Davis!$B$31:I$31), FALSE) -> 0.0091323276 | BZ9: =VLOOKUP(BR5, Davis!$B:$M, COLUMNS(Davis!$B$31:J$31), FALSE) -> 0.0085435742 | CA9: =VLOOKUP(BR5, Davis!$B:$M, COLUMNS(Davis!$B$31:K$31), FALSE) -> 0.010241428 | CB9: =VLOOKUP(BR5, Davis!$B:$M, COLUMNS(Davis!$B$31:L$31), FALSE) -> 0.01022693 | CC9: =VLOOKUP(BR5, Davis!$B:$M, COLUMNS(Davis!$B$31:M$31), FALSE) -> 0.0085282918
BF10: Salt Lake | BG10: =VLOOKUP(BE5, SaltLake!$B:$M, COLUMNS(SaltLake!$B$31:D$31), FALSE) -> 0.042931884 | BH10: =VLOOKUP(BE5, SaltLake!$B:$M, COLUMNS(SaltLake!$B$31:E$31), FALSE) -> 0.043507812 | BI10: =VLOOKUP(BE5, SaltLake!$B:$M, COLUMNS(SaltLake!$B$31:F$31), FALSE) -> 0.043455383 | BJ10: =VLOOKUP(BE5, SaltLake!$B:$M, COLUMNS(SaltLake!$B$31:G$31), FALSE) -> 0.04479927 | BK10: =VLOOKUP(BE5, SaltLake!$B:$M, COLUMNS(SaltLake!$B$31:H$31), FALSE) -> 0.046272278 | BL10: =VLOOKUP(BE5, SaltLake!$B:$M, COLUMNS(SaltLake!$B$31:I$31), FALSE) -> 0.049433922 | BM10: =VLOOKUP(BE5, SaltLake!$B:$M, COLUMNS(SaltLake!$B$31:J$31), FALSE) -> 0.051318901 | BN10: =VLOOKUP(BE5, SaltLake!$B:$M, COLUMNS(SaltLake!$B$31:K$31), FALSE) -> 0.055654606 | BO10: =VLOOKUP(BE5, SaltLake!$B:$M, COLUMNS(SaltLake!$B$31:L$31), FALSE) -> 0.059187541 | BP10: =VLOOKUP(BE5, SaltLake!$B:$M, COLUMNS(SaltLake!$B$31:M$31), FALSE) -> 0.06205852 | BS10: Salt Lake | BT10: =VLOOKUP(BR5, SaltLake!$B:$M, COLUMNS(SaltLake!$B$31:D$31), FALSE) -> 0.0044017011 | BU10: =VLOOKUP(BR5, SaltLake!$B:$M, COLUMNS(SaltLake!$B$31:E$31), FALSE) -> 0.004818468 | BV10: =VLOOKUP(BR5, SaltLake!$B:$M, COLUMNS(SaltLake!$B$31:F$31), FALSE) -> 0.0054479286 | BW10: =VLOOKUP(BR5, SaltLake!$B:$M, COLUMNS(SaltLake!$B$31:G$31), FALSE) -> 0.0053336242 | BX10: =VLOOKUP(BR5, SaltLake!$B:$M, COLUMNS(SaltLake!$B$31:H$31), FALSE) -> 0.0048646164 | BY10: =VLOOKUP(BR5, SaltLake!$B:$M, COLUMNS(SaltLake!$B$31:I$31), FALSE) -> 0.0046356714 | BZ10: =VLOOKUP(BR5, SaltLake!$B:$M, COLUMNS(SaltLake!$B$31:J$31), FALSE) -> 0.0055586098 | CA10: =VLOOKUP(BR5, SaltLake!$B:$M, COLUMNS(SaltLake!$B$31:K$31), FALSE) -> 0.0053631096 | CB10: =VLOOKUP(BR5, SaltLake!$B:$M, COLUMNS(SaltLake!$B$31:L$31), FALSE) -> 0.0051448335 | CC10: =VLOOKUP(BR5, SaltLake!$B:$M, COLUMNS(SaltLake!$B$31:M$31), FALSE) -> 0.0049504101
BF11: Utah | BG11: =VLOOKUP(BE5, Utah!$B:$M, COLUMNS(Utah!$B$31:D$31), FALSE) -> 0.061534608 | BH11: =VLOOKUP(BE5, Utah!$B:$M, COLUMNS(Utah!$B$31:E$31), FALSE) -> 0.060800768 | BI11: =VLOOKUP(BE5, Utah!$B:$M, COLUMNS(Utah!$B$31:F$31), FALSE) -> 0.058871541 | BJ11: =VLOOKUP(BE5, Utah!$B:$M, COLUMNS(Utah!$B$31:G$31), FALSE) -> 0.060458232 | BK11: =VLOOKUP(BE5, Utah!$B:$M, COLUMNS(Utah!$B$31:H$31), FALSE) -> 0.06048057 | BL11: =VLOOKUP(BE5, Utah!$B:$M, COLUMNS(Utah!$B$31:I$31), FALSE) -> 0.061172555 | BM11: =VLOOKUP(BE5, Utah!$B:$M, COLUMNS(Utah!$B$31:J$31), FALSE) -> 0.063242199 | BN11: =VLOOKUP(BE5, Utah!$B:$M, COLUMNS(Utah!$B$31:K$31), FALSE) -> 0.066567673 | BO11: =VLOOKUP(BE5, Utah!$B:$M, COLUMNS(Utah!$B$31:L$31), FALSE) -> 0.06906093 | BP11: =VLOOKUP(BE5, Utah!$B:$M, COLUMNS(Utah!$B$31:M$31), FALSE) -> 0.071920744 | BS11: Utah | BT11: =VLOOKUP(BR5, Utah!$B:$M, COLUMNS(Utah!$B$31:D$31), FALSE) -> 0.0096617427 | BU11: =VLOOKUP(BR5, Utah!$B:$M, COLUMNS(Utah!$B$31:E$31), FALSE) -> 0.0081120497 | BV11: =VLOOKUP(BR5, Utah!$B:$M, COLUMNS(Utah!$B$31:F$31), FALSE) -> 0.0076923778 | BW11: =VLOOKUP(BR5, Utah!$B:$M, COLUMNS(Utah!$B$31:G$31), FALSE) -> 0.00870974 | BX11: =VLOOKUP(BR5, Utah!$B:$M, COLUMNS(Utah!$B$31:H$31), FALSE) -> 0.0078422743 | BY11: =VLOOKUP(BR5, Utah!$B:$M, COLUMNS(Utah!$B$31:I$31), FALSE) -> 0.0073252939 | BZ11: =VLOOKUP(BR5, Utah!$B:$M, COLUMNS(Utah!$B$31:J$31), FALSE) -> 0.007175526 | CA11: =VLOOKUP(BR5, Utah!$B:$M, COLUMNS(Utah!$B$31:K$31), FALSE) -> 0.00703747 | CB11: =VLOOKUP(BR5, Utah!$B:$M, COLUMNS(Utah!$B$31:L$31), FALSE) -> 0.0063644016 | CC11: =VLOOKUP(BR5, Utah!$B:$M, COLUMNS(Utah!$B$31:M$31), FALSE) -> 0.0059933953
BF12: State of Utah | BG12: =VLOOKUP(BE5, StateOfUtah!$B:$M, COLUMNS(StateOfUtah!$B$31:D$31), FALSE) -> 0.048247967 | BH12: =VLOOKUP(BE5, StateOfUtah!$B:$M, COLUMNS(StateOfUtah!$B$31:E$31), FALSE) -> 0.048146251 | BI12: =VLOOKUP(BE5, StateOfUtah!$B:$M, COLUMNS(StateOfUtah!$B$31:F$31), FALSE) -> 0.047170408 | BJ12: =VLOOKUP(BE5, StateOfUtah!$B:$M, COLUMNS(StateOfUtah!$B$31:G$31), FALSE) -> 0.048242532 | BK12: =VLOOKUP(BE5, StateOfUtah!$B:$M, COLUMNS(StateOfUtah!$B$31:H$31), FALSE) -> 0.048818053 | BL12: =VLOOKUP(BE5, StateOfUtah!$B:$M, COLUMNS(StateOfUtah!$B$31:I$31), FALSE) -> 0.051301419 | BM12: =VLOOKUP(BE5, StateOfUtah!$B:$M, COLUMNS(StateOfUtah!$B$31:J$31), FALSE) -> 0.053654326 | BN12: =VLOOKUP(BE5, StateOfUtah!$B:$M, COLUMNS(StateOfUtah!$B$31:K$31), FALSE) -> 0.057712073 | BO12: =VLOOKUP(BE5, StateOfUtah!$B:$M, COLUMNS(StateOfUtah!$B$31:L$31), FALSE) -> 0.061576176 | BP12: =VLOOKUP(BE5, StateOfUtah!$B:$M, COLUMNS(StateOfUtah!$B$31:M$31), FALSE) -> 0.065641119 | BS12: State of Utah | BT12: =VLOOKUP(BR5, StateOfUtah!$B:$M, COLUMNS(StateOfUtah!$B$31:D$31), FALSE) -> 0.0031894729 | BU12: =VLOOKUP(BR5, StateOfUtah!$B:$M, COLUMNS(StateOfUtah!$B$31:E$31), FALSE) -> 0.0032712257 | BV12: =VLOOKUP(BR5, StateOfUtah!$B:$M, COLUMNS(StateOfUtah!$B$31:F$31), FALSE) -> 0.0030786093 | BW12: =VLOOKUP(BR5, StateOfUtah!$B:$M, COLUMNS(StateOfUtah!$B$31:G$31), FALSE) -> 0.0032256451 | BX12: =VLOOKUP(BR5, StateOfUtah!$B:$M, COLUMNS(StateOfUtah!$B$31:H$31), FALSE) -> 0.003071745 | BY12: =VLOOKUP(BR5, StateOfUtah!$B:$M, COLUMNS(StateOfUtah!$B$31:I$31), FALSE) -> 0.0031690738 | BZ12: =VLOOKUP(BR5, StateOfUtah!$B:$M, COLUMNS(StateOfUtah!$B$31:J$31), FALSE) -> 0.003446266 | CA12: =VLOOKUP(BR5, StateOfUtah!$B:$M, COLUMNS(StateOfUtah!$B$31:K$31), FALSE) -> 0.0036338294 | CB12: =VLOOKUP(BR5, StateOfUtah!$B:$M, COLUMNS(StateOfUtah!$B$31:L$31), FALSE) -> 0.0030311613 | CC12: =VLOOKUP(BR5, StateOfUtah!$B:$M, COLUMNS(StateOfUtah!$B$31:M$31), FALSE) -> 0.0028719764
BF13: USA | BG13: =VLOOKUP(BE5, USA!$B:$M, COLUMNS(USA!$B$31:D$31), FALSE) -> 0.041360975 | BH13: =VLOOKUP(BE5, USA!$B:$M, COLUMNS(USA!$B$31:E$31), FALSE) -> 0.042224129 | BI13: =VLOOKUP(BE5, USA!$B:$M, COLUMNS(USA!$B$31:F$31), FALSE) -> 0.042729813 | BJ13: =VLOOKUP(BE5, USA!$B:$M, COLUMNS(USA!$B$31:G$31), FALSE) -> 0.043254384 | BK13: =VLOOKUP(BE5, USA!$B:$M, COLUMNS(USA!$B$31:H$31), FALSE) -> 0.043665739 | BL13: =VLOOKUP(BE5, USA!$B:$M, COLUMNS(USA!$B$31:I$31), FALSE) -> 0.044232594 | BM13: =VLOOKUP(BE5, USA!$B:$M, COLUMNS(USA!$B$31:J$31), FALSE) -> 0.045672811 | BN13: =VLOOKUP(BE5, USA!$B:$M, COLUMNS(USA!$B$31:K$31), FALSE) -> 0.047344292 | BO13: =VLOOKUP(BE5, USA!$B:$M, COLUMNS(USA!$B$31:L$31), FALSE) -> 0.049298542 | BP13: =VLOOKUP(BE5, USA!$B:$M, COLUMNS(USA!$B$31:M$31), FALSE) -> 0.051713986 | BS13: USA | BT13: =VLOOKUP(BR5, USA!$B:$M, COLUMNS(USA!$B$31:D$31), FALSE) -> 0.00086686991 | BU13: =VLOOKUP(BR5, USA!$B:$M, COLUMNS(USA!$B$31:E$31), FALSE) -> 0.00095171487 | BV13: =VLOOKUP(BR5, USA!$B:$M, COLUMNS(USA!$B$31:F$31), FALSE) -> 0.00098940167 | BW13: =VLOOKUP(BR5, USA!$B:$M, COLUMNS(USA!$B$31:G$31), FALSE) -> 0.0010213637 | BX13: =VLOOKUP(BR5, USA!$B:$M, COLUMNS(USA!$B$31:H$31), FALSE) -> 0.0010052064 | BY13: =VLOOKUP(BR5, USA!$B:$M, COLUMNS(USA!$B$31:I$31), FALSE) -> 0.00099827901 | BZ13: =VLOOKUP(BR5, USA!$B:$M, COLUMNS(USA!$B$31:J$31), FALSE) -> 0.0010259272 | CA13: =VLOOKUP(BR5, USA!$B:$M, COLUMNS(USA!$B$31:K$31), FALSE) -> 0.0010335774 | CB13: =VLOOKUP(BR5, USA!$B:$M, COLUMNS(USA!$B$31:L$31), FALSE) -> 0.0011229118 | CC13: =VLOOKUP(BR5, USA!$B:$M, COLUMNS(USA!$B$31:M$31), FALSE) -> 0.0011134719
BR15: 203 | BS15: Drove Alone | CE15: 202 | CF15: Share of Workers that Used Auto
BT16: 2010 | BU16: 2011 | BV16: 2012 | BW16: 2013 | BX16: 2014 | BY16: 2015 | BZ16: 2016 | CA16: 2017 | CB16: 2018 | CC16: 2019 | CG16: 2010 | CH16: 2011 | CI16: 2012 | CJ16: 2013 | CK16: 2014 | CL16: 2015 | CM16: 2016 | CN16: 2017 | CO16: 2018 | CP16: 2019
BE17: 108 | BF17: Share of Workers that Used Public Transportation | BS17: Wasatch Front | BT17: =VLOOKUP(BR15, WasatchFront!$B:$M, COLUMNS(WasatchFront!$B$31:D$31), FALSE) -> 0.01098502 | BU17: =VLOOKUP(BR15, WasatchFront!$B:$M, COLUMNS(WasatchFront!$B$31:E$31), FALSE) -> 0.011261249 | BV17: =VLOOKUP(BR15, WasatchFront!$B:$M, COLUMNS(WasatchFront!$B$31:F$31), FALSE) -> 0.011072117 | BW17: =VLOOKUP(BR15, WasatchFront!$B:$M, COLUMNS(WasatchFront!$B$31:G$31), FALSE) -> 0.010832617 | BX17: =VLOOKUP(BR15, WasatchFront!$B:$M, COLUMNS(WasatchFront!$B$31:H$31), FALSE) -> 0.010838936 | BY17: =VLOOKUP(BR15, WasatchFront!$B:$M, COLUMNS(WasatchFront!$B$31:I$31), FALSE) -> 0.010652209 | BZ17: =VLOOKUP(BR15, WasatchFront!$B:$M, COLUMNS(WasatchFront!$B$31:J$31), FALSE) -> 0.01071664 | CA17: =VLOOKUP(BR15, WasatchFront!$B:$M, COLUMNS(WasatchFront!$B$31:K$31), FALSE) -> 0.010391027 | CB17: =VLOOKUP(BR15, WasatchFront!$B:$M, COLUMNS(WasatchFront!$B$31:L$31), FALSE) -> 0.010142915 | CC17: =VLOOKUP(BR15, WasatchFront!$B:$M, COLUMNS(WasatchFront!$B$31:M$31), FALSE) -> 0.0099742035 | CF17: Wasatch Front | CG17: =VLOOKUP(CE15, WasatchFront!$B:$M, COLUMNS(WasatchFront!$B$31:D$31), FALSE) -> 0.0087713552 | CH17: =VLOOKUP(CE15, WasatchFront!$B:$M, COLUMNS(WasatchFront!$B$31:E$31), FALSE) -> 0.0090789862 | CI17: =VLOOKUP(CE15, WasatchFront!$B:$M, COLUMNS(WasatchFront!$B$31:F$31), FALSE) -> 0.0090604122 | CJ17: =VLOOKUP(CE15, WasatchFront!$B:$M, COLUMNS(WasatchFront!$B$31:G$31), FALSE) -> 0.0087782988 | CK17: =VLOOKUP(CE15, WasatchFront!$B:$M, COLUMNS(WasatchFront!$B$31:H$31), FALSE) -> 0.0086781986 | CL17: =VLOOKUP(CE15, WasatchFront!$B:$M, COLUMNS(WasatchFront!$B$31:I$31), FALSE) -> 0.008579185 | CM17: =VLOOKUP(CE15, WasatchFront!$B:$M, COLUMNS(WasatchFront!$B$31:J$31), FALSE) -> 0.0094566722 | CN17: =VLOOKUP(CE15, WasatchFront!$B:$M, COLUMNS(WasatchFront!$B$31:K$31), FALSE) -> 0.0083900596 | CO17: =VLOOKUP(CE15, WasatchFront!$B:$M, COLUMNS(WasatchFront!$B$31:L$31), FALSE) -> 0.0081783585 | CP17: =VLOOKUP(CE15, WasatchFront!$B:$M, COLUMNS(WasatchFront!$B$31:M$31), FALSE) -> 0.0087975358
BG18: 2010 | BH18: 2011 | BI18: 2012 | BJ18: 2013 | BK18: 2014 | BL18: 2015 | BM18: 2016 | BN18: 2017 | BO18: 2018 | BP18: 2019 | BS18: Weber | BT18: =VLOOKUP(BR15, Weber!$B:$M, COLUMNS(Weber!$B$31:D$31), FALSE) -> 0.01883315 | BU18: =VLOOKUP(BR15, Weber!$B:$M, COLUMNS(Weber!$B$31:E$31), FALSE) -> 0.017578717 | BV18: =VLOOKUP(BR15, Weber!$B:$M, COLUMNS(Weber!$B$31:F$31), FALSE) -> 0.017579227 | BW18: =VLOOKUP(BR15, Weber!$B:$M, COLUMNS(Weber!$B$31:G$31), FALSE) -> 0.01489836 | BX18: =VLOOKUP(BR15, Weber!$B:$M, COLUMNS(Weber!$B$31:H$31), FALSE) -> 0.018440238 | BY18: =VLOOKUP(BR15, Weber!$B:$M, COLUMNS(Weber!$B$31:I$31), FALSE) -> 0.017425258 | BZ18: =VLOOKUP(BR15, Weber!$B:$M, COLUMNS(Weber!$B$31:J$31), FALSE) -> 0.019609606 | CA18: =VLOOKUP(BR15, Weber!$B:$M, COLUMNS(Weber!$B$31:K$31), FALSE) -> 0.016504453 | CB18: =VLOOKUP(BR15, Weber!$B:$M, COLUMNS(Weber!$B$31:L$31), FALSE) -> 0.014542353 | CC18: =VLOOKUP(BR15, Weber!$B:$M, COLUMNS(Weber!$B$31:M$31), FALSE) -> 0.017256964 | CF18: Weber | CG18: =VLOOKUP(CE15, Weber!$B:$M, COLUMNS(Weber!$B$31:D$31), FALSE) -> 0.014125788 | CH18: =VLOOKUP(CE15, Weber!$B:$M, COLUMNS(Weber!$B$31:E$31), FALSE) -> 0.013595929 | CI18: =VLOOKUP(CE15, Weber!$B:$M, COLUMNS(Weber!$B$31:F$31), FALSE) -> 0.013019944 | CJ18: =VLOOKUP(CE15, Weber!$B:$M, COLUMNS(Weber!$B$31:G$31), FALSE) -> 0.012519675 | CK18: =VLOOKUP(CE15, Weber!$B:$M, COLUMNS(Weber!$B$31:H$31), FALSE) -> 0.015069079 | CL18: =VLOOKUP(CE15, Weber!$B:$M, COLUMNS(Weber!$B$31:I$31), FALSE) -> 0.014864058 | CM18: =VLOOKUP(CE15, Weber!$B:$M, COLUMNS(Weber!$B$31:J$31), FALSE) -> 0.015489039 | CN18: =VLOOKUP(CE15, Weber!$B:$M, COLUMNS(Weber!$B$31:K$31), FALSE) -> 0.013547392 | CO18: =VLOOKUP(CE15, Weber!$B:$M, COLUMNS(Weber!$B$31:L$31), FALSE) -> 0.01221261 | CP18: =VLOOKUP(CE15, Weber!$B:$M, COLUMNS(Weber!$B$31:M$31), FALSE) -> 0.01471518
BF19: Wasatch Front | BG19: =VLOOKUP(BE17, WasatchFront!$B:$M, COLUMNS(WasatchFront!$B$31:D$31), FALSE) -> 0.02854331 | BH19: =VLOOKUP(BE17, WasatchFront!$B:$M, COLUMNS(WasatchFront!$B$31:E$31), FALSE) -> 0.027351122 | BI19: =VLOOKUP(BE17, WasatchFront!$B:$M, COLUMNS(WasatchFront!$B$31:F$31), FALSE) -> 0.027752214 | BJ19: =VLOOKUP(BE17, WasatchFront!$B:$M, COLUMNS(WasatchFront!$B$31:G$31), FALSE) -> 0.027719086 | BK19: =VLOOKUP(BE17, WasatchFront!$B:$M, COLUMNS(WasatchFront!$B$31:H$31), FALSE) -> 0.028044621 | BL19: =VLOOKUP(BE17, WasatchFront!$B:$M, COLUMNS(WasatchFront!$B$31:I$31), FALSE) -> 0.02915997 | BM19: =VLOOKUP(BE17, WasatchFront!$B:$M, COLUMNS(WasatchFront!$B$31:J$31), FALSE) -> 0.030253447 | BN19: =VLOOKUP(BE17, WasatchFront!$B:$M, COLUMNS(WasatchFront!$B$31:K$31), FALSE) -> 0.029647008 | BO19: =VLOOKUP(BE17, WasatchFront!$B:$M, COLUMNS(WasatchFront!$B$31:L$31), FALSE) -> 0.029126292 | BP19: =VLOOKUP(BE17, WasatchFront!$B:$M, COLUMNS(WasatchFront!$B$31:M$31), FALSE) -> 0.028806875 | BS19: Davis | BT19: =VLOOKUP(BR15, Davis!$B:$M, COLUMNS(Davis!$B$31:D$31), FALSE) -> 0.015301505 | BU19: =VLOOKUP(BR15, Davis!$B:$M, COLUMNS(Davis!$B$31:E$31), FALSE) -> 0.01468002 | BV19: =VLOOKUP(BR15, Davis!$B:$M, COLUMNS(Davis!$B$31:F$31), FALSE) -> 0.011854629 | BW19: =VLOOKUP(BR15, Davis!$B:$M, COLUMNS(Davis!$B$31:G$31), FALSE) -> 0.014304152 | BX19: =VLOOKUP(BR15, Davis!$B:$M, COLUMNS(Davis!$B$31:H$31), FALSE) -> 0.014501311 | BY19: =VLOOKUP(BR15, Davis!$B:$M, COLUMNS(Davis!$B$31:I$31), FALSE) -> 0.014864072 | BZ19: =VLOOKUP(BR15, Davis!$B:$M, COLUMNS(Davis!$B$31:J$31), FALSE) -> 0.012619948 | CA19: =VLOOKUP(BR15, Davis!$B:$M, COLUMNS(Davis!$B$31:K$31), FALSE) -> 0.015273331 | CB19: =VLOOKUP(BR15, Davis!$B:$M, COLUMNS(Davis!$B$31:L$31), FALSE) -> 0.013741697 | CC19: =VLOOKUP(BR15, Davis!$B:$M, COLUMNS(Davis!$B$31:M$31), FALSE) -> 0.012080415 | CF19: Davis | CG19: =VLOOKUP(CE15, Davis!$B:$M, COLUMNS(Davis!$B$31:D$31), FALSE) -> 0.01105704 | CH19: =VLOOKUP(CE15, Davis!$B:$M, COLUMNS(Davis!$B$31:E$31), FALSE) -> 0.012078023 | CI19: =VLOOKUP(CE15, Davis!$B:$M, COLUMNS(Davis!$B$31:F$31), FALSE) -> 0.011750909 | CJ19: =VLOOKUP(CE15, Davis!$B:$M, COLUMNS(Davis!$B$31:G$31), FALSE) -> 0.011554381 | CK19: =VLOOKUP(CE15, Davis!$B:$M, COLUMNS(Davis!$B$31:H$31), FALSE) -> 0.011554222 | CL19: =VLOOKUP(CE15, Davis!$B:$M, COLUMNS(Davis!$B$31:I$31), FALSE) -> 0.012066606 | CM19: =VLOOKUP(CE15, Davis!$B:$M, COLUMNS(Davis!$B$31:J$31), FALSE) -> 0.011833226 | CN19: =VLOOKUP(CE15, Davis!$B:$M, COLUMNS(Davis!$B$31:K$31), FALSE) -> 0.012938922 | CO19: =VLOOKUP(CE15, Davis!$B:$M, COLUMNS(Davis!$B$31:L$31), FALSE) -> 0.011708333 | CP19: =VLOOKUP(CE15, Davis!$B:$M, COLUMNS(Davis!$B$31:M$31), FALSE) -> 0.010177201
BF20: Weber | BG20: =VLOOKUP(BE17, Weber!$B:$M, COLUMNS(Weber!$B$31:D$31), FALSE) -> 0.020539153 | BH20: =VLOOKUP(BE17, Weber!$B:$M, COLUMNS(Weber!$B$31:E$31), FALSE) -> 0.016600722 | BI20: =VLOOKUP(BE17, Weber!$B:$M, COLUMNS(Weber!$B$31:F$31), FALSE) -> 0.017952058 | BJ20: =VLOOKUP(BE17, Weber!$B:$M, COLUMNS(Weber!$B$31:G$31), FALSE) -> 0.018182337 | BK20: =VLOOKUP(BE17, Weber!$B:$M, COLUMNS(Weber!$B$31:H$31), FALSE) -> 0.018644953 | BL20: =VLOOKUP(BE17, Weber!$B:$M, COLUMNS(Weber!$B$31:I$31), FALSE) -> 0.018322172 | BM20: =VLOOKUP(BE17, Weber!$B:$M, COLUMNS(Weber!$B$31:J$31), FALSE) -> 0.01844485 | BN20: =VLOOKUP(BE17, Weber!$B:$M, COLUMNS(Weber!$B$31:K$31), FALSE) -> 0.018274956 | BO20: =VLOOKUP(BE17, Weber!$B:$M, COLUMNS(Weber!$B$31:L$31), FALSE) -> 0.015397943 | BP20: =VLOOKUP(BE17, Weber!$B:$M, COLUMNS(Weber!$B$31:M$31), FALSE) -> 0.016747575 | BS20: Salt Lake | BT20: =VLOOKUP(BR15, SaltLake!$B:$M, COLUMNS(SaltLake!$B$31:D$31), FALSE) -> 0.0068310092 | BU20: =VLOOKUP(BR15, SaltLake!$B:$M, COLUMNS(SaltLake!$B$31:E$31), FALSE) -> 0.0082701439 | BV20: =VLOOKUP(BR15, SaltLake!$B:$M, COLUMNS(SaltLake!$B$31:F$31), FALSE) -> 0.0081892463 | BW20: =VLOOKUP(BR15, SaltLake!$B:$M, COLUMNS(SaltLake!$B$31:G$31), FALSE) -> 0.0086464552 | BX20: =VLOOKUP(BR15, SaltLake!$B:$M, COLUMNS(SaltLake!$B$31:H$31), FALSE) -> 0.0074854748 | BY20: =VLOOKUP(BR15, SaltLake!$B:$M, COLUMNS(SaltLake!$B$31:I$31), FALSE) -> 0.0076273782 | BZ20: =VLOOKUP(BR15, SaltLake!$B:$M, COLUMNS(SaltLake!$B$31:J$31), FALSE) -> 0.0084535961 | CA20: =VLOOKUP(BR15, SaltLake!$B:$M, COLUMNS(SaltLake!$B$31:K$31), FALSE) -> 0.0078740346 | CB20: =VLOOKUP(BR15, SaltLake!$B:$M, COLUMNS(SaltLake!$B$31:L$31), FALSE) -> 0.0086463378 | CC20: =VLOOKUP(BR15, SaltLake!$B:$M, COLUMNS(SaltLake!$B$31:M$31), FALSE) -> 0.0081470845 | CF20: Salt Lake | CG20: =VLOOKUP(CE15, SaltLake!$B:$M, COLUMNS(SaltLake!$B$31:D$31), FALSE) -> 0.0058570636 | CH20: =VLOOKUP(CE15, SaltLake!$B:$M, COLUMNS(SaltLake!$B$31:E$31), FALSE) -> 0.0062428186 | CI20: =VLOOKUP(CE15, SaltLake!$B:$M, COLUMNS(SaltLake!$B$31:F$31), FALSE) -> 0.0067501029 | CJ20: =VLOOKUP(CE15, SaltLake!$B:$M, COLUMNS(SaltLake!$B$31:G$31), FALSE) -> 0.0066051659 | CK20: =VLOOKUP(CE15, SaltLake!$B:$M, COLUMNS(SaltLake!$B$31:H$31), FALSE) -> 0.0060567096 | CL20: =VLOOKUP(CE15, SaltLake!$B:$M, COLUMNS(SaltLake!$B$31:I$31), FALSE) -> 0.005770943 | CM20: =VLOOKUP(CE15, SaltLake!$B:$M, COLUMNS(SaltLake!$B$31:J$31), FALSE) -> 0.0074588013 | CN20: =VLOOKUP(CE15, SaltLake!$B:$M, COLUMNS(SaltLake!$B$31:K$31), FALSE) -> 0.0060263942 | CO20: =VLOOKUP(CE15, SaltLake!$B:$M, COLUMNS(SaltLake!$B$31:L$31), FALSE) -> 0.0064569695 | CP20: =VLOOKUP(CE15, SaltLake!$B:$M, COLUMNS(SaltLake!$B$31:M$31), FALSE) -> 0.0074648081
