Workbook
Name lu_CoName: LookupIdx!$B$3:$C$35
Name lu_GEOID: LookupIdx!$A$3:$C$35
Name lu_WrkType: LookupIdx!$F$3:$G$73
Name lu_WrkTypeID_Est: LookupIdx!$H$3:$I$73
Name lu_WrkTypeID_MOE: LookupIdx!$J$3:$K$73

Sheet Forecast
A1: Forecast Share of Work At Home, Telecommute & Home-Based Workers
B3: 0.56 | C3: share of employment eligible to telecommute
B4: 5-Year ACS (2010-2019 Trend) | H4: 1-Year ACS (2010-2019 Trend) | N4: 5-Year ACS (2010-2014 Trend) | T4: Post Covid - Upper | Z4: Post Covid - Lower | AF4: Final
B5: Home-Based | C5: Telecommute | D5: Work At Home | E5: % of Workers Who Can Work At Home | H5: Home-Based | I5: Telecommute | J5: Work At Home | K5: % of Workers Who Can Work At Home | N5: Home-Based | O5: Telecommute | P5: Work At Home | Q5: % of Workers Who Can Work At Home | T5: Home-Based | U5: Telecommute | V5: Work At Home | W5: % of Workers Who Can Work At Home | Z5: Home-Based | AA5: Telecommute | AB5: Work At Home | AC5: % of Workers Who Can Work At Home | AF5: Home-Based | AG5: Telecommute | AH5: Work At Home | AI5: % of Workers Who Can Work At Home
A6: 2010 | B6: =HLOOKUP($A6, WAH_byCounty!$AZ$6:$BI$9, 2, FALSE) -> 0.024156393 | C6: =HLOOKUP($A6, WAH_byCounty!$AZ$6:$BI$9, 3, FALSE) -> 0.02188431 | D6: =SUM(B6:C6) -> 0.046040703 | H6: =B6/D6 * J6 -> 0.022378086 | I6: =C6/D6 * J6 -> 0.020273265 | J6: 0.042651351 | AF6: =$B6 -> 0.024156393 | AG6: =$C6 -> 0.02188431 | AH6: =SUM(AF6:AG6) -> 0.046040703 | AI6: =AF6/$B$3 -> 0.043136416 | AJ6: =AG6/$B$3 -> 0.039079125 | AK6: =AH6/$B$3 -> 0.082215541
A7: 2011 | B7: =HLOOKUP($A7, WAH_byCounty!$AZ$6:$BI$9, 2, FALSE) -> 0.023616541 | C7: =HLOOKUP($A7, WAH_byCounty!$AZ$6:$BI$9, 3, FALSE) -> 0.023317437 | D7: =SUM(B7:C7) -> 0.046933978 | E7: =B7/$B$3 -> 0.042172394 | F7: =C7/$B$3 -> 0.041638281 | G7: =D7/$B$3 -> 0.083810675 | H7: =B7/D7 * J7 -> 0.023758557 | I7: =C7/D7 * J7 -> 0.023457655 | J7: 0.047216212 | AF7: =$B7 -> 0.023616541 | AG7: =$C7 -> 0.023317437 | AH7: =SUM(AF7:AG7) -> 0.046933978 | AI7: =AF7/$B$3 -> 0.042172394 | AJ7: =AG7/$B$3 -> 0.041638281 | AK7: =AH7/$B$3 -> 0.083810675
A8: 2012 | B8: =HLOOKUP($A8, WAH_byCounty!$AZ$6:$BI$9, 2, FALSE) -> 0.022667213 | C8: =HLOOKUP($A8, WAH_byCounty!$AZ$6:$BI$9, 3, FALSE) -> 0.023317753 | D8: =SUM(B8:C8) -> 0.045984966 | E8: =B8/$B$3 -> 0.040477166 | F8: =C8/$B$3 -> 0.041638844 | G8: =D8/$B$3 -> 0.082116011 | H8: =B8/D8 * J8 -> 0.023339433 | I8: =C8/D8 * J8 -> 0.024009265 | J8: 0.047348698 | AF8: =$B8 -> 0.022667213 | AG8: =$C8 -> 0.023317753 | AH8: =SUM(AF8:AG8) -> 0.045984966 | AI8: =AF8/$B$3 -> 0.040477166 | AJ8: =AG8/$B$3 -> 0.041638844 | AK8: =AH8/$B$3 -> 0.082116011
A9: 2013 | B9: =HLOOKUP($A9, WAH_byCounty!$AZ$6:$BI$9, 2, FALSE) -> 0.022171769 | C9: =HLOOKUP($A9, WAH_byCounty!$AZ$6:$BI$9, 3, FALSE) -> 0.02528403 | D9: =SUM(B9:C9) -> 0.047455799 | E9: =B9/$B$3 -> 0.039592445 | F9: =C9/$B$3 -> 0.045150053 | G9: =D9/$B$3 -> 0.084742498 | H9: =B9/D9 * J9 -> 0.023907051 | I9: =C9/D9 * J9 -> 0.027262894 | J9: 0.051169945 | AF9: =$B9 -> 0.022171769 | AG9: =$C9 -> 0.02528403 | AH9: =SUM(AF9:AG9) -> 0.047455799 | AI9: =AF9/$B$3 -> 0.039592445 | AJ9: =AG9/$B$3 -> 0.045150053 | AK9: =AH9/$B$3 -> 0.084742498
A10: 2014 | B10: =HLOOKUP($A10, WAH_byCounty!$AZ$6:$BI$9, 2, FALSE) -> 0.022228968 | C10: =HLOOKUP($A10, WAH_byCounty!$AZ$6:$BI$9, 3, FALSE) -> 0.0266197 | D10: =SUM(B10:C10) -> 0.048848668 | E10: =B10/$B$3 -> 0.039694585 | F10: =C10/$B$3 -> 0.047535179 | G10: =D10/$B$3 -> 0.087229764 | H10: =B10/D10 * J10 -> 0.025486223 | I10: =C10/D10 * J10 -> 0.030520339 | J10: 0.056006562 | AF10: =$B10 -> 0.022228968 | AG10: =$C10 -> 0.0266197 | AH10: =SUM(AF10:AG10) -> 0.048848668 | AI10: =AF10/$B$3 -> 0.039694585 | AJ10: =AG10/$B$3 -> 0.047535179 | AK10: =AH10/$B$3 -> 0.087229764
A11: 2015 | B11: =HLOOKUP($A11, WAH_byCounty!$AZ$6:$BI$9, 2, FALSE) -> 0.022692701 | C11: =HLOOKUP($A11, WAH_byCounty!$AZ$6:$BI$9, 3, FALSE) -> 0.028966157 | D11: =SUM(B11:C11) -> 0.051658859 | E11: =B11/$B$3 -> 0.040522681 | F11: =C11/$B$3 -> 0.051725281 | G11: =D11/$B$3 -> 0.092247962 | H11: =B11/D11 * J11 -> 0.024860784 | I11: =C11/D11 * J11 -> 0.031733612 | J11: 0.056594397 | AF11: =$B11 -> 0.022692701 | AG11: =$C11 -> 0.028966157 | AH11: =SUM(AF11:AG11) -> 0.051658859 | AI11: =AF11/$B$3 -> 0.040522681 | AJ11: =AG11/$B$3 -> 0.051725281 | AK11: =AH11/$B$3 -> 0.092247962
A12: 2016 | B12: =HLOOKUP($A12, WAH_byCounty!$AZ$6:$BI$9, 2, FALSE) -> 0.023436385 | C12: =HLOOKUP($A12, WAH_byCounty!$AZ$6:$BI$9, 3, FALSE) -> 0.029703592 | D12: =SUM(B12:C12) -> 0.053139977 | E12: =B12/$B$3 -> 0.041850688 | F12: =C12/$B$3 -> 0.053042128 | G12: =D12/$B$3 -> 0.094892816 | H12: =B12/D12 * J12 -> 0.025492764 | I12: =C12/D12 * J12 -> 0.032309874 | J12: 0.057802638 | AF12: =$B12 -> 0.023436385 | AG12: =$C12 -> 0.029703592 | AH12: =SUM(AF12:AG12) -> 0.053139977 | AI12: =AF12/$B$3 -> 0.041850688 | AJ12: =AG12/$B$3 -> 0.053042128 | AK12: =AH12/$B$3 -> 0.094892816
A13: 2017 | B13: =HLOOKUP($A13, WAH_byCounty!$AZ$6:$BI$9, 2, FALSE) -> 0.025113206 | C13: =HLOOKUP($A13, WAH_byCounty!$AZ$6:$BI$9, 3, FALSE) -> 0.032081021 | D13: =SUM(B13:C13) -> 0.057194228 | E13: =B13/$B$3 -> 0.044845011 | F13: =C13/$B$3 -> 0.057287538 | G13: =D13/$B$3 -> 0.10213255 | H13: =B13/D13 * J13 -> 0.029327256 | I13: =C13/D13 * J13 -> 0.037464286 | J13: 0.066791542 | AF13: =$B13 -> 0.025113206 | AG13: =$C13 -> 0.032081021 | AH13: =SUM(AF13:AG13) -> 0.057194228 | AI13: =AF13/$B$3 -> 0.044845011 | AJ13: =AG13/$B$3 -> 0.057287538 | AK13: =AH13/$B$3 -> 0.10213255
A14: 2018 | B14: =HLOOKUP($A14, WAH_byCounty!$AZ$6:$BI$9, 2, FALSE) -> 0.026391708 | C14: =HLOOKUP($A14, WAH_byCounty!$AZ$6:$BI$9, 3, FALSE) -> 0.033935668 | D14: =SUM(B14:C14) -> 0.060327376 | E14: =B14/$B$3 -> 0.04712805 | F14: =C14/$B$3 -> 0.060599407 | G14: =D14/$B$3 -> 0.10772746 | H14: =B14/D14 * J14 -> 0.028318982 | I14: =C14/D14 * J14 -> 0.036413845 | J14: 0.064732827 | AF14: =$B14 -> 0.026391708 | AG14: =$C14 -> 0.033935668 | AH14: =SUM(AF14:AG14) -> 0.060327376 | AI14: =AF14/$B$3 -> 0.04712805 | AJ14: =AG14/$B$3 -> 0.060599407 | AK14: =AH14/$B$3 -> 0.10772746
A15: 2019 | B15: =HLOOKUP($A15, WAH_byCounty!$AZ$6:$BI$9, 2, FALSE) -> 0.026666597 | C15: =HLOOKUP($A15, WAH_byCounty!$AZ$6:$BI$9, 3, FALSE) -> 0.036494763 | D15: =SUM(B15:C15) -> 0.06316136 | E15: =B15/$B$3 -> 0.047618923 | F15: =C15/$B$3 -> 0.06516922 | G15: =D15/$B$3 -> 0.11278814 | H15: =B15/D15 * J15 -> 0.029748085 | I15: =C15/D15 * J15 -> 0.040711957 | J15: 0.070460042 | K15: =H15/$B$3 -> 0.053121581 | L15: =I15/$B$3 -> 0.072699923 | M15: =J15/$B$3 -> 0.1258215 | Q15: =N15/$B$3 -> 0 | R15: =O15/$B$3 -> 0 | S15: =P15/$B$3 -> 0 | T15: =B15 -> 0.026666597 | U15: =C15 -> 0.036494763 | V15: =SUM(T15:U15) -> 0.06316136 | W15: =T15/$B$3 -> 0.047618923 | X15: =U15/$B$3 -> 0.06516922 | Y15: =V15/$B$3 -> 0.11278814 | Z15: =B15 -> 0.026666597 | AA15: =C15 -> 0.036494763 | AB15: =SUM(Z15:AA15) -> 0.06316136 | AC15: =Z15/$B$3 -> 0.047618923 | AD15: =AA15/$B$3 -> 0.06516922 | AE15: =AB15/$B$3 -> 0.11278814 | AF15: =$B15 -> 0.026666597 | AG15: =$C15 -> 0.036494763 | AH15: =SUM(AF15:AG15) -> 0.06316136 | AI15: =AF15/$B$3 -> 0.047618923 | AJ15: =AG15/$B$3 -> 0.06516922 | AK15: =AH15/$B$3 -> 0.11278814 | AL15: =1/AD15 -> 15.344667 | AM15: =1/AE15 -> 8.8661802
A16: 2020 | B16: =FORECAST($A16, $B$6:$B$15, $A$6:$A$15) + 0.002 -> 0.027864333 | C16: =FORECAST($A16, $C$6:$C$15, $A$6:$A$15) + 0.001 -> 0.038001883 | D16: =SUM(B16:C16) -> 0.065866216 | E16: =B16/$B$3 -> 0.049757738 | F16: =C16/$B$3 -> 0.067860505 | G16: =D16/$B$3 -> 0.11761824 | H16: =FORECAST($A16, $H$6:$H$15, $A$6:$A$15) + 0.002 -> 0.032072515 | I16: =FORECAST($A16, $I$6:$I$15, $A$6:$A$15) + 0.001 -> 0.043358062 | J16: =SUM(H16:I16) -> 0.075430577 | K16: =H16/$B$3 -> 0.057272348 | L16: =I16/$B$3 -> 0.07742511 | M16: =J16/$B$3 -> 0.13469746 | N16: =$B$15 -> 0.026666597 | O16: =FORECAST($A16, $C$10:$C$15, $A$10:$A$15) + 0.001 -> 0.038966278 | P16: =SUM(N16:O16) -> 0.065632875 | Q16: =N16/$B$3 -> 0.047618923 | R16: =O16/$B$3 -> 0.069582639 | S16: =P16/$B$3 -> 0.11720156 | T16: 0.08 | U16: 0.35 | V16: =SUM(T16:U16) -> 0.43 | W16: =T16/$B$3 -> 0.14285714 | X16: =U16/$B$3 -> 0.625 | Y16: =V16/$B$3 -> 0.76785714 | Z16: 0.06 | AA16: 0.35 | AB16: =SUM(Z16:AA16) -> 0.41 | AC16: =Z16/$B$3 -> 0.10714286 | AD16: =AA16/$B$3 -> 0.625 | AE16: =AB16/$B$3 -> 0.73214286 | AF16: 0.06 | AG16: 0.35 | AH16: =SUM(AF16:AG16) -> 0.41 | AI16: =AF16/$B$3 -> 0.10714286 | AJ16: =AG16/$B$3 -> 0.625 | AK16: =AH16/$B$3 -> 0.73214286 | AL16: =1/AD16 -> 1.6 | AM16: =1/AE16 -> 1.3658537
A17: 2021 | B17: =FORECAST($A17, $B$6:$B$15, $A$6:$A$15) + 0.002 -> 0.028218912 | C17: =FORECAST($A17, $C$6:$C$15, $A$6:$A$15) + 0.001 -> 0.039609417 | D17: =SUM(B17:C17) -> 0.067828329 | E17: =B17/$B$3 -> 0.050390915 | F17: =C17/$B$3 -> 0.070731102 | G17: =D17/$B$3 -> 0.12112202 | H17: =FORECAST($A17, $H$6:$H$15, $A$6:$A$15) + 0.002 -> 0.032874477 | I17: =FORECAST($A17, $I$6:$I$15, $A$6:$A$15) + 0.001 -> 0.0455294 | J17: =SUM(H17:I17) -> 0.078403877 | K17: =H17/$B$3 -> 0.058704424 | L17: =I17/$B$3 -> 0.0813025 | M17: =J17/$B$3 -> 0.14000692 | N17: =$B$15 -> 0.026666597 | O17: =FORECAST($A17, $C$10:$C$15, $A$10:$A$15) + 0.001 -> 0.040870886 | P17: =SUM(N17:O17) -> 0.067537483 | Q17: =N17/$B$3 -> 0.047618923 | R17: =O17/$B$3 -> 0.072983725 | S17: =P17/$B$3 -> 0.12060265 | T17: 0.06 | U17: 0.2 | V17: =SUM(T17:U17) -> 0.26 | W17: =T17/$B$3 -> 0.10714286 | X17: =U17/$B$3 -> 0.35714286 | Y17: =V17/$B$3 -> 0.46428571 | Z17: 0.04 | AA17: 0.15 | AB17: =SUM(Z17:AA17) -> 0.19 | AC17: =Z17/$B$3 -> 0.071428571 | AD17: =AA17/$B$3 -> 0.26785714 | AE17: =AB17/$B$3 -> 0.33928571 | AF17: 0.04 | AG17: 0.17 | AH17: =SUM(AF17:AG17) -> 0.21 | AI17: =AF17/$B$3 -> 0.071428571 | AJ17: =AG17/$B$3 -> 0.30357143 | AK17: =AH17/$B$3 -> 0.375 | AL17: =1/AD17 -> 3.7333333 | AM17: =1/AE17 -> 2.9473684
A18: 2022 | B18: =FORECAST($A18, $B$6:$B$15, $A$6:$A$15) + 0.002 -> 0.028573491 | C18: =FORECAST($A18, $C$6:$C$15, $A$6:$A$15) + 0.001 -> 0.041216951 | D18: =SUM(B18:C18) -> 0.069790443 | E18: =B18/$B$3 -> 0.051024092 | F18: =C18/$B$3 -> 0.073601699 | G18: =D18/$B$3 -> 0.12462579 | H18: =FORECAST($A18, $H$6:$H$15, $A$6:$A$15) + 0.002 -> 0.03367644 | I18: =FORECAST($A18, $I$6:$I$15, $A$6:$A$15) + 0.001 -> 0.047700739 | J18: =SUM(H18:I18) -> 0.081377178 | K18: =H18/$B$3 -> 0.060136499 | L18: =I18/$B$3 -> 0.085179891 | M18: =J18/$B$3 -> 0.14531639 | N18: =$B$15 -> 0.026666597 | O18: =FORECAST($A18, $C$10:$C$15, $A$10:$A$15) + 0.001 -> 0.042775494 | P18: =SUM(N18:O18) -> 0.069442091 | Q18: =N18/$B$3 -> 0.047618923 | R18: =O18/$B$3 -> 0.07638481 | S18: =P18/$B$3 -> 0.12400373 | T18: 0.044 | U18: 0.15 | V18: =SUM(T18:U18) -> 0.194 | W18: =T18/$B$3 -> 0.078571429 | X18: =U18/$B$3 -> 0.26785714 | Y18: =V18/$B$3 -> 0.34642857 | Z18: 0.0325 | AA18: 0.1 | AB18: =SUM(Z18:AA18) -> 0.1325 | AC18: =Z18/$B$3 -> 0.058035714 | AD18: =AA18/$B$3 -> 0.17857143 | AE18: =AB18/$B$3 -> 0.23660714 | AF18: 0.0325 | AG18: 0.115 | AH18: =SUM(AF18:AG18) -> 0.1475 | AI18: =AF18/$B$3 -> 0.058035714 | AJ18: =AG18/$B$3 -> 0.20535714 | AK18: =AH18/$B$3 -> 0.26339286 | AL18: =1/AD18 -> 5.6 | AM18: =1/AE18 -> 4.2264151
A19: 2023 | B19: =FORECAST($A19, $B$6:$B$15, $A$6:$A$15) + 0.002 -> 0.028928071 | C19: =FORECAST($A19, $C$6:$C$15, $A$6:$A$15) + 0.001 -> 0.042824486 | D19: =SUM(B19:C19) -> 0.071752556 | E19: =B19/$B$3 -> 0.051657269 | F19: =C19/$B$3 -> 0.076472296 | G19: =D19/$B$3 -> 0.12812957 | H19: =FORECAST($A19, $H$6:$H$15, $A$6:$A$15) + 0.002 -> 0.034478402 | I19: =FORECAST($A19, $I$6:$I$15, $A$6:$A$15) + 0.001 -> 0.049872077 | J19: =SUM(H19:I19) -> 0.084350479 | K19: =H19/$B$3 -> 0.061568575 | L19: =I19/$B$3 -> 0.089057281 | M19: =J19/$B$3 -> 0.15062586 | N19: =$B$15 -> 0.026666597 | O19: =FORECAST($A19, $C$10:$C$15, $A$10:$A$15) + 0.001 -> 0.044680102 | P19: =SUM(N19:O19) -> 0.071346698 | Q19: =N19/$B$3 -> 0.047618923 | R19: =O19/$B$3 -> 0.079785896 | S19: =P19/$B$3 -> 0.12740482 | T19: 0.0375 | U19: 0.12 | V19: =SUM(T19:U19) -> 0.1575 | W19: =T19/$B$3 -> 0.066964286 | X19: =U19/$B$3 -> 0.21428571 | Y19: =V19/$B$3 -> 0.28125 | Z19: 0.03 | AA19: 0.083 | AB19: =SUM(Z19:AA19) -> 0.113 | AC19: =Z19/$B$3 -> 0.053571429 | AD19: =AA19/$B$3 -> 0.14821429 | AE19: =AB19/$B$3 -> 0.20178571 | AF19: 0.03 | AG19: 0.092 | AH19: =SUM(AF19:AG19) -> 0.122 | AI19: =AF19/$B$3 -> 0.053571429 | AJ19: =AG19/$B$3 -> 0.16428571 | AK19: =AH19/$B$3 -> 0.21785714 | AL19: =1/AD19 -> 6.746988 | AM19: =1/AE19 -> 4.9557522
A20: 2024 | B20: =FORECAST($A20, $B$6:$B$15, $A$6:$A$15) + 0.002 -> 0.02928265 | C20: =FORECAST($A20, $C$6:$C$15, $A$6:$A$15) + 0.001 -> 0.04443202 | D20: =SUM(B20:C20) -> 0.07371467 | E20: =B20/$B$3 -> 0.052290446 | F20: =C20/$B$3 -> 0.079342893 | G20: =D20/$B$3 -> 0.13163334 | H20: =FORECAST($A20, $H$6:$H$15, $A$6:$A$15) + 0.002 -> 0.035280364 | I20: =FORECAST($A20, $I$6:$I$15, $A$6:$A$15) + 0.001 -> 0.052043416 | J20: =SUM(H20:I20) -> 0.08732378 | K20: =H20/$B$3 -> 0.063000651 | L20: =I20/$B$3 -> 0.092934671 | M20: =J20/$B$3 -> 0.15593532 | N20: =$B$15 -> 0.026666597 | O20: =FORECAST($A20, $C$10:$C$15, $A$10:$A$15) + 0.001 -> 0.04658471 | P20: =SUM(N20:O20) -> 0.073251306 | Q20: =N20/$B$3 -> 0.047618923 | R20: =O20/$B$3 -> 0.083186981 | S20: =P20/$B$3 -> 0.1308059 | T20: 0.035 | U20: 0.1025 | V20: =SUM(T20:U20) -> 0.1375 | W20: =T20/$B$3 -> 0.0625 | X20: =U20/$B$3 -> 0.18303571 | Y20: =V20/$B$3 -> 0.24553571 | Z20: =Z19 -> 0.03 | AA20: 0.08 | AB20: =SUM(Z20:AA20) -> 0.11 | AC20: =Z20/$B$3 -> 0.053571429 | AD20: =AA20/$B$3 -> 0.14285714 | AE20: =AB20/$B$3 -> 0.19642857 | AF20: =AF19 -> 0.03 | AG20: 0.08 | AH20: =SUM(AF20:AG20) -> 0.11 | AI20: =AF20/$B$3 -> 0.053571429 | AJ20: =AG20/$B$3 -> 0.14285714 | AK20: =AH20/$B$3 -> 0.19642857 | AL20: =1/AD20 -> 7 | AM20: =1/AE20 -> 5.0909091
A21: 2025 | B21: =FORECAST($A21, $B$6:$B$15, $A$6:$A$15) + 0.002 -> 0.029637229 | C21: =FORECAST($A21, $C$6:$C$15, $A$6:$A$15) + 0.001 -> 0.046039555 | D21: =SUM(B21:C21) -> 0.075676783 | E21: =B21/$B$3 -> 0.052923623 | F21: =C21/$B$3 -> 0.082213491 | G21: =D21/$B$3 -> 0.13513711 | H21: =FORECAST($A21, $H$6:$H$15, $A$6:$A$15) + 0.002 -> 0.036082327 | I21: =FORECAST($A21, $I$6:$I$15, $A$6:$A$15) + 0.001 -> 0.054214755 | J21: =SUM(H21:I21) -> 0.090297081 | K21: =H21/$B$3 -> 0.064432726 | L21: =I21/$B$3 -> 0.096812062 | M21: =J21/$B$3 -> 0.16124479 | N21: =$B$15 -> 0.026666597 | O21: =FORECAST($A21, $C$10:$C$15, $A$10:$A$15) + 0.001 -> 0.048489317 | P21: =SUM(N21:O21) -> 0.075155914 | Q21: =N21/$B$3 -> 0.047618923 | R21: =O21/$B$3 -> 0.086588067 | S21: =P21/$B$3 -> 0.13420699 | T21: =T20 -> 0.035 | U21: 0.1 | V21: =SUM(T21:U21) -> 0.135 | W21: =T21/$B$3 -> 0.0625 | X21: =U21/$B$3 -> 0.17857143 | Y21: =V21/$B$3 -> 0.24107143 | Z21: =Z20 -> 0.03 | AA21: =AA20 -> 0.08 | AB21: =SUM(Z21:AA21) -> 0.11 | AC21: =Z21/$B$3 -> 0.053571429 | AD21: =AA21/$B$3 -> 0.14285714 | AE21: =AB21/$B$3 -> 0.19642857 | AF21: =AF20 -> 0.03 | AG21: 0.074 | AH21: =SUM(AF21:AG21) -> 0.104 | AI21: =AF21/$B$3 -> 0.053571429 | AJ21: =AG21/$B$3 -> 0.13214286 | AK21: =AH21/$B$3 -> 0.18571429 | AL21: =1/AD21 -> 7 | AM21: =1/AE21 -> 5.0909091
A22: 2026 | B22: =FORECAST($A22, $B$6:$B$15, $A$6:$A$15) + 0.002 -> 0.029991808 | C22: =FORECAST($A22, $C$6:$C$15, $A$6:$A$15) + 0.001 -> 0.047647089 | D22: =SUM(B22:C22) -> 0.077638897 | E22: =B22/$B$3 -> 0.0535568 | F22: =C22/$B$3 -> 0.085084088 | G22: =D22/$B$3 -> 0.13864089 | H22: =FORECAST($A22, $H$6:$H$15, $A$6:$A$15) + 0.002 -> 0.036884289 | I22: =FORECAST($A22, $I$6:$I$15, $A$6:$A$15) + 0.001 -> 0.056386093 | J22: =SUM(H22:I22) -> 0.093270382 | K22: =H22/$B$3 -> 0.065864802 | L22: =I22/$B$3 -> 0.10068945 | M22: =J22/$B$3 -> 0.16655425 | N22: =$B$15 -> 0.026666597 | O22: =FORECAST($A22, $C$10:$C$15, $A$10:$A$15) + 0.001 -> 0.050393925 | P22: =SUM(N22:O22) -> 0.077060522 | Q22: =N22/$B$3 -> 0.047618923 | R22: =O22/$B$3 -> 0.089989152 | S22: =P22/$B$3 -> 0.13760808 | T22: =T21 -> 0.035 | U22: =U21 -> 0.1 | V22: =SUM(T22:U22) -> 0.135 | W22: =T22/$B$3 -> 0.0625 | X22: =U22/$B$3 -> 0.17857143 | Y22: =V22/$B$3 -> 0.24107143 | Z22: =Z21 -> 0.03 | AA22: =AA21 -> 0.08 | AB22: =SUM(Z22:AA22) -> 0.11 | AC22: =Z22/$B$3 -> 0.053571429 | AD22: =AA22/$B$3 -> 0.14285714 | AE22: =AB22/$B$3 -> 0.19642857 | AF22: =AF21 -> 0.03 | AG22: 0.071 | AH22: =SUM(AF22:AG22) -> 0.101 | AI22: =AF22/$B$3 -> 0.053571429 | AJ22: =AG22/$B$3 -> 0.12678571 | AK22: =AH22/$B$3 -> 0.18035714 | AL22: =1/AD22 -> 7 | AM22: =1/AE22 -> 5.0909091
A23: 2027 | B23: =FORECAST($A23, $B$6:$B$15, $A$6:$A$15) + 0.002 -> 0.030346387 | C23: =FORECAST($A23, $C$6:$C$15, $A$6:$A$15) + 0.001 -> 0.049254624 | D23: =SUM(B23:C23) -> 0.079601011 | E23: =B23/$B$3 -> 0.054189977 | F23: =C23/$B$3 -> 0.087954685 | G23: =D23/$B$3 -> 0.14214466 | H23: =FORECAST($A23, $H$6:$H$15, $A$6:$A$15) + 0.002 -> 0.037686251 | I23: =FORECAST($A23, $I$6:$I$15, $A$6:$A$15) + 0.001 -> 0.058557432 | J23: =SUM(H23:I23) -> 0.096243683 | K23: =H23/$B$3 -> 0.067296877 | L23: =I23/$B$3 -> 0.10456684 | M23: =J23/$B$3 -> 0.17186372 | N23: =$B$15 -> 0.026666597 | O23: =FORECAST($A23, $C$10:$C$15, $A$10:$A$15) + 0.001 -> 0.052298533 | P23: =SUM(N23:O23) -> 0.07896513 | Q23: =N23/$B$3 -> 0.047618923 | R23: =O23/$B$3 -> 0.093390238 | S23: =P23/$B$3 -> 0.14100916 | T23: =T22 -> 0.035 | U23: =U22 -> 0.1 | V23: =SUM(T23:U23) -> 0.135 | W23: =T23/$B$3 -> 0.0625 | X23: =U23/$B$3 -> 0.17857143 | Y23: =V23/$B$3 -> 0.24107143 | Z23: =Z22 -> 0.03 | AA23: =AA22 -> 0.08 | AB23: =SUM(Z23:AA23) -> 0.11 | AC23: =Z23/$B$3 -> 0.053571429 | AD23: =AA23/$B$3 -> 0.14285714 | AE23: =AB23/$B$3 -> 0.19642857 | AF23: =AF22 -> 0.03 | AG23: 0.07 | AH23: =SUM(AF23:AG23) -> 0.1 | AI23: =AF23/$B$3 -> 0.053571429 | AJ23: =AG23/$B$3 -> 0.125 | AK23: =AH23/$B$3 -> 0.17857143 | AL23: =1/AD23 -> 7 | AM23: =1/AE23 -> 5.0909091
A24: 2028 | B24: =FORECAST($A24, $B$6:$B$15, $A$6:$A$15) + 0.002 -> 0.030700966 | C24: =FORECAST($A24, $C$6:$C$15, $A$6:$A$15) + 0.001 -> 0.050862158 | D24: =SUM(B24:C24) -> 0.081563124 | E24: =B24/$B$3 -> 0.054823154 | F24: =C24/$B$3 -> 0.090825282 | G24: =D24/$B$3 -> 0.14564844 | H24: =FORECAST($A24, $H$6:$H$15, $A$6:$A$15) + 0.002 -> 0.038488214 | I24: =FORECAST($A24, $I$6:$I$15, $A$6:$A$15) + 0.001 -> 0.06072877 | J24: =SUM(H24:I24) -> 0.099216984 | K24: =H24/$B$3 -> 0.068728953 | L24: =I24/$B$3 -> 0.10844423 | M24: =J24/$B$3 -> 0.17717319 | N24: =$B$15 -> 0.026666597 | O24: =FORECAST($A24, $C$10:$C$15, $A$10:$A$15) + 0.001 -> 0.054203141 | P24: =SUM(N24:O24) -> 0.080869738 | Q24: =N24/$B$3 -> 0.047618923 | R24: =O24/$B$3 -> 0.096791323 | S24: =P24/$B$3 -> 0.14441025 | T24: =T23 -> 0.035 | U24: =U23 -> 0.1 | V24: =SUM(T24:U24) -> 0.135 | W24: =T24/$B$3 -> 0.0625 | X24: =U24/$B$3 -> 0.17857143 | Y24: =V24/$B$3 -> 0.24107143 | Z24: =Z23 -> 0.03 | AA24: =AA23 -> 0.08 | AB24: =SUM(Z24:AA24) -> 0.11 | AC24: =Z24/$B$3 -> 0.053571429 | AD24: =AA24/$B$3 -> 0.14285714 | AE24: =AB24/$B$3 -> 0.19642857 | AF24: =AF23 -> 0.03 | AG24: 0.07 | AH24: =SUM(AF24:AG24) -> 0.1 | AI24: =AF24/$B$3 -> 0.053571429 | AJ24: =AG24/$B$3 -> 0.125 | AK24: =AH24/$B$3 -> 0.17857143 | AL24: =1/AD24 -> 7 | AM24: =1/AE24 -> 5.0909091
A25: 2029 | B25: =FORECAST($A25, $B$6:$B$15, $A$6:$A$15) + 0.002 -> 0.031055545 | C25: =FORECAST($A25, $C$6:$C$15, $A$6:$A$15) + 0.001 -> 0.052469692 | D25: =SUM(B25:C25) -> 0.083525238 | E25: =B25/$B$3 -> 0.055456331 | F25: =C25/$B$3 -> 0.093695879 | G25: =D25/$B$3 -> 0.14915221 | H25: =FORECAST($A25, $H$6:$H$15, $A$6:$A$15) + 0.002 -> 0.039290176 | I25: =FORECAST($A25, $I$6:$I$15, $A$6:$A$15) + 0.001 -> 0.062900109 | J25: =SUM(H25:I25) -> 0.10219028 | K25: =H25/$B$3 -> 0.070161029 | L25: =I25/$B$3 -> 0.11232162 | M25: =J25/$B$3 -> 0.18248265 | N25: =$B$15 -> 0.026666597 | O25: =FORECAST($A25, $C$10:$C$15, $A$10:$A$15) + 0.001 -> 0.056107749 | P25: =SUM(N25:O25) -> 0.082774346 | Q25: =N25/$B$3 -> 0.047618923 | R25: =O25/$B$3 -> 0.10019241 | S25: =P25/$B$3 -> 0.14781133 | T25: =T24 -> 0.035 | U25: =U24 -> 0.1 | V25: =SUM(T25:U25) -> 0.135 | W25: =T25/$B$3 -> 0.0625 | X25: =U25/$B$3 -> 0.17857143 | Y25: =V25/$B$3 -> 0.24107143 | Z25: =Z24 -> 0.03 | AA25: =AA24 -> 0.08 | AB25: =SUM(Z25:AA25) -> 0.11 | AC25: =Z25/$B$3 -> 0.053571429 | AD25: =AA25/$B$3 -> 0.14285714 | AE25: =AB25/$B$3 -> 0.19642857 | AF25: =AF24 -> 0.03 | AG25: 0.0705 | AH25: =SUM(AF25:AG25) -> 0.1005 | AI25: =AF25/$B$3 -> 0.053571429 | AJ25: =AG25/$B$3 -> 0.12589286 | AK25: =AH25/$B$3 -> 0.17946429 | AL25: =1/AD25 -> 7 | AM25: =1/AE25 -> 5.0909091
A26: 2030 | B26: =FORECAST($A26, $B$6:$B$15, $A$6:$A$15) + 0.002 -> 0.031410124 | C26: =FORECAST($A26, $C$6:$C$15, $A$6:$A$15) + 0.001 -> 0.054077227 | D26: =SUM(B26:C26) -> 0.085487351 | E26: =B26/$B$3 -> 0.056089508 | F26: =C26/$B$3 -> 0.096566477 | G26: =D26/$B$3 -> 0.15265598 | H26: =FORECAST($A26, $H$6:$H$15, $A$6:$A$15) + 0.002 -> 0.040092138 | I26: =FORECAST($A26, $I$6:$I$15, $A$6:$A$15) + 0.001 -> 0.065071448 | J26: =SUM(H26:I26) -> 0.10516359 | K26: =H26/$B$3 -> 0.071593104 | L26: =I26/$B$3 -> 0.11619901 | M26: =J26/$B$3 -> 0.18779212 | N26: =$B$15 -> 0.026666597 | O26: =FORECAST($A26, $C$10:$C$15, $A$10:$A$15) + 0.001 -> 0.058012357 | P26: =SUM(N26:O26) -> 0.084678954 | Q26: =N26/$B$3 -> 0.047618923 | R26: =O26/$B$3 -> 0.10359349 | S26: =P26/$B$3 -> 0.15121242 | T26: =T25 -> 0.035 | U26: =U25 -> 0.1 | V26: =SUM(T26:U26) -> 0.135 | W26: =T26/$B$3 -> 0.0625 | X26: =U26/$B$3 -> 0.17857143 | Y26: =V26/$B$3 -> 0.24107143 | Z26: =Z25 -> 0.03 | AA26: =AA25 -> 0.08 | AB26: =SUM(Z26:AA26) -> 0.11 | AC26: =Z26/$B$3 -> 0.053571429 | AD26: =AA26/$B$3 -> 0.14285714 | AE26: =AB26/$B$3 -> 0.19642857 | AF26: =AF25 -> 0.03 | AG26: 0.072 | AH26: =SUM(AF26:AG26) -> 0.102 | AI26: =AF26/$B$3 -> 0.053571429 | AJ26: =AG26/$B$3 -> 0.12857143 | AK26: =AH26/$B$3 -> 0.18214286 | AL26: =1/AD26 -> 7 | AM26: =1/AE26 -> 5.0909091
A27: 2031 | B27: =FORECAST($A27, $B$6:$B$15, $A$6:$A$15) + 0.002 -> 0.031764703 | C27: =FORECAST($A27, $C$6:$C$15, $A$6:$A$15) + 0.001 -> 0.055684761 | D27: =SUM(B27:C27) -> 0.087449465 | E27: =B27/$B$3 -> 0.056722685 | F27: =C27/$B$3 -> 0.099437074 | G27: =D27/$B$3 -> 0.15615976 | H27: =FORECAST($A27, $H$6:$H$15, $A$6:$A$15) + 0.002 -> 0.040894101 | I27: =FORECAST($A27, $I$6:$I$15, $A$6:$A$15) + 0.001 -> 0.067242786 | J27: =SUM(H27:I27) -> 0.10813689 | K27: =H27/$B$3 -> 0.07302518 | L27: =I27/$B$3 -> 0.1200764 | M27: =J27/$B$3 -> 0.19310158 | N27: =$B$15 -> 0.026666597 | O27: =FORECAST($A27, $C$10:$C$15, $A$10:$A$15) + 0.001 -> 0.059916965 | P27: =SUM(N27:O27) -> 0.086583562 | Q27: =N27/$B$3 -> 0.047618923 | R27: =O27/$B$3 -> 0.10699458 | S27: =P27/$B$3 -> 0.1546135 | T27: =T26 -> 0.035 | U27: =U26 -> 0.1 | V27: =SUM(T27:U27) -> 0.135 | W27: =T27/$B$3 -> 0.0625 | X27: =U27/$B$3 -> 0.17857143 | Y27: =V27/$B$3 -> 0.24107143 | Z27: =Z26 -> 0.03 | AA27: =AA26 -> 0.08 | AB27: =SUM(Z27:AA27) -> 0.11 | AC27: =Z27/$B$3 -> 0.053571429 | AD27: =AA27/$B$3 -> 0.14285714 | AE27: =AB27/$B$3 -> 0.19642857 | AF27: =AF26 -> 0.03 | AG27: =(AG$46-AG$26)/($A$46-$A$26) + AG26 -> 0.0734 | AH27: =SUM(AF27:AG27) -> 0.1034 | AI27: =AF27/$B$3 -> 0.053571429 | AJ27: =AG27/$B$3 -> 0.13107143 | AK27: =AH27/$B$3 -> 0.18464286 | AL27: =1/AD27 -> 7 | AM27: =1/AE27 -> 5.0909091
A28: 2032 | B28: =FORECAST($A28, $B$6:$B$15, $A$6:$A$15) + 0.002 -> 0.032119282 | C28: =FORECAST($A28, $C$6:$C$15, $A$6:$A$15) + 0.001 -> 0.057292296 | D28: =SUM(B28:C28) -> 0.089411578 | E28: =B28/$B$3 -> 0.057355862 | F28: =C28/$B$3 -> 0.10230767 | G28: =D28/$B$3 -> 0.15966353 | H28: =FORECAST($A28, $H$6:$H$15, $A$6:$A$15) + 0.002 -> 0.041696063 | I28: =FORECAST($A28, $I$6:$I$15, $A$6:$A$15) + 0.001 -> 0.069414125 | J28: =SUM(H28:I28) -> 0.11111019 | K28: =H28/$B$3 -> 0.074457255 | L28: =I28/$B$3 -> 0.12395379 | M28: =J28/$B$3 -> 0.19841105 | N28: =$B$15 -> 0.026666597 | O28: =FORECAST($A28, $C$10:$C$15, $A$10:$A$15) + 0.001 -> 0.061821573 | P28: =SUM(N28:O28) -> 0.088488169 | Q28: =N28/$B$3 -> 0.047618923 | R28: =O28/$B$3 -> 0.11039567 | S28: =P28/$B$3 -> 0.15801459 | T28: =T27 -> 0.035 | U28: =U27 -> 0.1 | V28: =SUM(T28:U28) -> 0.135 | W28: =T28/$B$3 -> 0.0625 | X28: =U28/$B$3 -> 0.17857143 | Y28: =V28/$B$3 -> 0.24107143 | Z28: =Z27 -> 0.03 | AA28: =AA27 -> 0.08 | AB28: =SUM(Z28:AA28) -> 0.11 | AC28: =Z28/$B$3 -> 0.053571429 | AD28: =AA28/$B$3 -> 0.14285714 | AE28: =AB28/$B$3 -> 0.19642857 | AF28: =AF27 -> 0.03 | AG28: =(AG$46-AG$26)/($A$46-$A$26) + AG27 -> 0.0748 | AH28: =SUM(AF28:AG28) -> 0.1048 | AI28: =AF28/$B$3 -> 0.053571429 | AJ28: =AG28/$B$3 -> 0.13357143 | AK28: =AH28/$B$3 -> 0.18714286 | AL28: =1/AD28 -> 7 | AM28: =1/AE28 -> 5.0909091
A29: 2033 | B29: =FORECAST($A29, $B$6:$B$15, $A$6:$A$15) + 0.002 -> 0.032473862 | C29: =FORECAST($A29, $C$6:$C$15, $A$6:$A$15) + 0.001 -> 0.05889983 | D29: =SUM(B29:C29) -> 0.091373692 | E29: =B29/$B$3 -> 0.057989039 | F29: =C29/$B$3 -> 0.10517827 | G29: =D29/$B$3 -> 0.16316731 | H29: =FORECAST($A29, $H$6:$H$15, $A$6:$A$15) + 0.002 -> 0.042498025 | I29: =FORECAST($A29, $I$6:$I$15, $A$6:$A$15) + 0.001 -> 0.071585463 | J29: =SUM(H29:I29) -> 0.11408349 | K29: =H29/$B$3 -> 0.075889331 | L29: =I29/$B$3 -> 0.12783118 | M29: =J29/$B$3 -> 0.20372052 | N29: =$B$15 -> 0.026666597 | O29: =FORECAST($A29, $C$10:$C$15, $A$10:$A$15) + 0.001 -> 0.06372618 | P29: =SUM(N29:O29) -> 0.090392777 | Q29: =N29/$B$3 -> 0.047618923 | R29: =O29/$B$3 -> 0.11379675 | S29: =P29/$B$3 -> 0.16141567 | T29: =T28 -> 0.035 | U29: =U28 -> 0.1 | V29: =SUM(T29:U29) -> 0.135 | W29: =T29/$B$3 -> 0.0625 | X29: =U29/$B$3 -> 0.17857143 | Y29: =V29/$B$3 -> 0.24107143 | Z29: =Z28 -> 0.03 | AA29: =AA28 -> 0.08 | AB29: =SUM(Z29:AA29) -> 0.11 | AC29: =Z29/$B$3 -> 0.053571429 | AD29: =AA29/$B$3 -> 0.14285714 | AE29: =AB29/$B$3 -> 0.19642857 | AF29: =AF28 -> 0.03 | AG29: =(AG$46-AG$26)/($A$46-$A$26) + AG28 -> 0.0762 | AH29: =SUM(AF29:AG29) -> 0.1062 | AI29: =AF29/$B$3 -> 0.053571429 | AJ29: =AG29/$B$3 -> 0.13607143 | AK29: =AH29/$B$3 -> 0.18964286 | AL29: =1/AD29 -> 7 | AM29: =1/AE29 -> 5.0909091
A30: 2034 | B30: =FORECAST($A30, $B$6:$B$15, $A$6:$A$15) + 0.002 -> 0.032828441 | C30: =FORECAST($A30, $C$6:$C$15, $A$6:$A$15) + 0.001 -> 0.060507365 | D30: =SUM(B30:C30) -> 0.093335805 | E30: =B30/$B$3 -> 0.058622216 | F30: =C30/$B$3 -> 0.10804887 | G30: =D30/$B$3 -> 0.16667108 | H30: =FORECAST($A30, $H$6:$H$15, $A$6:$A$15) + 0.002 -> 0.043299988 | I30: =FORECAST($A30, $I$6:$I$15, $A$6:$A$15) + 0.001 -> 0.073756802 | J30: =SUM(H30:I30) -> 0.11705679 | K30: =H30/$B$3 -> 0.077321407 | L30: =I30/$B$3 -> 0.13170857 | M30: =J30/$B$3 -> 0.20902998 | N30: =$B$15 -> 0.026666597 | O30: =FORECAST($A30, $C$10:$C$15, $A$10:$A$15) + 0.001 -> 0.065630788 | P30: =SUM(N30:O30) -> 0.092297385 | Q30: =N30/$B$3 -> 0.047618923 | R30: =O30/$B$3 -> 0.11719784 | S30: =P30/$B$3 -> 0.16481676 | T30: =T29 -> 0.035 | U30: =U29 -> 0.1 | V30: =SUM(T30:U30) -> 0.135 | W30: =T30/$B$3 -> 0.0625 | X30: =U30/$B$3 -> 0.17857143 | Y30: =V30/$B$3 -> 0.24107143 | Z30: =Z29 -> 0.03 | AA30: =AA29 -> 0.08 | AB30: =SUM(Z30:AA30) -> 0.11 | AC30: =Z30/$B$3 -> 0.053571429 | AD30: =AA30/$B$3 -> 0.14285714 | AE30: =AB30/$B$3 -> 0.19642857 | AF30: =AF29 -> 0.03 | AG30: =(AG$46-AG$26)/($A$46-$A$26) + AG29 -> 0.0776 | AH30: =SUM(AF30:AG30) -> 0.1076 | AI30: =AF30/$B$3 -> 0.053571429 | AJ30: =AG30/$B$3 -> 0.13857143 | AK30: =AH30/$B$3 -> 0.19214286 | AL30: =1/AD30 -> 7 | AM30: =1/AE30 -> 5.0909091
A31: 2035 | B31: =FORECAST($A31, $B$6:$B$15, $A$6:$A$15) + 0.002 -> 0.03318302 | C31: =FORECAST($A31, $C$6:$C$15, $A$6:$A$15) + 0.001 -> 0.062114899 | D31: =SUM(B31:C31) -> 0.095297919 | E31: =B31/$B$3 -> 0.059255393 | F31: =C31/$B$3 -> 0.11091946 | G31: =D31/$B$3 -> 0.17017486 | H31: =FORECAST($A31, $H$6:$H$15, $A$6:$A$15) + 0.002 -> 0.04410195 | I31: =FORECAST($A31, $I$6:$I$15, $A$6:$A$15) + 0.001 -> 0.075928141 | J31: =SUM(H31:I31) -> 0.12003009 | K31: =H31/$B$3 -> 0.078753482 | L31: =I31/$B$3 -> 0.13558597 | M31: =J31/$B$3 -> 0.21433945 | N31: =$B$15 -> 0.026666597 | O31: =FORECAST($A31, $C$10:$C$15, $A$10:$A$15) + 0.001 -> 0.067535396 | P31: =SUM(N31:O31) -> 0.094201993 | Q31: =N31/$B$3 -> 0.047618923 | R31: =O31/$B$3 -> 0.12059892 | S31: =P31/$B$3 -> 0.16821784 | T31: =T30 -> 0.035 | U31: =U30 -> 0.1 | V31: =SUM(T31:U31) -> 0.135 | W31: =T31/$B$3 -> 0.0625 | X31: =U31/$B$3 -> 0.17857143 | Y31: =V31/$B$3 -> 0.24107143 | Z31: =Z30 -> 0.03 | AA31: =AA30 -> 0.08 | AB31: =SUM(Z31:AA31) -> 0.11 | AC31: =Z31/$B$3 -> 0.053571429 | AD31: =AA31/$B$3 -> 0.14285714 | AE31: =AB31/$B$3 -> 0.19642857 | AF31: =AF30 -> 0.03 | AG31: =(AG$46-AG$26)/($A$46-$A$26) + AG30 -> 0.079 | AH31: =SUM(AF31:AG31) -> 0.109 | AI31: =AF31/$B$3 -> 0.053571429 | AJ31: =AG31/$B$3 -> 0.14107143 | AK31: =AH31/$B$3 -> 0.19464286 | AL31: =1/AD31 -> 7 | AM31: =1/AE31 -> 5.0909091
A32: 2036 | B32: =FORECAST($A32, $B$6:$B$15, $A$6:$A$15) + 0.002 -> 0.033537599 | C32: =FORECAST($A32, $C$6:$C$15, $A$6:$A$15) + 0.001 -> 0.063722433 | D32: =SUM(B32:C32) -> 0.097260032 | E32: =B32/$B$3 -> 0.05988857 | F32: =C32/$B$3 -> 0.11379006 | G32: =D32/$B$3 -> 0.17367863 | H32: =FORECAST($A32, $H$6:$H$15, $A$6:$A$15) + 0.002 -> 0.044903912 | I32: =FORECAST($A32, $I$6:$I$15, $A$6:$A$15) + 0.001 -> 0.078099479 | J32: =SUM(H32:I32) -> 0.12300339 | K32: =H32/$B$3 -> 0.080185558 | L32: =I32/$B$3 -> 0.13946336 | M32: =J32/$B$3 -> 0.21964891 | N32: =$B$15 -> 0.026666597 | O32: =FORECAST($A32, $C$10:$C$15, $A$10:$A$15) + 0.001 -> 0.069440004 | P32: =SUM(N32:O32) -> 0.096106601 | Q32: =N32/$B$3 -> 0.047618923 | R32: =O32/$B$3 -> 0.12400001 | S32: =P32/$B$3 -> 0.17161893 | T32: =T31 -> 0.035 | U32: =U31 -> 0.1 | V32: =SUM(T32:U32) -> 0.135 | W32: =T32/$B$3 -> 0.0625 | X32: =U32/$B$3 -> 0.17857143 | Y32: =V32/$B$3 -> 0.24107143 | Z32: =Z31 -> 0.03 | AA32: =AA31 -> 0.08 | AB32: =SUM(Z32:AA32) -> 0.11 | AC32: =Z32/$B$3 -> 0.053571429 | AD32: =AA32/$B$3 -> 0.14285714 | AE32: =AB32/$B$3 -> 0.19642857 | AF32: =AF31 -> 0.03 | AG32: =(AG$46-AG$26)/($A$46-$A$26) + AG31 -> 0.0804 | AH32: =SUM(AF32:AG32) -> 0.1104 | AI32: =AF32/$B$3 -> 0.053571429 | AJ32: =AG32/$B$3 -> 0.14357143 | AK32: =AH32/$B$3 -> 0.19714286 | AL32: =1/AD32 -> 7 | AM32: =1/AE32 -> 5.0909091
A33: 2037 | B33: =FORECAST($A33, $B$6:$B$15, $A$6:$A$15) + 0.002 -> 0.033892178 | C33: =FORECAST($A33, $C$6:$C$15, $A$6:$A$15) + 0.001 -> 0.065329968 | D33: =SUM(B33:C33) -> 0.099222146 | E33: =B33/$B$3 -> 0.060521746 | F33: =C33/$B$3 -> 0.11666066 | G33: =D33/$B$3 -> 0.1771824 | H33: =FORECAST($A33, $H$6:$H$15, $A$6:$A$15) + 0.002 -> 0.045705875 | I33: =FORECAST($A33, $I$6:$I$15, $A$6:$A$15) + 0.001 -> 0.080270818 | J33: =SUM(H33:I33) -> 0.12597669 | K33: =H33/$B$3 -> 0.081617633 | L33: =I33/$B$3 -> 0.14334075 | M33: =J33/$B$3 -> 0.22495838 | N33: =$B$15 -> 0.026666597 | O33: =FORECAST($A33, $C$10:$C$15, $A$10:$A$15) + 0.001 -> 0.071344612 | P33: =SUM(N33:O33) -> 0.098011209 | Q33: =N33/$B$3 -> 0.047618923 | R33: =O33/$B$3 -> 0.12740109 | S33: =P33/$B$3 -> 0.17502002 | T33: =T32 -> 0.035 | U33: =U32 -> 0.1 | V33: =SUM(T33:U33) -> 0.135 | W33: =T33/$B$3 -> 0.0625 | X33: =U33/$B$3 -> 0.17857143 | Y33: =V33/$B$3 -> 0.24107143 | Z33: =Z32 -> 0.03 | AA33: =AA32 -> 0.08 | AB33: =SUM(Z33:AA33) -> 0.11 | AC33: =Z33/$B$3 -> 0.053571429 | AD33: =AA33/$B$3 -> 0.14285714 | AE33: =AB33/$B$3 -> 0.19642857 | AF33: =AF32 -> 0.03 | AG33: =(AG$46-AG$26)/($A$46-$A$26) + AG32 -> 0.0818 | AH33: =SUM(AF33:AG33) -> 0.1118 | AI33: =AF33/$B$3 -> 0.053571429 | AJ33: =AG33/$B$3 -> 0.14607143 | AK33: =AH33/$B$3 -> 0.19964286 | AL33: =1/AD33 -> 7 | AM33: =1/AE33 -> 5.0909091
A34: 2038 | B34: =FORECAST($A34, $B$6:$B$15, $A$6:$A$15) + 0.002 -> 0.034246757 | C34: =FORECAST($A34, $C$6:$C$15, $A$6:$A$15) + 0.001 -> 0.066937502 | D34: =SUM(B34:C34) -> 0.10118426 | E34: =B34/$B$3 -> 0.061154923 | F34: =C34/$B$3 -> 0.11953125 | G34: =D34/$B$3 -> 0.18068618 | H34: =FORECAST($A34, $H$6:$H$15, $A$6:$A$15) + 0.002 -> 0.046507837 | I34: =FORECAST($A34, $I$6:$I$15, $A$6:$A$15) + 0.001 -> 0.082442156 | J34: =SUM(H34:I34) -> 0.12894999 | K34: =H34/$B$3 -> 0.083049709 | L34: =I34/$B$3 -> 0.14721814 | M34: =J34/$B$3 -> 0.23026785 | N34: =$B$15 -> 0.026666597 | O34: =FORECAST($A34, $C$10:$C$15, $A$10:$A$15) + 0.001 -> 0.07324922 | P34: =SUM(N34:O34) -> 0.099915817 | Q34: =N34/$B$3 -> 0.047618923 | R34: =O34/$B$3 -> 0.13080218 | S34: =P34/$B$3 -> 0.1784211 | T34: =T33 -> 0.035 | U34: =U33 -> 0.1 | V34: =SUM(T34:U34) -> 0.135 | W34: =T34/$B$3 -> 0.0625 | X34: =U34/$B$3 -> 0.17857143 | Y34: =V34/$B$3 -> 0.24107143 | Z34: =Z33 -> 0.03 | AA34: =AA33 -> 0.08 | AB34: =SUM(Z34:AA34) -> 0.11 | AC34: =Z34/$B$3 -> 0.053571429 | AD34: =AA34/$B$3 -> 0.14285714 | AE34: =AB34/$B$3 -> 0.19642857 | AF34: =AF33 -> 0.03 | AG34: =(AG$46-AG$26)/($A$46-$A$26) + AG33 -> 0.0832 | AH34: =SUM(AF34:AG34) -> 0.1132 | AI34: =AF34/$B$3 -> 0.053571429 | AJ34: =AG34/$B$3 -> 0.14857143 | AK34: =AH34/$B$3 -> 0.20214286 | AL34: =1/AD34 -> 7 | AM34: =1/AE34 -> 5.0909091
A35: 2039 | B35: =FORECAST($A35, $B$6:$B$15, $A$6:$A$15) + 0.002 -> 0.034601336 | C35: =FORECAST($A35, $C$6:$C$15, $A$6:$A$15) + 0.001 -> 0.068545037 | D35: =SUM(B35:C35) -> 0.10314637 | E35: =B35/$B$3 -> 0.0617881 | F35: =C35/$B$3 -> 0.12240185 | G35: =D35/$B$3 -> 0.18418995 | H35: =FORECAST($A35, $H$6:$H$15, $A$6:$A$15) + 0.002 -> 0.047309799 | I35: =FORECAST($A35, $I$6:$I$15, $A$6:$A$15) + 0.001 -> 0.084613495 | J35: =SUM(H35:I35) -> 0.13192329 | K35: =H35/$B$3 -> 0.084481785 | L35: =I35/$B$3 -> 0.15109553 | M35: =J35/$B$3 -> 0.23557731 | N35: =$B$15 -> 0.026666597 | O35: =FORECAST($A35, $C$10:$C$15, $A$10:$A$15) + 0.001 -> 0.075153828 | P35: =SUM(N35:O35) -> 0.10182042 | Q35: =N35/$B$3 -> 0.047618923 | R35: =O35/$B$3 -> 0.13420326 | S35: =P35/$B$3 -> 0.18182219 | T35: =T34 -> 0.035 | U35: =U34 -> 0.1 | V35: =SUM(T35:U35) -> 0.135 | W35: =T35/$B$3 -> 0.0625 | X35: =U35/$B$3 -> 0.17857143 | Y35: =V35/$B$3 -> 0.24107143 | Z35: =Z34 -> 0.03 | AA35: =AA34 -> 0.08 | AB35: =SUM(Z35:AA35) -> 0.11 | AC35: =Z35/$B$3 -> 0.053571429 | AD35: =AA35/$B$3 -> 0.14285714 | AE35: =AB35/$B$3 -> 0.19642857 | AF35: =AF34 -> 0.03 | AG35: =(AG$46-AG$26)/($A$46-$A$26) + AG34 -> 0.0846 | AH35: =SUM(AF35:AG35) -> 0.1146 | AI35: =AF35/$B$3 -> 0.053571429 | AJ35: =AG35/$B$3 -> 0.15107143 | AK35: =AH35/$B$3 -> 0.20464286 | AL35: =1/AD35 -> 7 | AM35: =1/AE35 -> 5.0909091
A36: 2040 | B36: =FORECAST($A36, $B$6:$B$15, $A$6:$A$15) + 0.002 -> 0.034955915 | C36: =FORECAST($A36, $C$6:$C$15, $A$6:$A$15) + 0.001 -> 0.070152571 | D36: =SUM(B36:C36) -> 0.10510849 | E36: =B36/$B$3 -> 0.062421277 | F36: =C36/$B$3 -> 0.12527245 | G36: =D36/$B$3 -> 0.18769373 | H36: =FORECAST($A36, $H$6:$H$15, $A$6:$A$15) + 0.002 -> 0.048111762 | I36: =FORECAST($A36, $I$6:$I$15, $A$6:$A$15) + 0.001 -> 0.086784834 | J36: =SUM(H36:I36) -> 0.1348966 | K36: =H36/$B$3 -> 0.08591386 | L36: =I36/$B$3 -> 0.15497292 | M36: =J36/$B$3 -> 0.24088678 | N36: =$B$15 -> 0.026666597 | O36: =FORECAST($A36, $C$10:$C$15, $A$10:$A$15) + 0.001 -> 0.077058436 | P36: =SUM(N36:O36) -> 0.10372503 | Q36: =N36/$B$3 -> 0.047618923 | R36: =O36/$B$3 -> 0.13760435 | S36: =P36/$B$3 -> 0.18522327 | T36: =T35 -> 0.035 | U36: =U35 -> 0.1 | V36: =SUM(T36:U36) -> 0.135 | W36: =T36/$B$3 -> 0.0625 | X36: =U36/$B$3 -> 0.17857143 | Y36: =V36/$B$3 -> 0.24107143 | Z36: =Z35 -> 0.03 | AA36: =AA35 -> 0.08 | AB36: =SUM(Z36:AA36) -> 0.11 | AC36: =Z36/$B$3 -> 0.053571429 | AD36: =AA36/$B$3 -> 0.14285714 | AE36: =AB36/$B$3 -> 0.19642857 | AF36: =AF35 -> 0.03 | AG36: =(AG$46-AG$26)/($A$46-$A$26) + AG35 -> 0.086 | AH36: =SUM(AF36:AG36) -> 0.116 | AI36: =AF36/$B$3 -> 0.053571429 | AJ36: =AG36/$B$3 -> 0.15357143 | AK36: =AH36/$B$3 -> 0.20714286 | AL36: =1/AD36 -> 7 | AM36: =1/AE36 -> 5.0909091
A37: 2041 | B37: =FORECAST($A37, $B$6:$B$15, $A$6:$A$15) + 0.002 -> 0.035310494 | C37: =FORECAST($A37, $C$6:$C$15, $A$6:$A$15) + 0.001 -> 0.071760106 | D37: =SUM(B37:C37) -> 0.1070706 | E37: =B37/$B$3 -> 0.063054454 | F37: =C37/$B$3 -> 0.12814305 | G37: =D37/$B$3 -> 0.1911975 | H37: =FORECAST($A37, $H$6:$H$15, $A$6:$A$15) + 0.002 -> 0.048913724 | I37: =FORECAST($A37, $I$6:$I$15, $A$6:$A$15) + 0.001 -> 0.088956172 | J37: =SUM(H37:I37) -> 0.1378699 | K37: =H37/$B$3 -> 0.087345936 | L37: =I37/$B$3 -> 0.15885031 | M37: =J37/$B$3 -> 0.24619624 | N37: =$B$15 -> 0.026666597 | O37: =FORECAST($A37, $C$10:$C$15, $A$10:$A$15) + 0.001 -> 0.078963044 | P37: =SUM(N37:O37) -> 0.10562964 | Q37: =N37/$B$3 -> 0.047618923 | R37: =O37/$B$3 -> 0.14100543 | S37: =P37/$B$3 -> 0.18862436 | T37: =T36 -> 0.035 | U37: =U36 -> 0.1 | V37: =SUM(T37:U37) -> 0.135 | W37: =T37/$B$3 -> 0.0625 | X37: =U37/$B$3 -> 0.17857143 | Y37: =V37/$B$3 -> 0.24107143 | Z37: =Z36 -> 0.03 | AA37: =AA36 -> 0.08 | AB37: =SUM(Z37:AA37) -> 0.11 | AC37: =Z37/$B$3 -> 0.053571429 | AD37: =AA37/$B$3 -> 0.14285714 | AE37: =AB37/$B$3 -> 0.19642857 | AF37: =AF36 -> 0.03 | AG37: =(AG$46-AG$26)/($A$46-$A$26) + AG36 -> 0.0874 | AH37: =SUM(AF37:AG37) -> 0.1174 | AI37: =AF37/$B$3 -> 0.053571429 | AJ37: =AG37/$B$3 -> 0.15607143 | AK37: =AH37/$B$3 -> 0.20964286 | AL37: =1/AD37 -> 7 | AM37: =1/AE37 -> 5.0909091
A38: 2042 | B38: =FORECAST($A38, $B$6:$B$15, $A$6:$A$15) + 0.002 -> 0.035665074 | C38: =FORECAST($A38, $C$6:$C$15, $A$6:$A$15) + 0.001 -> 0.07336764 | D38: =SUM(B38:C38) -> 0.10903271 | E38: =B38/$B$3 -> 0.063687631 | F38: =C38/$B$3 -> 0.13101364 | G38: =D38/$B$3 -> 0.19470127 | H38: =FORECAST($A38, $H$6:$H$15, $A$6:$A$15) + 0.002 -> 0.049715686 | I38: =FORECAST($A38, $I$6:$I$15, $A$6:$A$15) + 0.001 -> 0.091127511 | J38: =SUM(H38:I38) -> 0.1408432 | K38: =H38/$B$3 -> 0.088778011 | L38: =I38/$B$3 -> 0.1627277 | M38: =J38/$B$3 -> 0.25150571 | N38: =$B$15 -> 0.026666597 | O38: =FORECAST($A38, $C$10:$C$15, $A$10:$A$15) + 0.001 -> 0.080867651 | P38: =SUM(N38:O38) -> 0.10753425 | Q38: =N38/$B$3 -> 0.047618923 | R38: =O38/$B$3 -> 0.14440652 | S38: =P38/$B$3 -> 0.19202544 | T38: =T37 -> 0.035 | U38: =U37 -> 0.1 | V38: =SUM(T38:U38) -> 0.135 | W38: =T38/$B$3 -> 0.0625 | X38: =U38/$B$3 -> 0.17857143 | Y38: =V38/$B$3 -> 0.24107143 | Z38: =Z37 -> 0.03 | AA38: =AA37 -> 0.08 | AB38: =SUM(Z38:AA38) -> 0.11 | AC38: =Z38/$B$3 -> 0.053571429 | AD38: =AA38/$B$3 -> 0.14285714 | AE38: =AB38/$B$3 -> 0.19642857 | AF38: =AF37 -> 0.03 | AG38: =(AG$46-AG$26)/($A$46-$A$26) + AG37 -> 0.0888 | AH38: =SUM(AF38:AG38) -> 0.1188 | AI38: =AF38/$B$3 -> 0.053571429 | AJ38: =AG38/$B$3 -> 0.15857143 | AK38: =AH38/$B$3 -> 0.21214286 | AL38: =1/AD38 -> 7 | AM38: =1/AE38 -> 5.0909091
A39: 2043 | B39: =FORECAST($A39, $B$6:$B$15, $A$6:$A$15) + 0.002 -> 0.036019653 | C39: =FORECAST($A39, $C$6:$C$15, $A$6:$A$15) + 0.001 -> 0.074975174 | D39: =SUM(B39:C39) -> 0.11099483 | E39: =B39/$B$3 -> 0.064320808 | F39: =C39/$B$3 -> 0.13388424 | G39: =D39/$B$3 -> 0.19820505 | H39: =FORECAST($A39, $H$6:$H$15, $A$6:$A$15) + 0.002 -> 0.050517649 | I39: =FORECAST($A39, $I$6:$I$15, $A$6:$A$15) + 0.001 -> 0.093298849 | J39: =SUM(H39:I39) -> 0.1438165 | K39: =H39/$B$3 -> 0.090210087 | L39: =I39/$B$3 -> 0.16660509 | M39: =J39/$B$3 -> 0.25681518 | N39: =$B$15 -> 0.026666597 | O39: =FORECAST($A39, $C$10:$C$15, $A$10:$A$15) + 0.001 -> 0.082772259 | P39: =SUM(N39:O39) -> 0.10943886 | Q39: =N39/$B$3 -> 0.047618923 | R39: =O39/$B$3 -> 0.14780761 | S39: =P39/$B$3 -> 0.19542653 | T39: =(T$56-T$38)/($A$56-$A$38) + T38 -> 0.035277778 | U39: =(U$56-U$31)/($A$56-$A$31) + U31 -> 0.1012 | V39: =SUM(T39:U39) -> 0.13647778 | W39: =T39/$B$3 -> 0.062996032 | X39: =U39/$B$3 -> 0.18071429 | Y39: =V39/$B$3 -> 0.24371032 | Z39: =(Z$56-Z$38)/($A$56-$A$38) + Z38 -> 0.030277778 | AA39: =(AA$56-AA$31)/($A$56-$A$31) + AA31 -> 0.0812 | AB39: =SUM(Z39:AA39) -> 0.11147778 | AC39: =Z39/$B$3 -> 0.05406746 | AD39: =AA39/$B$3 -> 0.145 | AE39: =AB39/$B$3 -> 0.19906746 | AF39: =(AF$56-AF$38)/($A$56-$A$38) + AF38 -> 0.030277778 | AG39: =(AG$46-AG$26)/($A$46-$A$26) + AG38 -> 0.0902 | AH39: =SUM(AF39:AG39) -> 0.12047778 | AI39: =AF39/$B$3 -> 0.05406746 | AJ39: =AG39/$B$3 -> 0.16107143 | AK39: =AH39/$B$3 -> 0.21513889 | AL39: =1/AD39 -> 6.8965517 | AM39: =1/AE39 -> 5.0234227
A40: 2044 | B40: =FORECAST($A40, $B$6:$B$15, $A$6:$A$15) + 0.002 -> 0.036374232 | C40: =FORECAST($A40, $C$6:$C$15, $A$6:$A$15) + 0.001 -> 0.076582709 | D40: =SUM(B40:C40) -> 0.11295694 | E40: =B40/$B$3 -> 0.064953985 | F40: =C40/$B$3 -> 0.13675484 | G40: =D40/$B$3 -> 0.20170882 | H40: =FORECAST($A40, $H$6:$H$15, $A$6:$A$15) + 0.002 -> 0.051319611 | I40: =FORECAST($A40, $I$6:$I$15, $A$6:$A$15) + 0.001 -> 0.095470188 | J40: =SUM(H40:I40) -> 0.1467898 | K40: =H40/$B$3 -> 0.091642163 | L40: =I40/$B$3 -> 0.17048248 | M40: =J40/$B$3 -> 0.26212464 | N40: =$B$15 -> 0.026666597 | O40: =FORECAST($A40, $C$10:$C$15, $A$10:$A$15) + 0.001 -> 0.084676867 | P40: =SUM(N40:O40) -> 0.11134346 | Q40: =N40/$B$3 -> 0.047618923 | R40: =O40/$B$3 -> 0.15120869 | S40: =P40/$B$3 -> 0.19882761 | T40: =(T$56-T$38)/($A$56-$A$38) + T39 -> 0.035555556 | U40: =(U$56-U$38)/($A$56-$A$38) + U39 -> 0.10286667 | V40: =SUM(T40:U40) -> 0.13842222 | W40: =T40/$B$3 -> 0.063492063 | X40: =U40/$B$3 -> 0.18369048 | Y40: =V40/$B$3 -> 0.24718254 | Z40: =(Z$56-Z$38)/($A$56-$A$38) + Z39 -> 0.030555556 | AA40: =(AA$56-AA$38)/($A$56-$A$38) + AA39 -> 0.082866667 | AB40: =SUM(Z40:AA40) -> 0.11342222 | AC40: =Z40/$B$3 -> 0.054563492 | AD40: =AA40/$B$3 -> 0.14797619 | AE40: =AB40/$B$3 -> 0.20253968 | AF40: =(AF$56-AF$38)/($A$56-$A$38) + AF39 -> 0.030555556 | AG40: =(AG$46-AG$26)/($A$46-$A$26) + AG39 -> 0.0916 | AH40: =SUM(AF40:AG40) -> 0.12215556 | AI40: =AF40/$B$3 -> 0.054563492 | AJ40: =AG40/$B$3 -> 0.16357143 | AK40: =AH40/$B$3 -> 0.21813492 | AL40: =1/AD40 -> 6.7578439 | AM40: =1/AE40 -> 4.9373041
A41: 2045 | B41: =FORECAST($A41, $B$6:$B$15, $A$6:$A$15) + 0.002 -> 0.036728811 | C41: =FORECAST($A41, $C$6:$C$15, $A$6:$A$15) + 0.001 -> 0.078190243 | D41: =SUM(B41:C41) -> 0.11491905 | E41: =B41/$B$3 -> 0.065587162 | F41: =C41/$B$3 -> 0.13962543 | G41: =D41/$B$3 -> 0.2052126 | H41: =FORECAST($A41, $H$6:$H$15, $A$6:$A$15) + 0.002 -> 0.052121573 | I41: =FORECAST($A41, $I$6:$I$15, $A$6:$A$15) + 0.001 -> 0.097641527 | J41: =SUM(H41:I41) -> 0.1497631 | K41: =H41/$B$3 -> 0.093074238 | L41: =I41/$B$3 -> 0.17435987 | M41: =J41/$B$3 -> 0.26743411 | N41: =$B$15 -> 0.026666597 | O41: =FORECAST($A41, $C$10:$C$15, $A$10:$A$15) + 0.001 -> 0.086581475 | P41: =SUM(N41:O41) -> 0.11324807 | Q41: =N41/$B$3 -> 0.047618923 | R41: =O41/$B$3 -> 0.15460978 | S41: =P41/$B$3 -> 0.2022287 | T41: =(T$56-T$38)/($A$56-$A$38) + T40 -> 0.035833333 | U41: =(U$56-U$38)/($A$56-$A$38) + U40 -> 0.10453333 | V41: =SUM(T41:U41) -> 0.14036667 | W41: =T41/$B$3 -> 0.063988095 | X41: =U41/$B$3 -> 0.18666667 | Y41: =V41/$B$3 -> 0.25065476 | Z41: =(Z$56-Z$38)/($A$56-$A$38) + Z40 -> 0.030833333 | AA41: =(AA$56-AA$38)/($A$56-$A$38) + AA40 -> 0.084533333 | AB41: =SUM(Z41:AA41) -> 0.11536667 | AC41: =Z41/$B$3 -> 0.055059524 | AD41: =AA41/$B$3 -> 0.15095238 | AE41: =AB41/$B$3 -> 0.2060119 | AF41: =(AF$56-AF$38)/($A$56-$A$38) + AF40 -> 0.030833333 | AG41: =(AG$46-AG$26)/($A$46-$A$26) + AG40 -> 0.093 | AH41: =SUM(AF41:AG41) -> 0.12383333 | AI41: =AF41/$B$3 -> 0.055059524 | AJ41: =AG41/$B$3 -> 0.16607143 | AK41: =AH41/$B$3 -> 0.22113095 | AL41: =1/AD41 -> 6.6246057 | AM41: =1/AE41 -> 4.8540884
...

Sheet Forecast (r1)
A1: Forecast Share of Work At Home, Telecommute & Home-Based Workers
B3: 0.56 | C3: share of employment eligible to telecommute
B4: 5-Year ACS (2010-2019 Trend) | H4: 1-Year ACS (2010-2019 Trend) | N4: 5-Year ACS (2010-2014 Trend) | T4: Post Covid - Upper | Z4: Post Covid - Lower
B5: Home-Based | C5: Telecommute | D5: Work At Home | E5: % of Workers Who Can Work At Home | H5: Home-Based | I5: Telecommute | J5: Work At Home | K5: % of Workers Who Can Work At Home | N5: Home-Based | O5: Telecommute | P5: Work At Home | Q5: % of Workers Who Can Work At Home | T5: Home-Based | U5: Telecommute | V5: Work At Home | W5: % of Workers Who Can Work At Home | Z5: Home-Based | AA5: Telecommute | AB5: Work At Home | AC5: % of Workers Who Can Work At Home
A6: 2010 | B6: =HLOOKUP($A6, WAH_byCounty!$AZ$6:$BI$9, 2, FALSE) -> 0.024156393 | C6: =HLOOKUP($A6, WAH_byCounty!$AZ$6:$BI$9, 3, FALSE) -> 0.02188431 | D6: =SUM(B6:C6) -> 0.046040703 | H6: =B6/D6 * J6 -> 0.022378086 | I6: =C6/D6 * J6 -> 0.020273265 | J6: 0.042651351
A7: 2011 | B7: =HLOOKUP($A7, WAH_byCounty!$AZ$6:$BI$9, 2, FALSE) -> 0.023616541 | C7: =HLOOKUP($A7, WAH_byCounty!$AZ$6:$BI$9, 3, FALSE) -> 0.023317437 | D7: =SUM(B7:C7) -> 0.046933978 | E7: =B7/$B$3 -> 0.042172394 | F7: =C7/$B$3 -> 0.041638281 | G7: =D7/$B$3 -> 0.083810675 | H7: =B7/D7 * J7 -> 0.023758557 | I7: =C7/D7 * J7 -> 0.023457655 | J7: 0.047216212
A8: 2012 | B8: =HLOOKUP($A8, WAH_byCounty!$AZ$6:$BI$9, 2, FALSE) -> 0.022667213 | C8: =HLOOKUP($A8, WAH_byCounty!$AZ$6:$BI$9, 3, FALSE) -> 0.023317753 | D8: =SUM(B8:C8) -> 0.045984966 | E8: =B8/$B$3 -> 0.040477166 | F8: =C8/$B$3 -> 0.041638844 | G8: =D8/$B$3 -> 0.082116011 | H8: =B8/D8 * J8 -> 0.023339433 | I8: =C8/D8 * J8 -> 0.024009265 | J8: 0.047348698
A9: 2013 | B9: =HLOOKUP($A9, WAH_byCounty!$AZ$6:$BI$9, 2, FALSE) -> 0.022171769 | C9: =HLOOKUP($A9, WAH_byCounty!$AZ$6:$BI$9, 3, FALSE) -> 0.02528403 | D9: =SUM(B9:C9) -> 0.047455799 | E9: =B9/$B$3 -> 0.039592445 | F9: =C9/$B$3 -> 0.045150053 | G9: =D9/$B$3 -> 0.084742498 | H9: =B9/D9 * J9 -> 0.023907051 | I9: =C9/D9 * J9 -> 0.027262894 | J9: 0.051169945
A10: 2014 | B10: =HLOOKUP($A10, WAH_byCounty!$AZ$6:$BI$9, 2, FALSE) -> 0.022228968 | C10: =HLOOKUP($A10, WAH_byCounty!$AZ$6:$BI$9, 3, FALSE) -> 0.0266197 | D10: =SUM(B10:C10) -> 0.048848668 | E10: =B10/$B$3 -> 0.039694585 | F10: =C10/$B$3 -> 0.047535179 | G10: =D10/$B$3 -> 0.087229764 | H10: =B10/D10 * J10 -> 0.025486223 | I10: =C10/D10 * J10 -> 0.030520339 | J10: 0.056006562
A11: 2015 | B11: =HLOOKUP($A11, WAH_byCounty!$AZ$6:$BI$9, 2, FALSE) -> 0.022692701 | C11: =HLOOKUP($A11, WAH_byCounty!$AZ$6:$BI$9, 3, FALSE) -> 0.028966157 | D11: =SUM(B11:C11) -> 0.051658859 | E11: =B11/$B$3 -> 0.040522681 | F11: =C11/$B$3 -> 0.051725281 | G11: =D11/$B$3 -> 0.092247962 | H11: =B11/D11 * J11 -> 0.024860784 | I11: =C11/D11 * J11 -> 0.031733612 | J11: 0.056594397
A12: 2016 | B12: =HLOOKUP($A12, WAH_byCounty!$AZ$6:$BI$9, 2, FALSE) -> 0.023436385 | C12: =HLOOKUP($A12, WAH_byCounty!$AZ$6:$BI$9, 3, FALSE) -> 0.029703592 | D12: =SUM(B12:C12) -> 0.053139977 | E12: =B12/$B$3 -> 0.041850688 | F12: =C12/$B$3 -> 0.053042128 | G12: =D12/$B$3 -> 0.094892816 | H12: =B12/D12 * J12 -> 0.025492764 | I12: =C12/D12 * J12 -> 0.032309874 | J12: 0.057802638
A13: 2017 | B13: =HLOOKUP($A13, WAH_byCounty!$AZ$6:$BI$9, 2, FALSE) -> 0.025113206 | C13: =HLOOKUP($A13, WAH_byCounty!$AZ$6:$BI$9, 3, FALSE) -> 0.032081021 | D13: =SUM(B13:C13) -> 0.057194228 | E13: =B13/$B$3 -> 0.044845011 | F13: =C13/$B$3 -> 0.057287538 | G13: =D13/$B$3 -> 0.10213255 | H13: =B13/D13 * J13 -> 0.029327256 | I13: =C13/D13 * J13 -> 0.037464286 | J13: 0.066791542
A14: 2018 | B14: =HLOOKUP($A14, WAH_byCounty!$AZ$6:$BI$9, 2, FALSE) -> 0.026391708 | C14: =HLOOKUP($A14, WAH_byCounty!$AZ$6:$BI$9, 3, FALSE) -> 0.033935668 | D14: =SUM(B14:C14) -> 0.060327376 | E14: =B14/$B$3 -> 0.04712805 | F14: =C14/$B$3 -> 0.060599407 | G14: =D14/$B$3 -> 0.10772746 | H14: =B14/D14 * J14 -> 0.028318982 | I14: =C14/D14 * J14 -> 0.036413845 | J14: 0.064732827
A15: 2019 | B15: =HLOOKUP($A15, WAH_byCounty!$AZ$6:$BI$9, 2, FALSE) -> 0.026666597 | C15: =HLOOKUP($A15, WAH_byCounty!$AZ$6:$BI$9, 3, FALSE) -> 0.036494763 | D15: =SUM(B15:C15) -> 0.06316136 | E15: =B15/$B$3 -> 0.047618923 | F15: =C15/$B$3 -> 0.06516922 | G15: =D15/$B$3 -> 0.11278814 | H15: =B15/D15 * J15 -> 0.029748085 | I15: =C15/D15 * J15 -> 0.040711957 | J15: 0.070460042 | K15: =H15/$B$3 -> 0.053121581 | L15: =I15/$B$3 -> 0.072699923 | M15: =J15/$B$3 -> 0.1258215 | Q15: =N15/$B$3 -> 0 | R15: =O15/$B$3 -> 0 | S15: =P15/$B$3 -> 0 | T15: =B15 -> 0.026666597 | U15: =C15 -> 0.036494763 | V15: =SUM(T15:U15) -> 0.06316136 | W15: =T15/$B$3 -> 0.047618923 | X15: =U15/$B$3 -> 0.06516922 | Y15: =V15/$B$3 -> 0.11278814 | Z15: =B15 -> 0.026666597 | AA15: =C15 -> 0.036494763 | AB15: =SUM(Z15:AA15) -> 0.06316136 | AC15: =Z15/$B$3 -> 0.047618923 | AD15: =AA15/$B$3 -> 0.06516922 | AE15: =AB15/$B$3 -> 0.11278814 | AF15: =1/AD15 -> 15.344667 | AG15: =1/AE15 -> 8.8661802
A16: 2020 | B16: =FORECAST($A16, $B$6:$B$15, $A$6:$A$15) + 0.002 -> 0.027864333 | C16: =FORECAST($A16, $C$6:$C$15, $A$6:$A$15) + 0.001 -> 0.038001883 | D16: =SUM(B16:C16) -> 0.065866216 | E16: =B16/$B$3 -> 0.049757738 | F16: =C16/$B$3 -> 0.067860505 | G16: =D16/$B$3 -> 0.11761824 | H16: =FORECAST($A16, $H$6:$H$15, $A$6:$A$15) + 0.002 -> 0.032072515 | I16: =FORECAST($A16, $I$6:$I$15, $A$6:$A$15) + 0.001 -> 0.043358062 | J16: =SUM(H16:I16) -> 0.075430577 | K16: =H16/$B$3 -> 0.057272348 | L16: =I16/$B$3 -> 0.07742511 | M16: =J16/$B$3 -> 0.13469746 | N16: =$B$15 -> 0.026666597 | O16: =FORECAST($A16, $C$10:$C$15, $A$10:$A$15) + 0.001 -> 0.038966278 | P16: =SUM(N16:O16) -> 0.065632875 | Q16: =N16/$B$3 -> 0.047618923 | R16: =O16/$B$3 -> 0.069582639 | S16: =P16/$B$3 -> 0.11720156 | T16: 0.08 | U16: 0.35 | V16: =SUM(T16:U16) -> 0.43 | W16: =T16/$B$3 -> 0.14285714 | X16: =U16/$B$3 -> 0.625 | Y16: =V16/$B$3 -> 0.76785714 | Z16: 0.06 | AA16: 0.35 | AB16: =SUM(Z16:AA16) -> 0.41 | AC16: =Z16/$B$3 -> 0.10714286 | AD16: =AA16/$B$3 -> 0.625 | AE16: =AB16/$B$3 -> 0.73214286 | AF16: =1/AD16 -> 1.6 | AG16: =1/AE16 -> 1.3658537
A17: 2021 | B17: =FORECAST($A17, $B$6:$B$15, $A$6:$A$15) + 0.002 -> 0.028218912 | C17: =FORECAST($A17, $C$6:$C$15, $A$6:$A$15) + 0.001 -> 0.039609417 | D17: =SUM(B17:C17) -> 0.067828329 | E17: =B17/$B$3 -> 0.050390915 | F17: =C17/$B$3 -> 0.070731102 | G17: =D17/$B$3 -> 0.12112202 | H17: =FORECAST($A17, $H$6:$H$15, $A$6:$A$15) + 0.002 -> 0.032874477 | I17: =FORECAST($A17, $I$6:$I$15, $A$6:$A$15) + 0.001 -> 0.0455294 | J17: =SUM(H17:I17) -> 0.078403877 | K17: =H17/$B$3 -> 0.058704424 | L17: =I17/$B$3 -> 0.0813025 | M17: =J17/$B$3 -> 0.14000692 | N17: =$B$15 -> 0.026666597 | O17: =FORECAST($A17, $C$10:$C$15, $A$10:$A$15) + 0.001 -> 0.040870886 | P17: =SUM(N17:O17) -> 0.067537483 | Q17: =N17/$B$3 -> 0.047618923 | R17: =O17/$B$3 -> 0.072983725 | S17: =P17/$B$3 -> 0.12060265 | T17: 0.06 | U17: 0.2 | V17: =SUM(T17:U17) -> 0.26 | W17: =T17/$B$3 -> 0.10714286 | X17: =U17/$B$3 -> 0.35714286 | Y17: =V17/$B$3 -> 0.46428571 | Z17: 0.04 | AA17: 0.15 | AB17: =SUM(Z17:AA17) -> 0.19 | AC17: =Z17/$B$3 -> 0.071428571 | AD17: =AA17/$B$3 -> 0.26785714 | AE17: =AB17/$B$3 -> 0.33928571 | AF17: =1/AD17 -> 3.7333333 | AG17: =1/AE17 -> 2.9473684
A18: 2022 | B18: =FORECAST($A18, $B$6:$B$15, $A$6:$A$15) + 0.002 -> 0.028573491 | C18: =FORECAST($A18, $C$6:$C$15, $A$6:$A$15) + 0.001 -> 0.041216951 | D18: =SUM(B18:C18) -> 0.069790443 | E18: =B18/$B$3 -> 0.051024092 | F18: =C18/$B$3 -> 0.073601699 | G18: =D18/$B$3 -> 0.12462579 | H18: =FORECAST($A18, $H$6:$H$15, $A$6:$A$15) + 0.002 -> 0.03367644 | I18: =FORECAST($A18, $I$6:$I$15, $A$6:$A$15) + 0.001 -> 0.047700739 | J18: =SUM(H18:I18) -> 0.081377178 | K18: =H18/$B$3 -> 0.060136499 | L18: =I18/$B$3 -> 0.085179891 | M18: =J18/$B$3 -> 0.14531639 | N18: =$B$15 -> 0.026666597 | O18: =FORECAST($A18, $C$10:$C$15, $A$10:$A$15) + 0.001 -> 0.042775494 | P18: =SUM(N18:O18) -> 0.069442091 | Q18: =N18/$B$3 -> 0.047618923 | R18: =O18/$B$3 -> 0.07638481 | S18: =P18/$B$3 -> 0.12400373 | T18: 0.044 | U18: 0.15 | V18: =SUM(T18:U18) -> 0.194 | W18: =T18/$B$3 -> 0.078571429 | X18: =U18/$B$3 -> 0.26785714 | Y18: =V18/$B$3 -> 0.34642857 | Z18: 0.0325 | AA18: 0.1 | AB18: =SUM(Z18:AA18) -> 0.1325 | AC18: =Z18/$B$3 -> 0.058035714 | AD18: =AA18/$B$3 -> 0.17857143 | AE18: =AB18/$B$3 -> 0.23660714 | AF18: =1/AD18 -> 5.6 | AG18: =1/AE18 -> 4.2264151
A19: 2023 | B19: =FORECAST($A19, $B$6:$B$15, $A$6:$A$15) + 0.002 -> 0.028928071 | C19: =FORECAST($A19, $C$6:$C$15, $A$6:$A$15) + 0.001 -> 0.042824486 | D19: =SUM(B19:C19) -> 0.071752556 | E19: =B19/$B$3 -> 0.051657269 | F19: =C19/$B$3 -> 0.076472296 | G19: =D19/$B$3 -> 0.12812957 | H19: =FORECAST($A19, $H$6:$H$15, $A$6:$A$15) + 0.002 -> 0.034478402 | I19: =FORECAST($A19, $I$6:$I$15, $A$6:$A$15) + 0.001 -> 0.049872077 | J19: =SUM(H19:I19) -> 0.084350479 | K19: =H19/$B$3 -> 0.061568575 | L19: =I19/$B$3 -> 0.089057281 | M19: =J19/$B$3 -> 0.15062586 | N19: =$B$15 -> 0.026666597 | O19: =FORECAST($A19, $C$10:$C$15, $A$10:$A$15) + 0.001 -> 0.044680102 | P19: =SUM(N19:O19) -> 0.071346698 | Q19: =N19/$B$3 -> 0.047618923 | R19: =O19/$B$3 -> 0.079785896 | S19: =P19/$B$3 -> 0.12740482 | T19: 0.0375 | U19: 0.12 | V19: =SUM(T19:U19) -> 0.1575 | W19: =T19/$B$3 -> 0.066964286 | X19: =U19/$B$3 -> 0.21428571 | Y19: =V19/$B$3 -> 0.28125 | Z19: 0.03 | AA19: 0.083 | AB19: =SUM(Z19:AA19) -> 0.113 | AC19: =Z19/$B$3 -> 0.053571429 | AD19: =AA19/$B$3 -> 0.14821429 | AE19: =AB19/$B$3 -> 0.20178571 | AF19: =1/AD19 -> 6.746988 | AG19: =1/AE19 -> 4.9557522
A20: 2024 | B20: =FORECAST($A20, $B$6:$B$15, $A$6:$A$15) + 0.002 -> 0.02928265 | C20: =FORECAST($A20, $C$6:$C$15, $A$6:$A$15) + 0.001 -> 0.04443202 | D20: =SUM(B20:C20) -> 0.07371467 | E20: =B20/$B$3 -> 0.052290446 | F20: =C20/$B$3 -> 0.079342893 | G20: =D20/$B$3 -> 0.13163334 | H20: =FORECAST($A20, $H$6:$H$15, $A$6:$A$15) + 0.002 -> 0.035280364 | I20: =FORECAST($A20, $I$6:$I$15, $A$6:$A$15) + 0.001 -> 0.052043416 | J20: =SUM(H20:I20) -> 0.08732378 | K20: =H20/$B$3 -> 0.063000651 | L20: =I20/$B$3 -> 0.092934671 | M20: =J20/$B$3 -> 0.15593532 | N20: =$B$15 -> 0.026666597 | O20: =FORECAST($A20, $C$10:$C$15, $A$10:$A$15) + 0.001 -> 0.04658471 | P20: =SUM(N20:O20) -> 0.073251306 | Q20: =N20/$B$3 -> 0.047618923 | R20: =O20/$B$3 -> 0.083186981 | S20: =P20/$B$3 -> 0.1308059 | T20: 0.035 | U20: 0.1025 | V20: =SUM(T20:U20) -> 0.1375 | W20: =T20/$B$3 -> 0.0625 | X20: =U20/$B$3 -> 0.18303571 | Y20: =V20/$B$3 -> 0.24553571 | Z20: =Z19 -> 0.03 | AA20: 0.08 | AB20: =SUM(Z20:AA20) -> 0.11 | AC20: =Z20/$B$3 -> 0.053571429 | AD20: =AA20/$B$3 -> 0.14285714 | AE20: =AB20/$B$3 -> 0.19642857 | AF20: =1/AD20 -> 7 | AG20: =1/AE20 -> 5.0909091
A21: 2025 | B21: =FORECAST($A21, $B$6:$B$15, $A$6:$A$15) + 0.002 -> 0.029637229 | C21: =FORECAST($A21, $C$6:$C$15, $A$6:$A$15) + 0.001 -> 0.046039555 | D21: =SUM(B21:C21) -> 0.075676783 | E21: =B21/$B$3 -> 0.052923623 | F21: =C21/$B$3 -> 0.082213491 | G21: =D21/$B$3 -> 0.13513711 | H21: =FORECAST($A21, $H$6:$H$15, $A$6:$A$15) + 0.002 -> 0.036082327 | I21: =FORECAST($A21, $I$6:$I$15, $A$6:$A$15) + 0.001 -> 0.054214755 | J21: =SUM(H21:I21) -> 0.090297081 | K21: =H21/$B$3 -> 0.064432726 | L21: =I21/$B$3 -> 0.096812062 | M21: =J21/$B$3 -> 0.16124479 | N21: =$B$15 -> 0.026666597 | O21: =FORECAST($A21, $C$10:$C$15, $A$10:$A$15) + 0.001 -> 0.048489317 | P21: =SUM(N21:O21) -> 0.075155914 | Q21: =N21/$B$3 -> 0.047618923 | R21: =O21/$B$3 -> 0.086588067 | S21: =P21/$B$3 -> 0.13420699 | T21: =T20 -> 0.035 | U21: 0.1 | V21: =SUM(T21:U21) -> 0.135 | W21: =T21/$B$3 -> 0.0625 | X21: =U21/$B$3 -> 0.17857143 | Y21: =V21/$B$3 -> 0.24107143 | Z21: =Z20 -> 0.03 | AA21: =AA20 -> 0.08 | AB21: =SUM(Z21:AA21) -> 0.11 | AC21: =Z21/$B$3 -> 0.053571429 | AD21: =AA21/$B$3 -> 0.14285714 | AE21: =AB21/$B$3 -> 0.19642857 | AF21: =1/AD21 -> 7 | AG21: =1/AE21 -> 5.0909091
A22: 2026 | B22: =FORECAST($A22, $B$6:$B$15, $A$6:$A$15) + 0.002 -> 0.029991808 | C22: =FORECAST($A22, $C$6:$C$15, $A$6:$A$15) + 0.001 -> 0.047647089 | D22: =SUM(B22:C22) -> 0.077638897 | E22: =B22/$B$3 -> 0.0535568 | F22: =C22/$B$3 -> 0.085084088 | G22: =D22/$B$3 -> 0.13864089 | H22: =FORECAST($A22, $H$6:$H$15, $A$6:$A$15) + 0.002 -> 0.036884289 | I22: =FORECAST($A22, $I$6:$I$15, $A$6:$A$15) + 0.001 -> 0.056386093 | J22: =SUM(H22:I22) -> 0.093270382 | K22: =H22/$B$3 -> 0.065864802 | L22: =I22/$B$3 -> 0.10068945 | M22: =J22/$B$3 -> 0.16655425 | N22: =$B$15 -> 0.026666597 | O22: =FORECAST($A22, $C$10:$C$15, $A$10:$A$15) + 0.001 -> 0.050393925 | P22: =SUM(N22:O22) -> 0.077060522 | Q22: =N22/$B$3 -> 0.047618923 | R22: =O22/$B$3 -> 0.089989152 | S22: =P22/$B$3 -> 0.13760808 | T22: =T21 -> 0.035 | U22: =U21 -> 0.1 | V22: =SUM(T22:U22) -> 0.135 | W22: =T22/$B$3 -> 0.0625 | X22: =U22/$B$3 -> 0.17857143 | Y22: =V22/$B$3 -> 0.24107143 | Z22: =Z21 -> 0.03 | AA22: =AA21 -> 0.08 | AB22: =SUM(Z22:AA22) -> 0.11 | AC22: =Z22/$B$3 -> 0.053571429 | AD22: =AA22/$B$3 -> 0.14285714 | AE22: =AB22/$B$3 -> 0.19642857 | AF22: =1/AD22 -> 7 | AG22: =1/AE22 -> 5.0909091
A23: 2027 | B23: =FORECAST($A23, $B$6:$B$15, $A$6:$A$15) + 0.002 -> 0.030346387 | C23: =FORECAST($A23, $C$6:$C$15, $A$6:$A$15) + 0.001 -> 0.049254624 | D23: =SUM(B23:C23) -> 0.079601011 | E23: =B23/$B$3 -> 0.054189977 | F23: =C23/$B$3 -> 0.087954685 | G23: =D23/$B$3 -> 0.14214466 | H23: =FORECAST($A23, $H$6:$H$15, $A$6:$A$15) + 0.002 -> 0.037686251 | I23: =FORECAST($A23, $I$6:$I$15, $A$6:$A$15) + 0.001 -> 0.058557432 | J23: =SUM(H23:I23) -> 0.096243683 | K23: =H23/$B$3 -> 0.067296877 | L23: =I23/$B$3 -> 0.10456684 | M23: =J23/$B$3 -> 0.17186372 | N23: =$B$15 -> 0.026666597 | O23: =FORECAST($A23, $C$10:$C$15, $A$10:$A$15) + 0.001 -> 0.052298533 | P23: =SUM(N23:O23) -> 0.07896513 | Q23: =N23/$B$3 -> 0.047618923 | R23: =O23/$B$3 -> 0.093390238 | S23: =P23/$B$3 -> 0.14100916 | T23: =T22 -> 0.035 | U23: =U22 -> 0.1 | V23: =SUM(T23:U23) -> 0.135 | W23: =T23/$B$3 -> 0.0625 | X23: =U23/$B$3 -> 0.17857143 | Y23: =V23/$B$3 -> 0.24107143 | Z23: =Z22 -> 0.03 | AA23: =AA22 -> 0.08 | AB23: =SUM(Z23:AA23) -> 0.11 | AC23: =Z23/$B$3 -> 0.053571429 | AD23: =AA23/$B$3 -> 0.14285714 | AE23: =AB23/$B$3 -> 0.19642857 | AF23: =1/AD23 -> 7 | AG23: =1/AE23 -> 5.0909091
A24: 2028 | B24: =FORECAST($A24, $B$6:$B$15, $A$6:$A$15) + 0.002 -> 0.030700966 | C24: =FORECAST($A24, $C$6:$C$15, $A$6:$A$15) + 0.001 -> 0.050862158 | D24: =SUM(B24:C24) -> 0.081563124 | E24: =B24/$B$3 -> 0.054823154 | F24: =C24/$B$3 -> 0.090825282 | G24: =D24/$B$3 -> 0.14564844 | H24: =FORECAST($A24, $H$6:$H$15, $A$6:$A$15) + 0.002 -> 0.038488214 | I24: =FORECAST($A24, $I$6:$I$15, $A$6:$A$15) + 0.001 -> 0.06072877 | J24: =SUM(H24:I24) -> 0.099216984 | K24: =H24/$B$3 -> 0.068728953 | L24: =I24/$B$3 -> 0.10844423 | M24: =J24/$B$3 -> 0.17717319 | N24: =$B$15 -> 0.026666597 | O24: =FORECAST($A24, $C$10:$C$15, $A$10:$A$15) + 0.001 -> 0.054203141 | P24: =SUM(N24:O24) -> 0.080869738 | Q24: =N24/$B$3 -> 0.047618923 | R24: =O24/$B$3 -> 0.096791323 | S24: =P24/$B$3 -> 0.14441025 | T24: =T23 -> 0.035 | U24: =U23 -> 0.1 | V24: =SUM(T24:U24) -> 0.135 | W24: =T24/$B$3 -> 0.0625 | X24: =U24/$B$3 -> 0.17857143 | Y24: =V24/$B$3 -> 0.24107143 | Z24: =Z23 -> 0.03 | AA24: =AA23 -> 0.08 | AB24: =SUM(Z24:AA24) -> 0.11 | AC24: =Z24/$B$3 -> 0.053571429 | AD24: =AA24/$B$3 -> 0.14285714 | AE24: =AB24/$B$3 -> 0.19642857 | AF24: =1/AD24 -> 7 | AG24: =1/AE24 -> 5.0909091
A25: 2029 | B25: =FORECAST($A25, $B$6:$B$15, $A$6:$A$15) + 0.002 -> 0.031055545 | C25: =FORECAST($A25, $C$6:$C$15, $A$6:$A$15) + 0.001 -> 0.052469692 | D25: =SUM(B25:C25) -> 0.083525238 | E25: =B25/$B$3 -> 0.055456331 | F25: =C25/$B$3 -> 0.093695879 | G25: =D25/$B$3 -> 0.14915221 | H25: =FORECAST($A25, $H$6:$H$15, $A$6:$A$15) + 0.002 -> 0.039290176 | I25: =FORECAST($A25, $I$6:$I$15, $A$6:$A$15) + 0.001 -> 0.062900109 | J25: =SUM(H25:I25) -> 0.10219028 | K25: =H25/$B$3 -> 0.070161029 | L25: =I25/$B$3 -> 0.11232162 | M25: =J25/$B$3 -> 0.18248265 | N25: =$B$15 -> 0.026666597 | O25: =FORECAST($A25, $C$10:$C$15, $A$10:$A$15) + 0.001 -> 0.056107749 | P25: =SUM(N25:O25) -> 0.082774346 | Q25: =N25/$B$3 -> 0.047618923 | R25: =O25/$B$3 -> 0.10019241 | S25: =P25/$B$3 -> 0.14781133 | T25: =T24 -> 0.035 | U25: =U24 -> 0.1 | V25: =SUM(T25:U25) -> 0.135 | W25: =T25/$B$3 -> 0.0625 | X25: =U25/$B$3 -> 0.17857143 | Y25: =V25/$B$3 -> 0.24107143 | Z25: =Z24 -> 0.03 | AA25: =AA24 -> 0.08 | AB25: =SUM(Z25:AA25) -> 0.11 | AC25: =Z25/$B$3 -> 0.053571429 | AD25: =AA25/$B$3 -> 0.14285714 | AE25: =AB25/$B$3 -> 0.19642857 | AF25: =1/AD25 -> 7 | AG25: =1/AE25 -> 5.0909091
