Workbook
Name Base_2019: Base_2019!$1:$1048576
Name High_2019: High_2019!$1:$1048576
Name Low_2019: Low_2019!$1:$1048576
Name Med_2019: Med_2019!$1:$1048576

Sheet Summary 2019
B2: 2019 | C2: Peak | G2: Off-Peak | K2: Daily | P2: 2019 | Q2: Peak | U2: Off-Peak | Y2: Daily
B3: Home Based Work | C3: Base | D3: Low | E3: Medium | F3: High | G3: Base | H3: Low | I3: Medium | J3: High | K3: Base | L3: Low | M3: Medium | N3: High | P3: Non-Home Based | Q3: Base | R3: Low | S3: Medium | T3: High | U3: Base | V3: Low | W3: Medium | X3: High | Y3: Base | Z3: Low | AA3: Medium | AB3: High
B4: Non-Motorized | C4: =Base_2019!B5 -> 48337.1 | D4: =Low_2019!B5 -> 42205.6 | E4: =Med_2019!B5 -> 39651.9 | F4: =High_2019!B5 -> 37172.7 | G4: =Base_2019!B19 -> 35324.2 | H4: =Low_2019!B19 -> 30911.5 | I4: =Med_2019!B19 -> 29101 | J4: =High_2019!B19 -> 27296.7 | K4: =Base_2019!B33 -> 83661.3 | L4: =Low_2019!B33 -> 73117.2 | M4: =Med_2019!B33 -> 68752.9 | N4: =High_2019!B33 -> 64469.4 | P4: Non-Motorized | Q4: =Base_2019!E5 -> 29219.1 | R4: =Low_2019!E5 -> 28486.7 | S4: =Med_2019!E5 -> 28141.6 | T4: =High_2019!E5 -> 27807 | U4: =Base_2019!E19 -> 116487 | V4: =Low_2019!E19 -> 113691 | W4: =Med_2019!E19 -> 112358 | X4: =High_2019!E19 -> 111065 | Y4: =Base_2019!E33 -> 145706 | Z4: =Low_2019!E33 -> 142177 | AA4: =Med_2019!E33 -> 140500 | AB4: =High_2019!E33 -> 138872
B5: Auto | C5: =Base_2019!B6 -> 1050350 | D5: =Low_2019!B6 -> 934773 | E5: =Med_2019!B6 -> 884814 | F5: =High_2019!B6 -> 835960 | G5: =Base_2019!B20 -> 601000 | H5: =Low_2019!B20 -> 533312 | I5: =Med_2019!B20 -> 505358 | J5: =High_2019!B20 -> 476471 | K5: =Base_2019!B34 -> 1651350 | L5: =Low_2019!B34 -> 1468085 | M5: =Med_2019!B34 -> 1390171 | N5: =High_2019!B34 -> 1312431 | P5: Auto | Q5: =Base_2019!E6 -> 704036 | R5: =Low_2019!E6 -> 690847 | S5: =Med_2019!E6 -> 683935 | T5: =High_2019!E6 -> 677068 | U5: =Base_2019!E20 -> 1557602 | V5: =Low_2019!E20 -> 1528285 | W5: =Med_2019!E20 -> 1512880 | X5: =High_2019!E20 -> 1497578 | Y5: =Base_2019!E34 -> 2261638 | Z5: =Low_2019!E34 -> 2219131 | AA5: =Med_2019!E34 -> 2196815 | AB5: =High_2019!E34 -> 2174646
B6: School Bus | C6: =Base_2019!B7 -> 0 | D6: =Low_2019!B7 -> 0 | E6: =Med_2019!B7 -> 0 | F6: =High_2019!B7 -> 0 | G6: =Base_2019!B21 -> 0 | H6: =Low_2019!B21 -> 0 | I6: =Med_2019!B21 -> 0 | J6: =High_2019!B21 -> 0 | K6: =Base_2019!B35 -> 0 | L6: =Low_2019!B35 -> 0 | M6: =Med_2019!B35 -> 0 | N6: =High_2019!B35 -> 0 | P6: School Bus | Q6: =Base_2019!E7 -> 0 | R6: =Low_2019!E7 -> 0 | S6: =Med_2019!E7 -> 0 | T6: =High_2019!E7 -> 0 | U6: =Base_2019!E21 -> 0 | V6: =Low_2019!E21 -> 0 | W6: =Med_2019!E21 -> 0 | X6: =High_2019!E21 -> 0 | Y6: =Base_2019!E35 -> 0 | Z6: =Low_2019!E35 -> 0 | AA6: =Med_2019!E35 -> 0 | AB6: =High_2019!E35 -> 0
B7: Local Bus | C7: =Base_2019!B8 -> 10556 | D7: =Low_2019!B8 -> 9285.47 | E7: =Med_2019!B8 -> 8696.67 | F7: =High_2019!B8 -> 8142.31 | G7: =Base_2019!B22 -> 6272.83 | H7: =Low_2019!B22 -> 5446.42 | I7: =Med_2019!B22 -> 5115.79 | J7: =High_2019!B22 -> 4757.66 | K7: =Base_2019!B36 -> 16828.8 | L7: =Low_2019!B36 -> 14731.9 | M7: =Med_2019!B36 -> 13812.5 | N7: =High_2019!B36 -> 12900 | P7: Local Bus | Q7: =Base_2019!E8 -> 1529.98 | R7: =Low_2019!E8 -> 1495.44 | S7: =Med_2019!E8 -> 1478.49 | T7: =High_2019!E8 -> 1462.39 | U7: =Base_2019!E22 -> 2815.73 | V7: =Low_2019!E22 -> 2756.07 | W7: =Med_2019!E22 -> 2723.61 | X7: =High_2019!E22 -> 2692.26 | Y7: =Base_2019!E36 -> 4345.71 | Z7: =Low_2019!E36 -> 4251.51 | AA7: =Med_2019!E36 -> 4202.11 | AB7: =High_2019!E36 -> 4154.65
B8: BRT | C8: =Base_2019!B9 -> 128.3 | D8: =Low_2019!B9 -> 118.42 | E8: =Med_2019!B9 -> 112.65 | F8: =High_2019!B9 -> 106.84 | G8: =Base_2019!B23 -> 72.07 | H8: =Low_2019!B23 -> 65.61 | I8: =Med_2019!B23 -> 62.8 | J8: =High_2019!B23 -> 59.93 | K8: =Base_2019!B37 -> 200.36 | L8: =Low_2019!B37 -> 184.02 | M8: =Med_2019!B37 -> 175.45 | N8: =High_2019!B37 -> 166.77 | P8: BRT | Q8: =Base_2019!E9 -> 20.43 | R8: =Low_2019!E9 -> 20.12 | S8: =Med_2019!E9 -> 19.93 | T8: =High_2019!E9 -> 19.76 | U8: =Base_2019!E23 -> 38.89 | V8: =Low_2019!E23 -> 38.4 | W8: =Med_2019!E23 -> 38.08 | X8: =High_2019!E23 -> 37.81 | Y8: =Base_2019!E37 -> 59.32 | Z8: =Low_2019!E37 -> 58.52 | AA8: =Med_2019!E37 -> 58.02 | AB8: =High_2019!E37 -> 57.57
B9: MODE9 | C9: =Base_2019!B10 -> 1482.81 | D9: =Low_2019!B10 -> 1290.45 | E9: =Med_2019!B10 -> 1214.27 | F9: =High_2019!B10 -> 1140.62 | G9: =Base_2019!B24 -> 680.81 | H9: =Low_2019!B24 -> 584.75 | I9: =Med_2019!B24 -> 551.58 | J9: =High_2019!B24 -> 518.18 | K9: =Base_2019!B38 -> 2163.62 | L9: =Low_2019!B38 -> 1875.2 | M9: =Med_2019!B38 -> 1765.85 | N9: =High_2019!B38 -> 1658.79 | P9: MODE9 | Q9: =Base_2019!E10 -> 496.64 | R9: =Low_2019!E10 -> 481.42 | S9: =Med_2019!E10 -> 474.77 | T9: =High_2019!E10 -> 468.19 | U9: =Base_2019!E24 -> 727.5 | V9: =Low_2019!E24 -> 702.69 | W9: =Med_2019!E24 -> 693.49 | X9: =High_2019!E24 -> 684.12 | Y9: =Base_2019!E38 -> 1224.14 | Z9: =Low_2019!E38 -> 1184.11 | AA9: =Med_2019!E38 -> 1168.25 | AB9: =High_2019!E38 -> 1152.3
B10: Express Bus | C10: =Base_2019!B11 -> 1643.13 | D10: =Low_2019!B11 -> 1805.91 | E10: =Med_2019!B11 -> 1822.58 | F10: =High_2019!B11 -> 1858.99 | G10: =Base_2019!B25 -> 0 | H10: =Low_2019!B25 -> 0 | I10: =Med_2019!B25 -> 0 | J10: =High_2019!B25 -> 0 | K10: =Base_2019!B39 -> 1643.13 | L10: =Low_2019!B39 -> 1805.91 | M10: =Med_2019!B39 -> 1822.58 | N10: =High_2019!B39 -> 1858.99 | P10: Express Bus | Q10: =Base_2019!E11 -> 11.03 | R10: =Low_2019!E11 -> 14.2 | S10: =Med_2019!E11 -> 15.49 | T10: =High_2019!E11 -> 17.23 | U10: =Base_2019!E25 -> 0 | V10: =Low_2019!E25 -> 0 | W10: =Med_2019!E25 -> 0 | X10: =High_2019!E25 -> 0 | Y10: =Base_2019!E39 -> 11.03 | Z10: =Low_2019!E39 -> 14.2 | AA10: =Med_2019!E39 -> 15.49 | AB10: =High_2019!E39 -> 17.23
B11: Light Rail | C11: =Base_2019!B12 -> 16070.6 | D11: =Low_2019!B12 -> 13748 | E11: =Med_2019!B12 -> 12715.4 | F11: =High_2019!B12 -> 11789.3 | G11: =Base_2019!B26 -> 7911.35 | H11: =Low_2019!B26 -> 6854.93 | I11: =Med_2019!B26 -> 6418.55 | J11: =High_2019!B26 -> 5968.72 | K11: =Base_2019!B40 -> 23982 | L11: =Low_2019!B40 -> 20602.9 | M11: =Med_2019!B40 -> 19134 | N11: =High_2019!B40 -> 17758 | P11: Light Rail | Q11: =Base_2019!E12 -> 3427.58 | R11: =Low_2019!E12 -> 3286.05 | S11: =Med_2019!E12 -> 3217.28 | T11: =High_2019!E12 -> 3150.24 | U11: =Base_2019!E26 -> 6418.62 | V11: =Low_2019!E26 -> 6208.33 | W11: =Med_2019!E26 -> 6108.01 | X11: =High_2019!E26 -> 6006.92 | Y11: =Base_2019!E40 -> 9846.2 | Z11: =Low_2019!E40 -> 9494.39 | AA11: =Med_2019!E40 -> 9325.29 | AB11: =High_2019!E40 -> 9157.16
B12: Comm. Rail | C12: =Base_2019!B13 -> 12718.6 | D12: =Low_2019!B13 -> 10249.8 | E12: =Med_2019!B13 -> 9235.3 | F12: =High_2019!B13 -> 8315.6 | G12: =Base_2019!B27 -> 3559.3 | H12: =Low_2019!B27 -> 3062.97 | I12: =Med_2019!B27 -> 2876.15 | J12: =High_2019!B27 -> 2647.45 | K12: =Base_2019!B41 -> 16277.9 | L12: =Low_2019!B41 -> 13312.7 | M12: =Med_2019!B41 -> 12111.5 | N12: =High_2019!B41 -> 10963 | P12: Comm. Rail | Q12: =Base_2019!E13 -> 604.45 | R12: =Low_2019!E13 -> 566 | S12: =Med_2019!E13 -> 547.36 | T12: =High_2019!E13 -> 530.52 | U12: =Base_2019!E27 -> 757.97 | V12: =Low_2019!E27 -> 738.72 | W12: =Med_2019!E27 -> 729.96 | X12: =High_2019!E27 -> 727.17 | Y12: =Base_2019!E41 -> 1362.41 | Z12: =Low_2019!E41 -> 1304.72 | AA12: =Med_2019!E41 -> 1277.32 | AB12: =High_2019!E41 -> 1257.69
B13: Total Trips | C13: =Base_2019!B14 -> 1141287 | D13: =Low_2019!B14 -> 1013477 | E13: =Med_2019!B14 -> 958263 | F13: =High_2019!B14 -> 904486 | G13: =Base_2019!B28 -> 654821 | H13: =Low_2019!B28 -> 580238 | I13: =Med_2019!B28 -> 549483 | J13: =High_2019!B28 -> 517720 | K13: =Base_2019!B42 -> 1796108 | L13: =Low_2019!B42 -> 1593715 | M13: =Med_2019!B42 -> 1507746 | N13: =High_2019!B42 -> 1422206 | P13: Total Trips | Q13: =Base_2019!E14 -> 739345 | R13: =Low_2019!E14 -> 725197 | S13: =Med_2019!E14 -> 717830 | T13: =High_2019!E14 -> 710524 | U13: =Base_2019!E28 -> 1684848 | V13: =Low_2019!E28 -> 1652419 | W13: =Med_2019!E28 -> 1635531 | X13: =High_2019!E28 -> 1618791 | Y13: =Base_2019!E42 -> 2424193 | Z13: =Low_2019!E42 -> 2377616 | AA13: =Med_2019!E42 -> 2353361 | AB13: =High_2019!E42 -> 2329314
B16: 2019 | C16: Peak | G16: Off-Peak | K16: Daily | P16: 2019 | Q16: Peak | U16: Off-Peak | Y16: Daily
B17: Home Based College | C17: Base | D17: Low | E17: Medium | F17: High | G17: Base | H17: Low | I17: Medium | J17: High | K17: Base | L17: Low | M17: Medium | N17: High | P17: Home Based School | Q17: Base | R17: Low | S17: Medium | T17: High | U17: Base | V17: Low | W17: Medium | X17: High | Y17: Base | Z17: Low | AA17: Medium | AB17: High
B18: Non-Motorized | C18: =Base_2019!C5 -> 22397.1 | D18: =Low_2019!C5 -> 22345.6 | E18: =Med_2019!C5 -> 22328.9 | F18: =High_2019!C5 -> 22312 | G18: =Base_2019!C19 -> 0 | H18: =Low_2019!C19 -> 0 | I18: =Med_2019!C19 -> 0 | J18: =High_2019!C19 -> 0 | K18: =Base_2019!C33 -> 22397.1 | L18: =Low_2019!C33 -> 22345.6 | M18: =Med_2019!C33 -> 22328.9 | N18: =High_2019!C33 -> 22312 | P18: Non-Motorized | Q18: =Base_2019!F5 -> 182360 | R18: =Low_2019!F5 -> 181810 | S18: =Med_2019!F5 -> 181586 | T18: =High_2019!F5 -> 181386 | U18: =Base_2019!F19 -> 88808.3 | V18: =Low_2019!F19 -> 88540.3 | W18: =Med_2019!F19 -> 88431.6 | X18: =High_2019!F19 -> 88333.2 | Y18: =Base_2019!F33 -> 271169 | Z18: =Low_2019!F33 -> 270351 | AA18: =Med_2019!F33 -> 270017 | AB18: =High_2019!F33 -> 269719
B19: Auto | C19: =Base_2019!C6 -> 79886.1 | D19: =Low_2019!C6 -> 80041.8 | E19: =Med_2019!C6 -> 80141.5 | F19: =High_2019!C6 -> 80204.4 | G19: =Base_2019!C20 -> 0 | H19: =Low_2019!C20 -> 0 | I19: =Med_2019!C20 -> 0 | J19: =High_2019!C20 -> 0 | K19: =Base_2019!C34 -> 79886.1 | L19: =Low_2019!C34 -> 80041.8 | M19: =Med_2019!C34 -> 80141.5 | N19: =High_2019!C34 -> 80204.4 | P19: Auto | Q19: =Base_2019!F6 -> 77705.5 | R19: =Low_2019!F6 -> 77700.4 | S19: =Med_2019!F6 -> 77697.4 | T19: =High_2019!F6 -> 77697.7 | U19: =Base_2019!F20 -> 37511.2 | V19: =Low_2019!F20 -> 37502.4 | W19: =Med_2019!F20 -> 37500 | X19: =High_2019!F20 -> 37495.1 | Y19: =Base_2019!F34 -> 115217 | Z19: =Low_2019!F34 -> 115203 | AA19: =Med_2019!F34 -> 115197 | AB19: =High_2019!F34 -> 115193
B20: School Bus | C20: =Base_2019!C7 -> 0 | D20: =Low_2019!C7 -> 0 | E20: =Med_2019!C7 -> 0 | F20: =High_2019!C7 -> 0 | G20: =Base_2019!C21 -> 0 | H20: =Low_2019!C21 -> 0 | I20: =Med_2019!C21 -> 0 | J20: =High_2019!C21 -> 0 | K20: =Base_2019!C35 -> 0 | L20: =Low_2019!C35 -> 0 | M20: =Med_2019!C35 -> 0 | N20: =High_2019!C35 -> 0 | P20: School Bus | Q20: =Base_2019!F7 -> 174377 | R20: =Low_2019!F7 -> 174933 | S20: =Med_2019!F7 -> 175163 | T20: =High_2019!F7 -> 175365 | U20: =Base_2019!F21 -> 84821.7 | V20: =Low_2019!F21 -> 85083.5 | W20: =Med_2019!F21 -> 85191.5 | X20: =High_2019!F21 -> 85289.7 | Y20: =Base_2019!F35 -> 259198 | Z20: =Low_2019!F35 -> 260017 | AA20: =Med_2019!F35 -> 260354 | AB20: =High_2019!F35 -> 260655
B21: Local Bus | C21: =Base_2019!C8 -> 7310.87 | D21: =Low_2019!C8 -> 7331.17 | E21: =Med_2019!C8 -> 7361.93 | F21: =High_2019!C8 -> 7366.47 | G21: =Base_2019!C22 -> 0 | H21: =Low_2019!C22 -> 0 | I21: =Med_2019!C22 -> 0 | J21: =High_2019!C22 -> 0 | K21: =Base_2019!C36 -> 7310.87 | L21: =Low_2019!C36 -> 7331.17 | M21: =Med_2019!C36 -> 7361.93 | N21: =High_2019!C36 -> 7366.47 | P21: Local Bus | Q21: =Base_2019!F8 -> 0 | R21: =Low_2019!F8 -> 0 | S21: =Med_2019!F8 -> 0 | T21: =High_2019!F8 -> 0 | U21: =Base_2019!F22 -> 0 | V21: =Low_2019!F22 -> 0 | W21: =Med_2019!F22 -> 0 | X21: =High_2019!F22 -> 0 | Y21: =Base_2019!F36 -> 0 | Z21: =Low_2019!F36 -> 0 | AA21: =Med_2019!F36 -> 0 | AB21: =High_2019!F36 -> 0
B22: BRT | C22: =Base_2019!C9 -> 33.86 | D22: =Low_2019!C9 -> 34.13 | E22: =Med_2019!C9 -> 34.23 | F22: =High_2019!C9 -> 34.08 | G22: =Base_2019!C23 -> 0 | H22: =Low_2019!C23 -> 0 | I22: =Med_2019!C23 -> 0 | J22: =High_2019!C23 -> 0 | K22: =Base_2019!C37 -> 33.86 | L22: =Low_2019!C37 -> 34.13 | M22: =Med_2019!C37 -> 34.23 | N22: =High_2019!C37 -> 34.08 | P22: BRT | Q22: =Base_2019!F9 -> 0 | R22: =Low_2019!F9 -> 0 | S22: =Med_2019!F9 -> 0 | T22: =High_2019!F9 -> 0 | U22: =Base_2019!F23 -> 0 | V22: =Low_2019!F23 -> 0 | W22: =Med_2019!F23 -> 0 | X22: =High_2019!F23 -> 0 | Y22: =Base_2019!F37 -> 0 | Z22: =Low_2019!F37 -> 0 | AA22: =Med_2019!F37 -> 0 | AB22: =High_2019!F37 -> 0
B23: MODE9 | C23: =Base_2019!C10 -> 7009.28 | D23: =Low_2019!C10 -> 7003.69 | E23: =Med_2019!C10 -> 7001.88 | F23: =High_2019!C10 -> 7000.63 | G23: =Base_2019!C24 -> 0 | H23: =Low_2019!C24 -> 0 | I23: =Med_2019!C24 -> 0 | J23: =High_2019!C24 -> 0 | K23: =Base_2019!C38 -> 7009.28 | L23: =Low_2019!C38 -> 7003.69 | M23: =Med_2019!C38 -> 7001.88 | N23: =High_2019!C38 -> 7000.63 | P23: MODE9 | Q23: =Base_2019!F10 -> 0 | R23: =Low_2019!F10 -> 0 | S23: =Med_2019!F10 -> 0 | T23: =High_2019!F10 -> 0 | U23: =Base_2019!F24 -> 0 | V23: =Low_2019!F24 -> 0 | W23: =Med_2019!F24 -> 0 | X23: =High_2019!F24 -> 0 | Y23: =Base_2019!F38 -> 0 | Z23: =Low_2019!F38 -> 0 | AA23: =Med_2019!F38 -> 0 | AB23: =High_2019!F38 -> 0
B24: Express Bus | C24: =Base_2019!C11 -> 101.12 | D24: =Low_2019!C11 -> 134.29 | E24: =Med_2019!C11 -> 148.06 | F24: =High_2019!C11 -> 165.3 | G24: =Base_2019!C25 -> 0 | H24: =Low_2019!C25 -> 0 | I24: =Med_2019!C25 -> 0 | J24: =High_2019!C25 -> 0 | K24: =Base_2019!C39 -> 101.12 | L24: =Low_2019!C39 -> 134.29 | M24: =Med_2019!C39 -> 148.06 | N24: =High_2019!C39 -> 165.3 | P24: Express Bus | Q24: =Base_2019!F11 -> 0 | R24: =Low_2019!F11 -> 0 | S24: =Med_2019!F11 -> 0 | T24: =High_2019!F11 -> 0 | U24: =Base_2019!F25 -> 0 | V24: =Low_2019!F25 -> 0 | W24: =Med_2019!F25 -> 0 | X24: =High_2019!F25 -> 0 | Y24: =Base_2019!F39 -> 0 | Z24: =Low_2019!F39 -> 0 | AA24: =Med_2019!F39 -> 0 | AB24: =High_2019!F39 -> 0
B25: Light Rail | C25: =Base_2019!C12 -> 6700.86 | D25: =Low_2019!C12 -> 6627.18 | E25: =Med_2019!C12 -> 6587.77 | F25: =High_2019!C12 -> 6572.18 | G25: =Base_2019!C26 -> 0 | H25: =Low_2019!C26 -> 0 | I25: =Med_2019!C26 -> 0 | J25: =High_2019!C26 -> 0 | K25: =Base_2019!C40 -> 6700.86 | L25: =Low_2019!C40 -> 6627.18 | M25: =Med_2019!C40 -> 6587.77 | N25: =High_2019!C40 -> 6572.18 | P25: Light Rail | Q25: =Base_2019!F12 -> 0 | R25: =Low_2019!F12 -> 0 | S25: =Med_2019!F12 -> 0 | T25: =High_2019!F12 -> 0 | U25: =Base_2019!F26 -> 0 | V25: =Low_2019!F26 -> 0 | W25: =Med_2019!F26 -> 0 | X25: =High_2019!F26 -> 0 | Y25: =Base_2019!F40 -> 0 | Z25: =Low_2019!F40 -> 0 | AA25: =Med_2019!F40 -> 0 | AB25: =High_2019!F40 -> 0
B26: Comm. Rail | C26: =Base_2019!C13 -> 4073.22 | D26: =Low_2019!C13 -> 3994.54 | E26: =Med_2019!C13 -> 3908.24 | F26: =High_2019!C13 -> 3857.38 | G26: =Base_2019!C27 -> 0 | H26: =Low_2019!C27 -> 0 | I26: =Med_2019!C27 -> 0 | J26: =High_2019!C27 -> 0 | K26: =Base_2019!C41 -> 4073.22 | L26: =Low_2019!C41 -> 3994.54 | M26: =Med_2019!C41 -> 3908.24 | N26: =High_2019!C41 -> 3857.38 | P26: Comm. Rail | Q26: =Base_2019!F13 -> 0 | R26: =Low_2019!F13 -> 0 | S26: =Med_2019!F13 -> 0 | T26: =High_2019!F13 -> 0 | U26: =Base_2019!F27 -> 0 | V26: =Low_2019!F27 -> 0 | W26: =Med_2019!F27 -> 0 | X26: =High_2019!F27 -> 0 | Y26: =Base_2019!F41 -> 0 | Z26: =Low_2019!F41 -> 0 | AA26: =Med_2019!F41 -> 0 | AB26: =High_2019!F41 -> 0
B27: Total Trips | C27: =Base_2019!C14 -> 127512 | D27: =Low_2019!C14 -> 127512 | E27: =Med_2019!C14 -> 127512 | F27: =High_2019!C14 -> 127512 | G27: =Base_2019!C28 -> 0 | H27: =Low_2019!C28 -> 0 | I27: =Med_2019!C28 -> 0 | J27: =High_2019!C28 -> 0 | K27: =Base_2019!C42 -> 127512 | L27: =Low_2019!C42 -> 127512 | M27: =Med_2019!C42 -> 127512 | N27: =High_2019!C42 -> 127512 | P27: Total Trips | Q27: =Base_2019!F14 -> 434442 | R27: =Low_2019!F14 -> 434444 | S27: =Med_2019!F14 -> 434446 | T27: =High_2019!F14 -> 434448 | U27: =Base_2019!F28 -> 211141 | V27: =Low_2019!F28 -> 211126 | W27: =Med_2019!F28 -> 211123 | X27: =High_2019!F28 -> 211118 | Y27: =Base_2019!F42 -> 645584 | Z27: =Low_2019!F42 -> 645570 | AA27: =Med_2019!F42 -> 645569 | AB27: =High_2019!F42 -> 645566
B30: 2019 | C30: Peak | G30: Off-Peak | K30: Daily | P30: 2019 | Q30: Peak | U30: Off-Peak | Y30: Daily
B31: Home Based Other | C31: Base | D31: Low | E31: Medium | F31: High | G31: Base | H31: Low | I31: Medium | J31: High | K31: Base | L31: Low | M31: Medium | N31: High | P31: Total Trips | Q31: Base | R31: Low | S31: Medium | T31: High | U31: Base | V31: Low | W31: Medium | X31: High | Y31: Base | Z31: Low | AA31: Medium | AB31: High
B32: Non-Motorized | C32: =Base_2019!D5 -> 147453 | D32: =Low_2019!D5 -> 146588 | E32: =Med_2019!D5 -> 146229 | F32: =High_2019!D5 -> 145912 | G32: =Base_2019!D19 -> 368928 | H32: =Low_2019!D19 -> 367219 | I32: =Med_2019!D19 -> 366475 | J32: =High_2019!D19 -> 365834 | K32: =Base_2019!D33 -> 516381 | L32: =Low_2019!D33 -> 513807 | M32: =Med_2019!D33 -> 512704 | N32: =High_2019!D33 -> 511747 | P32: Non-Motorized | Q32: =Base_2019!G5 -> 429767 | R32: =Low_2019!G5 -> 421436 | S32: =Med_2019!G5 -> 417937 | T32: =High_2019!G5 -> 414590 | U32: =Base_2019!G19 -> 609547 | V32: =Low_2019!G19 -> 600361 | W32: =Med_2019!G19 -> 596366 | X32: =High_2019!G19 -> 592529 | Y32: =Base_2019!G33 -> 1039314 | Z32: =Low_2019!G33 -> 1021797 | AA32: =Med_2019!G33 -> 1014303 | AB32: =High_2019!G33 -> 1007119
B33: Auto | C33: =Base_2019!D6 -> 1313694 | D33: =Low_2019!D6 -> 1314480 | E33: =Med_2019!D6 -> 1314837 | F33: =High_2019!D6 -> 1315222 | G33: =Base_2019!D20 -> 2693602 | H33: =Low_2019!D20 -> 2695075 | I33: =Med_2019!D20 -> 2695733 | J33: =High_2019!D20 -> 2696409 | K33: =Base_2019!D34 -> 4007296 | L33: =Low_2019!D34 -> 4009555 | M33: =Med_2019!D34 -> 4010570 | N33: =High_2019!D34 -> 4011630 | P33: Auto | Q33: =Base_2019!G6 -> 3225671 | R33: =Low_2019!G6 -> 3097842 | S33: =Med_2019!G6 -> 3041425 | T33: =High_2019!G6 -> 2986152 | U33: =Base_2019!G20 -> 4889716 | V33: =Low_2019!G20 -> 4794174 | W33: =Med_2019!G20 -> 4751470 | X33: =High_2019!G20 -> 4707953 | Y33: =Base_2019!G34 -> 8115387 | Z33: =Low_2019!G34 -> 7892016 | AA33: =Med_2019!G34 -> 7792895 | AB33: =High_2019!G34 -> 7694105
B34: School Bus | C34: =Base_2019!D7 -> 0 | D34: =Low_2019!D7 -> 0 | E34: =Med_2019!D7 -> 0 | F34: =High_2019!D7 -> 0 | G34: =Base_2019!D21 -> 0 | H34: =Low_2019!D21 -> 0 | I34: =Med_2019!D21 -> 0 | J34: =High_2019!D21 -> 0 | K34: =Base_2019!D35 -> 0 | L34: =Low_2019!D35 -> 0 | M34: =Med_2019!D35 -> 0 | N34: =High_2019!D35 -> 0 | P34: School Bus | Q34: =Base_2019!G7 -> 174377 | R34: =Low_2019!G7 -> 174933 | S34: =Med_2019!G7 -> 175163 | T34: =High_2019!G7 -> 175365 | U34: =Base_2019!G21 -> 84821.7 | V34: =Low_2019!G21 -> 85083.5 | W34: =Med_2019!G21 -> 85191.5 | X34: =High_2019!G21 -> 85289.7 | Y34: =Base_2019!G35 -> 259198 | Z34: =Low_2019!G35 -> 260017 | AA34: =Med_2019!G35 -> 260354 | AB34: =High_2019!G35 -> 260655
B35: Local Bus | C35: =Base_2019!D8 -> 5221.78 | D35: =Low_2019!D8 -> 5237.96 | E35: =Med_2019!D8 -> 5241.5 | F35: =High_2019!D8 -> 5249.3 | G35: =Base_2019!D22 -> 9821.81 | H35: =Low_2019!D22 -> 9841.65 | I35: =Med_2019!D22 -> 9845.89 | J35: =High_2019!D22 -> 9859.07 | K35: =Base_2019!D36 -> 15043.6 | L35: =Low_2019!D36 -> 15079.6 | M35: =Med_2019!D36 -> 15087.4 | N35: =High_2019!D36 -> 15108.4 | P35: Local Bus | Q35: =Base_2019!G8 -> 24618.6 | R35: =Low_2019!G8 -> 23350 | S35: =Med_2019!G8 -> 22778.6 | T35: =High_2019!G8 -> 22220.5 | U35: =Base_2019!G22 -> 18910.4 | V35: =Low_2019!G22 -> 18044.1 | W35: =Med_2019!G22 -> 17685.3 | X35: =High_2019!G22 -> 17309 | Y35: =Base_2019!G36 -> 43529 | Z35: =Low_2019!G36 -> 41394.2 | AA35: =Med_2019!G36 -> 40463.9 | AB35: =High_2019!G36 -> 39529.5
B36: BRT | C36: =Base_2019!D9 -> 87.83 | D36: =Low_2019!D9 -> 88.11 | E36: =Med_2019!D9 -> 88.21 | F36: =High_2019!D9 -> 88.5 | G36: =Base_2019!D23 -> 154.42 | H36: =Low_2019!D23 -> 154.99 | I36: =Med_2019!D23 -> 155.19 | J36: =High_2019!D23 -> 155.63 | K36: =Base_2019!D37 -> 242.25 | L36: =Low_2019!D37 -> 243.1 | M36: =Med_2019!D37 -> 243.4 | N36: =High_2019!D37 -> 244.13 | P36: BRT | Q36: =Base_2019!G9 -> 270.43 | R36: =Low_2019!G9 -> 260.78 | S36: =Med_2019!G9 -> 255.03 | T36: =High_2019!G9 -> 249.18 | U36: =Base_2019!G23 -> 265.37 | V36: =Low_2019!G23 -> 259 | W36: =Med_2019!G23 -> 256.07 | X36: =High_2019!G23 -> 253.37 | Y36: =Base_2019!G37 -> 535.8 | Z36: =Low_2019!G37 -> 519.77 | AA36: =Med_2019!G37 -> 511.1 | AB36: =High_2019!G37 -> 502.55
B37: MODE9 | C37: =Base_2019!D10 -> 1366.42 | D37: =Low_2019!D10 -> 1365.37 | E37: =Med_2019!D10 -> 1364.51 | F37: =High_2019!D10 -> 1364.13 | G37: =Base_2019!D24 -> 1802.74 | H37: =Low_2019!D24 -> 1768.07 | I37: =Med_2019!D24 -> 1768.53 | J37: =High_2019!D24 -> 1768.53 | K37: =Base_2019!D38 -> 3169.17 | L37: =Low_2019!D38 -> 3133.44 | M37: =Med_2019!D38 -> 3133.04 | N37: =High_2019!D38 -> 3132.66 | P37: MODE9 | Q37: =Base_2019!G10 -> 10355.2 | R37: =Low_2019!G10 -> 10140.9 | S37: =Med_2019!G10 -> 10055.4 | T37: =High_2019!G10 -> 9973.56 | U37: =Base_2019!G24 -> 3211.05 | V37: =Low_2019!G24 -> 3055.51 | W37: =Med_2019!G24 -> 3013.59 | X37: =High_2019!G24 -> 2970.83 | Y37: =Base_2019!G38 -> 13566.2 | Z37: =Low_2019!G38 -> 13196.4 | AA37: =Med_2019!G38 -> 13069 | AB37: =High_2019!G38 -> 12944.4
B38: Express Bus | C38: =Base_2019!D11 -> 66.01 | D38: =Low_2019!D11 -> 71.83 | E38: =Med_2019!D11 -> 73.9 | F38: =High_2019!D11 -> 76.46 | G38: =Base_2019!D25 -> 0 | H38: =Low_2019!D25 -> 0 | I38: =Med_2019!D25 -> 0 | J38: =High_2019!D25 -> 0 | K38: =Base_2019!D39 -> 66.01 | L38: =Low_2019!D39 -> 71.83 | M38: =Med_2019!D39 -> 73.9 | N38: =High_2019!D39 -> 76.46 | P38: Express Bus | Q38: =Base_2019!G11 -> 1821.29 | R38: =Low_2019!G11 -> 2026.22 | S38: =Med_2019!G11 -> 2060.03 | T38: =High_2019!G11 -> 2117.99 | U38: =Base_2019!G25 -> 0 | V38: =Low_2019!G25 -> 0 | W38: =Med_2019!G25 -> 0 | X38: =High_2019!G25 -> 0 | Y38: =Base_2019!G39 -> 1821.29 | Z38: =Low_2019!G39 -> 2026.22 | AA38: =Med_2019!G39 -> 2060.03 | AB38: =High_2019!G39 -> 2117.99
B39: Light Rail | C39: =Base_2019!D12 -> 7638.61 | D39: =Low_2019!D12 -> 7601.1 | E39: =Med_2019!D12 -> 7579.25 | F39: =High_2019!D12 -> 7557.92 | G39: =Base_2019!D26 -> 11928 | H39: =Low_2019!D26 -> 11945.6 | I39: =Med_2019!D26 -> 11955.9 | J39: =High_2019!D26 -> 11946.5 | K39: =Base_2019!D40 -> 19566.6 | L39: =Low_2019!D40 -> 19546.7 | M39: =Med_2019!D40 -> 19535.1 | N39: =High_2019!D40 -> 19504.4 | P39: Light Rail | Q39: =Base_2019!G12 -> 33837.7 | R39: =Low_2019!G12 -> 31262.4 | S39: =Med_2019!G12 -> 30099.7 | T39: =High_2019!G12 -> 29069.6 | U39: =Base_2019!G26 -> 26258 | V39: =Low_2019!G26 -> 25008.8 | W39: =Med_2019!G26 -> 24482.4 | X39: =High_2019!G26 -> 23922.1 | Y39: =Base_2019!G40 -> 60095.6 | Z39: =Low_2019!G40 -> 56271.2 | AA39: =Med_2019!G40 -> 54582.2 | AB39: =High_2019!G40 -> 52991.8
B40: Comm. Rail | C40: =Base_2019!D13 -> 1474.28 | D40: =Low_2019!D13 -> 1439.52 | E40: =Med_2019!D13 -> 1421.2 | F40: =High_2019!D13 -> 1407.13 | G40: =Base_2019!D27 -> 1650.5 | H40: =Low_2019!D27 -> 1670.31 | I40: =Med_2019!D27 -> 1679.16 | J40: =High_2019!D27 -> 1690.98 | K40: =Base_2019!D41 -> 3124.78 | L40: =Low_2019!D41 -> 3109.83 | M40: =Med_2019!D41 -> 3100.37 | N40: =High_2019!D41 -> 3098.11 | P40: Comm. Rail | Q40: =Base_2019!G13 -> 18870.6 | R40: =Low_2019!G13 -> 16249.8 | S40: =Med_2019!G13 -> 15112.1 | T40: =High_2019!G13 -> 14110.6 | U40: =Base_2019!G27 -> 5967.77 | V40: =Low_2019!G27 -> 5472 | W40: =Med_2019!G27 -> 5285.28 | X40: =High_2019!G27 -> 5065.6 | Y40: =Base_2019!G41 -> 24838.3 | Z40: =Low_2019!G41 -> 21721.8 | AA40: =Med_2019!G41 -> 20397.4 | AB40: =High_2019!G41 -> 19176.2
B41: Total Trips | C41: =Base_2019!D14 -> 1477002 | D41: =Low_2019!D14 -> 1476872 | E41: =Med_2019!D14 -> 1476835 | F41: =High_2019!D14 -> 1476878 | G41: =Base_2019!D28 -> 3087888 | H41: =Low_2019!D28 -> 3087674 | I41: =Med_2019!D28 -> 3087613 | J41: =High_2019!D28 -> 3087664 | K41: =Base_2019!D42 -> 4564889 | L41: =Low_2019!D42 -> 4564546 | M41: =Med_2019!D42 -> 4564448 | N41: =High_2019!D42 -> 4564541 | P41: Total Trips | Q41: =Base_2019!G14 -> 3919589 | R41: =Low_2019!G14 -> 3777502 | S41: =Med_2019!G14 -> 3714886 | T41: =High_2019!G14 -> 3653848 | U41: =Base_2019!G28 -> 5638697 | V41: =Low_2019!G28 -> 5531458 | W41: =Med_2019!G28 -> 5483750 | X41: =High_2019!G28 -> 5435292 | Y41: =Base_2019!G42 -> 9558286 | Z41: =Low_2019!G42 -> 9308959 | AA41: =Med_2019!G42 -> 9198636 | AB41: =High_2019!G42 -> 9089141

Sheet Summary 2050
B2: 2050 | C2: Peak | G2: Off-Peak | K2: Daily | P2: 2050 | Q2: Peak | U2: Off-Peak | Y2: Daily
B3: Home Based Work | C3: Base | D3: Low | E3: Medium | F3: High | G3: Base | H3: Low | I3: Medium | J3: High | K3: Base | L3: Low | M3: Medium | N3: High | P3: Non-Home Based | Q3: Base | R3: Low | S3: Medium | T3: High | U3: Base | V3: Low | W3: Medium | X3: High | Y3: Base | Z3: Low | AA3: Medium | AB3: High
B4: Non-Motorized | C4: =Base_2050!B5 -> 0 | D4: =Low_2050!B5 -> 69917.7 | E4: =Med_2050!B5 -> 65325.8 | F4: =High_2050!B5 -> 60845.2 | G4: =Base_2050!B19 -> 0 | H4: =Low_2050!B19 -> 50960.1 | I4: =Med_2050!B19 -> 47731.1 | J4: =High_2050!B19 -> 44487.9 | K4: =Base_2050!B33 -> 0 | L4: =Low_2050!B33 -> 120878 | M4: =Med_2050!B33 -> 113057 | N4: =High_2050!B33 -> 105333 | P4: Non-Motorized | Q4: =Base_2050!E5 -> 0 | R4: =Low_2050!E5 -> 42843.1 | S4: =Med_2050!E5 -> 42230.3 | T4: =High_2050!E5 -> 41630.4 | U4: =Base_2050!E19 -> 0 | V4: =Low_2050!E19 -> 170708 | W4: =Med_2050!E19 -> 168386 | X4: =High_2050!E19 -> 166102 | Y4: =Base_2050!E33 -> 0 | Z4: =Low_2050!E33 -> 213551 | AA4: =Med_2050!E33 -> 210616 | AB4: =High_2050!E33 -> 207732
B5: Auto | C5: =Base_2050!B6 -> 0 | D5: =Low_2050!B6 -> 1449515 | E5: =Med_2050!B6 -> 1364486 | F5: =High_2050!B6 -> 1281252 | G5: =Base_2050!B20 -> 0 | H5: =Low_2050!B20 -> 831417 | I5: =Med_2050!B20 -> 783611 | J5: =High_2050!B20 -> 733660 | K5: =Base_2050!B34 -> 0 | L5: =Low_2050!B34 -> 2280932 | M5: =Med_2050!B34 -> 2148097 | N5: =High_2050!B34 -> 2014912 | P5: Auto | Q5: =Base_2050!E6 -> 0 | R5: =Low_2050!E6 -> 1077766 | S5: =Med_2050!E6 -> 1066283 | T5: =High_2050!E6 -> 1054721 | U5: =Base_2050!E20 -> 0 | V5: =Low_2050!E20 -> 2389879 | W5: =Med_2050!E20 -> 2364295 | X5: =High_2050!E20 -> 2338335 | Y5: =Base_2050!E34 -> 0 | Z5: =Low_2050!E34 -> 3467645 | AA5: =Med_2050!E34 -> 3430578 | AB5: =High_2050!E34 -> 3393055
B6: School Bus | C6: =Base_2050!B7 -> 0 | D6: =Low_2050!B7 -> 0 | E6: =Med_2050!B7 -> 0 | F6: =High_2050!B7 -> 0 | G6: =Base_2050!B21 -> 0 | H6: =Low_2050!B21 -> 0 | I6: =Med_2050!B21 -> 0 | J6: =High_2050!B21 -> 0 | K6: =Base_2050!B35 -> 0 | L6: =Low_2050!B35 -> 0 | M6: =Med_2050!B35 -> 0 | N6: =High_2050!B35 -> 0 | P6: School Bus | Q6: =Base_2050!E7 -> 0 | R6: =Low_2050!E7 -> 0 | S6: =Med_2050!E7 -> 0 | T6: =High_2050!E7 -> 0 | U6: =Base_2050!E21 -> 0 | V6: =Low_2050!E21 -> 0 | W6: =Med_2050!E21 -> 0 | X6: =High_2050!E21 -> 0 | Y6: =Base_2050!E35 -> 0 | Z6: =Low_2050!E35 -> 0 | AA6: =Med_2050!E35 -> 0 | AB6: =High_2050!E35 -> 0
B7: Local Bus | C7: =Base_2050!B8 -> 0 | D7: =Low_2050!B8 -> 6396.82 | E7: =Med_2050!B8 -> 5974.86 | F7: =High_2050!B8 -> 5584.06 | G7: =Base_2050!B22 -> 0 | H7: =Low_2050!B22 -> 3827.08 | I7: =Med_2050!B22 -> 3580.55 | J7: =High_2050!B22 -> 3315.01 | K7: =Base_2050!B36 -> 0 | L7: =Low_2050!B36 -> 10223.9 | M7: =Med_2050!B36 -> 9555.41 | N7: =High_2050!B36 -> 8899.07 | P7: Local Bus | Q7: =Base_2050!E8 -> 0 | R7: =Low_2050!E8 -> 1087.02 | S7: =Med_2050!E8 -> 1073.35 | T7: =High_2050!E8 -> 1063.38 | U7: =Base_2050!E22 -> 0 | V7: =Low_2050!E22 -> 2115.29 | W7: =Med_2050!E22 -> 2089.84 | X7: =High_2050!E22 -> 2068.37 | Y7: =Base_2050!E36 -> 0 | Z7: =Low_2050!E36 -> 3202.31 | AA7: =Med_2050!E36 -> 3163.19 | AB7: =High_2050!E36 -> 3131.75
B8: BRT | C8: =Base_2050!B9 -> 0 | D8: =Low_2050!B9 -> 14654.2 | E8: =Med_2050!B9 -> 13726.3 | F8: =High_2050!B9 -> 12849.1 | G8: =Base_2050!B23 -> 0 | H8: =Low_2050!B23 -> 6969.71 | I8: =Med_2050!B23 -> 6554.34 | J8: =High_2050!B23 -> 6098.1 | K8: =Base_2050!B37 -> 0 | L8: =Low_2050!B37 -> 21623.9 | M8: =Med_2050!B37 -> 20280.6 | N8: =High_2050!B37 -> 18947.2 | P8: BRT | Q8: =Base_2050!E9 -> 0 | R8: =Low_2050!E9 -> 3127.93 | S8: =Med_2050!E9 -> 3089.46 | T8: =High_2050!E9 -> 3051.6 | U8: =Base_2050!E23 -> 0 | V8: =Low_2050!E23 -> 4048.79 | W8: =Med_2050!E23 -> 3996.2 | X8: =High_2050!E23 -> 3944.1 | Y8: =Base_2050!E37 -> 0 | Z8: =Low_2050!E37 -> 7176.73 | AA8: =Med_2050!E37 -> 7085.66 | AB8: =High_2050!E37 -> 6995.69
B9: MODE9 | C9: =Base_2050!B10 -> 0 | D9: =Low_2050!B10 -> 5159 | E9: =Med_2050!B10 -> 4829.91 | F9: =High_2050!B10 -> 4536.31 | G9: =Base_2050!B24 -> 0 | H9: =Low_2050!B24 -> 2108.09 | I9: =Med_2050!B24 -> 1988.88 | J9: =High_2050!B24 -> 1858.36 | K9: =Base_2050!B38 -> 0 | L9: =Low_2050!B38 -> 7267.09 | M9: =Med_2050!B38 -> 6818.79 | N9: =High_2050!B38 -> 6394.67 | P9: MODE9 | Q9: =Base_2050!E10 -> 0 | R9: =Low_2050!E10 -> 1423.96 | S9: =Med_2050!E10 -> 1407 | T9: =High_2050!E10 -> 1391.16 | U9: =Base_2050!E24 -> 0 | V9: =Low_2050!E24 -> 1895.78 | W9: =Med_2050!E24 -> 1873.45 | X9: =High_2050!E24 -> 1852.6 | Y9: =Base_2050!E38 -> 0 | Z9: =Low_2050!E38 -> 3319.74 | AA9: =Med_2050!E38 -> 3280.45 | AB9: =High_2050!E38 -> 3243.75
B10: Express Bus | C10: =Base_2050!B11 -> 0 | D10: =Low_2050!B11 -> 2880.84 | E10: =Med_2050!B11 -> 3190.74 | F10: =High_2050!B11 -> 3517.9 | G10: =Base_2050!B25 -> 0 | H10: =Low_2050!B25 -> 33.21 | I10: =Med_2050!B25 -> 32.87 | J10: =High_2050!B25 -> 32.37 | K10: =Base_2050!B39 -> 0 | L10: =Low_2050!B39 -> 2914.05 | M10: =Med_2050!B39 -> 3223.61 | N10: =High_2050!B39 -> 3550.27 | P10: Express Bus | Q10: =Base_2050!E11 -> 0 | R10: =Low_2050!E11 -> 21.72 | S10: =Med_2050!E11 -> 26.92 | T10: =High_2050!E11 -> 33.07 | U10: =Base_2050!E25 -> 0 | V10: =Low_2050!E25 -> 0.42 | W10: =Med_2050!E25 -> 0.42 | X10: =High_2050!E25 -> 0.41 | Y10: =Base_2050!E39 -> 0 | Z10: =Low_2050!E39 -> 22.14 | AA10: =Med_2050!E39 -> 27.33 | AB10: =High_2050!E39 -> 33.48
B11: Light Rail | C11: =Base_2050!B12 -> 0 | D11: =Low_2050!B12 -> 25427.6 | E11: =Med_2050!B12 -> 23348.5 | F11: =High_2050!B12 -> 21464 | G11: =Base_2050!B26 -> 0 | H11: =Low_2050!B26 -> 14257.5 | I11: =Med_2050!B26 -> 13301.3 | J11: =High_2050!B26 -> 12219.7 | K11: =Base_2050!B40 -> 0 | L11: =Low_2050!B40 -> 39685.1 | M11: =Med_2050!B40 -> 36649.8 | N11: =High_2050!B40 -> 33683.7 | P11: Light Rail | Q11: =Base_2050!E12 -> 0 | R11: =Low_2050!E12 -> 4745.11 | S11: =Med_2050!E12 -> 4635.6 | T11: =High_2050!E12 -> 4522.09 | U11: =Base_2050!E26 -> 0 | V11: =Low_2050!E26 -> 9961.75 | W11: =Med_2050!E26 -> 9802.9 | X11: =High_2050!E26 -> 9631.92 | Y11: =Base_2050!E40 -> 0 | Z11: =Low_2050!E40 -> 14706.9 | AA11: =Med_2050!E40 -> 14438.5 | AB11: =High_2050!E40 -> 14154
B12: Comm. Rail | C12: =Base_2050!B13 -> 0 | D12: =Low_2050!B13 -> 26461.7 | E12: =Med_2050!B13 -> 23782.3 | F12: =High_2050!B13 -> 21617.6 | G12: =Base_2050!B27 -> 0 | H12: =Low_2050!B27 -> 8718.6 | I12: =Med_2050!B27 -> 8162.34 | J12: =High_2050!B27 -> 7473.86 | K12: =Base_2050!B41 -> 0 | L12: =Low_2050!B41 -> 35180.3 | M12: =Med_2050!B41 -> 31944.6 | N12: =High_2050!B41 -> 29091.5 | P12: Comm. Rail | Q12: =Base_2050!E13 -> 0 | R12: =Low_2050!E13 -> 1072.71 | S12: =Med_2050!E13 -> 1044.66 | T12: =High_2050!E13 -> 1019.19 | U12: =Base_2050!E27 -> 0 | V12: =Low_2050!E27 -> 1251.51 | W12: =Med_2050!E27 -> 1243.23 | X12: =High_2050!E27 -> 1230.27 | Y12: =Base_2050!E41 -> 0 | Z12: =Low_2050!E41 -> 2324.22 | AA12: =Med_2050!E41 -> 2287.89 | AB12: =High_2050!E41 -> 2249.46
B13: Total Trips | C13: =Base_2050!B14 -> 0 | D13: =Low_2050!B14 -> 1600413 | E13: =Med_2050!B14 -> 1504665 | F13: =High_2050!B14 -> 1411666 | G13: =Base_2050!B28 -> 0 | H13: =Low_2050!B28 -> 918291 | I13: =Med_2050!B28 -> 864962 | J13: =High_2050!B28 -> 809146 | K13: =Base_2050!B42 -> 0 | L13: =Low_2050!B42 -> 2518704 | M13: =Med_2050!B42 -> 2369627 | N13: =High_2050!B42 -> 2220812 | P13: Total Trips | Q13: =Base_2050!E14 -> 0 | R13: =Low_2050!E14 -> 1132088 | S13: =Med_2050!E14 -> 1119791 | T13: =High_2050!E14 -> 1107432 | U13: =Base_2050!E28 -> 0 | V13: =Low_2050!E28 -> 2579860 | W13: =Med_2050!E28 -> 2551687 | X13: =High_2050!E28 -> 2523164 | Y13: =Base_2050!E42 -> 0 | Z13: =Low_2050!E42 -> 3711948 | AA13: =Med_2050!E42 -> 3671477 | AB13: =High_2050!E42 -> 3630596
B16: 2050 | C16: Peak | G16: Off-Peak | K16: Daily | P16: 2050 | Q16: Peak | U16: Off-Peak | Y16: Daily
B17: Home Based College | C17: Base | D17: Low | E17: Medium | F17: High | G17: Base | H17: Low | I17: Medium | J17: High | K17: Base | L17: Low | M17: Medium | N17: High | P17: Home Based School | Q17: Base | R17: Low | S17: Medium | T17: High | U17: Base | V17: Low | W17: Medium | X17: High | Y17: Base | Z17: Low | AA17: Medium | AB17: High
B18: Non-Motorized | C18: =Base_2050!C5 -> 0 | D18: =Low_2050!C5 -> 25923.9 | E18: =Med_2050!C5 -> 25892.1 | F18: =High_2050!C5 -> 25861.8 | G18: =Base_2050!C19 -> 0 | H18: =Low_2050!C19 -> 0 | I18: =Med_2050!C19 -> 0 | J18: =High_2050!C19 -> 0 | K18: =Base_2050!C33 -> 0 | L18: =Low_2050!C33 -> 25923.9 | M18: =Med_2050!C33 -> 25892.1 | N18: =High_2050!C33 -> 25861.8 | P18: Non-Motorized | Q18: =Base_2050!F5 -> 0 | R18: =Low_2050!F5 -> 189443 | S18: =Med_2050!F5 -> 189069 | T18: =High_2050!F5 -> 188690 | U18: =Base_2050!F19 -> 0 | V18: =Low_2050!F19 -> 92257.4 | W18: =Med_2050!F19 -> 92075.8 | X18: =High_2050!F19 -> 91890.7 | Y18: =Base_2050!F33 -> 0 | Z18: =Low_2050!F33 -> 281701 | AA18: =Med_2050!F33 -> 281145 | AB18: =High_2050!F33 -> 280580
B19: Auto | C19: =Base_2050!C6 -> 0 | D19: =Low_2050!C6 -> 109890 | E19: =Med_2050!C6 -> 110127 | F19: =High_2050!C6 -> 110266 | G19: =Base_2050!C20 -> 0 | H19: =Low_2050!C20 -> 0 | I19: =Med_2050!C20 -> 0 | J19: =High_2050!C20 -> 0 | K19: =Base_2050!C34 -> 0 | L19: =Low_2050!C34 -> 109890 | M19: =Med_2050!C34 -> 110127 | N19: =High_2050!C34 -> 110266 | P19: Auto | Q19: =Base_2050!F6 -> 0 | R19: =Low_2050!F6 -> 99119.6 | S19: =Med_2050!F6 -> 99119.5 | T19: =High_2050!F6 -> 99117.7 | U19: =Base_2050!F20 -> 0 | V19: =Low_2050!F20 -> 47897.5 | W19: =Med_2050!F20 -> 47893.9 | X19: =High_2050!F20 -> 47884.8 | Y19: =Base_2050!F34 -> 0 | Z19: =Low_2050!F34 -> 147017 | AA19: =Med_2050!F34 -> 147013 | AB19: =High_2050!F34 -> 147003
B20: School Bus | C20: =Base_2050!C7 -> 0 | D20: =Low_2050!C7 -> 0 | E20: =Med_2050!C7 -> 0 | F20: =High_2050!C7 -> 0 | G20: =Base_2050!C21 -> 0 | H20: =Low_2050!C21 -> 0 | I20: =Med_2050!C21 -> 0 | J20: =High_2050!C21 -> 0 | K20: =Base_2050!C35 -> 0 | L20: =Low_2050!C35 -> 0 | M20: =Med_2050!C35 -> 0 | N20: =High_2050!C35 -> 0 | P20: School Bus | Q20: =Base_2050!F7 -> 0 | R20: =Low_2050!F7 -> 261600 | S20: =Med_2050!F7 -> 261979 | T20: =High_2050!F7 -> 262365 | U20: =Base_2050!F21 -> 0 | V20: =Low_2050!F21 -> 127364 | W20: =Med_2050!F21 -> 127545 | X20: =High_2050!F21 -> 127725 | Y20: =Base_2050!F35 -> 0 | Z20: =Low_2050!F35 -> 388964 | AA20: =Med_2050!F35 -> 389525 | AB20: =High_2050!F35 -> 390090
B21: Local Bus | C21: =Base_2050!C8 -> 0 | D21: =Low_2050!C8 -> 6074.8 | E21: =Med_2050!C8 -> 6071.24 | F21: =High_2050!C8 -> 6089.61 | G21: =Base_2050!C22 -> 0 | H21: =Low_2050!C22 -> 0 | I21: =Med_2050!C22 -> 0 | J21: =High_2050!C22 -> 0 | K21: =Base_2050!C36 -> 0 | L21: =Low_2050!C36 -> 6074.8 | M21: =Med_2050!C36 -> 6071.24 | N21: =High_2050!C36 -> 6089.61 | P21: Local Bus | Q21: =Base_2050!F8 -> 0 | R21: =Low_2050!F8 -> 0 | S21: =Med_2050!F8 -> 0 | T21: =High_2050!F8 -> 0 | U21: =Base_2050!F22 -> 0 | V21: =Low_2050!F22 -> 0 | W21: =Med_2050!F22 -> 0 | X21: =High_2050!F22 -> 0 | Y21: =Base_2050!F36 -> 0 | Z21: =Low_2050!F36 -> 0 | AA21: =Med_2050!F36 -> 0 | AB21: =High_2050!F36 -> 0
B22: BRT | C22: =Base_2050!C9 -> 0 | D22: =Low_2050!C9 -> 4456.09 | E22: =Med_2050!C9 -> 4457.76 | F22: =High_2050!C9 -> 4439.96 | G22: =Base_2050!C23 -> 0 | H22: =Low_2050!C23 -> 0 | I22: =Med_2050!C23 -> 0 | J22: =High_2050!C23 -> 0 | K22: =Base_2050!C37 -> 0 | L22: =Low_2050!C37 -> 4456.09 | M22: =Med_2050!C37 -> 4457.76 | N22: =High_2050!C37 -> 4439.96 | P22: BRT | Q22: =Base_2050!F9 -> 0 | R22: =Low_2050!F9 -> 0 | S22: =Med_2050!F9 -> 0 | T22: =High_2050!F9 -> 0 | U22: =Base_2050!F23 -> 0 | V22: =Low_2050!F23 -> 0 | W22: =Med_2050!F23 -> 0 | X22: =High_2050!F23 -> 0 | Y22: =Base_2050!F37 -> 0 | Z22: =Low_2050!F37 -> 0 | AA22: =Med_2050!F37 -> 0 | AB22: =High_2050!F37 -> 0
B23: MODE9 | C23: =Base_2050!C10 -> 0 | D23: =Low_2050!C10 -> 10274.1 | E23: =Med_2050!C10 -> 10262.6 | F23: =High_2050!C10 -> 10249.4 | G23: =Base_2050!C24 -> 0 | H23: =Low_2050!C24 -> 0 | I23: =Med_2050!C24 -> 0 | J23: =High_2050!C24 -> 0 | K23: =Base_2050!C38 -> 0 | L23: =Low_2050!C38 -> 10274.1 | M23: =Med_2050!C38 -> 10262.6 | N23: =High_2050!C38 -> 10249.4 | P23: MODE9 | Q23: =Base_2050!F10 -> 0 | R23: =Low_2050!F10 -> 0 | S23: =Med_2050!F10 -> 0 | T23: =High_2050!F10 -> 0 | U23: =Base_2050!F24 -> 0 | V23: =Low_2050!F24 -> 0 | W23: =Med_2050!F24 -> 0 | X23: =High_2050!F24 -> 0 | Y23: =Base_2050!F38 -> 0 | Z23: =Low_2050!F38 -> 0 | AA23: =Med_2050!F38 -> 0 | AB23: =High_2050!F38 -> 0
B24: Express Bus | C24: =Base_2050!C11 -> 0 | D24: =Low_2050!C11 -> 261.03 | E24: =Med_2050!C11 -> 306.33 | F24: =High_2050!C11 -> 419.4 | G24: =Base_2050!C25 -> 0 | H24: =Low_2050!C25 -> 0 | I24: =Med_2050!C25 -> 0 | J24: =High_2050!C25 -> 0 | K24: =Base_2050!C39 -> 0 | L24: =Low_2050!C39 -> 261.03 | M24: =Med_2050!C39 -> 306.33 | N24: =High_2050!C39 -> 419.4 | P24: Express Bus | Q24: =Base_2050!F11 -> 0 | R24: =Low_2050!F11 -> 0 | S24: =Med_2050!F11 -> 0 | T24: =High_2050!F11 -> 0 | U24: =Base_2050!F25 -> 0 | V24: =Low_2050!F25 -> 0 | W24: =Med_2050!F25 -> 0 | X24: =High_2050!F25 -> 0 | Y24: =Base_2050!F39 -> 0 | Z24: =Low_2050!F39 -> 0 | AA24: =Med_2050!F39 -> 0 | AB24: =High_2050!F39 -> 0
B25: Light Rail | C25: =Base_2050!C12 -> 0 | D25: =Low_2050!C12 -> 11208.5 | E25: =Med_2050!C12 -> 11069.4 | F25: =High_2050!C12 -> 10951.9 | G25: =Base_2050!C26 -> 0 | H25: =Low_2050!C26 -> 0 | I25: =Med_2050!C26 -> 0 | J25: =High_2050!C26 -> 0 | K25: =Base_2050!C40 -> 0 | L25: =Low_2050!C40 -> 11208.5 | M25: =Med_2050!C40 -> 11069.4 | N25: =High_2050!C40 -> 10951.9 | P25: Light Rail | Q25: =Base_2050!F12 -> 0 | R25: =Low_2050!F12 -> 0 | S25: =Med_2050!F12 -> 0 | T25: =High_2050!F12 -> 0 | U25: =Base_2050!F26 -> 0 | V25: =Low_2050!F26 -> 0 | W25: =Med_2050!F26 -> 0 | X25: =High_2050!F26 -> 0 | Y25: =Base_2050!F40 -> 0 | Z25: =Low_2050!F40 -> 0 | AA25: =Med_2050!F40 -> 0 | AB25: =High_2050!F40 -> 0
B26: Comm. Rail | C26: =Base_2050!C13 -> 0 | D26: =Low_2050!C13 -> 9873.23 | E26: =Med_2050!C13 -> 9775.33 | F26: =High_2050!C13 -> 9683.56 | G26: =Base_2050!C27 -> 0 | H26: =Low_2050!C27 -> 0 | I26: =Med_2050!C27 -> 0 | J26: =High_2050!C27 -> 0 | K26: =Base_2050!C41 -> 0 | L26: =Low_2050!C41 -> 9873.23 | M26: =Med_2050!C41 -> 9775.33 | N26: =High_2050!C41 -> 9683.56 | P26: Comm. Rail | Q26: =Base_2050!F13 -> 0 | R26: =Low_2050!F13 -> 0 | S26: =Med_2050!F13 -> 0 | T26: =High_2050!F13 -> 0 | U26: =Base_2050!F27 -> 0 | V26: =Low_2050!F27 -> 0 | W26: =Med_2050!F27 -> 0 | X26: =High_2050!F27 -> 0 | Y26: =Base_2050!F41 -> 0 | Z26: =Low_2050!F41 -> 0 | AA26: =Med_2050!F41 -> 0 | AB26: =High_2050!F41 -> 0
B27: Total Trips | C27: =Base_2050!C14 -> 0 | D27: =Low_2050!C14 -> 177962 | E27: =Med_2050!C14 -> 177962 | F27: =High_2050!C14 -> 177962 | G27: =Base_2050!C28 -> 0 | H27: =Low_2050!C28 -> 0 | I27: =Med_2050!C28 -> 0 | J27: =High_2050!C28 -> 0 | K27: =Base_2050!C42 -> 0 | L27: =Low_2050!C42 -> 177962 | M27: =Med_2050!C42 -> 177962 | N27: =High_2050!C42 -> 177962 | P27: Total Trips | Q27: =Base_2050!F14 -> 0 | R27: =Low_2050!F14 -> 550163 | S27: =Med_2050!F14 -> 550167 | T27: =High_2050!F14 -> 550172 | U27: =Base_2050!F28 -> 0 | V27: =Low_2050!F28 -> 267519 | W27: =Med_2050!F28 -> 267515 | X27: =High_2050!F28 -> 267500 | Y27: =Base_2050!F42 -> 0 | Z27: =Low_2050!F42 -> 817681 | AA27: =Med_2050!F42 -> 817683 | AB27: =High_2050!F42 -> 817672
B30: 2050 | C30: Peak | G30: Off-Peak | K30: Daily | P30: 2050 | Q30: Peak | U30: Off-Peak | Y30: Daily
B31: Home Based Other | C31: Base | D31: Low | E31: Medium | F31: High | G31: Base | H31: Low | I31: Medium | J31: High | K31: Base | L31: Low | M31: Medium | N31: High | P31: Total Trips | Q31: Base | R31: Low | S31: Medium | T31: High | U31: Base | V31: Low | W31: Medium | X31: High | Y31: Base | Z31: Low | AA31: Medium | AB31: High
B32: Non-Motorized | C32: =Base_2050!D5 -> 0 | D32: =Low_2050!D5 -> 227319 | E32: =Med_2050!D5 -> 226461 | F32: =High_2050!D5 -> 225606 | G32: =Base_2050!D19 -> 0 | H32: =Low_2050!D19 -> 578604 | I32: =Med_2050!D19 -> 576825 | J32: =High_2050!D19 -> 575027 | K32: =Base_2050!D33 -> 0 | L32: =Low_2050!D33 -> 805923 | M32: =Med_2050!D33 -> 803286 | N32: =High_2050!D33 -> 800633 | P32: Non-Motorized | Q32: =Base_2050!G5 -> 0 | R32: =Low_2050!G5 -> 555447 | S32: =Med_2050!G5 -> 548978 | T32: =High_2050!G5 -> 542633 | U32: =Base_2050!G19 -> 0 | V32: =Low_2050!G19 -> 892529 | W32: =Med_2050!G19 -> 885018 | X32: =High_2050!G19 -> 877507 | Y32: =Base_2050!G33 -> 0 | Z32: =Low_2050!G33 -> 1447976 | AA32: =Med_2050!G33 -> 1433996 | AB32: =High_2050!G33 -> 1420140
B33: Auto | C33: =Base_2050!D6 -> 0 | D33: =Low_2050!D6 -> 1930699 | E33: =Med_2050!D6 -> 1931537 | F33: =High_2050!D6 -> 1932229 | G33: =Base_2050!D20 -> 0 | H33: =Low_2050!D20 -> 3952314 | I33: =Med_2050!D20 -> 3953917 | J33: =High_2050!D20 -> 3955519 | K33: =Base_2050!D34 -> 0 | L33: =Low_2050!D34 -> 5883013 | M33: =Med_2050!D34 -> 5885454 | N33: =High_2050!D34 -> 5887748 | P33: Auto | Q33: =Base_2050!G6 -> 0 | R33: =Low_2050!G6 -> 4666991 | S33: =Med_2050!G6 -> 4571553 | T33: =High_2050!G6 -> 4477585 | U33: =Base_2050!G20 -> 0 | V33: =Low_2050!G20 -> 7221507 | W33: =Med_2050!G20 -> 7149716 | X33: =High_2050!G20 -> 7075399 | Y33: =Base_2050!G34 -> 0 | Z33: =Low_2050!G34 -> 10000000 | AA33: =Med_2050!G34 -> 10000000 | AB33: =High_2050!G34 -> 10000000
B34: School Bus | C34: =Base_2050!D7 -> 0 | D34: =Low_2050!D7 -> 0 | E34: =Med_2050!D7 -> 0 | F34: =High_2050!D7 -> 0 | G34: =Base_2050!D21 -> 0 | H34: =Low_2050!D21 -> 0 | I34: =Med_2050!D21 -> 0 | J34: =High_2050!D21 -> 0 | K34: =Base_2050!D35 -> 0 | L34: =Low_2050!D35 -> 0 | M34: =Med_2050!D35 -> 0 | N34: =High_2050!D35 -> 0 | P34: School Bus | Q34: =Base_2050!G7 -> 0 | R34: =Low_2050!G7 -> 261600 | S34: =Med_2050!G7 -> 261979 | T34: =High_2050!G7 -> 262365 | U34: =Base_2050!G21 -> 0 | V34: =Low_2050!G21 -> 127364 | W34: =Med_2050!G21 -> 127545 | X34: =High_2050!G21 -> 127725 | Y34: =Base_2050!G35 -> 0 | Z34: =Low_2050!G35 -> 388964 | AA34: =Med_2050!G35 -> 389525 | AB34: =High_2050!G35 -> 390090
B35: Local Bus | C35: =Base_2050!D8 -> 0 | D35: =Low_2050!D8 -> 4268 | E35: =Med_2050!D8 -> 4271.7 | F35: =High_2050!D8 -> 4276.73 | G35: =Base_2050!D22 -> 0 | H35: =Low_2050!D22 -> 8246.35 | I35: =Med_2050!D22 -> 8252.11 | J35: =High_2050!D22 -> 8265.61 | K35: =Base_2050!D36 -> 0 | L35: =Low_2050!D36 -> 12514.4 | M35: =Med_2050!D36 -> 12523.8 | N35: =High_2050!D36 -> 12542.3 | P35: Local Bus | Q35: =Base_2050!G8 -> 0 | R35: =Low_2050!G8 -> 17826.6 | S35: =Med_2050!G8 -> 17391.1 | T35: =High_2050!G8 -> 17013.8 | U35: =Base_2050!G22 -> 0 | V35: =Low_2050!G22 -> 14188.7 | W35: =Med_2050!G22 -> 13922.5 | X35: =High_2050!G22 -> 13649 | Y35: =Base_2050!G36 -> 0 | Z35: =Low_2050!G36 -> 32015.4 | AA35: =Med_2050!G36 -> 31313.6 | AB35: =High_2050!G36 -> 30662.8
B36: BRT | C36: =Base_2050!D9 -> 0 | D36: =Low_2050!D9 -> 12221.7 | E36: =Med_2050!D9 -> 12243.5 | F36: =High_2050!D9 -> 12259.7 | G36: =Base_2050!D23 -> 0 | H36: =Low_2050!D23 -> 18045.9 | I36: =Med_2050!D23 -> 18068.9 | J36: =High_2050!D23 -> 18086 | K36: =Base_2050!D37 -> 0 | L36: =Low_2050!D37 -> 30267.5 | M36: =Med_2050!D37 -> 30312.4 | N36: =High_2050!D37 -> 30345.6 | P36: BRT | Q36: =Base_2050!G9 -> 0 | R36: =Low_2050!G9 -> 34459.9 | S36: =Med_2050!G9 -> 33517 | T36: =High_2050!G9 -> 32600.3 | U36: =Base_2050!G23 -> 0 | V36: =Low_2050!G23 -> 29064.4 | W36: =Med_2050!G23 -> 28619.4 | X36: =High_2050!G23 -> 28128.2 | Y36: =Base_2050!G37 -> 0 | Z36: =Low_2050!G37 -> 63524.2 | AA36: =Med_2050!G37 -> 62136.4 | AB36: =High_2050!G37 -> 60728.4
B37: MODE9 | C37: =Base_2050!D10 -> 0 | D37: =Low_2050!D10 -> 5564.12 | E37: =Med_2050!D10 -> 5567.46 | F37: =High_2050!D10 -> 5569.92 | G37: =Base_2050!D24 -> 0 | H37: =Low_2050!D24 -> 6832.9 | I37: =Med_2050!D24 -> 6839.87 | J37: =High_2050!D24 -> 6850.16 | K37: =Base_2050!D38 -> 0 | L37: =Low_2050!D38 -> 12397 | M37: =Med_2050!D38 -> 12407.3 | N37: =High_2050!D38 -> 12420.1 | P37: MODE9 | Q37: =Base_2050!G10 -> 0 | R37: =Low_2050!G10 -> 22421.1 | S37: =Med_2050!G10 -> 22067 | T37: =High_2050!G10 -> 21746.7 | U37: =Base_2050!G24 -> 0 | V37: =Low_2050!G24 -> 10836.8 | W37: =Med_2050!G24 -> 10702.2 | X37: =High_2050!G24 -> 10561.1 | Y37: =Base_2050!G38 -> 0 | Z37: =Low_2050!G38 -> 33257.9 | AA37: =Med_2050!G38 -> 32769.2 | AB37: =High_2050!G38 -> 32307.9
B38: Express Bus | C38: =Base_2050!D11 -> 0 | D38: =Low_2050!D11 -> 117.71 | E38: =Med_2050!D11 -> 125.43 | F38: =High_2050!D11 -> 160.24 | G38: =Base_2050!D25 -> 0 | H38: =Low_2050!D25 -> 1.66 | I38: =Med_2050!D25 -> 1.66 | J38: =High_2050!D25 -> 1.66 | K38: =Base_2050!D39 -> 0 | L38: =Low_2050!D39 -> 119.37 | M38: =Med_2050!D39 -> 127.09 | N38: =High_2050!D39 -> 161.89 | P38: Express Bus | Q38: =Base_2050!G11 -> 0 | R38: =Low_2050!G11 -> 3281.3 | S38: =Med_2050!G11 -> 3649.42 | T38: =High_2050!G11 -> 4130.61 | U38: =Base_2050!G25 -> 0 | V38: =Low_2050!G25 -> 35.29 | W38: =Med_2050!G25 -> 34.95 | X38: =High_2050!G25 -> 34.44 | Y38: =Base_2050!G39 -> 0 | Z38: =Low_2050!G39 -> 3316.59 | AA38: =Med_2050!G39 -> 3684.37 | AB38: =High_2050!G39 -> 4165.04
B39: Light Rail | C39: =Base_2050!D12 -> 0 | D39: =Low_2050!D12 -> 17293.1 | E39: =Med_2050!D12 -> 17243.4 | F39: =High_2050!D12 -> 17182.3 | G39: =Base_2050!D26 -> 0 | H39: =Low_2050!D26 -> 31127.4 | I39: =Med_2050!D26 -> 31174.2 | J39: =High_2050!D26 -> 31181 | K39: =Base_2050!D40 -> 0 | L39: =Low_2050!D40 -> 48420.5 | M39: =Med_2050!D40 -> 48417.6 | N39: =High_2050!D40 -> 48363.3 | P39: Light Rail | Q39: =Base_2050!G12 -> 0 | R39: =Low_2050!G12 -> 58674.3 | S39: =Med_2050!G12 -> 56296.9 | T39: =High_2050!G12 -> 54120.2 | U39: =Base_2050!G26 -> 0 | V39: =Low_2050!G26 -> 55346.7 | W39: =Med_2050!G26 -> 54278.4 | X39: =High_2050!G26 -> 53032.6 | Y39: =Base_2050!G40 -> 0 | Z39: =Low_2050!G40 -> 114021 | AA39: =Med_2050!G40 -> 110575 | AB39: =High_2050!G40 -> 107153
B40: Comm. Rail | C40: =Base_2050!D13 -> 0 | D40: =Low_2050!D13 -> 3376.12 | E40: =Med_2050!D13 -> 3355.82 | F40: =High_2050!D13 -> 3344.51 | G40: =Base_2050!D27 -> 0 | H40: =Low_2050!D27 -> 4216.6 | I40: =Med_2050!D27 -> 4250.17 | J40: =High_2050!D27 -> 4284.3 | K40: =Base_2050!D41 -> 0 | L40: =Low_2050!D41 -> 7592.72 | M40: =Med_2050!D41 -> 7605.99 | N40: =High_2050!D41 -> 7628.82 | P40: Comm. Rail | Q40: =Base_2050!G13 -> 0 | R40: =Low_2050!G13 -> 40783.7 | S40: =Med_2050!G13 -> 37958.1 | T40: =High_2050!G13 -> 35664.9 | U40: =Base_2050!G27 -> 0 | V40: =Low_2050!G27 -> 14186.7 | W40: =Med_2050!G27 -> 13655.7 | X40: =High_2050!G27 -> 12988.4 | Y40: =Base_2050!G41 -> 0 | Z40: =Low_2050!G41 -> 54970.4 | AA40: =Med_2050!G41 -> 51613.9 | AB40: =High_2050!G41 -> 48653.3
B41: Total Trips | C41: =Base_2050!D14 -> 0 | D41: =Low_2050!D14 -> 2200859 | E41: =Med_2050!D14 -> 2200806 | F41: =High_2050!D14 -> 2200629 | G41: =Base_2050!D28 -> 0 | H41: =Low_2050!D28 -> 4599389 | I41: =Med_2050!D28 -> 4599329 | J41: =High_2050!D28 -> 4599215 | K41: =Base_2050!D42 -> 0 | L41: =Low_2050!D42 -> 6800247 | M41: =Med_2050!D42 -> 6800134 | N41: =High_2050!D42 -> 6799843 | P41: Total Trips | Q41: =Base_2050!G14 -> 0 | R41: =Low_2050!G14 -> 5661484 | S41: =Med_2050!G14 -> 5553390 | T41: =High_2050!G14 -> 5447860 | U41: =Base_2050!G28 -> 0 | V41: =Low_2050!G28 -> 8365059 | W41: =Med_2050!G28 -> 8283493 | X41: =High_2050!G28 -> 8199025 | Y41: =Base_2050!G42 -> 0 | Z41: =Low_2050!G42 -> 10000000 | AA41: =Med_2050!G42 -> 10000000 | AB41: =High_2050!G42 -> 10000000

Sheet Base_2019
A1: Scenarios\BY_2019 - base\
A3: Peak
A4: Mode | B4: HBW | C4: HBC | D4: HBO | E4: NHB | F4: HBSch | G4: Total
A5: Non-Motorized | B5: 48337.1 | C5: 22397.1 | D5: 147453 | E5: 29219.1 | F5: 182360 | G5: 429767
A6: Auto | B6: 1050350 | C6: 79886.1 | D6: 1313694 | E6: 704036 | F6: 77705.5 | G6: 3225671
A7: School Bus | B7: 0 | C7: 0 | D7: 0 | E7: 0 | F7: 174377 | G7: 174377
A8: Local Bus | B8: 10556 | C8: 7310.87 | D8: 5221.78 | E8: 1529.98 | F8: 0 | G8: 24618.6
A9: BRT 1 | B9: 128.3 | C9: 33.86 | D9: 87.83 | E9: 20.43 | F9: 0 | G9: 270.43
A10: BRT 3 | B10: 1482.81 | C10: 7009.28 | D10: 1366.42 | E10: 496.64 | F10: 0 | G10: 10355.2
A11: Express Bus | B11: 1643.13 | C11: 101.12 | D11: 66.01 | E11: 11.03 | F11: 0 | G11: 1821.29
A12: Light Rail | B12: 16070.6 | C12: 6700.86 | D12: 7638.61 | E12: 3427.58 | F12: 0 | G12: 33837.7
A13: Commuter Rail | B13: 12718.6 | C13: 4073.22 | D13: 1474.28 | E13: 604.45 | F13: 0 | G13: 18870.6
A14: Total Trips | B14: 1141287 | C14: 127512 | D14: 1477002 | E14: 739345 | F14: 434442 | G14: 3919589
A17: Off-Peak
A18: Mode | B18: HBW | C18: HBC | D18: HBO | E18: NHB | F18: HBSch | G18: Total
A19: Non-Motorized | B19: 35324.2 | C19: 0 | D19: 368928 | E19: 116487 | F19: 88808.3 | G19: 609547
A20: Auto | B20: 601000 | C20: 0 | D20: 2693602 | E20: 1557602 | F20: 37511.2 | G20: 4889716
A21: School Bus | B21: 0 | C21: 0 | D21: 0 | E21: 0 | F21: 84821.7 | G21: 84821.7
A22: Local Bus | B22: 6272.83 | C22: 0 | D22: 9821.81 | E22: 2815.73 | F22: 0 | G22: 18910.4
A23: BRT 1 | B23: 72.07 | C23: 0 | D23: 154.42 | E23: 38.89 | F23: 0 | G23: 265.37
A24: BRT 3 | B24: 680.81 | C24: 0 | D24: 1802.74 | E24: 727.5 | F24: 0 | G24: 3211.05
A25: Express Bus | B25: 0 | C25: 0 | D25: 0 | E25: 0 | F25: 0 | G25: 0
A26: Light Rail | B26: 7911.35 | C26: 0 | D26: 11928 | E26: 6418.62 | F26: 0 | G26: 26258
A27: Commuter Rail | B27: 3559.3 | C27: 0 | D27: 1650.5 | E27: 757.97 | F27: 0 | G27: 5967.77
A28: Total Trips | B28: 654821 | C28: 0 | D28: 3087888 | E28: 1684848 | F28: 211141 | G28: 5638697
A31: Daily
A32: Mode | B32: HBW | C32: HBC | D32: HBO | E32: NHB | F32: HBSch | G32: Total
A33: Non-Motorized | B33: 83661.3 | C33: 22397.1 | D33: 516381 | E33: 145706 | F33: 271169 | G33: 1039314
A34: Auto | B34: 1651350 | C34: 79886.1 | D34: 4007296 | E34: 2261638 | F34: 115217 | G34: 8115387
A35: School Bus | B35: 0 | C35: 0 | D35: 0 | E35: 0 | F35: 259198 | G35: 259198
A36: Local Bus | B36: 16828.8 | C36: 7310.87 | D36: 15043.6 | E36: 4345.71 | F36: 0 | G36: 43529
A37: BRT 1 | B37: 200.36 | C37: 33.86 | D37: 242.25 | E37: 59.32 | F37: 0 | G37: 535.8
A38: BRT 3 | B38: 2163.62 | C38: 7009.28 | D38: 3169.17 | E38: 1224.14 | F38: 0 | G38: 13566.2
A39: Express Bus | B39: 1643.13 | C39: 101.12 | D39: 66.01 | E39: 11.03 | F39: 0 | G39: 1821.29
A40: Light Rail | B40: 23982 | C40: 6700.86 | D40: 19566.6 | E40: 9846.2 | F40: 0 | G40: 60095.6
A41: Commuter Rail | B41: 16277.9 | C41: 4073.22 | D41: 3124.78 | E41: 1362.41 | F41: 0 | G41: 24838.3
A42: Total Trips | B42: 1796108 | C42: 127512 | D42: 4564889 | E42: 2424193 | F42: 645584 | G42: 9558286

Sheet Low_2019
A1: Scenarios\BY_2019 - low\
A3: Peak
A4: Mode | B4: HBW | C4: HBC | D4: HBO | E4: NHB | F4: HBSch | G4: Total
A5: Non-Motorized | B5: 42205.6 | C5: 22345.6 | D5: 146588 | E5: 28486.7 | F5: 181810 | G5: 421436
A6: Auto | B6: 934773 | C6: 80041.8 | D6: 1314480 | E6: 690847 | F6: 77700.4 | G6: 3097842
A7: School Bus | B7: 0 | C7: 0 | D7: 0 | E7: 0 | F7: 174933 | G7: 174933
A8: Local Bus | B8: 9285.47 | C8: 7331.17 | D8: 5237.96 | E8: 1495.44 | F8: 0 | G8: 23350
A9: BRT 1 | B9: 118.42 | C9: 34.13 | D9: 88.11 | E9: 20.12 | F9: 0 | G9: 260.78
A10: BRT 3 | B10: 1290.45 | C10: 7003.69 | D10: 1365.37 | E10: 481.42 | F10: 0 | G10: 10140.9
A11: Express Bus | B11: 1805.91 | C11: 134.29 | D11: 71.83 | E11: 14.2 | F11: 0 | G11: 2026.22
A12: Light Rail | B12: 13748 | C12: 6627.18 | D12: 7601.1 | E12: 3286.05 | F12: 0 | G12: 31262.4
A13: Commuter Rail | B13: 10249.8 | C13: 3994.54 | D13: 1439.52 | E13: 566 | F13: 0 | G13: 16249.8
A14: Total Trips | B14: 1013477 | C14: 127512 | D14: 1476872 | E14: 725197 | F14: 434444 | G14: 3777502
A17: Off-Peak
A18: Mode | B18: HBW | C18: HBC | D18: HBO | E18: NHB | F18: HBSch | G18: Total
A19: Non-Motorized | B19: 30911.5 | C19: 0 | D19: 367219 | E19: 113691 | F19: 88540.3 | G19: 600361
A20: Auto | B20: 533312 | C20: 0 | D20: 2695075 | E20: 1528285 | F20: 37502.4 | G20: 4794174
A21: School Bus | B21: 0 | C21: 0 | D21: 0 | E21: 0 | F21: 85083.5 | G21: 85083.5
A22: Local Bus | B22: 5446.42 | C22: 0 | D22: 9841.65 | E22: 2756.07 | F22: 0 | G22: 18044.1
A23: BRT 1 | B23: 65.61 | C23: 0 | D23: 154.99 | E23: 38.4 | F23: 0 | G23: 259
A24: BRT 3 | B24: 584.75 | C24: 0 | D24: 1768.07 | E24: 702.69 | F24: 0 | G24: 3055.51
A25: Express Bus | B25: 0 | C25: 0 | D25: 0 | E25: 0 | F25: 0 | G25: 0
A26: Light Rail | B26: 6854.93 | C26: 0 | D26: 11945.6 | E26: 6208.33 | F26: 0 | G26: 25008.8
A27: Commuter Rail | B27: 3062.97 | C27: 0 | D27: 1670.31 | E27: 738.72 | F27: 0 | G27: 5472
A28: Total Trips | B28: 580238 | C28: 0 | D28: 3087674 | E28: 1652419 | F28: 211126 | G28: 5531458
A31: Daily
A32: Mode | B32: HBW | C32: HBC | D32: HBO | E32: NHB | F32: HBSch | G32: Total
A33: Non-Motorized | B33: 73117.2 | C33: 22345.6 | D33: 513807 | E33: 142177 | F33: 270351 | G33: 1021797
A34: Auto | B34: 1468085 | C34: 80041.8 | D34: 4009555 | E34: 2219131 | F34: 115203 | G34: 7892016
A35: School Bus | B35: 0 | C35: 0 | D35: 0 | E35: 0 | F35: 260017 | G35: 260017
A36: Local Bus | B36: 14731.9 | C36: 7331.17 | D36: 15079.6 | E36: 4251.51 | F36: 0 | G36: 41394.2
A37: BRT 1 | B37: 184.02 | C37: 34.13 | D37: 243.1 | E37: 58.52 | F37: 0 | G37: 519.77
A38: BRT 3 | B38: 1875.2 | C38: 7003.69 | D38: 3133.44 | E38: 1184.11 | F38: 0 | G38: 13196.4
A39: Express Bus | B39: 1805.91 | C39: 134.29 | D39: 71.83 | E39: 14.2 | F39: 0 | G39: 2026.22
A40: Light Rail | B40: 20602.9 | C40: 6627.18 | D40: 19546.7 | E40: 9494.39 | F40: 0 | G40: 56271.2
A41: Commuter Rail | B41: 13312.7 | C41: 3994.54 | D41: 3109.83 | E41: 1304.72 | F41: 0 | G41: 21721.8
A42: Total Trips | B42: 1593715 | C42: 127512 | D42: 4564546 | E42: 2377616 | F42: 645570 | G42: 9308959

Sheet Med_2019
A1: Scenarios\BY_2019 - medium\
A3: Peak
A4: Mode | B4: HBW | C4: HBC | D4: HBO | E4: NHB | F4: HBSch | G4: Total
A5: Non-Motorized | B5: 39651.9 | C5: 22328.9 | D5: 146229 | E5: 28141.6 | F5: 181586 | G5: 417937
A6: Auto | B6: 884814 | C6: 80141.5 | D6: 1314837 | E6: 683935 | F6: 77697.4 | G6: 3041425
A7: School Bus | B7: 0 | C7: 0 | D7: 0 | E7: 0 | F7: 175163 | G7: 175163
A8: Local Bus | B8: 8696.67 | C8: 7361.93 | D8: 5241.5 | E8: 1478.49 | F8: 0 | G8: 22778.6
A9: BRT 1 | B9: 112.65 | C9: 34.23 | D9: 88.21 | E9: 19.93 | F9: 0 | G9: 255.03
A10: BRT 3 | B10: 1214.27 | C10: 7001.88 | D10: 1364.51 | E10: 474.77 | F10: 0 | G10: 10055.4
A11: Express Bus | B11: 1822.58 | C11: 148.06 | D11: 73.9 | E11: 15.49 | F11: 0 | G11: 2060.03
A12: Light Rail | B12: 12715.4 | C12: 6587.77 | D12: 7579.25 | E12: 3217.28 | F12: 0 | G12: 30099.7
A13: Commuter Rail | B13: 9235.3 | C13: 3908.24 | D13: 1421.2 | E13: 547.36 | F13: 0 | G13: 15112.1
A14: Total Trips | B14: 958263 | C14: 127512 | D14: 1476835 | E14: 717830 | F14: 434446 | G14: 3714886
A17: Off-Peak
A18: Mode | B18: HBW | C18: HBC | D18: HBO | E18: NHB | F18: HBSch | G18: Total
A19: Non-Motorized | B19: 29101 | C19: 0 | D19: 366475 | E19: 112358 | F19: 88431.6 | G19: 596366
A20: Auto | B20: 505358 | C20: 0 | D20: 2695733 | E20: 1512880 | F20: 37500 | G20: 4751470
A21: School Bus | B21: 0 | C21: 0 | D21: 0 | E21: 0 | F21: 85191.5 | G21: 85191.5
A22: Local Bus | B22: 5115.79 | C22: 0 | D22: 9845.89 | E22: 2723.61 | F22: 0 | G22: 17685.3
A23: BRT 1 | B23: 62.8 | C23: 0 | D23: 155.19 | E23: 38.08 | F23: 0 | G23: 256.07
A24: BRT 3 | B24: 551.58 | C24: 0 | D24: 1768.53 | E24: 693.49 | F24: 0 | G24: 3013.59
A25: Express Bus | B25: 0 | C25: 0 | D25: 0 | E25: 0 | F25: 0 | G25: 0
A26: Light Rail | B26: 6418.55 | C26: 0 | D26: 11955.9 | E26: 6108.01 | F26: 0 | G26: 24482.4
A27: Commuter Rail | B27: 2876.15 | C27: 0 | D27: 1679.16 | E27: 729.96 | F27: 0 | G27: 5285.28
A28: Total Trips | B28: 549483 | C28: 0 | D28: 3087613 | E28: 1635531 | F28: 211123 | G28: 5483750
A31: Daily
A32: Mode | B32: HBW | C32: HBC | D32: HBO | E32: NHB | F32: HBSch | G32: Total
A33: Non-Motorized | B33: 68752.9 | C33: 22328.9 | D33: 512704 | E33: 140500 | F33: 270017 | G33: 1014303
A34: Auto | B34: 1390171 | C34: 80141.5 | D34: 4010570 | E34: 2196815 | F34: 115197 | G34: 7792895
A35: School Bus | B35: 0 | C35: 0 | D35: 0 | E35: 0 | F35: 260354 | G35: 260354
A36: Local Bus | B36: 13812.5 | C36: 7361.93 | D36: 15087.4 | E36: 4202.11 | F36: 0 | G36: 40463.9
A37: BRT 1 | B37: 175.45 | C37: 34.23 | D37: 243.4 | E37: 58.02 | F37: 0 | G37: 511.1
A38: BRT 3 | B38: 1765.85 | C38: 7001.88 | D38: 3133.04 | E38: 1168.25 | F38: 0 | G38: 13069
A39: Express Bus | B39: 1822.58 | C39: 148.06 | D39: 73.9 | E39: 15.49 | F39: 0 | G39: 2060.03
A40: Light Rail | B40: 19134 | C40: 6587.77 | D40: 19535.1 | E40: 9325.29 | F40: 0 | G40: 54582.2
A41: Commuter Rail | B41: 12111.5 | C41: 3908.24 | D41: 3100.37 | E41: 1277.32 | F41: 0 | G41: 20397.4
A42: Total Trips | B42: 1507746 | C42: 127512 | D42: 4564448 | E42: 2353361 | F42: 645569 | G42: 9198636

Sheet High_2019
A1: Scenarios\BY_2019 - high\
A3: Peak
A4: Mode | B4: HBW | C4: HBC | D4: HBO | E4: NHB | F4: HBSch | G4: Total
A5: Non-Motorized | B5: 37172.7 | C5: 22312 | D5: 145912 | E5: 27807 | F5: 181386 | G5: 414590
A6: Auto | B6: 835960 | C6: 80204.4 | D6: 1315222 | E6: 677068 | F6: 77697.7 | G6: 2986152
A7: School Bus | B7: 0 | C7: 0 | D7: 0 | E7: 0 | F7: 175365 | G7: 175365
A8: Local Bus | B8: 8142.31 | C8: 7366.47 | D8: 5249.3 | E8: 1462.39 | F8: 0 | G8: 22220.5
A9: BRT 1 | B9: 106.84 | C9: 34.08 | D9: 88.5 | E9: 19.76 | F9: 0 | G9: 249.18
A10: BRT 3 | B10: 1140.62 | C10: 7000.63 | D10: 1364.13 | E10: 468.19 | F10: 0 | G10: 9973.56
A11: Express Bus | B11: 1858.99 | C11: 165.3 | D11: 76.46 | E11: 17.23 | F11: 0 | G11: 2117.99
A12: Light Rail | B12: 11789.3 | C12: 6572.18 | D12: 7557.92 | E12: 3150.24 | F12: 0 | G12: 29069.6
A13: Commuter Rail | B13: 8315.6 | C13: 3857.38 | D13: 1407.13 | E13: 530.52 | F13: 0 | G13: 14110.6
A14: Total Trips | B14: 904486 | C14: 127512 | D14: 1476878 | E14: 710524 | F14: 434448 | G14: 3653848
A17: Off-Peak
A18: Mode | B18: HBW | C18: HBC | D18: HBO | E18: NHB | F18: HBSch | G18: Total
A19: Non-Motorized | B19: 27296.7 | C19: 0 | D19: 365834 | E19: 111065 | F19: 88333.2 | G19: 592529
A20: Auto | B20: 476471 | C20: 0 | D20: 2696409 | E20: 1497578 | F20: 37495.1 | G20: 4707953
A21: School Bus | B21: 0 | C21: 0 | D21: 0 | E21: 0 | F21: 85289.7 | G21: 85289.7
A22: Local Bus | B22: 4757.66 | C22: 0 | D22: 9859.07 | E22: 2692.26 | F22: 0 | G22: 17309
A23: BRT 1 | B23: 59.93 | C23: 0 | D23: 155.63 | E23: 37.81 | F23: 0 | G23: 253.37
A24: BRT 3 | B24: 518.18 | C24: 0 | D24: 1768.53 | E24: 684.12 | F24: 0 | G24: 2970.83
A25: Express Bus | B25: 0 | C25: 0 | D25: 0 | E25: 0 | F25: 0 | G25: 0
A26: Light Rail | B26: 5968.72 | C26: 0 | D26: 11946.5 | E26: 6006.92 | F26: 0 | G26: 23922.1
A27: Commuter Rail | B27: 2647.45 | C27: 0 | D27: 1690.98 | E27: 727.17 | F27: 0 | G27: 5065.6
A28: Total Trips | B28: 517720 | C28: 0 | D28: 3087664 | E28: 1618791 | F28: 211118 | G28: 5435292
A31: Daily
A32: Mode | B32: HBW | C32: HBC | D32: HBO | E32: NHB | F32: HBSch | G32: Total
A33: Non-Motorized | B33: 64469.4 | C33: 22312 | D33: 511747 | E33: 138872 | F33: 269719 | G33: 1007119
A34: Auto | B34: 1312431 | C34: 80204.4 | D34: 4011630 | E34: 2174646 | F34: 115193 | G34: 7694105
A35: School Bus | B35: 0 | C35: 0 | D35: 0 | E35: 0 | F35: 260655 | G35: 260655
A36: Local Bus | B36: 12900 | C36: 7366.47 | D36: 15108.4 | E36: 4154.65 | F36: 0 | G36: 39529.5
A37: BRT 1 | B37: 166.77 | C37: 34.08 | D37: 244.13 | E37: 57.57 | F37: 0 | G37: 502.55
A38: BRT 3 | B38: 1658.79 | C38: 7000.63 | D38: 3132.66 | E38: 1152.3 | F38: 0 | G38: 12944.4
A39: Express Bus | B39: 1858.99 | C39: 165.3 | D39: 76.46 | E39: 17.23 | F39: 0 | G39: 2117.99
A40: Light Rail | B40: 17758 | C40: 6572.18 | D40: 19504.4 | E40: 9157.16 | F40: 0 | G40: 52991.8
