Workbook
Name Base_2019: Base_2019!$1:$1048576
Name High_2019: High_2019!$1:$1048576
Name Low_2019: Low_2019!$1:$1048576
Name Med_2019: Med_2019!$1:$1048576

Sheet Summary
B2: 2019 | C2: Daily | H2: 2019 | I2: Daily | N2: 2019 | O2: Daily | U2: 2019 | V2: Daily | AA2: 2019 | AB2: Daily | AG2: 2019 | AH2: Daily
B3: Home Based Work | C3: Base | D3: Low | E3: Medium | F3: High | H3: Non-Home Based | I3: Base | J3: Low | K3: Medium | L3: High | N3: Total Trips | O3: Base | P3: Low | Q3: Medium | R3: High | U3: Home Based Work | V3: Base | W3: Low | X3: Medium | Y3: High | AA3: Non-Home Based | AB3: Base | AC3: Low | AD3: Medium | AE3: High | AG3: Total Trips | AH3: Base | AI3: Low | AJ3: Medium | AK3: High
B4: Non-Motorized | C4: =V4 -> 83661.3 | D4: =W4 -> 73117.2 | E4: =X4 -> 68752.9 | F4: =Y4 -> 64469.4 | H4: Non-Motorized | I4: =AB4 -> 145706 | J4: =AC4 -> 142177 | K4: =AD4 -> 140500 | L4: =AE4 -> 138872 | N4: Non-Motorized | O4: =AH4 -> 1039314 | P4: =AI4 -> 1021797 | Q4: =AJ4 -> 1014303 | R4: =AK4 -> 1007119 | U4: Non-Motorized | V4: =Base_2019!B33 -> 83661.3 | W4: =Low_2019!B33 -> 73117.2 | X4: =Med_2019!B33 -> 68752.9 | Y4: =High_2019!B33 -> 64469.4 | AA4: Non-Motorized | AB4: =Base_2019!E33 -> 145706 | AC4: =Low_2019!E33 -> 142177 | AD4: =Med_2019!E33 -> 140500 | AE4: =High_2019!E33 -> 138872 | AG4: Non-Motorized | AH4: =Base_2019!G33 -> 1039314 | AI4: =Low_2019!G33 -> 1021797 | AJ4: =Med_2019!G33 -> 1014303 | AK4: =High_2019!G33 -> 1007119
B5: Local Bus | C5: =V7 -> 16828.8 | D5: =W7 -> 14731.9 | E5: =X7 -> 13812.5 | F5: =Y7 -> 12900 | H5: Local Bus | I5: =AB7 -> 4345.71 | J5: =AC7 -> 4251.51 | K5: =AD7 -> 4202.11 | L5: =AE7 -> 4154.65 | N5: Local Bus | O5: =AH7 -> 43529 | P5: =AI7 -> 41394.2 | Q5: =AJ7 -> 40463.9 | R5: =AK7 -> 39529.5 | U5: Auto | V5: =Base_2019!B34 -> 1651350 | W5: =Low_2019!B34 -> 1468085 | X5: =Med_2019!B34 -> 1390171 | Y5: =High_2019!B34 -> 1312431 | AA5: Auto | AB5: =Base_2019!E34 -> 2261638 | AC5: =Low_2019!E34 -> 2219131 | AD5: =Med_2019!E34 -> 2196815 | AE5: =High_2019!E34 -> 2174646 | AG5: Auto | AH5: =Base_2019!G34 -> 8115387 | AI5: =Low_2019!G34 -> 7892016 | AJ5: =Med_2019!G34 -> 7792895 | AK5: =High_2019!G34 -> 7694105
B6: BRT | C6: =V8 -> 200.36 | D6: =W8 -> 184.02 | E6: =X8 -> 175.45 | F6: =Y8 -> 166.77 | H6: BRT | I6: =AB8 -> 59.32 | J6: =AC8 -> 58.52 | K6: =AD8 -> 58.02 | L6: =AE8 -> 57.57 | N6: BRT | O6: =AH8 -> 535.8 | P6: =AI8 -> 519.77 | Q6: =AJ8 -> 511.1 | R6: =AK8 -> 502.55 | U6: School Bus | V6: =Base_2019!B35 -> 0 | W6: =Low_2019!B35 -> 0 | X6: =Med_2019!B35 -> 0 | Y6: =High_2019!B35 -> 0 | AA6: School Bus | AB6: =Base_2019!E35 -> 0 | AC6: =Low_2019!E35 -> 0 | AD6: =Med_2019!E35 -> 0 | AE6: =High_2019!E35 -> 0 | AG6: School Bus | AH6: =Base_2019!G35 -> 259198 | AI6: =Low_2019!G35 -> 260017 | AJ6: =Med_2019!G35 -> 260354 | AK6: =High_2019!G35 -> 260655
B7: MODE9 | C7: =V9 -> 2163.62 | D7: =W9 -> 1875.2 | E7: =X9 -> 1765.85 | F7: =Y9 -> 1658.79 | H7: MODE9 | I7: =AB9 -> 1224.14 | J7: =AC9 -> 1184.11 | K7: =AD9 -> 1168.25 | L7: =AE9 -> 1152.3 | N7: MODE9 | O7: =AH9 -> 13566.2 | P7: =AI9 -> 13196.4 | Q7: =AJ9 -> 13069 | R7: =AK9 -> 12944.4 | U7: Local Bus | V7: =Base_2019!B36 -> 16828.8 | W7: =Low_2019!B36 -> 14731.9 | X7: =Med_2019!B36 -> 13812.5 | Y7: =High_2019!B36 -> 12900 | AA7: Local Bus | AB7: =Base_2019!E36 -> 4345.71 | AC7: =Low_2019!E36 -> 4251.51 | AD7: =Med_2019!E36 -> 4202.11 | AE7: =High_2019!E36 -> 4154.65 | AG7: Local Bus | AH7: =Base_2019!G36 -> 43529 | AI7: =Low_2019!G36 -> 41394.2 | AJ7: =Med_2019!G36 -> 40463.9 | AK7: =High_2019!G36 -> 39529.5
B8: Express Bus | C8: =V10 -> 1643.13 | D8: =W10 -> 1805.91 | E8: =X10 -> 1822.58 | F8: =Y10 -> 1858.99 | H8: Express Bus | I8: =AB10 -> 11.03 | J8: =AC10 -> 14.2 | K8: =AD10 -> 15.49 | L8: =AE10 -> 17.23 | N8: Express Bus | O8: =AH10 -> 1821.29 | P8: =AI10 -> 2026.22 | Q8: =AJ10 -> 2060.03 | R8: =AK10 -> 2117.99 | U8: BRT | V8: =Base_2019!B37 -> 200.36 | W8: =Low_2019!B37 -> 184.02 | X8: =Med_2019!B37 -> 175.45 | Y8: =High_2019!B37 -> 166.77 | AA8: BRT | AB8: =Base_2019!E37 -> 59.32 | AC8: =Low_2019!E37 -> 58.52 | AD8: =Med_2019!E37 -> 58.02 | AE8: =High_2019!E37 -> 57.57 | AG8: BRT | AH8: =Base_2019!G37 -> 535.8 | AI8: =Low_2019!G37 -> 519.77 | AJ8: =Med_2019!G37 -> 511.1 | AK8: =High_2019!G37 -> 502.55
B9: Light Rail | C9: =V11 -> 23982 | D9: =W11 -> 20602.9 | E9: =X11 -> 19134 | F9: =Y11 -> 17758 | H9: Light Rail | I9: =AB11 -> 9846.2 | J9: =AC11 -> 9494.39 | K9: =AD11 -> 9325.29 | L9: =AE11 -> 9157.16 | N9: Light Rail | O9: =AH11 -> 60095.6 | P9: =AI11 -> 56271.2 | Q9: =AJ11 -> 54582.2 | R9: =AK11 -> 52991.8 | U9: MODE9 | V9: =Base_2019!B38 -> 2163.62 | W9: =Low_2019!B38 -> 1875.2 | X9: =Med_2019!B38 -> 1765.85 | Y9: =High_2019!B38 -> 1658.79 | AA9: MODE9 | AB9: =Base_2019!E38 -> 1224.14 | AC9: =Low_2019!E38 -> 1184.11 | AD9: =Med_2019!E38 -> 1168.25 | AE9: =High_2019!E38 -> 1152.3 | AG9: MODE9 | AH9: =Base_2019!G38 -> 13566.2 | AI9: =Low_2019!G38 -> 13196.4 | AJ9: =Med_2019!G38 -> 13069 | AK9: =High_2019!G38 -> 12944.4
B10: Comm. Rail | C10: =V12 -> 16277.9 | D10: =W12 -> 13312.7 | E10: =X12 -> 12111.5 | F10: =Y12 -> 10963 | H10: Comm. Rail | I10: =AB12 -> 1362.41 | J10: =AC12 -> 1304.72 | K10: =AD12 -> 1277.32 | L10: =AE12 -> 1257.69 | N10: Comm. Rail | O10: =AH12 -> 24838.3 | P10: =AI12 -> 21721.8 | Q10: =AJ12 -> 20397.4 | R10: =AK12 -> 19176.2 | U10: Express Bus | V10: =Base_2019!B39 -> 1643.13 | W10: =Low_2019!B39 -> 1805.91 | X10: =Med_2019!B39 -> 1822.58 | Y10: =High_2019!B39 -> 1858.99 | AA10: Express Bus | AB10: =Base_2019!E39 -> 11.03 | AC10: =Low_2019!E39 -> 14.2 | AD10: =Med_2019!E39 -> 15.49 | AE10: =High_2019!E39 -> 17.23 | AG10: Express Bus | AH10: =Base_2019!G39 -> 1821.29 | AI10: =Low_2019!G39 -> 2026.22 | AJ10: =Med_2019!G39 -> 2060.03 | AK10: =High_2019!G39 -> 2117.99
B11: Non-Auto Trips | C11: =SUM(C4:C10) -> 144757.11 | D11: =SUM(D4:D10) -> 125629.83 | E11: =SUM(E4:E10) -> 117574.78 | F11: =SUM(F4:F10) -> 109774.95 | H11: Non-Auto Trips | I11: =SUM(I4:I10) -> 162554.81 | J11: =SUM(J4:J10) -> 158484.45 | K11: =SUM(K4:K10) -> 156546.48 | L11: =SUM(L4:L10) -> 154668.6 | N11: Non-Auto Trips | O11: =SUM(O4:O10) -> 1183700.2 | P11: =SUM(P4:P10) -> 1156926.6 | Q11: =SUM(Q4:Q10) -> 1145386.6 | R11: =SUM(R4:R10) -> 1134381.4 | U11: Light Rail | V11: =Base_2019!B40 -> 23982 | W11: =Low_2019!B40 -> 20602.9 | X11: =Med_2019!B40 -> 19134 | Y11: =High_2019!B40 -> 17758 | AA11: Light Rail | AB11: =Base_2019!E40 -> 9846.2 | AC11: =Low_2019!E40 -> 9494.39 | AD11: =Med_2019!E40 -> 9325.29 | AE11: =High_2019!E40 -> 9157.16 | AG11: Light Rail | AH11: =Base_2019!G40 -> 60095.6 | AI11: =Low_2019!G40 -> 56271.2 | AJ11: =Med_2019!G40 -> 54582.2 | AK11: =High_2019!G40 -> 52991.8
U12: Comm. Rail | V12: =Base_2019!B41 -> 16277.9 | W12: =Low_2019!B41 -> 13312.7 | X12: =Med_2019!B41 -> 12111.5 | Y12: =High_2019!B41 -> 10963 | AA12: Comm. Rail | AB12: =Base_2019!E41 -> 1362.41 | AC12: =Low_2019!E41 -> 1304.72 | AD12: =Med_2019!E41 -> 1277.32 | AE12: =High_2019!E41 -> 1257.69 | AG12: Comm. Rail | AH12: =Base_2019!G41 -> 24838.3 | AI12: =Low_2019!G41 -> 21721.8 | AJ12: =Med_2019!G41 -> 20397.4 | AK12: =High_2019!G41 -> 19176.2
B13: Non-Motorized | C13: =C4 -> 83661.3 | D13: =D4 -> 73117.2 | E13: =E4 -> 68752.9 | F13: =F4 -> 64469.4 | H13: Non-Motorized | I13: =I4 -> 145706 | J13: =J4 -> 142177 | K13: =K4 -> 140500 | L13: =L4 -> 138872 | N13: Non-Motorized | O13: =O4 -> 1039314 | P13: =P4 -> 1021797 | Q13: =Q4 -> 1014303 | R13: =R4 -> 1007119 | U13: Total Trips | V13: =SUM(V4:V12) -> 1796107.1 | W13: =SUM(W4:W12) -> 1593714.8 | X13: =SUM(X4:X12) -> 1507745.8 | Y13: =SUM(Y4:Y12) -> 1422205.9 | AA13: Total Trips | AB13: =SUM(AB4:AB12) -> 2424192.8 | AC13: =SUM(AC4:AC12) -> 2377615.5 | AD13: =SUM(AD4:AD12) -> 2353361.5 | AE13: =SUM(AE4:AE12) -> 2329314.6 | AG13: Total Trips | AH13: =SUM(AH4:AH12) -> 9558285.2 | AI13: =SUM(AI4:AI12) -> 9308959.6 | AJ13: =SUM(AJ4:AJ12) -> 9198635.6 | AK13: =SUM(AK4:AK12) -> 9089141.4
B14: Transit | C14: =SUM(C5:C10) -> 61095.81 | D14: =SUM(D5:D10) -> 52512.63 | E14: =SUM(E5:E10) -> 48821.88 | F14: =SUM(F5:F10) -> 45305.55 | H14: Transit | I14: =SUM(I5:I10) -> 16848.81 | J14: =SUM(J5:J10) -> 16307.45 | K14: =SUM(K5:K10) -> 16046.48 | L14: =SUM(L5:L10) -> 15796.6 | N14: Transit | O14: =SUM(O5:O10) -> 144386.19 | P14: =SUM(P5:P10) -> 135129.59 | Q14: =SUM(Q5:Q10) -> 131083.63 | R14: =SUM(R5:R10) -> 127262.44
C15: =SUM(C13:C14) -> 144757.11 | D15: =SUM(D13:D14) -> 125629.83 | E15: =SUM(E13:E14) -> 117574.78 | F15: =SUM(F13:F14) -> 109774.95 | I15: =SUM(I13:I14) -> 162554.81 | J15: =SUM(J13:J14) -> 158484.45 | K15: =SUM(K13:K14) -> 156546.48 | L15: =SUM(L13:L14) -> 154668.6 | O15: =SUM(O13:O14) -> 1183700.2 | P15: =SUM(P13:P14) -> 1156926.6 | Q15: =SUM(Q13:Q14) -> 1145386.6 | R15: =SUM(R13:R14) -> 1134381.4
U16: 2050 | V16: Daily | AA16: 2050 | AB16: Daily | AG16: 2050 | AH16: Daily
B17: Non-Auto Trips | C17: =C15 -> 144757.11 | D17: =D15 -> 125629.83 | E17: =E15 -> 117574.78 | F17: =F15 -> 109774.95 | H17: Non-Auto Trips | I17: =I15 -> 162554.81 | J17: =J15 -> 158484.45 | K17: =K15 -> 156546.48 | L17: =L15 -> 154668.6 | N17: Non-Auto Trips | O17: =O15 -> 1183700.2 | P17: =P15 -> 1156926.6 | Q17: =Q15 -> 1145386.6 | R17: =R15 -> 1134381.4 | U17: Home Based Work | V17: Base | W17: Low | X17: Medium | Y17: High | AA17: Non-Home Based | AB17: Base | AC17: Low | AD17: Medium | AE17: High | AG17: Total Trips | AH17: Base | AI17: Low | AJ17: Medium | AK17: High
B18: Auto | C18: =V5 -> 1651350 | D18: =W5 -> 1468085 | E18: =X5 -> 1390171 | F18: =Y5 -> 1312431 | H18: Auto | I18: =AB5 -> 2261638 | J18: =AC5 -> 2219131 | K18: =AD5 -> 2196815 | L18: =AE5 -> 2174646 | N18: Auto | O18: =AH5 -> 8115387 | P18: =AI5 -> 7892016 | Q18: =AJ5 -> 7792895 | R18: =AK5 -> 7694105 | U18: Non-Motorized | V18: =Base_2050!B33 -> 139868.62 | W18: =Low_2050!B33 -> 120878 | X18: =Med_2050!B33 -> 113057 | Y18: =High_2050!B33 -> 105333 | AA18: Non-Motorized | AB18: =Base_2050!E33 -> 219882.83 | AC18: =Low_2050!E33 -> 213551 | AD18: =Med_2050!E33 -> 210616 | AE18: =High_2050!E33 -> 207732 | AG18: Non-Motorized | AH18: =Base_2050!G33 -> 1481262.4 | AI18: =Low_2050!G33 -> 1447976.9 | AJ18: =Med_2050!G33 -> 1433996.1 | AK18: =High_2050!G33 -> 1420139.8
C19: =SUM(C17:C18) -> 1796107.1 | D19: =SUM(D17:D18) -> 1593714.8 | E19: =SUM(E17:E18) -> 1507745.8 | F19: =SUM(F17:F18) -> 1422205.9 | I19: =SUM(I17:I18) -> 2424192.8 | J19: =SUM(J17:J18) -> 2377615.5 | K19: =SUM(K17:K18) -> 2353361.5 | L19: =SUM(L17:L18) -> 2329314.6 | O19: =SUM(O17:O18) -> 9299087.2 | P19: =SUM(P17:P18) -> 9048942.6 | Q19: =SUM(Q17:Q18) -> 8938281.6 | R19: =SUM(R17:R18) -> 8828486.4 | U19: Auto | V19: =Base_2050!B34 -> 2593983 | W19: =Low_2050!B34 -> 2280932 | X19: =Med_2050!B34 -> 2148097 | Y19: =High_2050!B34 -> 2014912 | AA19: Auto | AB19: =Base_2050!E34 -> 3541322.9 | AC19: =Low_2050!E34 -> 3467645 | AD19: =Med_2050!E34 -> 3430578 | AE19: =High_2050!E34 -> 3393055 | AG19: Auto | AH19: =Base_2050!G34 -> 12269466 | AI19: =Low_2050!G34 -> 11888497 | AJ19: =Med_2050!G34 -> 11721269 | AK19: =High_2050!G34 -> 11552984
U20: School Bus | V20: =Base_2050!B35 -> 0 | W20: =Low_2050!B35 -> 0 | X20: =Med_2050!B35 -> 0 | Y20: =High_2050!B35 -> 0 | AA20: School Bus | AB20: =Base_2050!E35 -> 0 | AC20: =Low_2050!E35 -> 0 | AD20: =Med_2050!E35 -> 0 | AE20: =High_2050!E35 -> 0 | AG20: School Bus | AH20: =Base_2050!G35 -> 387528.61 | AI20: =Low_2050!G35 -> 388964 | AJ20: =Med_2050!G35 -> 389525 | AK20: =High_2050!G35 -> 390090
U21: Local Bus | V21: =Base_2050!B36 -> 11751.38 | W21: =Low_2050!B36 -> 10223.9 | X21: =Med_2050!B36 -> 9555.41 | Y21: =High_2050!B36 -> 8899.07 | AA21: Local Bus | AB21: =Base_2050!E36 -> 3281.65 | AC21: =Low_2050!E36 -> 3202.31 | AD21: =Med_2050!E36 -> 3163.19 | AE21: =High_2050!E36 -> 3131.75 | AG21: Local Bus | AH21: =Base_2050!G36 -> 33571.44 | AI21: =Low_2050!G36 -> 32015.41 | AJ21: =Med_2050!G36 -> 31313.64 | AK21: =High_2050!G36 -> 30662.73
B22: 2019 | C22: Daily | H22: 2019 | I22: Daily | N22: 2019 | O22: Daily | U22: BRT | V22: =Base_2050!B37 -> 24569.09 | W22: =Low_2050!B37 -> 21623.9 | X22: =Med_2050!B37 -> 20280.6 | Y22: =High_2050!B37 -> 18947.2 | AA22: BRT | AB22: =Base_2050!E37 -> 7338.33 | AC22: =Low_2050!E37 -> 7176.73 | AD22: =Med_2050!E37 -> 7085.66 | AE22: =High_2050!E37 -> 6995.69 | AG22: BRT | AH22: =Base_2050!G37 -> 66498.22 | AI22: =Low_2050!G37 -> 63524.22 | AJ22: =Med_2050!G37 -> 62136.42 | AK22: =High_2050!G37 -> 60728.45
B23: Home Based Work | C23: Base | D23: Low | E23: Medium | F23: High | H23: Non-Home Based | I23: Base | J23: Low | K23: Medium | L23: High | N23: Total Trips | O23: Base | P23: Low | Q23: Medium | R23: High | U23: MODE9 | V23: =Base_2050!B38 -> 8294.12 | W23: =Low_2050!B38 -> 7267.09 | X23: =Med_2050!B38 -> 6818.79 | Y23: =High_2050!B38 -> 6394.67 | AA23: MODE9 | AB23: =Base_2050!E38 -> 3401.95 | AC23: =Low_2050!E38 -> 3319.74 | AD23: =Med_2050!E38 -> 3280.45 | AE23: =High_2050!E38 -> 3243.75 | AG23: MODE9 | AH23: =Base_2050!G38 -> 34280.33 | AI23: =Low_2050!G38 -> 33257.93 | AJ23: =Med_2050!G38 -> 32769.14 | AK23: =High_2050!G38 -> 32307.92
B24: Non-Motorized | C24: =C4 / C11 -> 0.5779426 | D24: =D4 / D11 -> 0.58200509 | E24: =E4 / E11 -> 0.58475891 | F24: =F4 / F11 -> 0.58728699 | H24: Non-Motorized | I24: =I4 / I11 -> 0.89634998 | J24: =J4 / J11 -> 0.89710379 | K24: =K4 / K11 -> 0.89749702 | L24: =L4 / L11 -> 0.89786809 | N24: Non-Motorized | O24: =O4 / O11 -> 0.87802132 | P24: =P4 / P11 -> 0.88319951 | Q24: =Q4 / Q11 -> 0.88555512 | R24: =R4 / R11 -> 0.88781336 | U24: Express Bus | V24: =Base_2050!B39 -> 2182.69 | W24: =Low_2050!B39 -> 2914.05 | X24: =Med_2050!B39 -> 3223.61 | Y24: =High_2050!B39 -> 3550.27 | AA24: Express Bus | AB24: =Base_2050!E39 -> 11.7 | AC24: =Low_2050!E39 -> 22.14 | AD24: =Med_2050!E39 -> 27.33 | AE24: =High_2050!E39 -> 33.48 | AG24: Express Bus | AH24: =Base_2050!G39 -> 2469.44 | AI24: =Low_2050!G39 -> 3316.59 | AJ24: =Med_2050!G39 -> 3684.36 | AK24: =High_2050!G39 -> 4165.04
B25: Local Bus | C25: =C5 / C11 -> 0.11625543 | D25: =D5 / D11 -> 0.11726435 | E25: =E5 / E11 -> 0.11747843 | F25: =F5 / F11 -> 0.11751315 | H25: Local Bus | I25: =I5 / I11 -> 0.026733814 | J25: =J5 / J11 -> 0.026826039 | K25: =K5 / K11 -> 0.026842571 | L25: =L5 / L11 -> 0.026861625 | N25: Local Bus | O25: =O5 / O11 -> 0.03677367 | P25: =P5 / P11 -> 0.035779453 | Q25: =Q5 / Q11 -> 0.035327722 | R25: =R5 / R11 -> 0.034846744 | U25: Light Rail | V25: =Base_2050!B40 -> 46716.56 | W25: =Low_2050!B40 -> 39685.1 | X25: =Med_2050!B40 -> 36649.8 | Y25: =High_2050!B40 -> 33683.7 | AA25: Light Rail | AB25: =Base_2050!E40 -> 15350.61 | AC25: =Low_2050!E40 -> 14706.9 | AD25: =Med_2050!E40 -> 14438.5 | AE25: =High_2050!E40 -> 14154 | AG25: Light Rail | AH25: =Base_2050!G40 -> 121952.15 | AI25: =Low_2050!G40 -> 114021 | AJ25: =Med_2050!G40 -> 110575.3 | AK25: =High_2050!G40 -> 107152.9
B26: BRT | C26: =C6 / C11 -> 0.0013841116 | D26: =D6 / D11 -> 0.0014647795 | E26: =E6 / E11 -> 0.0014922418 | F26: =F6 / F11 -> 0.0015191991 | H26: BRT | I26: =I6 / I11 -> 0.00036492307 | J26: =J6 / J11 -> 0.00036924758 | K26: =K6 / K11 -> 0.00037062475 | L26: =L6 / L11 -> 0.00037221517 | N26: BRT | O26: =O6 / O11 -> 0.0004526484 | P26: =P6 / P11 -> 0.00044926792 | Q26: =Q6 / Q11 -> 0.00044622487 | R26: =R6 / R11 -> 0.00044301677 | U26: Comm. Rail | V26: =Base_2050!B41 -> 42146.8 | W26: =Low_2050!B41 -> 35180.3 | X26: =Med_2050!B41 -> 31944.6 | Y26: =High_2050!B41 -> 29091.5 | AA26: Comm. Rail | AB26: =Base_2050!E41 -> 2380.04 | AC26: =Low_2050!E41 -> 2324.22 | AD26: =Med_2050!E41 -> 2287.89 | AE26: =High_2050!E41 -> 2249.46 | AG26: Comm. Rail | AH26: =Base_2050!G41 -> 62096.76 | AI26: =Low_2050!G41 -> 54970.47 | AJ26: =Med_2050!G41 -> 51613.81 | AK26: =High_2050!G41 -> 48653.34
B27: MODE9 | C27: =C7 / C11 -> 0.014946554 | D27: =D7 / D11 -> 0.014926391 | E27: =E7 / E11 -> 0.015018952 | F27: =F7 / F11 -> 0.015110824 | H27: MODE9 | I27: =I7 / I11 -> 0.0075306292 | J27: =J7 / J11 -> 0.0074714586 | K27: =K7 / K11 -> 0.0074626398 | L27: =L7 / L11 -> 0.0074501224 | N27: MODE9 | O27: =O7 / O11 -> 0.011460841 | P27: =P7 / P11 -> 0.011406428 | Q27: =Q7 / Q11 -> 0.011410121 | R27: =R7 / R11 -> 0.011410977 | U27: Total Trips | V27: =SUM(V18:V26) -> 2869512.3 | W27: =SUM(W18:W26) -> 2518704.3 | X27: =SUM(X18:X26) -> 2369626.8 | Y27: =SUM(Y18:Y26) -> 2220811.4 | AA27: Total Trips | AB27: =SUM(AB18:AB26) -> 3792970 | AC27: =SUM(AC18:AC26) -> 3711948 | AD27: =SUM(AD18:AD26) -> 3671477 | AE27: =SUM(AE18:AE26) -> 3630595.1 | AG27: Total Trips | AH27: =SUM(AH18:AH26) -> 14459125 | AI27: =SUM(AI18:AI26) -> 14026544 | AJ27: =SUM(AJ18:AJ26) -> 13836883 | AK27: =SUM(AK18:AK26) -> 13646884
B28: Express Bus | C28: =C8 / C11 -> 0.011350945 | D28: =D8 / D11 -> 0.01437485 | E28: =E8 / E11 -> 0.015501454 | F28: =F8 / F11 -> 0.016934556 | H28: Express Bus | I28: =I8 / I11 -> 6.7854036e-05 | J28: =J8 / J11 -> 8.9598696e-05 | K28: =K8 / K11 -> 9.8948248e-05 | L28: =L8 / L11 -> 0.00011139947 | N28: Express Bus | O28: =O8 / O11 -> 0.0015386413 | P28: =P8 / P11 -> 0.0017513816 | Q28: =Q8 / Q11 -> 0.0017985455 | R28: =R8 / R11 -> 0.001867088
B29: Light Rail | C29: =C9 / C11 -> 0.16567062 | D29: =D9 / D11 -> 0.16399688 | E29: =E9 / E11 -> 0.16273898 | F29: =F9 / F11 -> 0.16176732 | H29: Light Rail | I29: =I9 / I11 -> 0.06057157 | J29: =J9 / J11 -> 0.059907392 | K29: =K9 / K11 -> 0.059568826 | L29: =L9 / L11 -> 0.059205036 | N29: Light Rail | O29: =O9 / O11 -> 0.050769275 | P29: =P9 / P11 -> 0.048638523 | Q29: =Q9 / Q11 -> 0.047653952 | R29: =R9 / R11 -> 0.046714269
B30: Comm. Rail | C30: =C10 / C11 -> 0.11244974 | D30: =D10 / D11 -> 0.10596767 | E30: =E10 / E11 -> 0.10301104 | F30: =F10 / F11 -> 0.099867957 | H30: Comm. Rail | I30: =I10 / I11 -> 0.0083812346 | J30: =J10 / J11 -> 0.0082324796 | K30: =K10 / K11 -> 0.0081593658 | L30: =L10 / L11 -> 0.0081315147 | N30: Comm. Rail | O30: =O10 / O11 -> 0.020983607 | P30: =P10 / P11 -> 0.018775435 | Q30: =Q10 / Q11 -> 0.01780831 | R30: =R10 / R11 -> 0.016904543 | U30: 2019 | V30: Daily | AA30: 2019 | AB30: Daily | AG30: 2019 | AH30: Daily
C31: =SUM(C24:C30) -> 1 | D31: =SUM(D24:D30) -> 1 | E31: =SUM(E24:E30) -> 1 | F31: =SUM(F24:F30) -> 1 | I31: =SUM(I24:I30) -> 1 | J31: =SUM(J24:J30) -> 1 | K31: =SUM(K24:K30) -> 1 | L31: =SUM(L24:L30) -> 1 | O31: =SUM(O24:O30) -> 1 | P31: =SUM(P24:P30) -> 1 | Q31: =SUM(Q24:Q30) -> 1 | R31: =SUM(R24:R30) -> 1 | U31: Home Based Work | V31: Base | W31: Low | X31: Medium | Y31: High | AA31: Non-Home Based | AB31: Base | AC31: Low | AD31: Medium | AE31: High | AG31: Total Trips | AH31: Base | AI31: Low | AJ31: Medium | AK31: High
U32: Non-Motorized | V32: =V4/V13 -> 0.046579238 | W32: =W4/W13 -> 0.045878471 | X32: =X4/X13 -> 0.045599796 | Y32: =Y4/Y13 -> 0.045330566 | AA32: Non-Motorized | AB32: =AB4/AB13 -> 0.060104955 | AC32: =AC4/AC13 -> 0.059798148 | AD32: =AD4/AD13 -> 0.059701836 | AE32: =AE4/AE13 -> 0.059619255 | AG32: Non-Motorized | AH32: =AH4/AH13 -> 0.10873436 | AI32: =AI4/AI13 -> 0.1097649 | AJ32: =AJ4/AJ13 -> 0.11026668 | AK32: =AK4/AK13 -> 0.11080464
B33: Non-Motorized | C33: =C13 / C15 -> 0.5779426 | D33: =D13 / D15 -> 0.58200509 | E33: =E13 / E15 -> 0.58475891 | F33: =F13 / F15 -> 0.58728699 | H33: Non-Motorized | I33: =I13 / I15 -> 0.89634998 | J33: =J13 / J15 -> 0.89710379 | K33: =K13 / K15 -> 0.89749702 | L33: =L13 / L15 -> 0.89786809 | N33: Non-Motorized | O33: =O13 / O15 -> 0.87802132 | P33: =P13 / P15 -> 0.88319951 | Q33: =Q13 / Q15 -> 0.88555512 | R33: =R13 / R15 -> 0.88781336 | U33: Auto | V33: =V5/V13 -> 0.91940508 | W33: =W5/W13 -> 0.9211717 | X33: =X5/X13 -> 0.92201949 | Y33: =Y5/Y13 -> 0.92281361 | AA33: Auto | AB33: =AB5/AB13 -> 0.93294477 | AC33: =AC5/AC13 -> 0.93334311 | AD33: =AD5/AD13 -> 0.93347963 | AE33: =AE5/AE13 -> 0.93359909 | AG33: Auto | AH33: =AH5/AH13 -> 0.84904215 | AI33: =AI5/AI13 -> 0.84778712 | AJ33: =AJ5/AJ13 -> 0.84717944 | AK33: =AK5/AK13 -> 0.84651615
B34: Transit | C34: =C14 / C15 -> 0.4220574 | D34: =D14 / D15 -> 0.41799491 | E34: =E14 / E15 -> 0.41524109 | F34: =F14 / F15 -> 0.41271301 | H34: Transit | I34: =I14 / I15 -> 0.10365002 | J34: =J14 / J15 -> 0.10289621 | K34: =K14 / K15 -> 0.10250298 | L34: =L14 / L15 -> 0.10213191 | N34: Transit | O34: =O14 / O15 -> 0.12197868 | P34: =P14 / P15 -> 0.11680049 | Q34: =Q14 / Q15 -> 0.11444488 | R34: =R14 / R15 -> 0.11218664 | U34: School Bus | V34: =V6/V13 -> 0 | W34: =W6/W13 -> 0 | X34: =X6/X13 -> 0 | Y34: =Y6/Y13 -> 0 | AA34: School Bus | AB34: =AB6/AB13 -> 0 | AC34: =AC6/AC13 -> 0 | AD34: =AD6/AD13 -> 0 | AE34: =AE6/AE13 -> 0 | AG34: School Bus | AH34: =AH6/AH13 -> 0.027117626 | AI34: =AI6/AI13 -> 0.027931908 | AJ34: =AJ6/AJ13 -> 0.028303545 | AK34: =AK6/AK13 -> 0.028677626
C35: =SUM(C33:C34) -> 1 | D35: =SUM(D33:D34) -> 1 | E35: =SUM(E33:E34) -> 1 | F35: =SUM(F33:F34) -> 1 | I35: =SUM(I33:I34) -> 1 | J35: =SUM(J33:J34) -> 1 | K35: =SUM(K33:K34) -> 1 | L35: =SUM(L33:L34) -> 1 | O35: =SUM(O33:O34) -> 1 | P35: =SUM(P33:P34) -> 1 | Q35: =SUM(Q33:Q34) -> 1 | R35: =SUM(R33:R34) -> 1 | U35: Local Bus | V35: =V7/V13 -> 0.0093695971 | W35: =W7/W13 -> 0.0092437491 | X35: =X7/X13 -> 0.0091610271 | Y35: =Y7/Y13 -> 0.0090704163 | AA35: Local Bus | AB35: =AB7/AB13 -> 0.0017926421 | AC35: =AC7/AC13 -> 0.0017881403 | AD35: =AD7/AD13 -> 0.0017855778 | AE35: =AE7/AE13 -> 0.0017836363 | AG35: Local Bus | AH35: =AH7/AH13 -> 0.0045540596 | AI35: =AI7/AI13 -> 0.0044467053 | AJ35: =AJ7/AJ13 -> 0.0043989024 | AK35: =AK7/AK13 -> 0.0043490906
U36: BRT | V36: =V8/V13 -> 0.00011155237 | W36: =W8/W13 -> 0.00011546608 | X36: =X8/X13 -> 0.00011636577 | Y36: =Y8/Y13 -> 0.0001172615 | AA36: BRT | AB36: =AB8/AB13 -> 2.4470001e-05 | AC36: =AC8/AC13 -> 2.4612895e-05 | AD36: =AD8/AD13 -> 2.4654096e-05 | AE36: =AE8/AE13 -> 2.4715425e-05 | AG36: BRT | AH36: =AH8/AH13 -> 5.605608e-05 | AI36: =AI8/AI13 -> 5.5835456e-05 | AJ36: =AJ8/AJ13 -> 5.5562588e-05 | AK36: =AK8/AK13 -> 5.5291251e-05
B37: Non-Auto Trips | C37: =C17 / C19 -> 0.080594921 | D37: =D17 / D19 -> 0.0788283 | E37: =E17 / E19 -> 0.077980507 | F37: =F17 / F19 -> 0.077186395 | H37: Non-Auto Trips | I37: =I17 / I19 -> 0.067055231 | J37: =J17 / J19 -> 0.066656889 | K37: =K17 / K19 -> 0.066520372 | L37: =L17 / L19 -> 0.066400906 | N37: Non-Auto Trips | O37: =O17 / O19 -> 0.12729208 | P37: =P17 / P19 -> 0.12785213 | Q37: =Q17 / Q19 -> 0.12814394 | R37: =R17 / R19 -> 0.12849104 | U37: MODE9 | V37: =V9/V13 -> 0.0012046164 | W37: =W9/W13 -> 0.001176622 | X37: =X9/X13 -> 0.0011711855 | Y37: =Y9/Y13 -> 0.0011663501 | AA37: MODE9 | AB37: =AB9/AB13 -> 0.00050496808 | AC37: =AC9/AC13 -> 0.00049802419 | AD37: =AD9/AD13 -> 0.00049641758 | AE37: =AE9/AE13 -> 0.00049469488 | AG37: MODE9 | AH37: =AH9/AH13 -> 0.0014193132 | AI37: =AI9/AI13 -> 0.001417602 | AJ37: =AJ9/AJ13 -> 0.0014207542 | AK37: =AK9/AK13 -> 0.0014241609
B38: Auto | C38: =C18 / C19 -> 0.91940508 | D38: =D18 / D19 -> 0.9211717 | E38: =E18 / E19 -> 0.92201949 | F38: =F18 / F19 -> 0.92281361 | H38: Auto | I38: =I18 / I19 -> 0.93294477 | J38: =J18 / J19 -> 0.93334311 | K38: =K18 / K19 -> 0.93347963 | L38: =L18 / L19 -> 0.93359909 | N38: Auto | O38: =O18 / O19 -> 0.87270792 | P38: =P18 / P19 -> 0.87214787 | Q38: =Q18 / Q19 -> 0.87185606 | R38: =R18 / R19 -> 0.87150896 | U38: Express Bus | V38: =V10/V13 -> 0.00091482851 | W38: =W10/W13 -> 0.001133145 | X38: =X10/X13 -> 0.0012088112 | Y38: =Y10/Y13 -> 0.0013071173 | AA38: Express Bus | AB38: =AB10/AB13 -> 4.5499681e-06 | AC38: =AC10/AC13 -> 5.9723703e-06 | AD38: =AD10/AD13 -> 6.5820743e-06 | AE38: =AE10/AE13 -> 7.3970257e-06 | AG38: Express Bus | AH38: =AH10/AH13 -> 0.00019054569 | AI38: =AI10/AI13 -> 0.00021766342 | AJ38: =AJ10/AJ13 -> 0.00022394952 | AK38: =AK10/AK13 -> 0.00023302421
C39: =SUM(C37:C38) -> 1 | D39: =SUM(D37:D38) -> 1 | E39: =SUM(E37:E38) -> 1 | F39: =SUM(F37:F38) -> 1 | I39: =SUM(I37:I38) -> 1 | J39: =SUM(J37:J38) -> 1 | K39: =SUM(K37:K38) -> 1 | L39: =SUM(L37:L38) -> 1 | O39: =SUM(O37:O38) -> 1 | P39: =SUM(P37:P38) -> 1 | Q39: =SUM(Q37:Q38) -> 1 | R39: =SUM(R37:R38) -> 1 | U39: Light Rail | V39: =V11/V13 -> 0.01335221 | W39: =W11/W13 -> 0.012927595 | X39: =X11/X13 -> 0.012690468 | Y39: =Y11/Y13 -> 0.012486237 | AA39: Light Rail | AB39: =AB11/AB13 -> 0.0040616406 | AC39: =AC11/AC13 -> 0.0039932404 | AD39: =AD11/AD13 -> 0.0039625404 | AE39: =AE11/AE13 -> 0.003931268 | AG39: Light Rail | AH39: =AH11/AH13 -> 0.0062872784 | AI39: =AI11/AI13 -> 0.0060448431 | AJ39: =AJ11/AJ13 -> 0.0059337278 | AK39: =AK11/AK13 -> 0.0058302316
U40: Comm. Rail | V40: =V12/V13 -> 0.0090628782 | W40: =W12/W13 -> 0.008353251 | X40: =X12/X13 -> 0.0080328529 | Y40: =Y12/Y13 -> 0.0077084476 | AA40: Comm. Rail | AB40: =AB12/AB13 -> 0.00056200563 | AC40: =AC12/AC13 -> 0.00054875148 | AD40: =AD12/AD13 -> 0.00054276405 | AE40: =AE12/AE13 -> 0.00053993995 | AG40: Comm. Rail | AH40: =AH12/AH13 -> 0.0025986147 | AI40: =AI12/AI13 -> 0.0023334294 | AJ40: =AJ12/AJ13 -> 0.0022174375 | AK40: =AK12/AK13 -> 0.0021097922
U41: Total Trips | V41: =SUM(V32:V40) -> 1 | W41: =SUM(W32:W40) -> 1 | X41: =SUM(X32:X40) -> 1 | Y41: =SUM(Y32:Y40) -> 1 | AA41: Total Trips | AB41: =SUM(AB32:AB40) -> 1 | AC41: =SUM(AC32:AC40) -> 1 | AD41: =SUM(AD32:AD40) -> 1 | AE41: =SUM(AE32:AE40) -> 1 | AG41: Total Trips | AH41: =SUM(AH32:AH40) -> 1 | AI41: =SUM(AI32:AI40) -> 1 | AJ41: =SUM(AJ32:AJ40) -> 1 | AK41: =SUM(AK32:AK40) -> 1
...

Sheet Summary 2019
B2: 2019 | C2: Peak | G2: Off-Peak | K2: Daily | P2: 2019 | Q2: Peak | U2: Off-Peak | Y2: Daily
B3: Home Based Work | C3: Base | D3: Low | E3: Medium | F3: High | G3: Base | H3: Low | I3: Medium | J3: High | K3: Base | L3: Low | M3: Medium | N3: High | P3: Non-Home Based | Q3: Base | R3: Low | S3: Medium | T3: High | U3: Base | V3: Low | W3: Medium | X3: High | Y3: Base | Z3: Low | AA3: Medium | AB3: High
B4: Non-Motorized | C4: =Base_2019!B5 -> 48337.1 | D4: =Low_2019!B5 -> 42205.6 | E4: =Med_2019!B5 -> 39651.9 | F4: =High_2019!B5 -> 37172.7 | G4: =Base_2019!B19 -> 35324.2 | H4: =Low_2019!B19 -> 30911.5 | I4: =Med_2019!B19 -> 29101 | J4: =High_2019!B19 -> 27296.7 | K4: =Base_2019!B33 -> 83661.3 | L4: =Low_2019!B33 -> 73117.2 | M4: =Med_2019!B33 -> 68752.9 | N4: =High_2019!B33 -> 64469.4 | P4: Non-Motorized | Q4: =Base_2019!E5 -> 29219.1 | R4: =Low_2019!E5 -> 28486.7 | S4: =Med_2019!E5 -> 28141.6 | T4: =High_2019!E5 -> 27807 | U4: =Base_2019!E19 -> 116487 | V4: =Low_2019!E19 -> 113691 | W4: =Med_2019!E19 -> 112358 | X4: =High_2019!E19 -> 111065 | Y4: =Base_2019!E33 -> 145706 | Z4: =Low_2019!E33 -> 142177 | AA4: =Med_2019!E33 -> 140500 | AB4: =High_2019!E33 -> 138872
B5: Auto | C5: =Base_2019!B6 -> 1050350 | D5: =Low_2019!B6 -> 934773 | E5: =Med_2019!B6 -> 884814 | F5: =High_2019!B6 -> 835960 | G5: =Base_2019!B20 -> 601000 | H5: =Low_2019!B20 -> 533312 | I5: =Med_2019!B20 -> 505358 | J5: =High_2019!B20 -> 476471 | K5: =Base_2019!B34 -> 1651350 | L5: =Low_2019!B34 -> 1468085 | M5: =Med_2019!B34 -> 1390171 | N5: =High_2019!B34 -> 1312431 | P5: Auto | Q5: =Base_2019!E6 -> 704036 | R5: =Low_2019!E6 -> 690847 | S5: =Med_2019!E6 -> 683935 | T5: =High_2019!E6 -> 677068 | U5: =Base_2019!E20 -> 1557602 | V5: =Low_2019!E20 -> 1528285 | W5: =Med_2019!E20 -> 1512880 | X5: =High_2019!E20 -> 1497578 | Y5: =Base_2019!E34 -> 2261638 | Z5: =Low_2019!E34 -> 2219131 | AA5: =Med_2019!E34 -> 2196815 | AB5: =High_2019!E34 -> 2174646
B6: School Bus | C6: =Base_2019!B7 -> 0 | D6: =Low_2019!B7 -> 0 | E6: =Med_2019!B7 -> 0 | F6: =High_2019!B7 -> 0 | G6: =Base_2019!B21 -> 0 | H6: =Low_2019!B21 -> 0 | I6: =Med_2019!B21 -> 0 | J6: =High_2019!B21 -> 0 | K6: =Base_2019!B35 -> 0 | L6: =Low_2019!B35 -> 0 | M6: =Med_2019!B35 -> 0 | N6: =High_2019!B35 -> 0 | P6: School Bus | Q6: =Base_2019!E7 -> 0 | R6: =Low_2019!E7 -> 0 | S6: =Med_2019!E7 -> 0 | T6: =High_2019!E7 -> 0 | U6: =Base_2019!E21 -> 0 | V6: =Low_2019!E21 -> 0 | W6: =Med_2019!E21 -> 0 | X6: =High_2019!E21 -> 0 | Y6: =Base_2019!E35 -> 0 | Z6: =Low_2019!E35 -> 0 | AA6: =Med_2019!E35 -> 0 | AB6: =High_2019!E35 -> 0
B7: Local Bus | C7: =Base_2019!B8 -> 10556 | D7: =Low_2019!B8 -> 9285.47 | E7: =Med_2019!B8 -> 8696.67 | F7: =High_2019!B8 -> 8142.31 | G7: =Base_2019!B22 -> 6272.83 | H7: =Low_2019!B22 -> 5446.42 | I7: =Med_2019!B22 -> 5115.79 | J7: =High_2019!B22 -> 4757.66 | K7: =Base_2019!B36 -> 16828.8 | L7: =Low_2019!B36 -> 14731.9 | M7: =Med_2019!B36 -> 13812.5 | N7: =High_2019!B36 -> 12900 | P7: Local Bus | Q7: =Base_2019!E8 -> 1529.98 | R7: =Low_2019!E8 -> 1495.44 | S7: =Med_2019!E8 -> 1478.49 | T7: =High_2019!E8 -> 1462.39 | U7: =Base_2019!E22 -> 2815.73 | V7: =Low_2019!E22 -> 2756.07 | W7: =Med_2019!E22 -> 2723.61 | X7: =High_2019!E22 -> 2692.26 | Y7: =Base_2019!E36 -> 4345.71 | Z7: =Low_2019!E36 -> 4251.51 | AA7: =Med_2019!E36 -> 4202.11 | AB7: =High_2019!E36 -> 4154.65
B8: BRT | C8: =Base_2019!B9 -> 128.3 | D8: =Low_2019!B9 -> 118.42 | E8: =Med_2019!B9 -> 112.65 | F8: =High_2019!B9 -> 106.84 | G8: =Base_2019!B23 -> 72.07 | H8: =Low_2019!B23 -> 65.61 | I8: =Med_2019!B23 -> 62.8 | J8: =High_2019!B23 -> 59.93 | K8: =Base_2019!B37 -> 200.36 | L8: =Low_2019!B37 -> 184.02 | M8: =Med_2019!B37 -> 175.45 | N8: =High_2019!B37 -> 166.77 | P8: BRT | Q8: =Base_2019!E9 -> 20.43 | R8: =Low_2019!E9 -> 20.12 | S8: =Med_2019!E9 -> 19.93 | T8: =High_2019!E9 -> 19.76 | U8: =Base_2019!E23 -> 38.89 | V8: =Low_2019!E23 -> 38.4 | W8: =Med_2019!E23 -> 38.08 | X8: =High_2019!E23 -> 37.81 | Y8: =Base_2019!E37 -> 59.32 | Z8: =Low_2019!E37 -> 58.52 | AA8: =Med_2019!E37 -> 58.02 | AB8: =High_2019!E37 -> 57.57
B9: MODE9 | C9: =Base_2019!B10 -> 1482.81 | D9: =Low_2019!B10 -> 1290.45 | E9: =Med_2019!B10 -> 1214.27 | F9: =High_2019!B10 -> 1140.62 | G9: =Base_2019!B24 -> 680.81 | H9: =Low_2019!B24 -> 584.75 | I9: =Med_2019!B24 -> 551.58 | J9: =High_2019!B24 -> 518.18 | K9: =Base_2019!B38 -> 2163.62 | L9: =Low_2019!B38 -> 1875.2 | M9: =Med_2019!B38 -> 1765.85 | N9: =High_2019!B38 -> 1658.79 | P9: MODE9 | Q9: =Base_2019!E10 -> 496.64 | R9: =Low_2019!E10 -> 481.42 | S9: =Med_2019!E10 -> 474.77 | T9: =High_2019!E10 -> 468.19 | U9: =Base_2019!E24 -> 727.5 | V9: =Low_2019!E24 -> 702.69 | W9: =Med_2019!E24 -> 693.49 | X9: =High_2019!E24 -> 684.12 | Y9: =Base_2019!E38 -> 1224.14 | Z9: =Low_2019!E38 -> 1184.11 | AA9: =Med_2019!E38 -> 1168.25 | AB9: =High_2019!E38 -> 1152.3
B10: Express Bus | C10: =Base_2019!B11 -> 1643.13 | D10: =Low_2019!B11 -> 1805.91 | E10: =Med_2019!B11 -> 1822.58 | F10: =High_2019!B11 -> 1858.99 | G10: =Base_2019!B25 -> 0 | H10: =Low_2019!B25 -> 0 | I10: =Med_2019!B25 -> 0 | J10: =High_2019!B25 -> 0 | K10: =Base_2019!B39 -> 1643.13 | L10: =Low_2019!B39 -> 1805.91 | M10: =Med_2019!B39 -> 1822.58 | N10: =High_2019!B39 -> 1858.99 | P10: Express Bus | Q10: =Base_2019!E11 -> 11.03 | R10: =Low_2019!E11 -> 14.2 | S10: =Med_2019!E11 -> 15.49 | T10: =High_2019!E11 -> 17.23 | U10: =Base_2019!E25 -> 0 | V10: =Low_2019!E25 -> 0 | W10: =Med_2019!E25 -> 0 | X10: =High_2019!E25 -> 0 | Y10: =Base_2019!E39 -> 11.03 | Z10: =Low_2019!E39 -> 14.2 | AA10: =Med_2019!E39 -> 15.49 | AB10: =High_2019!E39 -> 17.23
B11: Light Rail | C11: =Base_2019!B12 -> 16070.6 | D11: =Low_2019!B12 -> 13748 | E11: =Med_2019!B12 -> 12715.4 | F11: =High_2019!B12 -> 11789.3 | G11: =Base_2019!B26 -> 7911.35 | H11: =Low_2019!B26 -> 6854.93 | I11: =Med_2019!B26 -> 6418.55 | J11: =High_2019!B26 -> 5968.72 | K11: =Base_2019!B40 -> 23982 | L11: =Low_2019!B40 -> 20602.9 | M11: =Med_2019!B40 -> 19134 | N11: =High_2019!B40 -> 17758 | P11: Light Rail | Q11: =Base_2019!E12 -> 3427.58 | R11: =Low_2019!E12 -> 3286.05 | S11: =Med_2019!E12 -> 3217.28 | T11: =High_2019!E12 -> 3150.24 | U11: =Base_2019!E26 -> 6418.62 | V11: =Low_2019!E26 -> 6208.33 | W11: =Med_2019!E26 -> 6108.01 | X11: =High_2019!E26 -> 6006.92 | Y11: =Base_2019!E40 -> 9846.2 | Z11: =Low_2019!E40 -> 9494.39 | AA11: =Med_2019!E40 -> 9325.29 | AB11: =High_2019!E40 -> 9157.16
B12: Comm. Rail | C12: =Base_2019!B13 -> 12718.6 | D12: =Low_2019!B13 -> 10249.8 | E12: =Med_2019!B13 -> 9235.3 | F12: =High_2019!B13 -> 8315.6 | G12: =Base_2019!B27 -> 3559.3 | H12: =Low_2019!B27 -> 3062.97 | I12: =Med_2019!B27 -> 2876.15 | J12: =High_2019!B27 -> 2647.45 | K12: =Base_2019!B41 -> 16277.9 | L12: =Low_2019!B41 -> 13312.7 | M12: =Med_2019!B41 -> 12111.5 | N12: =High_2019!B41 -> 10963 | P12: Comm. Rail | Q12: =Base_2019!E13 -> 604.45 | R12: =Low_2019!E13 -> 566 | S12: =Med_2019!E13 -> 547.36 | T12: =High_2019!E13 -> 530.52 | U12: =Base_2019!E27 -> 757.97 | V12: =Low_2019!E27 -> 738.72 | W12: =Med_2019!E27 -> 729.96 | X12: =High_2019!E27 -> 727.17 | Y12: =Base_2019!E41 -> 1362.41 | Z12: =Low_2019!E41 -> 1304.72 | AA12: =Med_2019!E41 -> 1277.32 | AB12: =High_2019!E41 -> 1257.69
B13: Total Trips | C13: =Base_2019!B14 -> 1141287 | D13: =Low_2019!B14 -> 1013477 | E13: =Med_2019!B14 -> 958263 | F13: =High_2019!B14 -> 904486 | G13: =Base_2019!B28 -> 654821 | H13: =Low_2019!B28 -> 580238 | I13: =Med_2019!B28 -> 549483 | J13: =High_2019!B28 -> 517720 | K13: =Base_2019!B42 -> 1796108 | L13: =Low_2019!B42 -> 1593715 | M13: =Med_2019!B42 -> 1507746 | N13: =High_2019!B42 -> 1422206 | P13: Total Trips | Q13: =Base_2019!E14 -> 739345 | R13: =Low_2019!E14 -> 725197 | S13: =Med_2019!E14 -> 717830 | T13: =High_2019!E14 -> 710524 | U13: =Base_2019!E28 -> 1684848 | V13: =Low_2019!E28 -> 1652419 | W13: =Med_2019!E28 -> 1635531 | X13: =High_2019!E28 -> 1618791 | Y13: =Base_2019!E42 -> 2424193 | Z13: =Low_2019!E42 -> 2377616 | AA13: =Med_2019!E42 -> 2353361 | AB13: =High_2019!E42 -> 2329314
D14: =D13/C13 - 1 -> -0.11198761 | E14: =E13/C13 - 1 -> -0.16036632 | F14: =F13/C13 - 1 -> -0.20748593 | H14: =H13/G13 - 1 -> -0.1138983 | I14: =I13/G13 - 1 -> -0.16086534 | J14: =J13/G13 - 1 -> -0.20937172 | L14: =L13/K13 - 1 -> -0.1126842 | M14: =M13/K13 - 1 -> -0.16054825 | N14: =N13/K13 - 1 -> -0.20817345 | R14: =R13/Q13 - 1 -> -0.019135857 | S14: =S13/Q13 - 1 -> -0.029100082 | T14: =T13/Q13 - 1 -> -0.038981801 | V14: =V13/U13 - 1 -> -0.019247434 | W14: =W13/U13 - 1 -> -0.02927089 | X14: =X13/U13 - 1 -> -0.039206504 | Z14: =Z13/Y13 - 1 -> -0.019213404 | AA14: =AA13/Y13 - 1 -> -0.029218796 | AB14: =AB13/Y13 - 1 -> -0.039138385
B16: 2019 | C16: Peak | G16: Off-Peak | K16: Daily | P16: 2019 | Q16: Peak | U16: Off-Peak | Y16: Daily
B17: Home Based College | C17: Base | D17: Low | E17: Medium | F17: High | G17: Base | H17: Low | I17: Medium | J17: High | K17: Base | L17: Low | M17: Medium | N17: High | P17: Home Based School | Q17: Base | R17: Low | S17: Medium | T17: High | U17: Base | V17: Low | W17: Medium | X17: High | Y17: Base | Z17: Low | AA17: Medium | AB17: High
B18: Non-Motorized | C18: =Base_2019!C5 -> 22397.1 | D18: =Low_2019!C5 -> 22345.6 | E18: =Med_2019!C5 -> 22328.9 | F18: =High_2019!C5 -> 22312 | G18: =Base_2019!C19 -> 0 | H18: =Low_2019!C19 -> 0 | I18: =Med_2019!C19 -> 0 | J18: =High_2019!C19 -> 0 | K18: =Base_2019!C33 -> 22397.1 | L18: =Low_2019!C33 -> 22345.6 | M18: =Med_2019!C33 -> 22328.9 | N18: =High_2019!C33 -> 22312 | P18: Non-Motorized | Q18: =Base_2019!F5 -> 182360 | R18: =Low_2019!F5 -> 181810 | S18: =Med_2019!F5 -> 181586 | T18: =High_2019!F5 -> 181386 | U18: =Base_2019!F19 -> 88808.3 | V18: =Low_2019!F19 -> 88540.3 | W18: =Med_2019!F19 -> 88431.6 | X18: =High_2019!F19 -> 88333.2 | Y18: =Base_2019!F33 -> 271169 | Z18: =Low_2019!F33 -> 270351 | AA18: =Med_2019!F33 -> 270017 | AB18: =High_2019!F33 -> 269719
B19: Auto | C19: =Base_2019!C6 -> 79886.1 | D19: =Low_2019!C6 -> 80041.8 | E19: =Med_2019!C6 -> 80141.5 | F19: =High_2019!C6 -> 80204.4 | G19: =Base_2019!C20 -> 0 | H19: =Low_2019!C20 -> 0 | I19: =Med_2019!C20 -> 0 | J19: =High_2019!C20 -> 0 | K19: =Base_2019!C34 -> 79886.1 | L19: =Low_2019!C34 -> 80041.8 | M19: =Med_2019!C34 -> 80141.5 | N19: =High_2019!C34 -> 80204.4 | P19: Auto | Q19: =Base_2019!F6 -> 77705.5 | R19: =Low_2019!F6 -> 77700.4 | S19: =Med_2019!F6 -> 77697.4 | T19: =High_2019!F6 -> 77697.7 | U19: =Base_2019!F20 -> 37511.2 | V19: =Low_2019!F20 -> 37502.4 | W19: =Med_2019!F20 -> 37500 | X19: =High_2019!F20 -> 37495.1 | Y19: =Base_2019!F34 -> 115217 | Z19: =Low_2019!F34 -> 115203 | AA19: =Med_2019!F34 -> 115197 | AB19: =High_2019!F34 -> 115193
B20: School Bus | C20: =Base_2019!C7 -> 0 | D20: =Low_2019!C7 -> 0 | E20: =Med_2019!C7 -> 0 | F20: =High_2019!C7 -> 0 | G20: =Base_2019!C21 -> 0 | H20: =Low_2019!C21 -> 0 | I20: =Med_2019!C21 -> 0 | J20: =High_2019!C21 -> 0 | K20: =Base_2019!C35 -> 0 | L20: =Low_2019!C35 -> 0 | M20: =Med_2019!C35 -> 0 | N20: =High_2019!C35 -> 0 | P20: School Bus | Q20: =Base_2019!F7 -> 174377 | R20: =Low_2019!F7 -> 174933 | S20: =Med_2019!F7 -> 175163 | T20: =High_2019!F7 -> 175365 | U20: =Base_2019!F21 -> 84821.7 | V20: =Low_2019!F21 -> 85083.5 | W20: =Med_2019!F21 -> 85191.5 | X20: =High_2019!F21 -> 85289.7 | Y20: =Base_2019!F35 -> 259198 | Z20: =Low_2019!F35 -> 260017 | AA20: =Med_2019!F35 -> 260354 | AB20: =High_2019!F35 -> 260655
B21: Local Bus | C21: =Base_2019!C8 -> 7310.87 | D21: =Low_2019!C8 -> 7331.17 | E21: =Med_2019!C8 -> 7361.93 | F21: =High_2019!C8 -> 7366.47 | G21: =Base_2019!C22 -> 0 | H21: =Low_2019!C22 -> 0 | I21: =Med_2019!C22 -> 0 | J21: =High_2019!C22 -> 0 | K21: =Base_2019!C36 -> 7310.87 | L21: =Low_2019!C36 -> 7331.17 | M21: =Med_2019!C36 -> 7361.93 | N21: =High_2019!C36 -> 7366.47 | P21: Local Bus | Q21: =Base_2019!F8 -> 0 | R21: =Low_2019!F8 -> 0 | S21: =Med_2019!F8 -> 0 | T21: =High_2019!F8 -> 0 | U21: =Base_2019!F22 -> 0 | V21: =Low_2019!F22 -> 0 | W21: =Med_2019!F22 -> 0 | X21: =High_2019!F22 -> 0 | Y21: =Base_2019!F36 -> 0 | Z21: =Low_2019!F36 -> 0 | AA21: =Med_2019!F36 -> 0 | AB21: =High_2019!F36 -> 0
B22: BRT | C22: =Base_2019!C9 -> 33.86 | D22: =Low_2019!C9 -> 34.13 | E22: =Med_2019!C9 -> 34.23 | F22: =High_2019!C9 -> 34.08 | G22: =Base_2019!C23 -> 0 | H22: =Low_2019!C23 -> 0 | I22: =Med_2019!C23 -> 0 | J22: =High_2019!C23 -> 0 | K22: =Base_2019!C37 -> 33.86 | L22: =Low_2019!C37 -> 34.13 | M22: =Med_2019!C37 -> 34.23 | N22: =High_2019!C37 -> 34.08 | P22: BRT | Q22: =Base_2019!F9 -> 0 | R22: =Low_2019!F9 -> 0 | S22: =Med_2019!F9 -> 0 | T22: =High_2019!F9 -> 0 | U22: =Base_2019!F23 -> 0 | V22: =Low_2019!F23 -> 0 | W22: =Med_2019!F23 -> 0 | X22: =High_2019!F23 -> 0 | Y22: =Base_2019!F37 -> 0 | Z22: =Low_2019!F37 -> 0 | AA22: =Med_2019!F37 -> 0 | AB22: =High_2019!F37 -> 0
B23: MODE9 | C23: =Base_2019!C10 -> 7009.28 | D23: =Low_2019!C10 -> 7003.69 | E23: =Med_2019!C10 -> 7001.88 | F23: =High_2019!C10 -> 7000.63 | G23: =Base_2019!C24 -> 0 | H23: =Low_2019!C24 -> 0 | I23: =Med_2019!C24 -> 0 | J23: =High_2019!C24 -> 0 | K23: =Base_2019!C38 -> 7009.28 | L23: =Low_2019!C38 -> 7003.69 | M23: =Med_2019!C38 -> 7001.88 | N23: =High_2019!C38 -> 7000.63 | P23: MODE9 | Q23: =Base_2019!F10 -> 0 | R23: =Low_2019!F10 -> 0 | S23: =Med_2019!F10 -> 0 | T23: =High_2019!F10 -> 0 | U23: =Base_2019!F24 -> 0 | V23: =Low_2019!F24 -> 0 | W23: =Med_2019!F24 -> 0 | X23: =High_2019!F24 -> 0 | Y23: =Base_2019!F38 -> 0 | Z23: =Low_2019!F38 -> 0 | AA23: =Med_2019!F38 -> 0 | AB23: =High_2019!F38 -> 0
B24: Express Bus | C24: =Base_2019!C11 -> 101.12 | D24: =Low_2019!C11 -> 134.29 | E24: =Med_2019!C11 -> 148.06 | F24: =High_2019!C11 -> 165.3 | G24: =Base_2019!C25 -> 0 | H24: =Low_2019!C25 -> 0 | I24: =Med_2019!C25 -> 0 | J24: =High_2019!C25 -> 0 | K24: =Base_2019!C39 -> 101.12 | L24: =Low_2019!C39 -> 134.29 | M24: =Med_2019!C39 -> 148.06 | N24: =High_2019!C39 -> 165.3 | P24: Express Bus | Q24: =Base_2019!F11 -> 0 | R24: =Low_2019!F11 -> 0 | S24: =Med_2019!F11 -> 0 | T24: =High_2019!F11 -> 0 | U24: =Base_2019!F25 -> 0 | V24: =Low_2019!F25 -> 0 | W24: =Med_2019!F25 -> 0 | X24: =High_2019!F25 -> 0 | Y24: =Base_2019!F39 -> 0 | Z24: =Low_2019!F39 -> 0 | AA24: =Med_2019!F39 -> 0 | AB24: =High_2019!F39 -> 0
B25: Light Rail | C25: =Base_2019!C12 -> 6700.86 | D25: =Low_2019!C12 -> 6627.18 | E25: =Med_2019!C12 -> 6587.77 | F25: =High_2019!C12 -> 6572.18 | G25: =Base_2019!C26 -> 0 | H25: =Low_2019!C26 -> 0 | I25: =Med_2019!C26 -> 0 | J25: =High_2019!C26 -> 0 | K25: =Base_2019!C40 -> 6700.86 | L25: =Low_2019!C40 -> 6627.18 | M25: =Med_2019!C40 -> 6587.77 | N25: =High_2019!C40 -> 6572.18 | P25: Light Rail | Q25: =Base_2019!F12 -> 0 | R25: =Low_2019!F12 -> 0 | S25: =Med_2019!F12 -> 0 | T25: =High_2019!F12 -> 0 | U25: =Base_2019!F26 -> 0 | V25: =Low_2019!F26 -> 0 | W25: =Med_2019!F26 -> 0 | X25: =High_2019!F26 -> 0 | Y25: =Base_2019!F40 -> 0 | Z25: =Low_2019!F40 -> 0 | AA25: =Med_2019!F40 -> 0 | AB25: =High_2019!F40 -> 0
B26: Comm. Rail | C26: =Base_2019!C13 -> 4073.22 | D26: =Low_2019!C13 -> 3994.54 | E26: =Med_2019!C13 -> 3908.24 | F26: =High_2019!C13 -> 3857.38 | G26: =Base_2019!C27 -> 0 | H26: =Low_2019!C27 -> 0 | I26: =Med_2019!C27 -> 0 | J26: =High_2019!C27 -> 0 | K26: =Base_2019!C41 -> 4073.22 | L26: =Low_2019!C41 -> 3994.54 | M26: =Med_2019!C41 -> 3908.24 | N26: =High_2019!C41 -> 3857.38 | P26: Comm. Rail | Q26: =Base_2019!F13 -> 0 | R26: =Low_2019!F13 -> 0 | S26: =Med_2019!F13 -> 0 | T26: =High_2019!F13 -> 0 | U26: =Base_2019!F27 -> 0 | V26: =Low_2019!F27 -> 0 | W26: =Med_2019!F27 -> 0 | X26: =High_2019!F27 -> 0 | Y26: =Base_2019!F41 -> 0 | Z26: =Low_2019!F41 -> 0 | AA26: =Med_2019!F41 -> 0 | AB26: =High_2019!F41 -> 0
B27: Total Trips | C27: =Base_2019!C14 -> 127512 | D27: =Low_2019!C14 -> 127512 | E27: =Med_2019!C14 -> 127512 | F27: =High_2019!C14 -> 127512 | G27: =Base_2019!C28 -> 0 | H27: =Low_2019!C28 -> 0 | I27: =Med_2019!C28 -> 0 | J27: =High_2019!C28 -> 0 | K27: =Base_2019!C42 -> 127512 | L27: =Low_2019!C42 -> 127512 | M27: =Med_2019!C42 -> 127512 | N27: =High_2019!C42 -> 127512 | P27: Total Trips | Q27: =Base_2019!F14 -> 434442 | R27: =Low_2019!F14 -> 434444 | S27: =Med_2019!F14 -> 434446 | T27: =High_2019!F14 -> 434448 | U27: =Base_2019!F28 -> 211141 | V27: =Low_2019!F28 -> 211126 | W27: =Med_2019!F28 -> 211123 | X27: =High_2019!F28 -> 211118 | Y27: =Base_2019!F42 -> 645584 | Z27: =Low_2019!F42 -> 645570 | AA27: =Med_2019!F42 -> 645569 | AB27: =High_2019!F42 -> 645566
D28: =D27/C27 - 1 -> 0 | E28: =E27/C27 - 1 -> 0 | F28: =F27/C27 - 1 -> 0 | H28: =H27/G27 - 1 -> #DIV/0! | I28: =I27/G27 - 1 -> #DIV/0! | J28: =J27/G27 - 1 -> #DIV/0! | L28: =L27/K27 - 1 -> 0 | M28: =M27/K27 - 1 -> 0 | N28: =N27/K27 - 1 -> 0 | R28: =R27/Q27 - 1 -> 4.6036065e-06 | S28: =S27/Q27 - 1 -> 9.2072129e-06 | T28: =T27/Q27 - 1 -> 1.3810819e-05 | V28: =V27/U27 - 1 -> -7.1042573e-05 | W28: =W27/U27 - 1 -> -8.5251088e-05 | X28: =X27/U27 - 1 -> -0.00010893195 | Z28: =Z27/Y27 - 1 -> -2.1685791e-05 | AA28: =AA27/Y27 - 1 -> -2.3234777e-05 | AB28: =AB27/Y27 - 1 -> -2.7881732e-05
B30: 2019 | C30: Peak | G30: Off-Peak | K30: Daily | P30: 2019 | Q30: Peak | U30: Off-Peak | Y30: Daily
B31: Home Based Other | C31: Base | D31: Low | E31: Medium | F31: High | G31: Base | H31: Low | I31: Medium | J31: High | K31: Base | L31: Low | M31: Medium | N31: High | P31: Total Trips | Q31: Base | R31: Low | S31: Medium | T31: High | U31: Base | V31: Low | W31: Medium | X31: High | Y31: Base | Z31: Low | AA31: Medium | AB31: High
B32: Non-Motorized | C32: =Base_2019!D5 -> 147453 | D32: =Low_2019!D5 -> 146588 | E32: =Med_2019!D5 -> 146229 | F32: =High_2019!D5 -> 145912 | G32: =Base_2019!D19 -> 368928 | H32: =Low_2019!D19 -> 367219 | I32: =Med_2019!D19 -> 366475 | J32: =High_2019!D19 -> 365834 | K32: =Base_2019!D33 -> 516381 | L32: =Low_2019!D33 -> 513807 | M32: =Med_2019!D33 -> 512704 | N32: =High_2019!D33 -> 511747 | P32: Non-Motorized | Q32: =Base_2019!G5 -> 429767 | R32: =Low_2019!G5 -> 421436 | S32: =Med_2019!G5 -> 417937 | T32: =High_2019!G5 -> 414590 | U32: =Base_2019!G19 -> 609547 | V32: =Low_2019!G19 -> 600361 | W32: =Med_2019!G19 -> 596366 | X32: =High_2019!G19 -> 592529 | Y32: =Base_2019!G33 -> 1039314 | Z32: =Low_2019!G33 -> 1021797 | AA32: =Med_2019!G33 -> 1014303 | AB32: =High_2019!G33 -> 1007119
B33: Auto | C33: =Base_2019!D6 -> 1313694 | D33: =Low_2019!D6 -> 1314480 | E33: =Med_2019!D6 -> 1314837 | F33: =High_2019!D6 -> 1315222 | G33: =Base_2019!D20 -> 2693602 | H33: =Low_2019!D20 -> 2695075 | I33: =Med_2019!D20 -> 2695733 | J33: =High_2019!D20 -> 2696409 | K33: =Base_2019!D34 -> 4007296 | L33: =Low_2019!D34 -> 4009555 | M33: =Med_2019!D34 -> 4010570 | N33: =High_2019!D34 -> 4011630 | P33: Auto | Q33: =Base_2019!G6 -> 3225671 | R33: =Low_2019!G6 -> 3097842 | S33: =Med_2019!G6 -> 3041425 | T33: =High_2019!G6 -> 2986152 | U33: =Base_2019!G20 -> 4889716 | V33: =Low_2019!G20 -> 4794174 | W33: =Med_2019!G20 -> 4751470 | X33: =High_2019!G20 -> 4707953 | Y33: =Base_2019!G34 -> 8115387 | Z33: =Low_2019!G34 -> 7892016 | AA33: =Med_2019!G34 -> 7792895 | AB33: =High_2019!G34 -> 7694105
B34: School Bus | C34: =Base_2019!D7 -> 0 | D34: =Low_2019!D7 -> 0 | E34: =Med_2019!D7 -> 0 | F34: =High_2019!D7 -> 0 | G34: =Base_2019!D21 -> 0 | H34: =Low_2019!D21 -> 0 | I34: =Med_2019!D21 -> 0 | J34: =High_2019!D21 -> 0 | K34: =Base_2019!D35 -> 0 | L34: =Low_2019!D35 -> 0 | M34: =Med_2019!D35 -> 0 | N34: =High_2019!D35 -> 0 | P34: School Bus | Q34: =Base_2019!G7 -> 174377 | R34: =Low_2019!G7 -> 174933 | S34: =Med_2019!G7 -> 175163 | T34: =High_2019!G7 -> 175365 | U34: =Base_2019!G21 -> 84821.7 | V34: =Low_2019!G21 -> 85083.5 | W34: =Med_2019!G21 -> 85191.5 | X34: =High_2019!G21 -> 85289.7 | Y34: =Base_2019!G35 -> 259198 | Z34: =Low_2019!G35 -> 260017 | AA34: =Med_2019!G35 -> 260354 | AB34: =High_2019!G35 -> 260655
B35: Local Bus | C35: =Base_2019!D8 -> 5221.78 | D35: =Low_2019!D8 -> 5237.96 | E35: =Med_2019!D8 -> 5241.5 | F35: =High_2019!D8 -> 5249.3 | G35: =Base_2019!D22 -> 9821.81 | H35: =Low_2019!D22 -> 9841.65 | I35: =Med_2019!D22 -> 9845.89 | J35: =High_2019!D22 -> 9859.07 | K35: =Base_2019!D36 -> 15043.6 | L35: =Low_2019!D36 -> 15079.6 | M35: =Med_2019!D36 -> 15087.4 | N35: =High_2019!D36 -> 15108.4 | P35: Local Bus | Q35: =Base_2019!G8 -> 24618.6 | R35: =Low_2019!G8 -> 23350 | S35: =Med_2019!G8 -> 22778.6 | T35: =High_2019!G8 -> 22220.5 | U35: =Base_2019!G22 -> 18910.4 | V35: =Low_2019!G22 -> 18044.1 | W35: =Med_2019!G22 -> 17685.3 | X35: =High_2019!G22 -> 17309 | Y35: =Base_2019!G36 -> 43529 | Z35: =Low_2019!G36 -> 41394.2 | AA35: =Med_2019!G36 -> 40463.9 | AB35: =High_2019!G36 -> 39529.5
B36: BRT | C36: =Base_2019!D9 -> 87.83 | D36: =Low_2019!D9 -> 88.11 | E36: =Med_2019!D9 -> 88.21 | F36: =High_2019!D9 -> 88.5 | G36: =Base_2019!D23 -> 154.42 | H36: =Low_2019!D23 -> 154.99 | I36: =Med_2019!D23 -> 155.19 | J36: =High_2019!D23 -> 155.63 | K36: =Base_2019!D37 -> 242.25 | L36: =Low_2019!D37 -> 243.1 | M36: =Med_2019!D37 -> 243.4 | N36: =High_2019!D37 -> 244.13 | P36: BRT | Q36: =Base_2019!G9 -> 270.43 | R36: =Low_2019!G9 -> 260.78 | S36: =Med_2019!G9 -> 255.03 | T36: =High_2019!G9 -> 249.18 | U36: =Base_2019!G23 -> 265.37 | V36: =Low_2019!G23 -> 259 | W36: =Med_2019!G23 -> 256.07 | X36: =High_2019!G23 -> 253.37 | Y36: =Base_2019!G37 -> 535.8 | Z36: =Low_2019!G37 -> 519.77 | AA36: =Med_2019!G37 -> 511.1 | AB36: =High_2019!G37 -> 502.55
B37: MODE9 | C37: =Base_2019!D10 -> 1366.42 | D37: =Low_2019!D10 -> 1365.37 | E37: =Med_2019!D10 -> 1364.51 | F37: =High_2019!D10 -> 1364.13 | G37: =Base_2019!D24 -> 1802.74 | H37: =Low_2019!D24 -> 1768.07 | I37: =Med_2019!D24 -> 1768.53 | J37: =High_2019!D24 -> 1768.53 | K37: =Base_2019!D38 -> 3169.17 | L37: =Low_2019!D38 -> 3133.44 | M37: =Med_2019!D38 -> 3133.04 | N37: =High_2019!D38 -> 3132.66 | P37: MODE9 | Q37: =Base_2019!G10 -> 10355.2 | R37: =Low_2019!G10 -> 10140.9 | S37: =Med_2019!G10 -> 10055.4 | T37: =High_2019!G10 -> 9973.56 | U37: =Base_2019!G24 -> 3211.05 | V37: =Low_2019!G24 -> 3055.51 | W37: =Med_2019!G24 -> 3013.59 | X37: =High_2019!G24 -> 2970.83 | Y37: =Base_2019!G38 -> 13566.2 | Z37: =Low_2019!G38 -> 13196.4 | AA37: =Med_2019!G38 -> 13069 | AB37: =High_2019!G38 -> 12944.4
B38: Express Bus | C38: =Base_2019!D11 -> 66.01 | D38: =Low_2019!D11 -> 71.83 | E38: =Med_2019!D11 -> 73.9 | F38: =High_2019!D11 -> 76.46 | G38: =Base_2019!D25 -> 0 | H38: =Low_2019!D25 -> 0 | I38: =Med_2019!D25 -> 0 | J38: =High_2019!D25 -> 0 | K38: =Base_2019!D39 -> 66.01 | L38: =Low_2019!D39 -> 71.83 | M38: =Med_2019!D39 -> 73.9 | N38: =High_2019!D39 -> 76.46 | P38: Express Bus | Q38: =Base_2019!G11 -> 1821.29 | R38: =Low_2019!G11 -> 2026.22 | S38: =Med_2019!G11 -> 2060.03 | T38: =High_2019!G11 -> 2117.99 | U38: =Base_2019!G25 -> 0 | V38: =Low_2019!G25 -> 0 | W38: =Med_2019!G25 -> 0 | X38: =High_2019!G25 -> 0 | Y38: =Base_2019!G39 -> 1821.29 | Z38: =Low_2019!G39 -> 2026.22 | AA38: =Med_2019!G39 -> 2060.03 | AB38: =High_2019!G39 -> 2117.99
B39: Light Rail | C39: =Base_2019!D12 -> 7638.61 | D39: =Low_2019!D12 -> 7601.1 | E39: =Med_2019!D12 -> 7579.25 | F39: =High_2019!D12 -> 7557.92 | G39: =Base_2019!D26 -> 11928 | H39: =Low_2019!D26 -> 11945.6 | I39: =Med_2019!D26 -> 11955.9 | J39: =High_2019!D26 -> 11946.5 | K39: =Base_2019!D40 -> 19566.6 | L39: =Low_2019!D40 -> 19546.7 | M39: =Med_2019!D40 -> 19535.1 | N39: =High_2019!D40 -> 19504.4 | P39: Light Rail | Q39: =Base_2019!G12 -> 33837.7 | R39: =Low_2019!G12 -> 31262.4 | S39: =Med_2019!G12 -> 30099.7 | T39: =High_2019!G12 -> 29069.6 | U39: =Base_2019!G26 -> 26258 | V39: =Low_2019!G26 -> 25008.8 | W39: =Med_2019!G26 -> 24482.4 | X39: =High_2019!G26 -> 23922.1 | Y39: =Base_2019!G40 -> 60095.6 | Z39: =Low_2019!G40 -> 56271.2 | AA39: =Med_2019!G40 -> 54582.2 | AB39: =High_2019!G40 -> 52991.8
B40: Comm. Rail | C40: =Base_2019!D13 -> 1474.28 | D40: =Low_2019!D13 -> 1439.52 | E40: =Med_2019!D13 -> 1421.2 | F40: =High_2019!D13 -> 1407.13 | G40: =Base_2019!D27 -> 1650.5 | H40: =Low_2019!D27 -> 1670.31 | I40: =Med_2019!D27 -> 1679.16 | J40: =High_2019!D27 -> 1690.98 | K40: =Base_2019!D41 -> 3124.78 | L40: =Low_2019!D41 -> 3109.83 | M40: =Med_2019!D41 -> 3100.37 | N40: =High_2019!D41 -> 3098.11 | P40: Comm. Rail | Q40: =Base_2019!G13 -> 18870.6 | R40: =Low_2019!G13 -> 16249.8 | S40: =Med_2019!G13 -> 15112.1 | T40: =High_2019!G13 -> 14110.6 | U40: =Base_2019!G27 -> 5967.77 | V40: =Low_2019!G27 -> 5472 | W40: =Med_2019!G27 -> 5285.28 | X40: =High_2019!G27 -> 5065.6 | Y40: =Base_2019!G41 -> 24838.3 | Z40: =Low_2019!G41 -> 21721.8 | AA40: =Med_2019!G41 -> 20397.4 | AB40: =High_2019!G41 -> 19176.2
B41: Total Trips | C41: =Base_2019!D14 -> 1477002 | D41: =Low_2019!D14 -> 1476872 | E41: =Med_2019!D14 -> 1476835 | F41: =High_2019!D14 -> 1476878 | G41: =Base_2019!D28 -> 3087888 | H41: =Low_2019!D28 -> 3087674 | I41: =Med_2019!D28 -> 3087613 | J41: =High_2019!D28 -> 3087664 | K41: =Base_2019!D42 -> 4564889 | L41: =Low_2019!D42 -> 4564546 | M41: =Med_2019!D42 -> 4564448 | N41: =High_2019!D42 -> 4564541 | P41: Total Trips | Q41: =Base_2019!G14 -> 3919589 | R41: =Low_2019!G14 -> 3777502 | S41: =Med_2019!G14 -> 3714886 | T41: =High_2019!G14 -> 3653848 | U41: =Base_2019!G28 -> 5638697 | V41: =Low_2019!G28 -> 5531458 | W41: =Med_2019!G28 -> 5483750 | X41: =High_2019!G28 -> 5435292 | Y41: =Base_2019!G42 -> 9558286 | Z41: =Low_2019!G42 -> 9308959 | AA41: =Med_2019!G42 -> 9198636 | AB41: =High_2019!G42 -> 9089141
D42: =D41/C41 - 1 -> -8.801613e-05 | E42: =E41/C41 - 1 -> -0.00011306687 | F42: =F41/C41 - 1 -> -8.3953847e-05 | H42: =H41/G41 - 1 -> -6.9303032e-05 | I42: =I41/G41 - 1 -> -8.9057634e-05 | J42: =J41/G41 - 1 -> -7.2541491e-05 | L42: =L41/K41 - 1 -> -7.5138738e-05 | M42: =M41/K41 - 1 -> -9.6606949e-05 | N42: =N41/K41 - 1 -> -7.6234055e-05 | R42: =R41/Q41 - 1 -> -0.036250484 | S42: =S41/Q41 - 1 -> -0.052225629 | T42: =T41/Q41 - 1 -> -0.06779818 | V42: =V41/U41 - 1 -> -0.019018401 | W42: =W41/U41 - 1 -> -0.027479221 | X42: =X41/U41 - 1 -> -0.03607305 | Z42: =Z41/Y41 - 1 -> -0.026084907 | AA42: =AA41/Y41 - 1 -> -0.037627039 | AB42: =AB41/Y41 - 1 -> -0.049082545

Sheet Summary 2050
B2: 2050 | C2: Peak | G2: Off-Peak | K2: Daily | P2: 2050 | Q2: Peak | U2: Off-Peak | Y2: Daily
B3: Home Based Work | C3: Base | D3: Low | E3: Medium | F3: High | G3: Base | H3: Low | I3: Medium | J3: High | K3: Base | L3: Low | M3: Medium | N3: High | P3: Non-Home Based | Q3: Base | R3: Low | S3: Medium | T3: High | U3: Base | V3: Low | W3: Medium | X3: High | Y3: Base | Z3: Low | AA3: Medium | AB3: High
B4: Non-Motorized | C4: =Base_2050!B5 -> 81021.29 | D4: =Low_2050!B5 -> 69917.7 | E4: =Med_2050!B5 -> 65325.8 | F4: =High_2050!B5 -> 60845.2 | G4: =Base_2050!B19 -> 58847.32 | H4: =Low_2050!B19 -> 50960.1 | I4: =Med_2050!B19 -> 47731.1 | J4: =High_2050!B19 -> 44487.9 | K4: =Base_2050!B33 -> 139868.62 | L4: =Low_2050!B33 -> 120878 | M4: =Med_2050!B33 -> 113057 | N4: =High_2050!B33 -> 105333 | P4: Non-Motorized | Q4: =Base_2050!E5 -> 44177.34 | R4: =Low_2050!E5 -> 42843.1 | S4: =Med_2050!E5 -> 42230.3 | T4: =High_2050!E5 -> 41630.4 | U4: =Base_2050!E19 -> 175705.49 | V4: =Low_2050!E19 -> 170708 | W4: =Med_2050!E19 -> 168386 | X4: =High_2050!E19 -> 166102 | Y4: =Base_2050!E33 -> 219882.83 | Z4: =Low_2050!E33 -> 213551 | AA4: =Med_2050!E33 -> 210616 | AB4: =High_2050!E33 -> 207732
B5: Auto | C5: =Base_2050!B6 -> 1646769.4 | D5: =Low_2050!B6 -> 1449515 | E5: =Med_2050!B6 -> 1364486 | F5: =High_2050!B6 -> 1281252 | G5: =Base_2050!B20 -> 947213.6 | H5: =Low_2050!B20 -> 831417 | I5: =Med_2050!B20 -> 783611 | J5: =High_2050!B20 -> 733660 | K5: =Base_2050!B34 -> 2593983 | L5: =Low_2050!B34 -> 2280932 | M5: =Med_2050!B34 -> 2148097 | N5: =High_2050!B34 -> 2014912 | P5: Auto | Q5: =Base_2050!E6 -> 1100545.5 | R5: =Low_2050!E6 -> 1077766 | S5: =Med_2050!E6 -> 1066283 | T5: =High_2050!E6 -> 1054721 | U5: =Base_2050!E20 -> 2440777.4 | V5: =Low_2050!E20 -> 2389879 | W5: =Med_2050!E20 -> 2364295 | X5: =High_2050!E20 -> 2338335 | Y5: =Base_2050!E34 -> 3541322.9 | Z5: =Low_2050!E34 -> 3467645 | AA5: =Med_2050!E34 -> 3430578 | AB5: =High_2050!E34 -> 3393055
B6: School Bus | C6: =Base_2050!B7 -> 0 | D6: =Low_2050!B7 -> 0 | E6: =Med_2050!B7 -> 0 | F6: =High_2050!B7 -> 0 | G6: =Base_2050!B21 -> 0 | H6: =Low_2050!B21 -> 0 | I6: =Med_2050!B21 -> 0 | J6: =High_2050!B21 -> 0 | K6: =Base_2050!B35 -> 0 | L6: =Low_2050!B35 -> 0 | M6: =Med_2050!B35 -> 0 | N6: =High_2050!B35 -> 0 | P6: School Bus | Q6: =Base_2050!E7 -> 0 | R6: =Low_2050!E7 -> 0 | S6: =Med_2050!E7 -> 0 | T6: =High_2050!E7 -> 0 | U6: =Base_2050!E21 -> 0 | V6: =Low_2050!E21 -> 0 | W6: =Med_2050!E21 -> 0 | X6: =High_2050!E21 -> 0 | Y6: =Base_2050!E35 -> 0 | Z6: =Low_2050!E35 -> 0 | AA6: =Med_2050!E35 -> 0 | AB6: =High_2050!E35 -> 0
B7: Local Bus | C7: =Base_2050!B8 -> 7335.34 | D7: =Low_2050!B8 -> 6396.82 | E7: =Med_2050!B8 -> 5974.86 | F7: =High_2050!B8 -> 5584.06 | G7: =Base_2050!B22 -> 4416.04 | H7: =Low_2050!B22 -> 3827.08 | I7: =Med_2050!B22 -> 3580.55 | J7: =High_2050!B22 -> 3315.01 | K7: =Base_2050!B36 -> 11751.38 | L7: =Low_2050!B36 -> 10223.9 | M7: =Med_2050!B36 -> 9555.41 | N7: =High_2050!B36 -> 8899.07 | P7: Local Bus | Q7: =Base_2050!E8 -> 1115.06 | R7: =Low_2050!E8 -> 1087.02 | S7: =Med_2050!E8 -> 1073.35 | T7: =High_2050!E8 -> 1063.38 | U7: =Base_2050!E22 -> 2166.6 | V7: =Low_2050!E22 -> 2115.29 | W7: =Med_2050!E22 -> 2089.84 | X7: =High_2050!E22 -> 2068.37 | Y7: =Base_2050!E36 -> 3281.65 | Z7: =Low_2050!E36 -> 3202.31 | AA7: =Med_2050!E36 -> 3163.19 | AB7: =High_2050!E36 -> 3131.75
B8: BRT | C8: =Base_2050!B9 -> 16606.79 | D8: =Low_2050!B9 -> 14654.2 | E8: =Med_2050!B9 -> 13726.3 | F8: =High_2050!B9 -> 12849.1 | G8: =Base_2050!B23 -> 7962.3 | H8: =Low_2050!B23 -> 6969.71 | I8: =Med_2050!B23 -> 6554.34 | J8: =High_2050!B23 -> 6098.1 | K8: =Base_2050!B37 -> 24569.09 | L8: =Low_2050!B37 -> 21623.9 | M8: =Med_2050!B37 -> 20280.6 | N8: =High_2050!B37 -> 18947.2 | P8: BRT | Q8: =Base_2050!E9 -> 3195.87 | R8: =Low_2050!E9 -> 3127.93 | S8: =Med_2050!E9 -> 3089.46 | T8: =High_2050!E9 -> 3051.6 | U8: =Base_2050!E23 -> 4142.46 | V8: =Low_2050!E23 -> 4048.79 | W8: =Med_2050!E23 -> 3996.2 | X8: =High_2050!E23 -> 3944.1 | Y8: =Base_2050!E37 -> 7338.33 | Z8: =Low_2050!E37 -> 7176.73 | AA8: =Med_2050!E37 -> 7085.66 | AB8: =High_2050!E37 -> 6995.69
B9: MODE9 | C9: =Base_2050!B10 -> 5889.74 | D9: =Low_2050!B10 -> 5159 | E9: =Med_2050!B10 -> 4829.91 | F9: =High_2050!B10 -> 4536.31 | G9: =Base_2050!B24 -> 2404.38 | H9: =Low_2050!B24 -> 2108.09 | I9: =Med_2050!B24 -> 1988.88 | J9: =High_2050!B24 -> 1858.36 | K9: =Base_2050!B38 -> 8294.12 | L9: =Low_2050!B38 -> 7267.09 | M9: =Med_2050!B38 -> 6818.79 | N9: =High_2050!B38 -> 6394.67 | P9: MODE9 | Q9: =Base_2050!E10 -> 1456.29 | R9: =Low_2050!E10 -> 1423.96 | S9: =Med_2050!E10 -> 1407 | T9: =High_2050!E10 -> 1391.16 | U9: =Base_2050!E24 -> 1945.65 | V9: =Low_2050!E24 -> 1895.78 | W9: =Med_2050!E24 -> 1873.45 | X9: =High_2050!E24 -> 1852.6 | Y9: =Base_2050!E38 -> 3401.95 | Z9: =Low_2050!E38 -> 3319.74 | AA9: =Med_2050!E38 -> 3280.45 | AB9: =High_2050!E38 -> 3243.75
B10: Express Bus | C10: =Base_2050!B11 -> 2148.97 | D10: =Low_2050!B11 -> 2880.84 | E10: =Med_2050!B11 -> 3190.74 | F10: =High_2050!B11 -> 3517.9 | G10: =Base_2050!B25 -> 33.72 | H10: =Low_2050!B25 -> 33.21 | I10: =Med_2050!B25 -> 32.87 | J10: =High_2050!B25 -> 32.37 | K10: =Base_2050!B39 -> 2182.69 | L10: =Low_2050!B39 -> 2914.05 | M10: =Med_2050!B39 -> 3223.61 | N10: =High_2050!B39 -> 3550.27 | P10: Express Bus | Q10: =Base_2050!E11 -> 11.27 | R10: =Low_2050!E11 -> 21.72 | S10: =Med_2050!E11 -> 26.92 | T10: =High_2050!E11 -> 33.07 | U10: =Base_2050!E25 -> 0.43 | V10: =Low_2050!E25 -> 0.42 | W10: =Med_2050!E25 -> 0.42 | X10: =High_2050!E25 -> 0.41 | Y10: =Base_2050!E39 -> 11.7 | Z10: =Low_2050!E39 -> 22.14 | AA10: =Med_2050!E39 -> 27.33 | AB10: =High_2050!E39 -> 33.48
B11: Light Rail | C11: =Base_2050!B12 -> 30214.27 | D11: =Low_2050!B12 -> 25427.6 | E11: =Med_2050!B12 -> 23348.5 | F11: =High_2050!B12 -> 21464 | G11: =Base_2050!B26 -> 16502.29 | H11: =Low_2050!B26 -> 14257.5 | I11: =Med_2050!B26 -> 13301.3 | J11: =High_2050!B26 -> 12219.7 | K11: =Base_2050!B40 -> 46716.56 | L11: =Low_2050!B40 -> 39685.1 | M11: =Med_2050!B40 -> 36649.8 | N11: =High_2050!B40 -> 33683.7 | P11: Light Rail | Q11: =Base_2050!E12 -> 5019.49 | R11: =Low_2050!E12 -> 4745.11 | S11: =Med_2050!E12 -> 4635.6 | T11: =High_2050!E12 -> 4522.09 | U11: =Base_2050!E26 -> 10331.12 | V11: =Low_2050!E26 -> 9961.75 | W11: =Med_2050!E26 -> 9802.9 | X11: =High_2050!E26 -> 9631.92 | Y11: =Base_2050!E40 -> 15350.61 | Z11: =Low_2050!E40 -> 14706.9 | AA11: =Med_2050!E40 -> 14438.5 | AB11: =High_2050!E40 -> 14154
B12: Comm. Rail | C12: =Base_2050!B13 -> 32054.58 | D12: =Low_2050!B13 -> 26461.7 | E12: =Med_2050!B13 -> 23782.3 | F12: =High_2050!B13 -> 21617.6 | G12: =Base_2050!B27 -> 10092.22 | H12: =Low_2050!B27 -> 8718.6 | I12: =Med_2050!B27 -> 8162.34 | J12: =High_2050!B27 -> 7473.86 | K12: =Base_2050!B41 -> 42146.8 | L12: =Low_2050!B41 -> 35180.3 | M12: =Med_2050!B41 -> 31944.6 | N12: =High_2050!B41 -> 29091.5 | P12: Comm. Rail | Q12: =Base_2050!E13 -> 1109.33 | R12: =Low_2050!E13 -> 1072.71 | S12: =Med_2050!E13 -> 1044.66 | T12: =High_2050!E13 -> 1019.19 | U12: =Base_2050!E27 -> 1270.72 | V12: =Low_2050!E27 -> 1251.51 | W12: =Med_2050!E27 -> 1243.23 | X12: =High_2050!E27 -> 1230.27 | Y12: =Base_2050!E41 -> 2380.04 | Z12: =Low_2050!E41 -> 2324.22 | AA12: =Med_2050!E41 -> 2287.89 | AB12: =High_2050!E41 -> 2249.46
B13: Total Trips | C13: =Base_2050!B14 -> 1822040.4 | D13: =Low_2050!B14 -> 1600413 | E13: =Med_2050!B14 -> 1504665 | F13: =High_2050!B14 -> 1411666 | G13: =Base_2050!B28 -> 1047471.9 | H13: =Low_2050!B28 -> 918291 | I13: =Med_2050!B28 -> 864962 | J13: =High_2050!B28 -> 809146 | K13: =Base_2050!B42 -> 2869512.3 | L13: =Low_2050!B42 -> 2518704 | M13: =Med_2050!B42 -> 2369627 | N13: =High_2050!B42 -> 2220812 | P13: Total Trips | Q13: =Base_2050!E14 -> 1156630.1 | R13: =Low_2050!E14 -> 1132088 | S13: =Med_2050!E14 -> 1119791 | T13: =High_2050!E14 -> 1107432 | U13: =Base_2050!E28 -> 2636339.9 | V13: =Low_2050!E28 -> 2579860 | W13: =Med_2050!E28 -> 2551687 | X13: =High_2050!E28 -> 2523164 | Y13: =Base_2050!E42 -> 3792970 | Z13: =Low_2050!E42 -> 3711948 | AA13: =Med_2050!E42 -> 3671477 | AB13: =High_2050!E42 -> 3630596
B16: 2050 | C16: Peak | G16: Off-Peak | K16: Daily | P16: 2050 | Q16: Peak | U16: Off-Peak | Y16: Daily
B17: Home Based College | C17: Base | D17: Low | E17: Medium | F17: High | G17: Base | H17: Low | I17: Medium | J17: High | K17: Base | L17: Low | M17: Medium | N17: High | P17: Home Based School | Q17: Base | R17: Low | S17: Medium | T17: High | U17: Base | V17: Low | W17: Medium | X17: High | Y17: Base | Z17: Low | AA17: Medium | AB17: High
