Workbook
Name lu_CoName: LookupIdx!$B$3:$C$35
Name lu_GEOID: LookupIdx!$A$3:$C$35
Name lu_WrkID: LookupIdx!$F$3:$G$108
Name lu_WrkID_Est: LookupIdx!$H$3:$I$108
Name lu_WrkID_MOE: LookupIdx!$J$3:$K$108

Sheet Calc_HBJ_Share_of_WAH
B1: Wasatch Front
B4: Share of HBJ by Industry Classification
D5: 2010 | E5: 2011 | F5: 2012 | G5: 2013 | H5: 2014 | I5: 2015 | J5: 2016 | K5: 2017 | L5: 2018 | M5: 2019
B6: 0 | C6: Share of Work At Home | D6: =D43 * D55 -> 0.024156393 | E6: =E43 * E55 -> 0.023616541 | F6: =F43 * F55 -> 0.022667213 | G6: =G43 * G55 -> 0.022171769 | H6: =H43 * H55 -> 0.022228968 | I6: =I43 * I55 -> 0.022692701 | J6: =J43 * J55 -> 0.023436385 | K6: =K43 * K55 -> 0.025113206 | ... M6: =M43 * M55 -> 0.026666597
B7: 1 | C7: Agriculture, forestry, fishing and hunting, and mining | D7: =D43 * D56 -> 0.028926933 | E7: =E43 * E56 -> 0.025759823 | F7: =F43 * F56 -> 0.025540774 | G7: =G43 * G56 -> 0.020695744 | H7: =H43 * H56 -> 0.024151369 | I7: =I43 * I56 -> 0.024516287 | J7: =J43 * J56 -> 0.024251412 | K7: =K43 * K56 -> 0.023685704 | ... M7: =M43 * M56 -> 0.026063103
B8: 2 | C8: Construction | D8: =D43 * D57 -> 0.020401628 | E8: =E43 * E57 -> 0.019866698 | F8: =F43 * F57 -> 0.01989078 | G8: =G43 * G57 -> 0.019142023 | H8: =H43 * H57 -> 0.018777085 | I8: =I43 * I57 -> 0.016818116 | J8: =J43 * J57 -> 0.018833265 | K8: =K43 * K57 -> 0.019227454 | ... M8: =M43 * M57 -> 0.024102364
B9: 3 | C9: Manufacturing | D9: =D43 * D58 -> 0.012618033 | E9: =E43 * E58 -> 0.012716493 | F9: =F43 * F58 -> 0.013193002 | G9: =G43 * G58 -> 0.014094349 | H9: =H43 * H58 -> 0.01455017 | I9: =I43 * I58 -> 0.015823725 | J9: =J43 * J58 -> 0.016148542 | K9: =K43 * K58 -> 0.016705625 | ... M9: =M43 * M58 -> 0.016139368
B10: 4 | C10: Wholesale trade | D10: =D43 * D59 -> 0.025053598 | E10: =E43 * E59 -> 0.026193457 | F10: =F43 * F59 -> 0.024940808 | G10: =G43 * G59 -> 0.025942702 | H10: =H43 * H59 -> 0.024463377 | I10: =I43 * I59 -> 0.024958558 | J10: =J43 * J59 -> 0.024959379 | K10: =K43 * K59 -> 0.026925452 | ... M10: =M43 * M59 -> 0.026699481
B11: 5 | C11: Retail trade | D11: =D43 * D60 -> 0.016420596 | E11: =E43 * E60 -> 0.01550784 | F11: =F43 * F60 -> 0.015151232 | G11: =G43 * G60 -> 0.014903 | H11: =H43 * H60 -> 0.016392175 | I11: =I43 * I60 -> 0.016443326 | J11: =J43 * J60 -> 0.017950413 | K11: =K43 * K60 -> 0.020255837 | ... M11: =M43 * M60 -> 0.021807323
B12: 6 | C12: Transportation and warehousing, and utilities | D12: =D43 * D61 -> 0.022347498 | E12: =E43 * E61 -> 0.022951641 | F12: =F43 * F61 -> 0.022506329 | G12: =G43 * G61 -> 0.024997982 | H12: =H43 * H61 -> 0.023589988 | I12: =I43 * I61 -> 0.0232402 | J12: =J43 * J61 -> 0.0236551 | K12: =K43 * K61 -> 0.026391714 | ... M12: =M43 * M61 -> 0.024159399
B13: 7 | C13: Information | D13: =D43 * D62 -> 0.038033632 | E13: =E43 * E62 -> 0.036853463 | F13: =F43 * F62 -> 0.034127171 | G13: =G43 * G62 -> 0.034265194 | H13: =H43 * H62 -> 0.034015561 | I13: =I43 * I62 -> 0.037287675 | J13: =J43 * J62 -> 0.038088284 | K13: =K43 * K62 -> 0.042323748 | ... M13: =M43 * M62 -> 0.042525713
B14: 8 | C14: Finance and insurance, and real estate and rental and leasing | D14: =D43 * D63 -> 0.040211064 | E14: =E43 * E63 -> 0.039231726 | F14: =F43 * F63 -> 0.036402789 | G14: =G43 * G63 -> 0.034850945 | H14: =H43 * H63 -> 0.036510898 | I14: =I43 * I63 -> 0.03656242 | J14: =J43 * J63 -> 0.037522329 | K14: =K43 * K63 -> 0.038938553 | ... M14: =M43 * M63 -> 0.042201901
B15: 9 | C15: Professional, scientific, and management, and administrative and waste management services | D15: =D43 * D64 -> 0.044781339 | E15: =E43 * E64 -> 0.045444582 | F15: =F43 * F64 -> 0.044912712 | G15: =G43 * G64 -> 0.043296293 | H15: =H43 * H64 -> 0.042126226 | I15: =I43 * I64 -> 0.04332289 | J15: =J43 * J64 -> 0.044821449 | K15: =K43 * K64 -> 0.047946536 | ... M15: =M43 * M64 -> 0.051221975
B16: 10 | C16: Educational services, and health care and social assistance | D16: =D43 * D65 -> 0.022884449 | E16: =E43 * E65 -> 0.021786293 | F16: =F43 * F65 -> 0.02008109 | G16: =G43 * G65 -> 0.018833962 | H16: =H43 * H65 -> 0.017754188 | I16: =I43 * I65 -> 0.018441034 | J16: =J43 * J65 -> 0.018405692 | K16: =K43 * K65 -> 0.019508314 | ... M16: =M43 * M65 -> 0.020631552
B17: 11 | C17: Arts, entertainment, and recreation, and accommodation and food services | D17: =D43 * D66 -> 0.015176955 | E17: =E43 * E66 -> 0.015107751 | F17: =F43 * F66 -> 0.013348207 | G17: =G43 * G66 -> 0.012373047 | H17: =H43 * H66 -> 0.012193943 | I17: =I43 * I66 -> 0.012977773 | J17: =J43 * J66 -> 0.012000781 | K17: =K43 * K66 -> 0.012644576 | ... M17: =M43 * M66 -> 0.013584306
B18: 12 | C18: Other services (except public administration) | D18: =D43 * D67 -> 0.0370407 | E18: =E43 * E67 -> 0.034843747 | F18: =F43 * F67 -> 0.031882408 | G18: =G43 * G67 -> 0.031183405 | H18: =H43 * H67 -> 0.032072271 | I18: =I43 * I67 -> 0.028371682 | J18: =J43 * J67 -> 0.030468262 | K18: =K43 * K67 -> 0.032404195 | ... M18: =M43 * M67 -> 0.033843656
B19: 13 | C19: Public administration | D19: =D43 * D68 -> 0.0069048032 | E19: =E43 * E68 -> 0.0058160855 | F19: =F43 * F68 -> 0.0053210738 | G19: =G43 * G68 -> 0.0064269526 | H19: =H43 * H68 -> 0.0079629037 | I19: =I43 * I68 -> 0.010351308 | J19: =J43 * J68 -> 0.010653504 | K19: =K43 * K68 -> 0.011333888 | ... M19: =M43 * M68 -> 0.011623328
B20: 14 | C20: Armed forces | D20: =D43 * D69 -> 0.0033953424 | E20: =E43 * E69 -> 0.0049739852 | F20: =F43 * F69 -> 0.0041627729 | G20: =G43 * G69 -> 0.0039087889 | H20: =H43 * H69 -> 0.0039345717 | I20: =I43 * I69 -> 0.007077675 | J20: =J43 * J69 -> 0.0080526989 | K20: =K43 * K69 -> 0.011119043 | ... M20: =M43 * M69 -> 0.008817924
B22: Share of Telecommute by Industry Classification
D23: 2010 | E23: 2011 | F23: 2012 | G23: 2013 | H23: 2014 | I23: 2015 | J23: 2016 | K23: 2017 | L23: 2018 | M23: 2019
B24: 0 | C24: Share of Work At Home | D24: =D44 * D55 -> 0.02188431 | E24: =E44 * E55 -> 0.023317437 | F24: =F44 * F55 -> 0.023317753 | G24: =G44 * G55 -> 0.02528403 | H24: =H44 * H55 -> 0.0266197 | I24: =I44 * I55 -> 0.028966157 | J24: =J44 * J55 -> 0.029703592 | K24: =K44 * K55 -> 0.032081021 | ... M24: =M44 * M55 -> 0.036494763
B25: 1 | C25: Agriculture, forestry, fishing and hunting, and mining | D25: =D44 * D56 -> 0.026206147 | E25: =E44 * E56 -> 0.025433575 | F25: =F44 * F56 -> 0.026273784 | G25: =G44 * G56 -> 0.023600814 | H25: =H44 * H56 -> 0.028921821 | I25: =I44 * I56 -> 0.031293877 | J25: =J44 * J56 -> 0.030736568 | K25: =K44 * K56 -> 0.03025745 | ... M25: =M44 * M56 -> 0.035668848
B26: 2 | C26: Construction | D26: =D44 * D57 -> 0.018482708 | E26: =E44 * E57 -> 0.019615086 | F26: =F44 * F57 -> 0.020461637 | G26: =G44 * G57 -> 0.021828997 | H26: =H44 * H57 -> 0.022485991 | I26: =I44 * I57 -> 0.021467528 | J26: =J44 * J57 -> 0.023869535 | K26: =K44 * K57 -> 0.02456223 | ... M26: =M44 * M57 -> 0.032985464
B27: 3 | C27: Manufacturing | D27: =D44 * D58 -> 0.011431216 | E27: =E44 * E58 -> 0.012555438 | F27: =F44 * F58 -> 0.013571636 | G27: =G44 * G58 -> 0.016072778 | H27: =H44 * H58 -> 0.017424163 | I27: =I44 * I58 -> 0.020198235 | J27: =J44 * J58 -> 0.02046688 | K27: =K44 * K58 -> 0.021340704 | ... M27: =M44 * M58 -> 0.022087649
B28: 4 | C28: Wholesale trade | D28: =D44 * D59 -> 0.022697127 | E28: =E44 * E59 -> 0.025861717 | F28: =F44 * F59 -> 0.025656599 | G28: =G44 * G59 -> 0.02958429 | H28: =H44 * H59 -> 0.029295458 | I28: =I44 * I59 -> 0.031858416 | J28: =J44 * J59 -> 0.031633855 | K28: =K44 * K59 -> 0.034396087 | ... M28: =M44 * M59 -> 0.036539767
B29: 5 | C29: Retail trade | D29: =D44 * D60 -> 0.01487612 | E29: =E44 * E60 -> 0.015311434 | F29: =F44 * F60 -> 0.015586067 | G29: =G44 * G60 -> 0.01699494 | H29: =H44 * H60 -> 0.019630008 | I29: =I44 * I60 -> 0.020989126 | J29: =J44 * J60 -> 0.022750597 | K29: =K44 * K60 -> 0.025875945 | ... M29: =M44 * M60 -> 0.029844569
B30: 6 | C30: Transportation and warehousing, and utilities | D30: =D44 * D61 -> 0.020245555 | E30: =E44 * E61 -> 0.022660959 | F30: =F44 * F61 -> 0.023152252 | G30: =G44 * G61 -> 0.028506959 | H30: =H44 * H61 -> 0.028249554 | I30: =I44 * I61 -> 0.029665013 | J30: =J44 * J61 -> 0.029980794 | K30: =K44 * K61 -> 0.03371426 | ... M30: =M44 * M61 -> 0.03306352
B31: 7 | C31: Information | D31: =D44 * D62 -> 0.034456294 | E31: =E44 * E62 -> 0.036386714 | F31: =F44 * F62 -> 0.035106607 | G31: =G44 * G62 -> 0.039075013 | H31: =H44 * H62 -> 0.040734418 | I31: =I44 * I62 -> 0.047595949 | J31: =J44 * J62 -> 0.048273606 | K31: =K44 * K62 -> 0.054066736 | ... M31: =M44 * M62 -> 0.05819887
B32: 8 | C32: Finance and insurance, and real estate and rental and leasing | D32: =D44 * D63 -> 0.036428923 | E32: =E44 * E63 -> 0.038734856 | F32: =F44 * F63 -> 0.037447534 | G32: =G44 * G63 -> 0.039742987 | H32: =H44 * H63 -> 0.043722641 | I32: =I44 * I63 -> 0.046670194 | J32: =J44 * J63 -> 0.047556308 | K32: =K44 * K63 -> 0.049742296 | ... M32: =M44 * M63 -> 0.057755715
B33: 9 | C33: Professional, scientific, and management, and administrative and waste management services | D33: =D44 * D64 -> 0.040569331 | E33: =E44 * E64 -> 0.044869026 | F33: =F44 * F64 -> 0.046201688 | G33: =G44 * G64 -> 0.049373812 | H33: =H44 * H64 -> 0.050447126 | I33: =I44 * I64 -> 0.055299614 | J33: =J44 * J64 -> 0.056807312 | K33: =K44 * K64 -> 0.061249601 | ... M33: =M44 * M64 -> 0.070100203
B34: 10 | C34: Educational services, and health care and social assistance | D34: =D44 * D65 -> 0.020732002 | E34: =E44 * E65 -> 0.021510369 | F34: =F44 * F65 -> 0.020657409 | G34: =G44 * G65 -> 0.021477693 | H34: =H44 * H65 -> 0.021261049 | I34: =I44 * I65 -> 0.023539105 | J34: =J44 * J65 -> 0.023327624 | K34: =K44 * K65 -> 0.024921017 | ... M34: =M44 * M65 -> 0.028235459
B35: 11 | C35: Arts, entertainment, and recreation, and accommodation and food services | D35: =D44 * D66 -> 0.013749453 | E35: =E44 * E66 -> 0.014916411 | F35: =F44 * F66 -> 0.013731295 | G35: =G44 * G66 -> 0.014109857 | H35: =H44 * H66 -> 0.014602528 | I35: =I44 * I66 -> 0.016565512 | J35: =J44 * J66 -> 0.015209952 | K35: =K44 * K66 -> 0.016152892 | ... M35: =M44 * M66 -> 0.0185909
B36: 12 | C36: Other services (except public administration) | D36: =D44 * D67 -> 0.033556755 | E36: =E44 * E67 -> 0.034402451 | F36: =F44 * F67 -> 0.03279742 | G36: =G44 * G67 -> 0.035560633 | H36: =H44 * H67 -> 0.038407283 | I36: =I44 * I67 -> 0.036215107 | J36: =J44 * J67 -> 0.038615887 | K36: =K44 * K67 -> 0.041394941 | ... M36: =M44 * M67 -> 0.04631698
B37: 13 | C37: Public administration | D37: =D44 * D68 -> 0.0062553567 | E37: =E44 * E68 -> 0.0057424248 | F37: =F44 * F68 -> 0.0054737865 | G37: =G44 * G68 -> 0.0073291066 | H37: =H44 * H68 -> 0.0095357605 | I37: =I44 * I68 -> 0.013212954 | J37: =J44 * J68 -> 0.013502395 | K37: =K44 * K68 -> 0.014478546 | ... M37: =M44 * M68 -> 0.015907189
B38: 14 | C38: Armed forces | D38: =D44 * D69 -> 0.003075986 | E38: =E44 * E69 -> 0.0049109897 | F38: =F44 * F69 -> 0.0042822427 | G38: =G44 * G69 -> 0.0044574672 | H38: =H44 * H69 -> 0.0047117401 | I38: =I44 * I69 -> 0.0090343165 | J38: =J44 * J69 -> 0.0102061 | K38: =K44 * K69 -> 0.014204091 | ... M38: =M44 * M69 -> 0.012067833
B41: Share of Work At Home by HBJ & Telecommute
D42: 2010 | E42: 2011 | F42: 2012 | G42: 2013 | H42: 2014 | I42: 2015 | J42: 2016 | K42: 2017 | L42: 2018 | M42: 2019
C43: Home-Based-Job | D43: =D48/D50 -> 0.52467472 | E43: =E48/E50 -> 0.50318643 | F43: =F48/F50 -> 0.4929266 | G43: =G48/G50 -> 0.46720885 | H43: =H48/H50 -> 0.4550578 | I43: =I48/I50 -> 0.43927996 | J43: =J48/J50 -> 0.44103115 | K43: =K48/K50 -> 0.43908638 | ... M43: =M48/M50 -> 0.42219795
C44: Telecommute | D44: =D49/D50 -> 0.47532528 | E44: =E49/E50 -> 0.49681357 | F44: =F49/F50 -> 0.5070734 | G44: =G49/G50 -> 0.53279115 | H44: =H49/H50 -> 0.5449422 | I44: =I49/I50 -> 0.56072004 | J44: =J49/J50 -> 0.55896885 | K44: =K49/K50 -> 0.56091362 | ... M44: =M49/M50 -> 0.57780205
C45: Total Work At Home | D45: =SUM(D43:D44) -> 1 | E45: =SUM(E43:E44) -> 1 | F45: =SUM(F43:F44) -> 1 | G45: =SUM(G43:G44) -> 1 | H45: =SUM(H43:H44) -> 1 | I45: =SUM(I43:I44) -> 1 | J45: =SUM(J43:J44) -> 1 | K45: =SUM(K43:K44) -> 1 | ... M45: =SUM(M43:M44) -> 1
...

Sheet WAH_byCounty
B1: Share of Work At Home Charts by County | BK1: Share of Work At Home Charts | CI1: Calculate Share: Work At Home | CV1: Calculate Share: Telecommute | DI1: Calculate Share: Home-Based-Job | DV1: Calculate Telecommute Workers | EI1: Calculate Home-Based-Job Workers | EW1: Extract Worker Tables: Total Workers, Worked at Home, Self-employed in own incorporated & not incorporated business
CP4: Work-At-Home Share of Total Workers | DC4: Telecommute Worker Share of Total Workers | DP4: Home-Based-Job Worker Share of Total Workers | DW4: Telecommute Job Workers | EC4: Workers | EJ4: Home-Based Job Workers | EP4: Workers | EW4: 100 | EX4: Total Workers | FD4: Workers | FJ4: 700 | FK4: Worked at home | FQ4: Workers | FW4: 712 | FX4: Self-employed in own incorporated business workers | GD4: Workers | GJ4: 760 | GK4: Self-employed in own not incorporated business workers | GQ4: Workers
AX5: 101 | AY5: Wasatch Front | DW5: (Non-Self-Employed Workers Who Work At Home) | EJ5: (Self-Employed Workers Who Work At Home)
AZ6: 2010 | BA6: 2011 | BB6: 2012 | BC6: 2013 | BD6: 2014 | BE6: 2015 | BF6: 2016 | BG6: 2017 | BH6: 2018 | BI6: 2019 | CK6: 2010 | CL6: 2011 | CM6: 2012 | CN6: 2013 | CO6: 2014 | CP6: 2015 | CQ6: 2016 | CR6: 2017 | CS6: 2018 | CT6: 2019 | CX6: 2010 | CY6: 2011 | CZ6: 2012 | DA6: 2013 | DB6: 2014 | DC6: 2015 | DD6: 2016 | DE6: 2017 | DF6: 2018 | DG6: 2019 | DK6: 2010 | DL6: 2011 | DM6: 2012 | DN6: 2013 | DO6: 2014 | DP6: 2015 | DQ6: 2016 | DR6: 2017 | DS6: 2018 | DT6: 2019 | DX6: 2010 | DY6: 2011 | DZ6: 2012 | EA6: 2013 | EB6: 2014 | EC6: 2015 | ED6: 2016 | EE6: 2017 | EF6: 2018 | EG6: 2019 | EK6: 2010 | EL6: 2011 | EM6: 2012 | EN6: 2013 | EO6: 2014 | EP6: 2015 | EQ6: 2016 | ER6: 2017 | ES6: 2018 | ET6: 2019 | EY6: 2010 | EZ6: 2011 | FA6: 2012 | FB6: 2013 | FC6: 2014 | FD6: 2015 | FE6: 2016 | FF6: 2017 | FG6: 2018 | FH6: 2019 | FL6: 2010 | FM6: 2011 | FN6: 2012 | FO6: 2013 | FP6: 2014 | FQ6: 2015 | FR6: 2016 | FS6: 2017 | FT6: 2018 | FU6: 2019 | FY6: 2010 | FZ6: 2011 | GA6: 2012 | GB6: 2013 | GC6: 2014 | GD6: 2015 | GE6: 2016 | GF6: 2017 | GG6: 2018 | GH6: 2019 | GL6: 2010 | GM6: 2011 | GN6: 2012 | GO6: 2013 | GP6: 2014 | GQ6: 2015 | GR6: 2016 | GS6: 2017 | GT6: 2018 | GU6: 2019
AY7: Home-Based-Job | AZ7: =INDEX($DK$7:$DT$13, MATCH(AY5, $DJ$7:$DJ$13,0), MATCH(AZ$6, $DK$6:$DT$6, 0)) -> 0.024156393 | BA7: =INDEX($DK$7:$DT$13, MATCH(AY5, $DJ$7:$DJ$13,0), MATCH(BA$6, $DK$6:$DT$6, 0)) -> 0.023616541 | BB7: =INDEX($DK$7:$DT$13, MATCH(AY5, $DJ$7:$DJ$13,0), MATCH(BB$6, $DK$6:$DT$6, 0)) -> 0.022667213 | BC7: =INDEX($DK$7:$DT$13, MATCH(AY5, $DJ$7:$DJ$13,0), MATCH(BC$6, $DK$6:$DT$6, 0)) -> 0.022171769 | BD7: =INDEX($DK$7:$DT$13, MATCH(AY5, $DJ$7:$DJ$13,0), MATCH(BD$6, $DK$6:$DT$6, 0)) -> 0.022228968 | BE7: =INDEX($DK$7:$DT$13, MATCH(AY5, $DJ$7:$DJ$13,0), MATCH(BE$6, $DK$6:$DT$6, 0)) -> 0.022692701 | BF7: =INDEX($DK$7:$DT$13, MATCH(AY5, $DJ$7:$DJ$13,0), MATCH(BF$6, $DK$6:$DT$6, 0)) -> 0.023436385 | BG7: =INDEX($DK$7:$DT$13, MATCH(AY5, $DJ$7:$DJ$13,0), MATCH(BG$6, $DK$6:$DT$6, 0)) -> 0.025113206 | BH7: =INDEX($DK$7:$DT$13, MATCH(AY5, $DJ$7:$DJ$13,0), MATCH(BH$6, $DK$6:$DT$6, 0)) -> 0.026391708 | BI7: =INDEX($DK$7:$DT$13, MATCH(AY5, $DJ$7:$DJ$13,0), MATCH(BI$6, $DK$6:$DT$6, 0)) -> 0.026666597 | BJ7: =BI7/BI9 -> 0.42219795 | CI7: 101 | CJ7: Wasatch Front | CK7: =CX7 + DK7 -> 0.046040703 | CL7: =CY7 + DL7 -> 0.046933978 | CM7: =CZ7 + DM7 -> 0.045984966 | CN7: =DA7 + DN7 -> 0.047455799 | CO7: =DB7 + DO7 -> 0.048848668 | CP7: =DC7 + DP7 -> 0.051658859 | CQ7: =DD7 + DQ7 -> 0.053139977 | CR7: =DE7 + DR7 -> 0.057194228 | ... CT7: =DG7 + DT7 -> 0.06316136 | CV7: =$CI7 -> 101 | CW7: =$CJ7 -> Wasatch Front | CX7: =IFERROR(DX7/EY7, 0) -> 0.02188431 | CY7: =IFERROR(DY7/EZ7, 0) -> 0.023317437 | CZ7: =IFERROR(DZ7/FA7, 0) -> 0.023317753 | DA7: =IFERROR(EA7/FB7, 0) -> 0.02528403 | DB7: =IFERROR(EB7/FC7, 0) -> 0.0266197 | DC7: =IFERROR(EC7/FD7, 0) -> 0.028966157 | DD7: =IFERROR(ED7/FE7, 0) -> 0.029703592 | DE7: =IFERROR(EE7/FF7, 0) -> 0.032081021 | ... DG7: =IFERROR(EG7/FH7, 0) -> 0.036494763 | DI7: =$CI7 -> 101 | DJ7: =$CJ7 -> Wasatch Front | DK7: =IFERROR(EK7/EY7, 0) -> 0.024156393 | DL7: =IFERROR(EL7/EZ7, 0) -> 0.023616541 | DM7: =IFERROR(EM7/FA7, 0) -> 0.022667213 | DN7: =IFERROR(EN7/FB7, 0) -> 0.022171769 | DO7: =IFERROR(EO7/FC7, 0) -> 0.022228968 | DP7: =IFERROR(EP7/FD7, 0) -> 0.022692701 | DQ7: =IFERROR(EQ7/FE7, 0) -> 0.023436385 | DR7: =IFERROR(ER7/FF7, 0) -> 0.025113206 | ... DT7: =IFERROR(ET7/FH7, 0) -> 0.026666597 | DV7: =$CI7 -> 101 | DW7: =$CJ7 -> Wasatch Front | DX7: =SUM(DX8:DX11) -> 20458 | DY7: =SUM(DY8:DY11) -> 22140 | DZ7: =SUM(DZ8:DZ11) -> 22474 | EA7: =SUM(EA8:EA11) -> 24567 | EB7: =SUM(EB8:EB11) -> 26397 | EC7: =SUM(EC8:EC11) -> 29592 | ED7: =SUM(ED8:ED11) -> 31224 | EE7: =SUM(EE8:EE11) -> 34651 | ... EG7: =SUM(EG8:EG11) -> 41793 | EI7: =$CI7 -> 101 | EJ7: =$CJ7 -> Wasatch Front | EK7: =SUM(EK8:EK11) -> 22582 | EL7: =SUM(EL8:EL11) -> 22424 | EM7: =SUM(EM8:EM11) -> 21847 | EN7: =SUM(EN8:EN11) -> 21543 | EO7: =SUM(EO8:EO11) -> 22043 | EP7: =SUM(EP8:EP11) -> 23183 | EQ7: =SUM(EQ8:EQ11) -> 24636 | ER7: =SUM(ER8:ER11) -> 27125 | ... ET7: =SUM(ET8:ET11) -> 30538 | EW7: 101 | EX7: Wasatch Front | EY7: 934825 | EZ7: 949504 | FA7: 963815 | FB7: 971641 | FC7: 991634 | FD7: 1021606 | FE7: 1051186 | FF7: 1080109 | FG7: 1110955 | FH7: 1145178 | FJ7: 101 | FK7: Wasatch Front | FL7: 43040 | FM7: 44564 | FN7: 44321 | FO7: 46110 | FP7: 48440 | FQ7: 52775 | FR7: 55860 | FS7: 61776 | FT7: 67021 | FU7: 72331 | FW7: 101 | FX7: Wasatch Front | FY7: 6818 | FZ7: 6858 | GA7: 6765 | GB7: 6729 | GC7: 7273 | GD7: 8231 | GE7: 8891 | GF7: 10376 | GG7: 11410 | GH7: 11780 | GJ7: 101 | GK7: Wasatch Front | GL7: 15764 | GM7: 15566 | GN7: 15082 | GO7: 14814 | GP7: 14770 | GQ7: 14952 | GR7: 15745 | GS7: 16749 | GT7: 17910 | GU7: 18758
AY8: Telecommute | AZ8: =INDEX($CX$7:$DG$13, MATCH(AY5, $CW$7:$CW$13,0), MATCH(AZ$6, $CX$6:$DG$6, 0)) -> 0.02188431 | BA8: =INDEX($CX$7:$DG$13, MATCH(AY5, $CW$7:$CW$13,0), MATCH(BA$6, $CX$6:$DG$6, 0)) -> 0.023317437 | BB8: =INDEX($CX$7:$DG$13, MATCH(AY5, $CW$7:$CW$13,0), MATCH(BB$6, $CX$6:$DG$6, 0)) -> 0.023317753 | BC8: =INDEX($CX$7:$DG$13, MATCH(AY5, $CW$7:$CW$13,0), MATCH(BC$6, $CX$6:$DG$6, 0)) -> 0.02528403 | BD8: =INDEX($CX$7:$DG$13, MATCH(AY5, $CW$7:$CW$13,0), MATCH(BD$6, $CX$6:$DG$6, 0)) -> 0.0266197 | BE8: =INDEX($CX$7:$DG$13, MATCH(AY5, $CW$7:$CW$13,0), MATCH(BE$6, $CX$6:$DG$6, 0)) -> 0.028966157 | BF8: =INDEX($CX$7:$DG$13, MATCH(AY5, $CW$7:$CW$13,0), MATCH(BF$6, $CX$6:$DG$6, 0)) -> 0.029703592 | BG8: =INDEX($CX$7:$DG$13, MATCH(AY5, $CW$7:$CW$13,0), MATCH(BG$6, $CX$6:$DG$6, 0)) -> 0.032081021 | BH8: =INDEX($CX$7:$DG$13, MATCH(AY5, $CW$7:$CW$13,0), MATCH(BH$6, $CX$6:$DG$6, 0)) -> 0.033935668 | BI8: =INDEX($CX$7:$DG$13, MATCH(AY5, $CW$7:$CW$13,0), MATCH(BI$6, $CX$6:$DG$6, 0)) -> 0.036494763 | BJ8: =BI8/BI9 -> 0.57780205 | CI8: 57 | CJ8: Weber | CK8: =CX8 + DK8 -> 0.031489478 | CL8: =CY8 + DL8 -> 0.03423657 | CM8: =CZ8 + DM8 -> 0.032300393 | CN8: =DA8 + DN8 -> 0.033006032 | CO8: =DB8 + DO8 -> 0.035722947 | CP8: =DC8 + DP8 -> 0.041130466 | CQ8: =DD8 + DQ8 -> 0.041244982 | CR8: =DE8 + DR8 -> 0.046252189 | ... CT8: =DG8 + DT8 -> 0.054330715 | CV8: =$CI8 -> 57 | CW8: =$CJ8 -> Weber | CX8: =IFERROR(DX8/EY8, 0) -> 0.014684716 | CY8: =IFERROR(DY8/EZ8, 0) -> 0.016552351 | CZ8: =IFERROR(DZ8/FA8, 0) -> 0.016069374 | DA8: =IFERROR(EA8/FB8, 0) -> 0.017601949 | DB8: =IFERROR(EB8/FC8, 0) -> 0.018449083 | DC8: =IFERROR(EC8/FD8, 0) -> 0.022089778 | DD8: =IFERROR(ED8/FE8, 0) -> 0.022162555 | DE8: =IFERROR(EE8/FF8, 0) -> 0.024474606 | ... DG8: =IFERROR(EG8/FH8, 0) -> 0.031508848 | DI8: =$CI8 -> 57 | DJ8: =$CJ8 -> Weber | DK8: =IFERROR(EK8/EY8, 0) -> 0.016804761 | DL8: =IFERROR(EL8/EZ8, 0) -> 0.017684219 | DM8: =IFERROR(EM8/FA8, 0) -> 0.016231019 | DN8: =IFERROR(EN8/FB8, 0) -> 0.015404084 | DO8: =IFERROR(EO8/FC8, 0) -> 0.017273863 | DP8: =IFERROR(EP8/FD8, 0) -> 0.019040688 | DQ8: =IFERROR(EQ8/FE8, 0) -> 0.019082427 | DR8: =IFERROR(ER8/FF8, 0) -> 0.021777583 | ... DT8: =IFERROR(ET8/FH8, 0) -> 0.022821867 | DV8: =$CI8 -> 57 | DW8: =$CJ8 -> Weber | DX8: =DX45 -> 1510 | DY8: =DY45 -> 1711 | DZ8: =DZ45 -> 1690 | EA8: =EA45 -> 1850 | EB8: =EB45 -> 1978 | EC8: =EC45 -> 2398 | ED8: =ED45 -> 2468 | EE8: =EE45 -> 2795 | ... EG8: =EG45 -> 3823 | EI8: =$CI8 -> 57 | EJ8: =$CJ8 -> Weber | EK8: =EK45 -> 1728 | EL8: =EL45 -> 1828 | EM8: =EM45 -> 1707 | EN8: =EN45 -> 1619 | EO8: =EO45 -> 1852 | EP8: =EP45 -> 2067 | EQ8: =EQ45 -> 2125 | ER8: =ER45 -> 2487 | ... ET8: =ET45 -> 2769 | EW8: 57 | EX8: Weber | EY8: 102828 | EZ8: 103369 | FA8: 105169 | FB8: 105102 | FC8: 107214 | FD8: 108557 | FE8: 111359 | FF8: 114200 | FG8: 117743 | FH8: 121331 | FJ8: 57 | FK8: Weber | FL8: 3238 | FM8: 3539 | FN8: 3397 | FO8: 3469 | FP8: 3830 | FQ8: 4465 | FR8: 4593 | FS8: 5282 | FT8: 5765 | FU8: 6592 | FW8: 57 | FX8: Weber | FY8: 537 | FZ8: 582 | GA8: 573 | GB8: 534 | GC8: 666 | GD8: 846 | GE8: 923 | GF8: 1103 | GG8: 1229 | GH8: 1324 | GJ8: 57 | GK8: Weber | GL8: 1191 | GM8: 1246 | GN8: 1134 | GO8: 1085 | GP8: 1186 | GQ8: 1221 | GR8: 1202 | GS8: 1384 | GT8: 1338 | GU8: 1445
AY9: Total Work At Home | AZ9: =SUM(AZ7:AZ8) -> 0.046040703 | BA9: =SUM(BA7:BA8) -> 0.046933978 | BB9: =SUM(BB7:BB8) -> 0.045984966 | BC9: =SUM(BC7:BC8) -> 0.047455799 | BD9: =SUM(BD7:BD8) -> 0.048848668 | BE9: =SUM(BE7:BE8) -> 0.051658859 | BF9: =SUM(BF7:BF8) -> 0.053139977 | BG9: =SUM(BG7:BG8) -> 0.057194228 | ... BI9: =SUM(BI7:BI8) -> 0.06316136 | CI9: 11 | CJ9: Davis | CK9: =CX9 + DK9 -> 0.044575681 | CL9: =CY9 + DL9 -> 0.047153855 | CM9: =CZ9 + DM9 -> 0.045106261 | CN9: =DA9 + DN9 -> 0.047290962 | CO9: =DB9 + DO9 -> 0.049455062 | CP9: =DC9 + DP9 -> 0.052148088 | CQ9: =DD9 + DQ9 -> 0.05199921 | CR9: =DE9 + DR9 -> 0.055483498 | ... CT9: =DG9 + DT9 -> 0.058858596 | CV9: =$CI9 -> 11 | CW9: =$CJ9 -> Davis | CX9: =IFERROR(DX9/EY9, 0) -> 0.020632471 | CY9: =IFERROR(DY9/EZ9, 0) -> 0.025479704 | CZ9: =IFERROR(DZ9/FA9, 0) -> 0.023610364 | DA9: =IFERROR(EA9/FB9, 0) -> 0.025847373 | DB9: =IFERROR(EB9/FC9, 0) -> 0.028318695 | DC9: =IFERROR(EC9/FD9, 0) -> 0.031001316 | DD9: =IFERROR(ED9/FE9, 0) -> 0.03059087 | DE9: =IFERROR(EE9/FF9, 0) -> 0.034743804 | ... DG9: =IFERROR(EG9/FH9, 0) -> 0.036449019 | DI9: =$CI9 -> 11 | DJ9: =$CJ9 -> Davis | DK9: =IFERROR(EK9/EY9, 0) -> 0.02394321 | DL9: =IFERROR(EL9/EZ9, 0) -> 0.021674151 | DM9: =IFERROR(EM9/FA9, 0) -> 0.021495896 | DN9: =IFERROR(EN9/FB9, 0) -> 0.021443589 | DO9: =IFERROR(EO9/FC9, 0) -> 0.021136367 | DP9: =IFERROR(EP9/FD9, 0) -> 0.021146772 | DQ9: =IFERROR(EQ9/FE9, 0) -> 0.021408339 | DR9: =IFERROR(ER9/FF9, 0) -> 0.020739694 | ... DT9: =IFERROR(ET9/FH9, 0) -> 0.022409577 | DV9: =$CI9 -> 11 | DW9: =$CJ9 -> Davis | DX9: =DX22 -> 2767 | DY9: =DY22 -> 3495 | DZ9: =DZ22 -> 3294 | EA9: =EA22 -> 3639 | EB9: =EB22 -> 4069 | EC9: =EC22 -> 4593 | ED9: =ED22 -> 4644 | EE9: =EE22 -> 5411 | ... EG9: =EG22 -> 5992 | EI9: =$CI9 -> 11 | EJ9: =$CJ9 -> Davis | EK9: =EK22 -> 3211 | EL9: =EL22 -> 2973 | EM9: =EM22 -> 2999 | EN9: =EN22 -> 3019 | EO9: =EO22 -> 3037 | EP9: =EP22 -> 3133 | EQ9: =EQ22 -> 3250 | ER9: =ER22 -> 3230 | ... ET9: =ET22 -> 3684 | EW9: 11 | EX9: Davis | EY9: 134109 | EZ9: 137168 | FA9: 139515 | FB9: 140788 | FC9: 143686 | FD9: 148155 | FE9: 151810 | FF9: 155740 | FG9: 158992 | FH9: 164394 | FJ9: 11 | FK9: Davis | FL9: 5978 | FM9: 6468 | FN9: 6293 | FO9: 6658 | FP9: 7106 | FQ9: 7726 | FR9: 7894 | FS9: 8641 | FT9: 9265 | FU9: 9676 | FW9: 11 | FX9: Davis | FY9: 879 | FZ9: 805 | GA9: 781 | GB9: 798 | GC9: 832 | GD9: 957 | GE9: 1053 | GF9: 1218 | GG9: 1423 | GH9: 1626 | GJ9: 11 | GK9: Davis | GL9: 2332 | GM9: 2168 | GN9: 2218 | GO9: 2221 | GP9: 2205 | GQ9: 2176 | GR9: 2197 | GS9: 2012 | GT9: 2201 | GU9: 2058
CI10: 35 | CJ10: Salt Lake | CK10: =CX10 + DK10 -> 0.042931884 | CL10: =CY10 + DL10 -> 0.043507812 | CM10: =CZ10 + DM10 -> 0.043455383 | CN10: =DA10 + DN10 -> 0.04479927 | CO10: =DB10 + DO10 -> 0.046272278 | CP10: =DC10 + DP10 -> 0.049433922 | CQ10: =DD10 + DQ10 -> 0.051318901 | CR10: =DE10 + DR10 -> 0.055654606 | ... CT10: =DG10 + DT10 -> 0.06205852 | CV10: =$CI10 -> 35 | CW10: =$CJ10 -> Salt Lake | CX10: =IFERROR(DX10/EY10, 0) -> 0.020160525 | CY10: =IFERROR(DY10/EZ10, 0) -> 0.020714153 | CZ10: =IFERROR(DZ10/FA10, 0) -> 0.021753701 | DA10: =IFERROR(EA10/FB10, 0) -> 0.023663123 | DB10: =IFERROR(EB10/FC10, 0) -> 0.024920935 | DC10: =IFERROR(EC10/FD10, 0) -> 0.027333628 | DD10: =IFERROR(ED10/FE10, 0) -> 0.028398168 | DE10: =IFERROR(EE10/FF10, 0) -> 0.030665065 | ... DG10: =IFERROR(EG10/FH10, 0) -> 0.034882724 | DI10: =$CI10 -> 35 | DJ10: =$CJ10 -> Salt Lake | DK10: =IFERROR(EK10/EY10, 0) -> 0.022771358 | DL10: =IFERROR(EL10/EZ10, 0) -> 0.02279366 | DM10: =IFERROR(EM10/FA10, 0) -> 0.021701682 | DN10: =IFERROR(EN10/FB10, 0) -> 0.021136147 | DO10: =IFERROR(EO10/FC10, 0) -> 0.021351343 | DP10: =IFERROR(EP10/FD10, 0) -> 0.022100294 | DQ10: =IFERROR(EQ10/FE10, 0) -> 0.022920733 | DR10: =IFERROR(ER10/FF10, 0) -> 0.024989541 | ... DT10: =IFERROR(ET10/FH10, 0) -> 0.027175796 | DV10: =$CI10 -> 35 | DW10: =$CJ10 -> Salt Lake | DX10: =DX34 -> 9884 | DY10: =DY34 -> 10240 | DZ10: =DZ34 -> 10873 | EA10: =EA34 -> 11930 | EB10: =EB34 -> 12797 | EC10: =EC34 -> 14452 | ED10: =ED34 -> 15393 | EE10: =EE34 -> 17079 | ... EG10: =EG34 -> 20336 | EI10: =$CI10 -> 35 | EJ10: =$CJ10 -> Salt Lake | EK10: =EK34 -> 11164 | EL10: =EL34 -> 11268 | EM10: =EM34 -> 10847 | EN10: =EN34 -> 10656 | EO10: =EO34 -> 10964 | EP10: =EP34 -> 11685 | EQ10: =EQ34 -> 12424 | ER10: =ER34 -> 13918 | ... ET10: =ET34 -> 15843 | EW10: 35 | EX10: Salt Lake | EY10: 490265 | EZ10: 494348 | FA10: 499823 | FB10: 504160 | FC10: 513504 | FD10: 528726 | FE10: 542042 | FF10: 556953 | FG10: 569309 | FH10: 582982 | FJ10: 35 | FK10: Salt Lake | FL10: 21048 | FM10: 21508 | FN10: 21720 | FO10: 22586 | FP10: 23761 | FQ10: 26137 | FR10: 27817 | FS10: 30997 | FT10: 33696 | FU10: 36179 | FW10: 35 | FX10: Salt Lake | FY10: 3397 | FZ10: 3406 | GA10: 3293 | GB10: 3194 | GC10: 3560 | GD10: 4111 | GE10: 4474 | GF10: 5127 | GG10: 5687 | GH10: 5565 | GJ10: 35 | GK10: Salt Lake | GL10: 7767 | GM10: 7862 | GN10: 7554 | GO10: 7462 | GP10: 7404 | GQ10: 7574 | GR10: 7950 | GS10: 8791 | GT10: 9548 | GU10: 10278
AX11: 57 | AY11: Weber | CI11: 49 | CJ11: Utah | CK11: =CX11 + DK11 -> 0.061534608 | CL11: =CY11 + DL11 -> 0.060800768 | CM11: =CZ11 + DM11 -> 0.058871541 | CN11: =DA11 + DN11 -> 0.060458232 | CO11: =DB11 + DO11 -> 0.06048057 | CP11: =DC11 + DP11 -> 0.061172555 | CQ11: =DD11 + DQ11 -> 0.063242199 | CR11: =DE11 + DR11 -> 0.066567673 | ... CT11: =DG11 + DT11 -> 0.071920744 | CV11: =$CI11 -> 49 | CW11: =$CJ11 -> Utah | CX11: =IFERROR(DX11/EY11, 0) -> 0.03032901 | CY11: =IFERROR(DY11/EZ11, 0) -> 0.031190156 | CZ11: =IFERROR(DZ11/FA11, 0) -> 0.030172178 | DA11: =IFERROR(EA11/FB11, 0) -> 0.032257628 | DB11: =IFERROR(EB11/FC11, 0) -> 0.033239449 | DC11: =IFERROR(EC11/FD11, 0) -> 0.034505098 | DD11: =IFERROR(ED11/FE11, 0) -> 0.035446692 | DE11: =IFERROR(EE11/FF11, 0) -> 0.036988184 | ... DG11: =IFERROR(EG11/FH11, 0) -> 0.042109299 | DI11: =$CI11 -> 49 | DJ11: =$CJ11 -> Utah | DK11: =IFERROR(EK11/EY11, 0) -> 0.031205599 | DL11: =IFERROR(EL11/EZ11, 0) -> 0.029610612 | DM11: =IFERROR(EM11/FA11, 0) -> 0.028699363 | DN11: =IFERROR(EN11/FB11, 0) -> 0.028200604 | DO11: =IFERROR(EO11/FC11, 0) -> 0.027241121 | DP11: =IFERROR(EP11/FD11, 0) -> 0.026667457 | DQ11: =IFERROR(EQ11/FE11, 0) -> 0.027795508 | DR11: =IFERROR(ER11/FF11, 0) -> 0.029579489 | ... DT11: =IFERROR(ET11/FH11, 0) -> 0.029811445 | DV11: =$CI11 -> 49 | DW11: =$CJ11 -> Utah | DX11: =DX41 -> 6297 | DY11: =DY41 -> 6694 | DZ11: =DZ41 -> 6617 | EA11: =EA41 -> 7148 | EB11: =EB41 -> 7553 | EC11: =EC41 -> 8149 | ED11: =ED41 -> 8719 | EE11: =EE41 -> 9366 | ... EG11: =EG41 -> 11642 | EI11: =$CI11 -> 49 | EJ11: =$CJ11 -> Utah | EK11: =EK41 -> 6479 | EL11: =EL41 -> 6355 | EM11: =EM41 -> 6294 | EN11: =EN41 -> 6249 | EO11: =EO41 -> 6190 | EP11: =EP41 -> 6298 | EQ11: =EQ41 -> 6837 | ER11: =ER41 -> 7490 | ... ET11: =ET41 -> 8242 | EW11: 49 | EX11: Utah | EY11: 207623 | EZ11: 214619 | FA11: 219308 | FB11: 221591 | FC11: 227230 | FD11: 236168 | FE11: 245975 | FF11: 253216 | FG11: 264911 | FH11: 276471 | FJ11: 49 | FK11: Utah | FL11: 12776 | FM11: 13049 | FN11: 12911 | FO11: 13397 | FP11: 13743 | FQ11: 14447 | FR11: 15556 | FS11: 16856 | FT11: 18295 | FU11: 19884 | FW11: 49 | FX11: Utah | FY11: 2005 | FZ11: 2065 | GA11: 2118 | GB11: 2203 | GC11: 2215 | GD11: 2317 | GE11: 2441 | GF11: 2928 | GG11: 3071 | GH11: 3265 | GJ11: 49 | GK11: Utah | GL11: 4474 | GM11: 4290 | GN11: 4176 | GO11: 4046 | GP11: 3975 | GQ11: 3981 | GR11: 4396 | GS11: 4562 | GT11: 4823 | GU11: 4977
AZ12: 2010 | BA12: 2011 | BB12: 2012 | BC12: 2013 | BD12: 2014 | BE12: 2015 | BF12: 2016 | BG12: 2017 | BH12: 2018 | BI12: 2019 | CI12: 1049 | CJ12: State of Utah | CK12: =CX12 + DK12 -> 0.048247967 | CL12: =CY12 + DL12 -> 0.048146251 | CM12: =CZ12 + DM12 -> 0.047170408 | CN12: =DA12 + DN12 -> 0.048242532 | CO12: =DB12 + DO12 -> 0.048818053 | CP12: =DC12 + DP12 -> 0.051301419 | CQ12: =DD12 + DQ12 -> 0.053654326 | CR12: =DE12 + DR12 -> 0.057712073 | ... CT12: =DG12 + DT12 -> 0.065641119 | CV12: =$CI12 -> 1049 | CW12: =$CJ12 -> State of Utah | CX12: =IFERROR(DX12/EY12, 0) -> 0.022286052 | CY12: =IFERROR(DY12/EZ12, 0) -> 0.023168413 | CZ12: =IFERROR(DZ12/FA12, 0) -> 0.02324078 | DA12: =IFERROR(EA12/FB12, 0) -> 0.024825238 | DB12: =IFERROR(EB12/FC12, 0) -> 0.025823246 | DC12: =IFERROR(EC12/FD12, 0) -> 0.02787694 | DD12: =IFERROR(ED12/FE12, 0) -> 0.0291896 | DE12: =IFERROR(EE12/FF12, 0) -> 0.031481466 | ... DG12: =IFERROR(EG12/FH12, 0) -> 0.036790903 | DI12: =$CI12 -> 1049 | DJ12: =$CJ12 -> State of Utah | DK12: =IFERROR(EK12/EY12, 0) -> 0.025961915 | DL12: =IFERROR(EL12/EZ12, 0) -> 0.024977838 | DM12: =IFERROR(EM12/FA12, 0) -> 0.023929627 | DN12: =IFERROR(EN12/FB12, 0) -> 0.023417294 | DO12: =IFERROR(EO12/FC12, 0) -> 0.022994807 | DP12: =IFERROR(EP12/FD12, 0) -> 0.023424479 | DQ12: =IFERROR(EQ12/FE12, 0) -> 0.024464726 | DR12: =IFERROR(ER12/FF12, 0) -> 0.026230607 | ... DT12: =IFERROR(ET12/FH12, 0) -> 0.028850216 | DV12: =$CI12 -> 1049 | DW12: =$CJ12 -> State of Utah | DX12: =DX46 -> 27125 | DY12: =DY46 -> 28592 | DZ12: =DZ46 -> 29049 | EA12: =EA46 -> 31262 | EB12: =EB46 -> 33114 | EC12: =EC46 -> 36796 | ED12: =ED46 -> 39563 | EE12: =EE46 -> 43863 | ... EG12: =EG46 -> 54431 | EI12: =$CI12 -> 1049 | EJ12: =$CJ12 -> State of Utah | EK12: =EK46 -> 31599 | EL12: =EL46 -> 30825 | EM12: =EM46 -> 29910 | EN12: =EN46 -> 29489 | EO12: =EO46 -> 29487 | EP12: =EP46 -> 30919 | EQ12: =EQ46 -> 33159 | ER12: =ER46 -> 36547 | ... ET12: =ET46 -> 42683 | EW12: 1049 | EX12: State of Utah | EY12: 1217129 | EZ12: 1234094 | FA12: 1249915 | FB12: 1259283 | FC12: 1282333 | FD12: 1319944 | FE12: 1355380 | FF12: 1393296 | FG12: 1433444 | FH12: 1479469 | FJ12: 1049 | FK12: State of Utah | FL12: 58724 | FM12: 59417 | FN12: 58959 | FO12: 60751 | FP12: 62601 | FQ12: 67715 | FR12: 72722 | FS12: 80410 | FT12: 88266 | FU12: 97114 | FW12: 1049 | FX12: State of Utah | FY12: 9643 | FZ12: 9471 | GA12: 9504 | GB12: 9680 | GC12: 10254 | GD12: 11439 | GE12: 12195 | GF12: 13968 | GG12: 16082 | GH12: 16994 | GJ12: 1049 | GK12: State of Utah | GL12: 21956 | GM12: 21354 | GN12: 20406 | GO12: 19809 | GP12: 19233 | GQ12: 19480 | GR12: 20964 | GS12: 22579 | GT12: 23992 | GU12: 25689
AY13: Home-Based-Job | AZ13: =INDEX($DK$7:$DT$13, MATCH(AY11, $DJ$7:$DJ$13,0), MATCH(AZ$6, $DK$6:$DT$6, 0)) -> 0.016804761 | BA13: =INDEX($DK$7:$DT$13, MATCH(AY11, $DJ$7:$DJ$13,0), MATCH(BA$6, $DK$6:$DT$6, 0)) -> 0.017684219 | BB13: =INDEX($DK$7:$DT$13, MATCH(AY11, $DJ$7:$DJ$13,0), MATCH(BB$6, $DK$6:$DT$6, 0)) -> 0.016231019 | BC13: =INDEX($DK$7:$DT$13, MATCH(AY11, $DJ$7:$DJ$13,0), MATCH(BC$6, $DK$6:$DT$6, 0)) -> 0.015404084 | BD13: =INDEX($DK$7:$DT$13, MATCH(AY11, $DJ$7:$DJ$13,0), MATCH(BD$6, $DK$6:$DT$6, 0)) -> 0.017273863 | BE13: =INDEX($DK$7:$DT$13, MATCH(AY11, $DJ$7:$DJ$13,0), MATCH(BE$6, $DK$6:$DT$6, 0)) -> 0.019040688 | BF13: =INDEX($DK$7:$DT$13, MATCH(AY11, $DJ$7:$DJ$13,0), MATCH(BF$6, $DK$6:$DT$6, 0)) -> 0.019082427 | BG13: =INDEX($DK$7:$DT$13, MATCH(AY11, $DJ$7:$DJ$13,0), MATCH(BG$6, $DK$6:$DT$6, 0)) -> 0.021777583 | BH13: =INDEX($DK$7:$DT$13, MATCH(AY11, $DJ$7:$DJ$13,0), MATCH(BH$6, $DK$6:$DT$6, 0)) -> 0.021801721 | BI13: =INDEX($DK$7:$DT$13, MATCH(AY11, $DJ$7:$DJ$13,0), MATCH(BI$6, $DK$6:$DT$6, 0)) -> 0.022821867 | BJ13: =BI13/BI15 -> 0.42005461 | CI13: 1000 | CJ13: United States | CK13: =CX13 + DK13 -> 0.041360975 | CL13: =CY13 + DL13 -> 0.042224129 | CM13: =CZ13 + DM13 -> 0.042729813 | CN13: =DA13 + DN13 -> 0.043254384 | CO13: =DB13 + DO13 -> 0.043665739 | CP13: =DC13 + DP13 -> 0.044232594 | CQ13: =DD13 + DQ13 -> 0.045672811 | CR13: =DE13 + DR13 -> 0.047344292 | ... CT13: =DG13 + DT13 -> 0.051713986 | CV13: =$CI13 -> 1000 | CW13: =$CJ13 -> United States | CX13: =IFERROR(DX13/EY13, 0) -> 0.020312996 | CY13: =IFERROR(DY13/EZ13, 0) -> 0.021408025 | CZ13: =IFERROR(DZ13/FA13, 0) -> 0.022257295 | DA13: =IFERROR(EA13/FB13, 0) -> 0.023061732 | DB13: =IFERROR(EB13/FC13, 0) -> 0.023882179 | DC13: =IFERROR(EC13/FD13, 0) -> 0.024745544 | DD13: =IFERROR(ED13/FE13, 0) -> 0.025975568 | DE13: =IFERROR(EE13/FF13, 0) -> 0.027440342 | ... DG13: =IFERROR(EG13/FH13, 0) -> 0.031329077 | DI13: =$CI13 -> 1000 | DJ13: =$CJ13 -> United States | DK13: =IFERROR(EK13/EY13, 0) -> 0.021047979 | DL13: =IFERROR(EL13/EZ13, 0) -> 0.020816104 | DM13: =IFERROR(EM13/FA13, 0) -> 0.020472518 | DN13: =IFERROR(EN13/FB13, 0) -> 0.020192652 | DO13: =IFERROR(EO13/FC13, 0) -> 0.01978356 | DP13: =IFERROR(EP13/FD13, 0) -> 0.01948705 | DQ13: =IFERROR(EQ13/FE13, 0) -> 0.019697244 | DR13: =IFERROR(ER13/FF13, 0) -> 0.01990395 | ... DT13: =IFERROR(ET13/FH13, 0) -> 0.020384909 | DV13: =$CI13 -> 1000 | DW13: =$CJ13 -> United States | DX13: =DX47 -> 2828687 | DY13: =DY47 -> 2986167 | DZ13: =DZ47 -> 3113654 | EA13: =EA47 -> 3223722 | EB13: =EB47 -> 3375439 | EC13: =EC47 -> 3553984 | ED13: =ED47 -> 3788828 | EE13: =EE47 -> 4073026 | ... EG13: =EG47 -> 4785071 | EI13: =$CI13 -> 1000 | EJ13: =$CJ13 -> United States | EK13: =EK47 -> 2931037 | EL13: =EL47 -> 2903601 | EM13: =EM47 -> 2863975 | EN13: =EN47 -> 2822663 | EO13: =EO47 -> 2796152 | EP13: =EP47 -> 2798753 | EQ13: =EQ47 -> 2873064 | ER13: =ER47 -> 2954384 | ... ET13: =ET47 -> 3113505 | EW13: 1000 | EX13: United States | EY13: 139255035 | EZ13: 139488206 | FA13: 139893639 | FB13: 139786639 | FC13: 141337148 | FD13: 143621171 | FE13: 145861221 | FF13: 148432042 | FG13: 150571044 | FH13: 152735781 | FJ13: 1000 | FK13: United States | FL13: 5759724 | FM13: 5889768 | FN13: 5977629 | FO13: 6046385 | FP13: 6171591 | FQ13: 6352737 | FR13: 6661892 | FS13: 7027410 | FT13: 7422933 | FU13: 7898576 | FW13: 1000 | FX13: United States | FY13: 815897 | FZ13: 825316 | GA13: 834222 | GB13: 831600 | GC13: 835384 | GD13: 848753 | GE13: 895042 | GF13: 939971 | GG13: 986852 | GH13: 1017531 | GJ13: 1000 | GK13: United States | GL13: 2115140 | GM13: 2078285 | GN13: 2029753 | GO13: 1991063 | GP13: 1960768 | GQ13: 1950000 | GR13: 1978022 | GS13: 2014413 | GT13: 2061804 | GU13: 2095974
AY14: Telecommute | AZ14: =INDEX($CX$7:$DG$13, MATCH(AY11, $CW$7:$CW$13,0), MATCH(AZ$6, $CX$6:$DG$6, 0)) -> 0.014684716 | BA14: =INDEX($CX$7:$DG$13, MATCH(AY11, $CW$7:$CW$13,0), MATCH(BA$6, $CX$6:$DG$6, 0)) -> 0.016552351 | BB14: =INDEX($CX$7:$DG$13, MATCH(AY11, $CW$7:$CW$13,0), MATCH(BB$6, $CX$6:$DG$6, 0)) -> 0.016069374 | BC14: =INDEX($CX$7:$DG$13, MATCH(AY11, $CW$7:$CW$13,0), MATCH(BC$6, $CX$6:$DG$6, 0)) -> 0.017601949 | BD14: =INDEX($CX$7:$DG$13, MATCH(AY11, $CW$7:$CW$13,0), MATCH(BD$6, $CX$6:$DG$6, 0)) -> 0.018449083 | BE14: =INDEX($CX$7:$DG$13, MATCH(AY11, $CW$7:$CW$13,0), MATCH(BE$6, $CX$6:$DG$6, 0)) -> 0.022089778 | BF14: =INDEX($CX$7:$DG$13, MATCH(AY11, $CW$7:$CW$13,0), MATCH(BF$6, $CX$6:$DG$6, 0)) -> 0.022162555 | BG14: =INDEX($CX$7:$DG$13, MATCH(AY11, $CW$7:$CW$13,0), MATCH(BG$6, $CX$6:$DG$6, 0)) -> 0.024474606 | BH14: =INDEX($CX$7:$DG$13, MATCH(AY11, $CW$7:$CW$13,0), MATCH(BH$6, $CX$6:$DG$6, 0)) -> 0.02716085 | BI14: =INDEX($CX$7:$DG$13, MATCH(AY11, $CW$7:$CW$13,0), MATCH(BI$6, $CX$6:$DG$6, 0)) -> 0.031508848 | BJ14: =BI14/BI15 -> 0.57994539
AY15: Total Work At Home | AZ15: =SUM(AZ13:AZ14) -> 0.031489478 | BA15: =SUM(BA13:BA14) -> 0.03423657 | BB15: =SUM(BB13:BB14) -> 0.032300393 | BC15: =SUM(BC13:BC14) -> 0.033006032 | BD15: =SUM(BD13:BD14) -> 0.035722947 | BE15: =SUM(BE13:BE14) -> 0.041130466 | BF15: =SUM(BF13:BF14) -> 0.041244982 | BG15: =SUM(BG13:BG14) -> 0.046252189 | ... BI15: =SUM(BI13:BI14) -> 0.054330715 | EW15: 100.1 | EX15: Total Workers | FD15: Workers | FJ15: 700.1 | FK15: Worked at home | FQ15: Workers | FW15: 712.1 | FX15: Self-employed in own incorporated business workers | GD15: Workers | GJ15: 760.1 | GK15: Self-employed in own not incorporated business workers | GQ15: Workers
CJ16: County | CK16: 2010 | CL16: 2011 | CM16: 2012 | CN16: 2013 | CO16: 2014 | CP16: 2015 | CQ16: 2016 | CR16: 2017 | CS16: 2018 | CT16: 2019 | CW16: County | CX16: 2010 | CY16: 2011 | CZ16: 2012 | DA16: 2013 | DB16: 2014 | DC16: 2015 | DD16: 2016 | DE16: 2017 | DF16: 2018 | DG16: 2019 | DJ16: County | DK16: 2010 | DL16: 2011 | DM16: 2012 | DN16: 2013 | DO16: 2014 | DP16: 2015 | DQ16: 2016 | DR16: 2017 | DS16: 2018 | DT16: 2019 | DW16: County | DX16: 2010 | DY16: 2011 | DZ16: 2012 | EA16: 2013 | EB16: 2014 | EC16: 2015 | ED16: 2016 | EE16: 2017 | EF16: 2018 | EG16: 2019 | EJ16: County | EK16: 2010 | EL16: 2011 | EM16: 2012 | EN16: 2013 | EO16: 2014 | EP16: 2015 | EQ16: 2016 | ER16: 2017 | ES16: 2018 | ET16: 2019 | EX16: County | EY16: 2010 | EZ16: 2011 | FA16: 2012 | FB16: 2013 | FC16: 2014 | FD16: 2015 | FE16: 2016 | FF16: 2017 | FG16: 2018 | FH16: 2019 | FK16: County | FL16: 2010 | FM16: 2011 | FN16: 2012 | FO16: 2013 | FP16: 2014 | FQ16: 2015 | FR16: 2016 | FS16: 2017 | FT16: 2018 | FU16: 2019 | FX16: County | FY16: 2010 | FZ16: 2011 | GA16: 2012 | GB16: 2013 | GC16: 2014 | GD16: 2015 | GE16: 2016 | GF16: 2017 | GG16: 2018 | GH16: 2019 | GK16: County | GL16: 2010 | GM16: 2011 | GN16: 2012 | GO16: 2013 | GP16: 2014 | GQ16: 2015 | GR16: 2016 | GS16: 2017 | GT16: 2018 | GU16: 2019
AX17: 11 | AY17: Davis | CI17: 1 | CJ17: Beaver | CK17: =CX17 + DK17 -> 0.069719472 | CL17: =CY17 + DL17 -> 0.053738318 | CM17: =CZ17 + DM17 -> 0.034535687 | CN17: =DA17 + DN17 -> 0.033383346 | CO17: =DB17 + DO17 -> 0.025906736 | CP17: =DC17 + DP17 -> 0.01426087 | CQ17: =DD17 + DQ17 -> 0.020356234 | CR17: =DE17 + DR17 -> 0.034034417 | ... CT17: =DG17 + DT17 -> 0.059796916 | CV17: =$CI17*10 + 0 -> 10 | CW17: =$CJ17 -> Beaver | CX17: =IFERROR(DX17/EY17, 0) -> 0.029290429 | CY17: =IFERROR(DY17/EZ17, 0) -> 0.026869159 | CZ17: =IFERROR(DZ17/FA17, 0) -> 0.013814275 | DA17: =IFERROR(EA17/FB17, 0) -> 0.018379595 | DB17: =IFERROR(EB17/FC17, 0) -> 0.0077720207 | DC17: =IFERROR(EC17/FD17, 0) -> 0.0017391304 | DD17: =IFERROR(ED17/FE17, 0) -> 0.0010905125 | DE17: =IFERROR(EE17/FF17, 0) -> 0.014913958 | ... DG17: =IFERROR(EG17/FH17, 0) -> 0.025197443 | DI17: =$CI17*10 + 0 -> 10 | DJ17: =$CJ17 -> Beaver | DK17: =IFERROR(EK17/EY17, 0) -> 0.040429043 | DL17: =IFERROR(EL17/EZ17, 0) -> 0.026869159 | DM17: =IFERROR(EM17/FA17, 0) -> 0.020721412 | DN17: =IFERROR(EN17/FB17, 0) -> 0.015003751 | DO17: =IFERROR(EO17/FC17, 0) -> 0.018134715 | DP17: =IFERROR(EP17/FD17, 0) -> 0.012521739 | DQ17: =IFERROR(EQ17/FE17, 0) -> 0.019265722 | DR17: =IFERROR(ER17/FF17, 0) -> 0.019120459 | ... DT17: =IFERROR(ET17/FH17, 0) -> 0.034599473 | DV17: =$CI17*10 + 0 -> 10 | DW17: =$CJ17 -> Beaver | DX17: =FL17 - EK17 -> 71 | DY17: =FM17 - EL17 -> 69 | DZ17: =FN17 - EM17 -> 36 | EA17: =FO17 - EN17 -> 49 | EB17: =FP17 - EO17 -> 21 | EC17: =FQ17 - EP17 -> 5 | ED17: =FR17 - EQ17 -> 3 | EE17: =FS17 - ER17 -> 39 | ... EG17: =FU17 - ET17 -> 67 | EI17: =$CI17*10 + 0 -> 10 | EJ17: =$CJ17 -> Beaver | EK17: =FY17 + GL17 -> 98 | EL17: =FZ17 + GM17 -> 69 | EM17: =GA17 + GN17 -> 54 | EN17: =GB17 + GO17 -> 40 | EO17: =GC17 + GP17 -> 49 | EP17: =GD17 + GQ17 -> 36 | EQ17: =GE17 + GR17 -> 53 | ER17: =GF17 + GS17 -> 50 | ... ET17: =GH17 + GU17 -> 92 | EW17: 1 | EX17: Beaver | EY17: 2424 | EZ17: 2568 | FA17: 2606 | FB17: 2666 | FC17: 2702 | FD17: 2875 | FE17: 2751 | FF17: 2615 | FG17: 2692 | FH17: 2659 | FJ17: 1 | FK17: Beaver | FL17: 169 | FM17: 138 | FN17: 90 | FO17: 89 | FP17: 70 | FQ17: 41 | FR17: 56 | FS17: 89 | FT17: 108 | FU17: 159 | FW17: 1 | FX17: Beaver | FY17: 39 | FZ17: 13 | GA17: 12 | GB17: 0 | GC17: 12 | GD17: 12 | GE17: 14 | GF17: 15 | GG17: 35 | GH17: 22 | GJ17: 1 | GK17: Beaver | GL17: 59 | GM17: 56 | GN17: 42 | GO17: 40 | GP17: 37 | GQ17: 24 | GR17: 39 | GS17: 35 | GT17: 20 | GU17: 70
AZ18: 2010 | BA18: 2011 | BB18: 2012 | BC18: 2013 | BD18: 2014 | BE18: 2015 | BF18: 2016 | BG18: 2017 | BH18: 2018 | BI18: 2019 | CI18: 3 | CJ18: Box Elder | CK18: =CX18 + DK18 -> 0.050635961 | CL18: =CY18 + DL18 -> 0.049246374 | CM18: =CZ18 + DM18 -> 0.043755654 | CN18: =DA18 + DN18 -> 0.039484174 | CO18: =DB18 + DO18 -> 0.034524987 | CP18: =DC18 + DP18 -> 0.033645035 | CQ18: =DD18 + DQ18 -> 0.039750221 | CR18: =DE18 + DR18 -> 0.040007249 | ... CT18: =DG18 + DT18 -> 0.052917861 | CV18: =$CI18*10 + 0 -> 30 | CW18: =$CJ18 -> Box Elder | CX18: =IFERROR(DX18/EY18, 0) -> 0.014839083 | CY18: =IFERROR(DY18/EZ18, 0) -> 0.015119917 | CZ18: =IFERROR(DZ18/FA18, 0) -> 0.013331429 | DA18: =IFERROR(EA18/FB18, 0) -> 0.011395076 | DB18: =IFERROR(EB18/FC18, 0) -> 0.011257124 | DC18: =IFERROR(EC18/FD18, 0) -> 0.014473004 | DD18: =IFERROR(ED18/FE18, 0) -> 0.01700918 | DE18: =IFERROR(EE18/FF18, 0) -> 0.018032713 | ... DG18: =IFERROR(EG18/FH18, 0) -> 0.02863046 | DI18: =$CI18*10 + 0 -> 30 | DJ18: =$CJ18 -> Box Elder | DK18: =IFERROR(EK18/EY18, 0) -> 0.035796878 | DL18: =IFERROR(EL18/EZ18, 0) -> 0.034126457 | DM18: =IFERROR(EM18/FA18, 0) -> 0.030424225 | DN18: =IFERROR(EN18/FB18, 0) -> 0.028089097 | DO18: =IFERROR(EO18/FC18, 0) -> 0.023267863 | DP18: =IFERROR(EP18/FD18, 0) -> 0.019172031 | DQ18: =IFERROR(EQ18/FE18, 0) -> 0.022741041 | DR18: =IFERROR(ER18/FF18, 0) -> 0.021974537 | ... DT18: =IFERROR(ET18/FH18, 0) -> 0.024287401 | DV18: =$CI18*10 + 0 -> 30 | DW18: =$CJ18 -> Box Elder | DX18: =FL18 - EK18 -> 308 | DY18: =FM18 - EL18 -> 319 | DZ18: =FN18 - EM18 -> 280 | EA18: =FO18 - EN18 -> 243 | EB18: =FP18 - EO18 -> 239 | EC18: =FQ18 - EP18 -> 308 | ED18: =FR18 - EQ18 -> 365 | EE18: =FS18 - ER18 -> 398 | ... EG18: =FU18 - ET18 -> 679 | EI18: =$CI18*10 + 0 -> 30 | EJ18: =$CJ18 -> Box Elder | EK18: =FY18 + GL18 -> 743 | EL18: =FZ18 + GM18 -> 720 | EM18: =GA18 + GN18 -> 639 | EN18: =GB18 + GO18 -> 599 | EO18: =GC18 + GP18 -> 494 | EP18: =GD18 + GQ18 -> 408 | EQ18: =GE18 + GR18 -> 488 | ER18: =GF18 + GS18 -> 485 | ... ET18: =GH18 + GU18 -> 576 | EW18: 3 | EX18: Box Elder | EY18: 20756 | EZ18: 21098 | FA18: 21003 | FB18: 21325 | FC18: 21231 | FD18: 21281 | FE18: 21459 | FF18: 22071 | FG18: 22814 | FH18: 23716 | FJ18: 3 | FK18: Box Elder | FL18: 1051 | FM18: 1039 | FN18: 919 | FO18: 842 | FP18: 733 | FQ18: 716 | FR18: 853 | FS18: 883 | FT18: 1142 | FU18: 1255 | FW18: 3 | FX18: Box Elder | FY18: 165 | FZ18: 170 | GA18: 151 | GB18: 151 | GC18: 165 | GD18: 146 | GE18: 111 | GF18: 131 | GG18: 166 | GH18: 120 | GJ18: 3 | GK18: Box Elder | GL18: 578 | GM18: 550 | GN18: 488 | GO18: 448 | GP18: 329 | GQ18: 262 | GR18: 377 | GS18: 354 | GT18: 436 | GU18: 456
AY19: Home-Based-Job | AZ19: =INDEX($DK$7:$DT$13, MATCH(AY17, $DJ$7:$DJ$13,0), MATCH(AZ$6, $DK$6:$DT$6, 0)) -> 0.02394321 | BA19: =INDEX($DK$7:$DT$13, MATCH(AY17, $DJ$7:$DJ$13,0), MATCH(BA$6, $DK$6:$DT$6, 0)) -> 0.021674151 | BB19: =INDEX($DK$7:$DT$13, MATCH(AY17, $DJ$7:$DJ$13,0), MATCH(BB$6, $DK$6:$DT$6, 0)) -> 0.021495896 | BC19: =INDEX($DK$7:$DT$13, MATCH(AY17, $DJ$7:$DJ$13,0), MATCH(BC$6, $DK$6:$DT$6, 0)) -> 0.021443589 | BD19: =INDEX($DK$7:$DT$13, MATCH(AY17, $DJ$7:$DJ$13,0), MATCH(BD$6, $DK$6:$DT$6, 0)) -> 0.021136367 | BE19: =INDEX($DK$7:$DT$13, MATCH(AY17, $DJ$7:$DJ$13,0), MATCH(BE$6, $DK$6:$DT$6, 0)) -> 0.021146772 | BF19: =INDEX($DK$7:$DT$13, MATCH(AY17, $DJ$7:$DJ$13,0), MATCH(BF$6, $DK$6:$DT$6, 0)) -> 0.021408339 | BG19: =INDEX($DK$7:$DT$13, MATCH(AY17, $DJ$7:$DJ$13,0), MATCH(BG$6, $DK$6:$DT$6, 0)) -> 0.020739694 | BH19: =INDEX($DK$7:$DT$13, MATCH(AY17, $DJ$7:$DJ$13,0), MATCH(BH$6, $DK$6:$DT$6, 0)) -> 0.0227936 | BI19: =INDEX($DK$7:$DT$13, MATCH(AY17, $DJ$7:$DJ$13,0), MATCH(BI$6, $DK$6:$DT$6, 0)) -> 0.022409577 | BJ19: =BI19/BI21 -> 0.38073584 | CI19: 5 | CJ19: Cache | CK19: =CX19 + DK19 -> 0.053870467 | CL19: =CY19 + DL19 -> 0.045694404 | CM19: =CZ19 + DM19 -> 0.043328221 | CN19: =DA19 + DN19 -> 0.044274955 | CO19: =DB19 + DO19 -> 0.041536687 | CP19: =DC19 + DP19 -> 0.045870032 | CQ19: =DD19 + DQ19 -> 0.050949051 | CR19: =DE19 + DR19 -> 0.051726899 | ... CT19: =DG19 + DT19 -> 0.062955688 | CV19: =$CI19*10 + 0 -> 50 | CW19: =$CJ19 -> Cache | CX19: =IFERROR(DX19/EY19, 0) -> 0.027151187 | CY19: =IFERROR(DY19/EZ19, 0) -> 0.023059824 | CZ19: =IFERROR(DZ19/FA19, 0) -> 0.021587423 | DA19: =IFERROR(EA19/FB19, 0) -> 0.022175613 | DB19: =IFERROR(EB19/FC19, 0) -> 0.021269355 | DC19: =IFERROR(EC19/FD19, 0) -> 0.023036785 | DD19: =IFERROR(ED19/FE19, 0) -> 0.025211152 | DE19: =IFERROR(EE19/FF19, 0) -> 0.026157049 | ... DG19: =IFERROR(EG19/FH19, 0) -> 0.034557379 | DI19: =$CI19*10 + 0 -> 50 | DJ19: =$CJ19 -> Cache | DK19: =IFERROR(EK19/EY19, 0) -> 0.026719281 | DL19: =IFERROR(EL19/EZ19, 0) -> 0.02263458 | DM19: =IFERROR(EM19/FA19, 0) -> 0.021740798 | DN19: =IFERROR(EN19/FB19, 0) -> 0.022099342 | DO19: =IFERROR(EO19/FC19, 0) -> 0.020267332 | DP19: =IFERROR(EP19/FD19, 0) -> 0.022833247 | DQ19: =IFERROR(EQ19/FE19, 0) -> 0.025737898 | DR19: =IFERROR(ER19/FF19, 0) -> 0.02556985 | ... DT19: =IFERROR(ET19/FH19, 0) -> 0.028398309 | DV19: =$CI19*10 + 0 -> 50 | DW19: =$CJ19 -> Cache | DX19: =FL19 - EK19 -> 1383 | DY19: =FM19 - EL19 -> 1193 | DZ19: =FN19 - EM19 -> 1126 | EA19: =FO19 - EN19 -> 1163 | EB19: =FP19 - EO19 -> 1125 | EC19: =FQ19 - EP19 -> 1245 | ED19: =FR19 - EQ19 -> 1388 | EE19: =FS19 - ER19 -> 1470 | ... EG19: =FU19 - ET19 -> 2076 | EI19: =$CI19*10 + 0 -> 50 | EJ19: =$CJ19 -> Cache | EK19: =FY19 + GL19 -> 1361 | EL19: =FZ19 + GM19 -> 1171 | EM19: =GA19 + GN19 -> 1134 | EN19: =GB19 + GO19 -> 1159 | EO19: =GC19 + GP19 -> 1072 | EP19: =GD19 + GQ19 -> 1234 | EQ19: =GE19 + GR19 -> 1417 | ER19: =GF19 + GS19 -> 1437 | ... ET19: =GH19 + GU19 -> 1706 | EW19: 5 | EX19: Cache | EY19: 50937 | EZ19: 51735 | FA19: 52160 | FB19: 52445 | FC19: 52893 | FD19: 54044 | FE19: 55055 | FF19: 56199 | FG19: 58265 | FH19: 60074 | FJ19: 5 | FK19: Cache | FL19: 2744 | FM19: 2364 | FN19: 2260 | FO19: 2322 | FP19: 2197 | FQ19: 2479 | FR19: 2805 | FS19: 2907 | FT19: 3232 | FU19: 3782 | FW19: 5 | FX19: Cache | FY19: 375 | FZ19: 334 | GA19: 327 | GB19: 331 | GC19: 312 | GD19: 456 | GE19: 565 | GF19: 662 | GG19: 798 | GH19: 893 | GJ19: 5 | GK19: Cache | GL19: 986 | GM19: 837 | GN19: 807 | GO19: 828 | GP19: 760 | GQ19: 778 | GR19: 852 | GS19: 775 | GT19: 753 | GU19: 813
AY20: Telecommute | AZ20: =INDEX($CX$7:$DG$13, MATCH(AY17, $CW$7:$CW$13,0), MATCH(AZ$6, $CX$6:$DG$6, 0)) -> 0.020632471 | BA20: =INDEX($CX$7:$DG$13, MATCH(AY17, $CW$7:$CW$13,0), MATCH(BA$6, $CX$6:$DG$6, 0)) -> 0.025479704 | BB20: =INDEX($CX$7:$DG$13, MATCH(AY17, $CW$7:$CW$13,0), MATCH(BB$6, $CX$6:$DG$6, 0)) -> 0.023610364 | BC20: =INDEX($CX$7:$DG$13, MATCH(AY17, $CW$7:$CW$13,0), MATCH(BC$6, $CX$6:$DG$6, 0)) -> 0.025847373 | BD20: =INDEX($CX$7:$DG$13, MATCH(AY17, $CW$7:$CW$13,0), MATCH(BD$6, $CX$6:$DG$6, 0)) -> 0.028318695 | BE20: =INDEX($CX$7:$DG$13, MATCH(AY17, $CW$7:$CW$13,0), MATCH(BE$6, $CX$6:$DG$6, 0)) -> 0.031001316 | BF20: =INDEX($CX$7:$DG$13, MATCH(AY17, $CW$7:$CW$13,0), MATCH(BF$6, $CX$6:$DG$6, 0)) -> 0.03059087 | BG20: =INDEX($CX$7:$DG$13, MATCH(AY17, $CW$7:$CW$13,0), MATCH(BG$6, $CX$6:$DG$6, 0)) -> 0.034743804 | BH20: =INDEX($CX$7:$DG$13, MATCH(AY17, $CW$7:$CW$13,0), MATCH(BH$6, $CX$6:$DG$6, 0)) -> 0.035479773 | BI20: =INDEX($CX$7:$DG$13, MATCH(AY17, $CW$7:$CW$13,0), MATCH(BI$6, $CX$6:$DG$6, 0)) -> 0.036449019 | BJ20: =BI20/BI21 -> 0.61926416 | CI20: 7 | CJ20: Carbon | CK20: =CX20 + DK20 -> 0.034883721 | CL20: =CY20 + DL20 -> 0.026702115 | CM20: =CZ20 + DM20 -> 0.029777524 | CN20: =DA20 + DN20 -> 0.030474041 | CO20: =DB20 + DO20 -> 0.02980576 | CP20: =DC20 + DP20 -> 0.02583435 | CQ20: =DD20 + DQ20 -> 0.031452254 | CR20: =DE20 + DR20 -> 0.033025404 | ... CT20: =DG20 + DT20 -> 0.041319362 | CV20: =$CI20*10 + 0 -> 70 | CW20: =$CJ20 -> Carbon | CX20: =IFERROR(DX20/EY20, 0) -> 0.02 | CY20: =IFERROR(DY20/EZ20, 0) -> 0.014218009 | CZ20: =IFERROR(DZ20/FA20, 0) -> 0.014489447 | DA20: =IFERROR(EA20/FB20, 0) -> 0.017268623 | DB20: =IFERROR(EB20/FC20, 0) -> 0.014512168 | DC20: =IFERROR(EC20/FD20, 0) -> 0.013970507 | DD20: =IFERROR(ED20/FE20, 0) -> 0.019984104 | DE20: =IFERROR(EE20/FF20, 0) -> 0.019399538 | ... DG20: =IFERROR(EG20/FH20, 0) -> 0.015598952 | DI20: =$CI20*10 + 0 -> 70 | DJ20: =$CJ20 -> Carbon | DK20: =IFERROR(EK20/EY20, 0) -> 0.014883721 | DL20: =IFERROR(EL20/EZ20, 0) -> 0.012484106 | DM20: =IFERROR(EM20/FA20, 0) -> 0.015288078 | DN20: =IFERROR(EN20/FB20, 0) -> 0.013205418 | DO20: =IFERROR(EO20/FC20, 0) -> 0.015293592 | DP20: =IFERROR(EP20/FD20, 0) -> 0.011863843 | DQ20: =IFERROR(EQ20/FE20, 0) -> 0.01146815 | DR20: =IFERROR(ER20/FF20, 0) -> 0.013625866 | ... DT20: =IFERROR(ET20/FH20, 0) -> 0.02572041 | DV20: =$CI20*10 + 0 -> 70 | DW20: =$CJ20 -> Carbon | DX20: =FL20 - EK20 -> 172 | DY20: =FM20 - EL20 -> 123 | DZ20: =FN20 - EM20 -> 127 | EA20: =FO20 - EN20 -> 153 | EB20: =FP20 - EO20 -> 130 | EC20: =FQ20 - EP20 -> 126 | ED20: =FR20 - EQ20 -> 176 | EE20: =FS20 - ER20 -> 168 | ... EG20: =FU20 - ET20 -> 131 | EI20: =$CI20*10 + 0 -> 70 | EJ20: =$CJ20 -> Carbon | EK20: =FY20 + GL20 -> 128 | EL20: =FZ20 + GM20 -> 108 | EM20: =GA20 + GN20 -> 134 | EN20: =GB20 + GO20 -> 117 | EO20: =GC20 + GP20 -> 137 | EP20: =GD20 + GQ20 -> 107 | EQ20: =GE20 + GR20 -> 101 | ER20: =GF20 + GS20 -> 118 | ... ET20: =GH20 + GU20 -> 216 | EW20: 7 | EX20: Carbon | EY20: 8600 | EZ20: 8651 | FA20: 8765 | FB20: 8860 | FC20: 8958 | FD20: 9019 | FE20: 8807 | FF20: 8660 | FG20: 8581 | FH20: 8398 | FJ20: 7 | FK20: Carbon | FL20: 300 | FM20: 231 | FN20: 261 | FO20: 270 | FP20: 267 | FQ20: 233 | FR20: 277 | FS20: 286 | FT20: 376 | FU20: 347 | FW20: 7 | FX20: Carbon | FY20: 15 | FZ20: 2 | GA20: 10 | GB20: 6 | GC20: 21 | GD20: 21 | GE20: 25 | GF20: 41 | GG20: 109 | GH20: 92 | GJ20: 7 | GK20: Carbon | GL20: 113 | GM20: 106 | GN20: 124 | GO20: 111 | GP20: 116 | GQ20: 86 | GR20: 76 | GS20: 77 | GT20: 106 | GU20: 124
AY21: Total Work At Home | AZ21: =SUM(AZ19:AZ20) -> 0.044575681 | BA21: =SUM(BA19:BA20) -> 0.047153855 | BB21: =SUM(BB19:BB20) -> 0.045106261 | BC21: =SUM(BC19:BC20) -> 0.047290962 | BD21: =SUM(BD19:BD20) -> 0.049455062 | BE21: =SUM(BE19:BE20) -> 0.052148088 | BF21: =SUM(BF19:BF20) -> 0.05199921 | BG21: =SUM(BG19:BG20) -> 0.055483498 | ... BI21: =SUM(BI19:BI20) -> 0.058858596 | CI21: 9 | CJ21: Daggett | CK21: =CX21 + DK21 -> 0.092261905 | CL21: =CY21 + DL21 -> 0.10755814 | CM21: =CZ21 + DM21 -> 0.078066914 | CN21: =DA21 + DN21 -> 0.11864407 | CO21: =DB21 + DO21 -> 0.155 | CP21: =DC21 + DP21 -> 0.055813953 | CQ21: =DD21 + DQ21 -> 0.078853047 | CR21: =DE21 + DR21 -> 0.081272085 | ... CT21: =DG21 + DT21 -> 0.04290429 | CV21: =$CI21*10 + 0 -> 90 | CW21: =$CJ21 -> Daggett | CX21: =IFERROR(DX21/EY21, 0) -> 0 | CY21: =IFERROR(DY21/EZ21, 0) -> 0.014534884 | CZ21: =IFERROR(DZ21/FA21, 0) -> 0.011152416 | DA21: =IFERROR(EA21/FB21, 0) -> 0.0084745763 | DB21: =IFERROR(EB21/FC21, 0) -> 0.015 | DC21: =IFERROR(EC21/FD21, 0) -> 0.018604651 | DD21: =IFERROR(ED21/FE21, 0) -> 0.010752688 | DE21: =IFERROR(EE21/FF21, 0) -> 0.010600707 | ... DG21: =IFERROR(EG21/FH21, 0) -> 0 | DI21: =$CI21*10 + 0 -> 90 | DJ21: =$CJ21 -> Daggett | DK21: =IFERROR(EK21/EY21, 0) -> 0.092261905 | DL21: =IFERROR(EL21/EZ21, 0) -> 0.093023256 | DM21: =IFERROR(EM21/FA21, 0) -> 0.066914498 | DN21: =IFERROR(EN21/FB21, 0) -> 0.11016949 | DO21: =IFERROR(EO21/FC21, 0) -> 0.14 | DP21: =IFERROR(EP21/FD21, 0) -> 0.037209302 | DQ21: =IFERROR(EQ21/FE21, 0) -> 0.068100358 | DR21: =IFERROR(ER21/FF21, 0) -> 0.070671378 | ... DT21: =IFERROR(ET21/FH21, 0) -> 0.04290429 | DV21: =$CI21*10 + 0 -> 90 | DW21: =$CJ21 -> Daggett | DX21: =FL21 - EK21 -> 0 | DY21: =FM21 - EL21 -> 5 | DZ21: =FN21 - EM21 -> 3 | EA21: =FO21 - EN21 -> 2 | EB21: =FP21 - EO21 -> 3 | EC21: =FQ21 - EP21 -> 4 | ED21: =FR21 - EQ21 -> 3 | EE21: =FS21 - ER21 -> 3 | ... EG21: =FU21 - ET21 -> 0 | EI21: =$CI21*10 + 0 -> 90 | EJ21: =$CJ21 -> Daggett | EK21: =FY21 + GL21 -> 31 | EL21: =FZ21 + GM21 -> 32 | EM21: =GA21 + GN21 -> 18 | EN21: =GB21 + GO21 -> 26 | EO21: =GC21 + GP21 -> 28 | EP21: =GD21 + GQ21 -> 8 | EQ21: =GE21 + GR21 -> 19 | ER21: =GF21 + GS21 -> 20 | ... ET21: =GH21 + GU21 -> 13 | EW21: 9 | EX21: Daggett | EY21: 336 | EZ21: 344 | FA21: 269 | FB21: 236 | FC21: 200 | FD21: 215 | FE21: 279 | FF21: 283 | FG21: 250 | FH21: 303 | FJ21: 9 | FK21: Daggett | FL21: 31 | FM21: 37 | FN21: 21 | FO21: 28 | FP21: 31 | FQ21: 12 | FR21: 22 | FS21: 23 | FT21: 12 | FU21: 13 | FW21: 9 | FX21: Daggett | FY21: 31 | FZ21: 32 | GA21: 18 | GB21: 20 | GC21: 22 | GD21: 0 | GE21: 10 | GF21: 11 | GG21: 9 | GH21: 13 | GJ21: 9 | GK21: Daggett | GL21: 0 | GM21: 0 | GN21: 0 | GO21: 6 | GP21: 6 | GQ21: 8 | GR21: 9 | GS21: 9 | GT21: 0 | GU21: 0
CI22: 11 | CJ22: Davis | CK22: =CX22 + DK22 -> 0.044575681 | CL22: =CY22 + DL22 -> 0.047153855 | CM22: =CZ22 + DM22 -> 0.045106261 | CN22: =DA22 + DN22 -> 0.047290962 | CO22: =DB22 + DO22 -> 0.049455062 | CP22: =DC22 + DP22 -> 0.052148088 | CQ22: =DD22 + DQ22 -> 0.05199921 | CR22: =DE22 + DR22 -> 0.055483498 | ... CT22: =DG22 + DT22 -> 0.058858596 | CV22: =$CI22*10 + 0 -> 110 | CW22: =$CJ22 -> Davis | CX22: =IFERROR(DX22/EY22, 0) -> 0.020632471 | CY22: =IFERROR(DY22/EZ22, 0) -> 0.025479704 | CZ22: =IFERROR(DZ22/FA22, 0) -> 0.023610364 | DA22: =IFERROR(EA22/FB22, 0) -> 0.025847373 | DB22: =IFERROR(EB22/FC22, 0) -> 0.028318695 | DC22: =IFERROR(EC22/FD22, 0) -> 0.031001316 | DD22: =IFERROR(ED22/FE22, 0) -> 0.03059087 | DE22: =IFERROR(EE22/FF22, 0) -> 0.034743804 | ... DG22: =IFERROR(EG22/FH22, 0) -> 0.036449019 | DI22: =$CI22*10 + 0 -> 110 | DJ22: =$CJ22 -> Davis | DK22: =IFERROR(EK22/EY22, 0) -> 0.02394321 | DL22: =IFERROR(EL22/EZ22, 0) -> 0.021674151 | DM22: =IFERROR(EM22/FA22, 0) -> 0.021495896 | DN22: =IFERROR(EN22/FB22, 0) -> 0.021443589 | DO22: =IFERROR(EO22/FC22, 0) -> 0.021136367 | DP22: =IFERROR(EP22/FD22, 0) -> 0.021146772 | DQ22: =IFERROR(EQ22/FE22, 0) -> 0.021408339 | DR22: =IFERROR(ER22/FF22, 0) -> 0.020739694 | ... DT22: =IFERROR(ET22/FH22, 0) -> 0.022409577 | DV22: =$CI22*10 + 0 -> 110 | DW22: =$CJ22 -> Davis | DX22: =FL22 - EK22 -> 2767 | DY22: =FM22 - EL22 -> 3495 | DZ22: =FN22 - EM22 -> 3294 | EA22: =FO22 - EN22 -> 3639 | EB22: =FP22 - EO22 -> 4069 | EC22: =FQ22 - EP22 -> 4593 | ED22: =FR22 - EQ22 -> 4644 | EE22: =FS22 - ER22 -> 5411 | ... EG22: =FU22 - ET22 -> 5992 | EI22: =$CI22*10 + 0 -> 110 | EJ22: =$CJ22 -> Davis | EK22: =FY22 + GL22 -> 3211 | EL22: =FZ22 + GM22 -> 2973 | EM22: =GA22 + GN22 -> 2999 | EN22: =GB22 + GO22 -> 3019 | EO22: =GC22 + GP22 -> 3037 | EP22: =GD22 + GQ22 -> 3133 | EQ22: =GE22 + GR22 -> 3250 | ER22: =GF22 + GS22 -> 3230 | ... ET22: =GH22 + GU22 -> 3684 | EW22: 11 | EX22: Davis | EY22: 134109 | EZ22: 137168 | FA22: 139515 | FB22: 140788 | FC22: 143686 | FD22: 148155 | FE22: 151810 | FF22: 155740 | FG22: 158992 | FH22: 164394 | FJ22: 11 | FK22: Davis | FL22: 5978 | FM22: 6468 | FN22: 6293 | FO22: 6658 | FP22: 7106 | FQ22: 7726 | FR22: 7894 | FS22: 8641 | FT22: 9265 | FU22: 9676 | FW22: 11 | FX22: Davis | FY22: 879 | FZ22: 805 | GA22: 781 | GB22: 798 | GC22: 832 | GD22: 957 | GE22: 1053 | GF22: 1218 | GG22: 1423 | GH22: 1626 | GJ22: 11 | GK22: Davis | GL22: 2332 | GM22: 2168 | GN22: 2218 | GO22: 2221 | GP22: 2205 | GQ22: 2176 | GR22: 2197 | GS22: 2012 | GT22: 2201 | GU22: 2058
AX23: 35 | AY23: Salt Lake | CI23: 13 | CJ23: Duchesne | CK23: =CX23 + DK23 -> 0.050149594 | CL23: =CY23 + DL23 -> 0.046601406 | CM23: =CZ23 + DM23 -> 0.035044825 | CN23: =DA23 + DN23 -> 0.03659348 | CO23: =DB23 + DO23 -> 0.029887758 | CP23: =DC23 + DP23 -> 0.030806909 | CQ23: =DD23 + DQ23 -> 0.046913262 | CR23: =DE23 + DR23 -> 0.066683732 | ... CT23: =DG23 + DT23 -> 0.098852604 | CV23: =$CI23*10 + 0 -> 130 | CW23: =$CJ23 -> Duchesne | CX23: =IFERROR(DX23/EY23, 0) -> 0.02293774 | CY23: =IFERROR(DY23/EZ23, 0) -> 0.02040535 | CZ23: =IFERROR(DZ23/FA23, 0) -> 0.018065743 | DA23: =IFERROR(EA23/FB23, 0) -> 0.018895542 | DB23: =IFERROR(EB23/FC23, 0) -> 0.014748108 | DC23: =IFERROR(EC23/FD23, 0) -> 0.013663315 | DD23: =IFERROR(ED23/FE23, 0) -> 0.020621214 | DE23: =IFERROR(EE23/FF23, 0) -> 0.027902214 | ... DG23: =IFERROR(EG23/FH23, 0) -> 0.037952339 | DI23: =$CI23*10 + 0 -> 130 | DJ23: =$CJ23 -> Duchesne | DK23: =IFERROR(EK23/EY23, 0) -> 0.027211854 | DL23: =IFERROR(EL23/EZ23, 0) -> 0.026196057 | DM23: =IFERROR(EM23/FA23, 0) -> 0.016979082 | DN23: =IFERROR(EN23/FB23, 0) -> 0.017697937 | DO23: =IFERROR(EO23/FC23, 0) -> 0.01513965 | DP23: =IFERROR(EP23/FD23, 0) -> 0.017143594 | DQ23: =IFERROR(EQ23/FE23, 0) -> 0.026292048 | DR23: =IFERROR(ER23/FF23, 0) -> 0.038781518 | ... DT23: =IFERROR(ET23/FH23, 0) -> 0.060900265 | DV23: =$CI23*10 + 0 -> 130 | DW23: =$CJ23 -> Duchesne | DX23: =FL23 - EK23 -> 161 | DY23: =FM23 - EL23 -> 148 | DZ23: =FN23 - EM23 -> 133 | EA23: =FO23 - EN23 -> 142 | EB23: =FP23 - EO23 -> 113 | EC23: =FQ23 - EP23 -> 106 | ED23: =FR23 - EQ23 -> 160 | EE23: =FS23 - ER23 -> 218 | ... EG23: =FU23 - ET23 -> 301 | EI23: =$CI23*10 + 0 -> 130 | EJ23: =$CJ23 -> Duchesne | EK23: =FY23 + GL23 -> 191 | EL23: =FZ23 + GM23 -> 190 | EM23: =GA23 + GN23 -> 125 | EN23: =GB23 + GO23 -> 133 | EO23: =GC23 + GP23 -> 116 | EP23: =GD23 + GQ23 -> 133 | EQ23: =GE23 + GR23 -> 204 | ER23: =GF23 + GS23 -> 303 | ... ET23: =GH23 + GU23 -> 483 | EW23: 13 | EX23: Duchesne | EY23: 7019 | EZ23: 7253 | FA23: 7362 | FB23: 7515 | FC23: 7662 | FD23: 7758 | FE23: 7759 | FF23: 7813 | FG23: 7928 | FH23: 7931 | FJ23: 13 | FK23: Duchesne | FL23: 352 | FM23: 338 | FN23: 258 | FO23: 275 | FP23: 229 | FQ23: 239 | FR23: 364 | FS23: 521 | FT23: 675 | FU23: 784 | FW23: 13 | FX23: Duchesne | FY23: 37 | FZ23: 19 | GA23: 28 | GB23: 35 | GC23: 45 | GD23: 71 | GE23: 99 | GF23: 133 | GG23: 156 | GH23: 196 | GJ23: 13 | GK23: Duchesne | GL23: 154 | GM23: 171 | GN23: 97 | GO23: 98 | GP23: 71 | GQ23: 62 | GR23: 105 | GS23: 170 | GT23: 235 | GU23: 287
